Workbook

Sheet Summary
A1: The Council — AI Post-Deployment Monitoring & Review Log
A2: AIG-OPS-02 · v1.6 draft · Draft for Council review · OFFICIAL · Playbook §3.10.5, §6.4
A3: Purpose: create auditable evidence that each live AI system is monitored against its approved metrics and thresholds. One row records one metric or review result against the permanent AIR-ID. Threshold breaches and material changes require documented consideration of risk reassessment and governance escalation.
A4: Status statement: draft design. No monitoring is yet operating; thresholds, owners and cadences are set per system on adoption. This log is a controlled evidence record, not a reporting summary; portfolio reporting draws from it via the Dashboard (AIG-OPS-06).
A6: Document control | B6: Controlled value
A7: Document ID | B7: AIG-OPS-02
A8: Version | B8: 1.6 draft
A9: Status | B9: Draft for Council review
A10: Document owner | B10: AI Governance Lead; Service Owners operate the monitoring record for their systems
A11: Approving authority | B11: Relevant delegated Council authority adopts the controlled template; AI Assurance Board provides assurance, not approval of individual deployments
A12: Effective date | B12: Pending formal approval
A13: Review frequency | B13: On material change and at each management review (9.3); scheduled portfolio review otherwise
A14: Links to | B14: AI Register (AIG-INV-04) via AIR-ID; Incident Report (AIG-OPS-03); Nonconformity & Corrective Action (AIG-AIMS-08); Gate Log (AIG-DEC-04)
A15: Source position | B15: Playbook §3.10.5 governance review and reassessment; §6.4 AI performance monitoring
A16: Classification | B16: OFFICIAL
A18: Version / date | B18: Change
... A25: 1.6 draft — 30 September 2026 | B25: v3.9.2: Monitoring Log columns AO “Review type (§6.4.4: operational / performance / formal)” and AP “Agentic cadence raise applied? (action-capable uses)” added with controlled lists. The derived cadence (AJ) and the closure check (AH) now apply the Playbook §6.4.4 minimum for the review type (for example Medium: operational monthly, performance quarterly, formal annual; High: operational continuous, performance monthly, formal quarterly), require the review type, and flag an action-capable use whose agentic raise is not yet set (the size of the raise is a Council decision). Continuous monitoring is logged at least monthly. Sampling Method cites §6.4.4 (scenario finding W-08). Follow-up from the v3.9.2 re-test (NEW-02): AP is required on every row; the log identifies an action-capable use only from AP, so a blank AP shows the same flag as “Action-capable: raise not yet set” (choose “Not action-capable” where the use cannot act). Proposed — for Council confirmation.

Sheet Monitoring Log
A1: The Council — AI Post-Deployment Monitoring & Review Log
A2: AIG-OPS-02 | Controlled monitoring evidence. Record a UC-ID for use-specific measures (scope ‘UC-ID specific’); mark a blank UC-ID explicitly as ‘Shared system baseline’. Shared monitoring is not evidence that every use is approved. The example row is on the Instructions sheet.
A4: AIR-ID | B4: AI System / Service | C4: Monitoring Period | D4: Review Date | E4: Monitoring Owner | F4: Metric Category | G4: Metric / Indicator | H4: Approved Threshold / Tolerance | I4: Actual Result | J4: Trend | K4: Threshold Breach? | L4: Severity | M4: Action / Decision | N4: Action Owner | O4: Due Date | P4: Incident / CAPA Ref | Q4: Material Change? | R4: Risk Reassessment Required? | S4: Residual Risk After Review | T4: Governance Escalation? | U4: AIG-DEC-04 Event ID (Gate Log ref) | V4: Complaints / Challenges | W4: Human Override Rate / Trend | X4: Evidence Location | Y4: Next Review Date | Z4: Review Status | AA4: Sample Source / Population of Record | AB4: Selection Basis | AC4: Population Size | AD4: Sample Size Reviewed | AE4: Sampling Window | AF4: UC-ID (blank only for an explicitly shared system measure) | AG4: Measure scope (UC-ID specific / Shared system baseline) | AH4: Closure and evidence check | AI4: Risk tier (UC-ID, AIG-ASS-02) | AJ4: Required minimum cadence (derived) | AK4: Minimum sample (derived) | AL4: Reassessment trigger (Appendix E.4) | AM4: Reassessment / consideration ref (AIG-ASS-02) | AN4: AIG-DEC-04 Condition ID (if monitoring a condition) | AO4: Review type (§6.4.4: operational / performance / formal) | AP4: Agentic cadence raise applied? (action-capable uses)
AH5: =IF(COUNTA(A5:AG5,AI5,AL5:AP5)=0,"",IF(TRIM(A5)="","AIR-ID REQUIRED",IF(OR(AND(K5<>"",ISNA(MATCH(K5,{"Yes","No","Unknown"},0))),AND(Q5<>"",ISNA(MATCH(Q5,{"Yes","No","Unknown"},0))),AND(R5<>"",ISNA(MATCH(R5,{"Yes","No","Unknown"},0))),AND(T5<>"",ISNA(MATCH(T5,{"Yes","No","Unknown"},0))),AND(J5<>"",ISNA(MATCH(J5,{"Improving","Stable","Deteriorating","New / Baseline","Not yet known"},0))),AND(Z5<>"",ISNA(MATCH(Z5,{"Open","Reviewed","Action Open","Escalated","Closed"},0))),AND(AG5<>"",ISNA(MATCH(AG5,{"UC-ID specific","Shared system baseline"},0))),AND(AI5<>"",ISNA(MATCH(AI5,{"Low","Medium","High","Critical"},0))),AND(AL5<>"",COUNTIF(Lists!$A$3:$A$10,AL5)=0),AND(AO5<>"",ISNA(MATCH(AO5,{"Operational monitoring","Performance review","Formal review"},0))),AND(AP5<>"",ISNA(MATCH(AP5,{"Raised per Monitoring and Review Plan","Not action-capable","Action-capable: raise not yet set"},0)))),"INVALID VALUE — use the dropdown list",IF(AND(AG5="UC-ID specific",OR(AF5="",AF5="None")),"UC-ID REQUIRED",IF(OR(J5="",K5="",Q5="",R5="",T5="",AL5="",J5="Not yet known",K5="Unknown",Q5="Unknown",R5="Unknown",T5="Unknown"),"UNKNOWN TO RESOLVE",IF(AND(K5="Yes",OR(H5="",I5="",M5="",N5="",O5="",P5="",P5="None",X5="")),"BREACH ACTION INCOMPLETE",IF(AND(OR(K5="Yes",Q5="Yes"),AL5="None"),"TRIGGER NOT RECORDED — select the E.4 trigger",IF(AND(OR(AND(AL5<>"",AL5<>"None"),R5="Yes"),AM5=""),"REASSESSMENT / CONSIDERATION REF REQUIRED",IF(AND(OR(R5="Yes",T5="Yes"),U5=""),"GATE LOG EVENT ID REQUIRED",IF(OR(AND(D5<>"",NOT(ISNUMBER(D5))),AND(Y5<>"",NOT(ISNUMBER(Y5))),AND(ISNUMBER(D5),ISNUMBER(Y5),Y5<=D5)),"DATE CHECK — Review and Next Review must be dates, Next after Review",IF(AND(ISNUMBER(AC5),ISNUMBER(AD5),AD5>AC5),"SAMPLE EXCEEDS POPULATION",IF(AND(ISNUMBER(AD5),ISNUMBER(AK5),AD5<AK5),"SAMPLE BELOW TIER MINIMUM",IF(AND(AI5<>"",ISNUMBER(Y5),AO5=""),"REVIEW TYPE REQUIRED: operational, performance or formal (§6.4.4)",IF(AND(ISNUMBER(D5),ISNUMBER(Y5),AI5<>"",Y5-D5>IF(AI5="Critical",31,IF(AI5="High",IF(OR(AO5="Operational monitoring",AO5="Performance review"),31,92),IF(AI5="Medium",IF(AO5="Operational monitoring",31,IF(AO5="Performance review",92,366)),366)))),"NEXT REVIEW EXCEEDS TIER CADENCE",IF(OR(AP5="",AP5="Action-capable: raise not yet set"),"AGENTIC CADENCE RAISE NOT SET (§6.4.4; size to be set by the Council)",IF(AND(Z5="Closed",OR(D5="",E5="",G5="",H5="",I5="",X5="",Y5="",AA5="",AB5="",NOT(ISNUMBER(AC5)),NOT(ISNUMBER(AD5)),AC5<1,AD5<1,AE5="",AG5="",AI5="")),"CLOSURE EVIDENCE MISSING",IF(Z5="Closed","Closure ready for independent review","Open / review"))))))))))))))))) | AJ5: =IF(AI5="","",IF(AO5="Operational monitoring",IF(AI5="Low","Routine operational monitoring by the Service Owner",IF(AI5="Medium","Monthly","Continuous (logged at least monthly)")),IF(AO5="Performance review",IF(AI5="Critical","At least monthly",IF(AI5="High","Monthly",IF(AI5="Medium","Quarterly","Annual"))),IF(AI5="Critical","Continuous monitoring; formal review at least monthly",IF(AI5="High","Quarterly","Annual"))))) | AK5: =IF(OR(AI5="",NOT(ISNUMBER(AC5))),"",IF(OR(AI5="Critical",AI5="High"),MIN(AC5,MAX(30,ROUNDUP(0.05*AC5,0))),IF(AI5="Medium",MIN(AC5,20),MIN(AC5,10))))
AH6: =IF(COUNTA(A6:AG6,AI6,AL6:AP6)=0,"",IF(TRIM(A6)="","AIR-ID REQUIRED",IF(OR(AND(K6<>"",ISNA(MATCH(K6,{"Yes","No","Unknown"},0))),AND(Q6<>"",ISNA(MATCH(Q6,{"Yes","No","Unknown"},0))),AND(R6<>"",ISNA(MATCH(R6,{"Yes","No","Unknown"},0))),AND(T6<>"",ISNA(MATCH(T6,{"Yes","No","Unknown"},0))),AND(J6<>"",ISNA(MATCH(J6,{"Improving","Stable","Deteriorating","New / Baseline","Not yet known"},0))),AND(Z6<>"",ISNA(MATCH(Z6,{"Open","Reviewed","Action Open","Escalated","Closed"},0))),AND(AG6<>"",ISNA(MATCH(AG6,{"UC-ID specific","Shared system baseline"},0))),AND(AI6<>"",ISNA(MATCH(AI6,{"Low","Medium","High","Critical"},0))),AND(AL6<>"",COUNTIF(Lists!$A$3:$A$10,AL6)=0),AND(AO6<>"",ISNA(MATCH(AO6,{"Operational monitoring","Performance review","Formal review"},0))),AND(AP6<>"",ISNA(MATCH(AP6,{"Raised per Monitoring and Review Plan","Not action-capable","Action-capable: raise not yet set"},0)))),"INVALID VALUE — use the dropdown list",IF(AND(AG6="UC-ID specific",OR(AF6="",AF6="None")),"UC-ID REQUIRED",IF(OR(J6="",K6="",Q6="",R6="",T6="",AL6="",J6="Not yet known",K6="Unknown",Q6="Unknown",R6="Unknown",T6="Unknown"),"UNKNOWN TO RESOLVE",IF(AND(K6="Yes",OR(H6="",I6="",M6="",N6="",O6="",P6="",P6="None",X6="")),"BREACH ACTION INCOMPLETE",IF(AND(OR(K6="Yes",Q6="Yes"),AL6="None"),"TRIGGER NOT RECORDED — select the E.4 trigger",IF(AND(OR(AND(AL6<>"",AL6<>"None"),R6="Yes"),AM6=""),"REASSESSMENT / CONSIDERATION REF REQUIRED",IF(AND(OR(R6="Yes",T6="Yes"),U6=""),"GATE LOG EVENT ID REQUIRED",IF(OR(AND(D6<>"",NOT(ISNUMBER(D6))),AND(Y6<>"",NOT(ISNUMBER(Y6))),AND(ISNUMBER(D6),ISNUMBER(Y6),Y6<=D6)),"DATE CHECK — Review and Next Review must be dates, Next after Review",IF(AND(ISNUMBER(AC6),ISNUMBER(AD6),AD6>AC6),"SAMPLE EXCEEDS POPULATION",IF(AND(ISNUMBER(AD6),ISNUMBER(AK6),AD6<AK6),"SAMPLE BELOW TIER MINIMUM",IF(AND(AI6<>"",ISNUMBER(Y6),AO6=""),"REVIEW TYPE REQUIRED: operational, performance or formal (§6.4.4)",IF(AND(ISNUMBER(D6),ISNUMBER(Y6),AI6<>"",Y6-D6>IF(AI6="Critical",31,IF(AI6="High",IF(OR(AO6="Operational monitoring",AO6="Performance review"),31,92),IF(AI6="Medium",IF(AO6="Operational monitoring",31,IF(AO6="Performance review",92,366)),366)))),"NEXT REVIEW EXCEEDS TIER CADENCE",IF(OR(AP6="",AP6="Action-capable: raise not yet set"),"AGENTIC CADENCE RAISE NOT SET (§6.4.4; size to be set by the Council)",IF(AND(Z6="Closed",OR(D6="",E6="",G6="",H6="",I6="",X6="",Y6="",AA6="",AB6="",NOT(ISNUMBER(AC6)),NOT(ISNUMBER(AD6)),AC6<1,AD6<1,AE6="",AG6="",AI6="")),"CLOSURE EVIDENCE MISSING",IF(Z6="Closed","Closure ready for independent review","Open / review"))))))))))))))))) | AJ6: =IF(AI6="","",IF(AO6="Operational monitoring",IF(AI6="Low","Routine operational monitoring by the Service Owner",IF(AI6="Medium","Monthly","Continuous (logged at least monthly)")),IF(AO6="Performance review",IF(AI6="Critical","At least monthly",IF(AI6="High","Monthly",IF(AI6="Medium","Quarterly","Annual"))),IF(AI6="Critical","Continuous monitoring; formal review at least monthly",IF(AI6="High","Quarterly","Annual"))))) | AK6: =IF(OR(AI6="",NOT(ISNUMBER(AC6))),"",IF(OR(AI6="Critical",AI6="High"),MIN(AC6,MAX(30,ROUNDUP(0.05*AC6,0))),IF(AI6="Medium",MIN(AC6,20),MIN(AC6,10))))
AH7: =IF(COUNTA(A7:AG7,AI7,AL7:AP7)=0,"",IF(TRIM(A7)="","AIR-ID REQUIRED",IF(OR(AND(K7<>"",ISNA(MATCH(K7,{"Yes","No","Unknown"},0))),AND(Q7<>"",ISNA(MATCH(Q7,{"Yes","No","Unknown"},0))),AND(R7<>"",ISNA(MATCH(R7,{"Yes","No","Unknown"},0))),AND(T7<>"",ISNA(MATCH(T7,{"Yes","No","Unknown"},0))),AND(J7<>"",ISNA(MATCH(J7,{"Improving","Stable","Deteriorating","New / Baseline","Not yet known"},0))),AND(Z7<>"",ISNA(MATCH(Z7,{"Open","Reviewed","Action Open","Escalated","Closed"},0))),AND(AG7<>"",ISNA(MATCH(AG7,{"UC-ID specific","Shared system baseline"},0))),AND(AI7<>"",ISNA(MATCH(AI7,{"Low","Medium","High","Critical"},0))),AND(AL7<>"",COUNTIF(Lists!$A$3:$A$10,AL7)=0),AND(AO7<>"",ISNA(MATCH(AO7,{"Operational monitoring","Performance review","Formal review"},0))),AND(AP7<>"",ISNA(MATCH(AP7,{"Raised per Monitoring and Review Plan","Not action-capable","Action-capable: raise not yet set"},0)))),"INVALID VALUE — use the dropdown list",IF(AND(AG7="UC-ID specific",OR(AF7="",AF7="None")),"UC-ID REQUIRED",IF(OR(J7="",K7="",Q7="",R7="",T7="",AL7="",J7="Not yet known",K7="Unknown",Q7="Unknown",R7="Unknown",T7="Unknown"),"UNKNOWN TO RESOLVE",IF(AND(K7="Yes",OR(H7="",I7="",M7="",N7="",O7="",P7="",P7="None",X7="")),"BREACH ACTION INCOMPLETE",IF(AND(OR(K7="Yes",Q7="Yes"),AL7="None"),"TRIGGER NOT RECORDED — select the E.4 trigger",IF(AND(OR(AND(AL7<>"",AL7<>"None"),R7="Yes"),AM7=""),"REASSESSMENT / CONSIDERATION REF REQUIRED",IF(AND(OR(R7="Yes",T7="Yes"),U7=""),"GATE LOG EVENT ID REQUIRED",IF(OR(AND(D7<>"",NOT(ISNUMBER(D7))),AND(Y7<>"",NOT(ISNUMBER(Y7))),AND(ISNUMBER(D7),ISNUMBER(Y7),Y7<=D7)),"DATE CHECK — Review and Next Review must be dates, Next after Review",IF(AND(ISNUMBER(AC7),ISNUMBER(AD7),AD7>AC7),"SAMPLE EXCEEDS POPULATION",IF(AND(ISNUMBER(AD7),ISNUMBER(AK7),AD7<AK7),"SAMPLE BELOW TIER MINIMUM",IF(AND(AI7<>"",ISNUMBER(Y7),AO7=""),"REVIEW TYPE REQUIRED: operational, performance or formal (§6.4.4)",IF(AND(ISNUMBER(D7),ISNUMBER(Y7),AI7<>"",Y7-D7>IF(AI7="Critical",31,IF(AI7="High",IF(OR(AO7="Operational monitoring",AO7="Performance review"),31,92),IF(AI7="Medium",IF(AO7="Operational monitoring",31,IF(AO7="Performance review",92,366)),366)))),"NEXT REVIEW EXCEEDS TIER CADENCE",IF(OR(AP7="",AP7="Action-capable: raise not yet set"),"AGENTIC CADENCE RAISE NOT SET (§6.4.4; size to be set by the Council)",IF(AND(Z7="Closed",OR(D7="",E7="",G7="",H7="",I7="",X7="",Y7="",AA7="",AB7="",NOT(ISNUMBER(AC7)),NOT(ISNUMBER(AD7)),AC7<1,AD7<1,AE7="",AG7="",AI7="")),"CLOSURE EVIDENCE MISSING",IF(Z7="Closed","Closure ready for independent review","Open / review"))))))))))))))))) | AJ7: =IF(AI7="","",IF(AO7="Operational monitoring",IF(AI7="Low","Routine operational monitoring by the Service Owner",IF(AI7="Medium","Monthly","Continuous (logged at least monthly)")),IF(AO7="Performance review",IF(AI7="Critical","At least monthly",IF(AI7="High","Monthly",IF(AI7="Medium","Quarterly","Annual"))),IF(AI7="Critical","Continuous monitoring; formal review at least monthly",IF(AI7="High","Quarterly","Annual"))))) | AK7: =IF(OR(AI7="",NOT(ISNUMBER(AC7))),"",IF(OR(AI7="Critical",AI7="High"),MIN(AC7,MAX(30,ROUNDUP(0.05*AC7,0))),IF(AI7="Medium",MIN(AC7,20),MIN(AC7,10))))
AH8: =IF(COUNTA(A8:AG8,AI8,AL8:AP8)=0,"",IF(TRIM(A8)="","AIR-ID REQUIRED",IF(OR(AND(K8<>"",ISNA(MATCH(K8,{"Yes","No","Unknown"},0))),AND(Q8<>"",ISNA(MATCH(Q8,{"Yes","No","Unknown"},0))),AND(R8<>"",ISNA(MATCH(R8,{"Yes","No","Unknown"},0))),AND(T8<>"",ISNA(MATCH(T8,{"Yes","No","Unknown"},0))),AND(J8<>"",ISNA(MATCH(J8,{"Improving","Stable","Deteriorating","New / Baseline","Not yet known"},0))),AND(Z8<>"",ISNA(MATCH(Z8,{"Open","Reviewed","Action Open","Escalated","Closed"},0))),AND(AG8<>"",ISNA(MATCH(AG8,{"UC-ID specific","Shared system baseline"},0))),AND(AI8<>"",ISNA(MATCH(AI8,{"Low","Medium","High","Critical"},0))),AND(AL8<>"",COUNTIF(Lists!$A$3:$A$10,AL8)=0),AND(AO8<>"",ISNA(MATCH(AO8,{"Operational monitoring","Performance review","Formal review"},0))),AND(AP8<>"",ISNA(MATCH(AP8,{"Raised per Monitoring and Review Plan","Not action-capable","Action-capable: raise not yet set"},0)))),"INVALID VALUE — use the dropdown list",IF(AND(AG8="UC-ID specific",OR(AF8="",AF8="None")),"UC-ID REQUIRED",IF(OR(J8="",K8="",Q8="",R8="",T8="",AL8="",J8="Not yet known",K8="Unknown",Q8="Unknown",R8="Unknown",T8="Unknown"),"UNKNOWN TO RESOLVE",IF(AND(K8="Yes",OR(H8="",I8="",M8="",N8="",O8="",P8="",P8="None",X8="")),"BREACH ACTION INCOMPLETE",IF(AND(OR(K8="Yes",Q8="Yes"),AL8="None"),"TRIGGER NOT RECORDED — select the E.4 trigger",IF(AND(OR(AND(AL8<>"",AL8<>"None"),R8="Yes"),AM8=""),"REASSESSMENT / CONSIDERATION REF REQUIRED",IF(AND(OR(R8="Yes",T8="Yes"),U8=""),"GATE LOG EVENT ID REQUIRED",IF(OR(AND(D8<>"",NOT(ISNUMBER(D8))),AND(Y8<>"",NOT(ISNUMBER(Y8))),AND(ISNUMBER(D8),ISNUMBER(Y8),Y8<=D8)),"DATE CHECK — Review and Next Review must be dates, Next after Review",IF(AND(ISNUMBER(AC8),ISNUMBER(AD8),AD8>AC8),"SAMPLE EXCEEDS POPULATION",IF(AND(ISNUMBER(AD8),ISNUMBER(AK8),AD8<AK8),"SAMPLE BELOW TIER MINIMUM",IF(AND(AI8<>"",ISNUMBER(Y8),AO8=""),"REVIEW TYPE REQUIRED: operational, performance or formal (§6.4.4)",IF(AND(ISNUMBER(D8),ISNUMBER(Y8),AI8<>"",Y8-D8>IF(AI8="Critical",31,IF(AI8="High",IF(OR(AO8="Operational monitoring",AO8="Performance review"),31,92),IF(AI8="Medium",IF(AO8="Operational monitoring",31,IF(AO8="Performance review",92,366)),366)))),"NEXT REVIEW EXCEEDS TIER CADENCE",IF(OR(AP8="",AP8="Action-capable: raise not yet set"),"AGENTIC CADENCE RAISE NOT SET (§6.4.4; size to be set by the Council)",IF(AND(Z8="Closed",OR(D8="",E8="",G8="",H8="",I8="",X8="",Y8="",AA8="",AB8="",NOT(ISNUMBER(AC8)),NOT(ISNUMBER(AD8)),AC8<1,AD8<1,AE8="",AG8="",AI8="")),"CLOSURE EVIDENCE MISSING",IF(Z8="Closed","Closure ready for independent review","Open / review"))))))))))))))))) | AJ8: =IF(AI8="","",IF(AO8="Operational monitoring",IF(AI8="Low","Routine operational monitoring by the Service Owner",IF(AI8="Medium","Monthly","Continuous (logged at least monthly)")),IF(AO8="Performance review",IF(AI8="Critical","At least monthly",IF(AI8="High","Monthly",IF(AI8="Medium","Quarterly","Annual"))),IF(AI8="Critical","Continuous monitoring; formal review at least monthly",IF(AI8="High","Quarterly","Annual"))))) | AK8: =IF(OR(AI8="",NOT(ISNUMBER(AC8))),"",IF(OR(AI8="Critical",AI8="High"),MIN(AC8,MAX(30,ROUNDUP(0.05*AC8,0))),IF(AI8="Medium",MIN(AC8,20),MIN(AC8,10))))
AH9: =IF(COUNTA(A9:AG9,AI9,AL9:AP9)=0,"",IF(TRIM(A9)="","AIR-ID REQUIRED",IF(OR(AND(K9<>"",ISNA(MATCH(K9,{"Yes","No","Unknown"},0))),AND(Q9<>"",ISNA(MATCH(Q9,{"Yes","No","Unknown"},0))),AND(R9<>"",ISNA(MATCH(R9,{"Yes","No","Unknown"},0))),AND(T9<>"",ISNA(MATCH(T9,{"Yes","No","Unknown"},0))),AND(J9<>"",ISNA(MATCH(J9,{"Improving","Stable","Deteriorating","New / Baseline","Not yet known"},0))),AND(Z9<>"",ISNA(MATCH(Z9,{"Open","Reviewed","Action Open","Escalated","Closed"},0))),AND(AG9<>"",ISNA(MATCH(AG9,{"UC-ID specific","Shared system baseline"},0))),AND(AI9<>"",ISNA(MATCH(AI9,{"Low","Medium","High","Critical"},0))),AND(AL9<>"",COUNTIF(Lists!$A$3:$A$10,AL9)=0),AND(AO9<>"",ISNA(MATCH(AO9,{"Operational monitoring","Performance review","Formal review"},0))),AND(AP9<>"",ISNA(MATCH(AP9,{"Raised per Monitoring and Review Plan","Not action-capable","Action-capable: raise not yet set"},0)))),"INVALID VALUE — use the dropdown list",IF(AND(AG9="UC-ID specific",OR(AF9="",AF9="None")),"UC-ID REQUIRED",IF(OR(J9="",K9="",Q9="",R9="",T9="",AL9="",J9="Not yet known",K9="Unknown",Q9="Unknown",R9="Unknown",T9="Unknown"),"UNKNOWN TO RESOLVE",IF(AND(K9="Yes",OR(H9="",I9="",M9="",N9="",O9="",P9="",P9="None",X9="")),"BREACH ACTION INCOMPLETE",IF(AND(OR(K9="Yes",Q9="Yes"),AL9="None"),"TRIGGER NOT RECORDED — select the E.4 trigger",IF(AND(OR(AND(AL9<>"",AL9<>"None"),R9="Yes"),AM9=""),"REASSESSMENT / CONSIDERATION REF REQUIRED",IF(AND(OR(R9="Yes",T9="Yes"),U9=""),"GATE LOG EVENT ID REQUIRED",IF(OR(AND(D9<>"",NOT(ISNUMBER(D9))),AND(Y9<>"",NOT(ISNUMBER(Y9))),AND(ISNUMBER(D9),ISNUMBER(Y9),Y9<=D9)),"DATE CHECK — Review and Next Review must be dates, Next after Review",IF(AND(ISNUMBER(AC9),ISNUMBER(AD9),AD9>AC9),"SAMPLE EXCEEDS POPULATION",IF(AND(ISNUMBER(AD9),ISNUMBER(AK9),AD9<AK9),"SAMPLE BELOW TIER MINIMUM",IF(AND(AI9<>"",ISNUMBER(Y9),AO9=""),"REVIEW TYPE REQUIRED: operational, performance or formal (§6.4.4)",IF(AND(ISNUMBER(D9),ISNUMBER(Y9),AI9<>"",Y9-D9>IF(AI9="Critical",31,IF(AI9="High",IF(OR(AO9="Operational monitoring",AO9="Performance review"),31,92),IF(AI9="Medium",IF(AO9="Operational monitoring",31,IF(AO9="Performance review",92,366)),366)))),"NEXT REVIEW EXCEEDS TIER CADENCE",IF(OR(AP9="",AP9="Action-capable: raise not yet set"),"AGENTIC CADENCE RAISE NOT SET (§6.4.4; size to be set by the Council)",IF(AND(Z9="Closed",OR(D9="",E9="",G9="",H9="",I9="",X9="",Y9="",AA9="",AB9="",NOT(ISNUMBER(AC9)),NOT(ISNUMBER(AD9)),AC9<1,AD9<1,AE9="",AG9="",AI9="")),"CLOSURE EVIDENCE MISSING",IF(Z9="Closed","Closure ready for independent review","Open / review"))))))))))))))))) | AJ9: =IF(AI9="","",IF(AO9="Operational monitoring",IF(AI9="Low","Routine operational monitoring by the Service Owner",IF(AI9="Medium","Monthly","Continuous (logged at least monthly)")),IF(AO9="Performance review",IF(AI9="Critical","At least monthly",IF(AI9="High","Monthly",IF(AI9="Medium","Quarterly","Annual"))),IF(AI9="Critical","Continuous monitoring; formal review at least monthly",IF(AI9="High","Quarterly","Annual"))))) | AK9: =IF(OR(AI9="",NOT(ISNUMBER(AC9))),"",IF(OR(AI9="Critical",AI9="High"),MIN(AC9,MAX(30,ROUNDUP(0.05*AC9,0))),IF(AI9="Medium",MIN(AC9,20),MIN(AC9,10))))
AH10: =IF(COUNTA(A10:AG10,AI10,AL10:AP10)=0,"",IF(TRIM(A10)="","AIR-ID REQUIRED",IF(OR(AND(K10<>"",ISNA(MATCH(K10,{"Yes","No","Unknown"},0))),AND(Q10<>"",ISNA(MATCH(Q10,{"Yes","No","Unknown"},0))),AND(R10<>"",ISNA(MATCH(R10,{"Yes","No","Unknown"},0))),AND(T10<>"",ISNA(MATCH(T10,{"Yes","No","Unknown"},0))),AND(J10<>"",ISNA(MATCH(J10,{"Improving","Stable","Deteriorating","New / Baseline","Not yet known"},0))),AND(Z10<>"",ISNA(MATCH(Z10,{"Open","Reviewed","Action Open","Escalated","Closed"},0))),AND(AG10<>"",ISNA(MATCH(AG10,{"UC-ID specific","Shared system baseline"},0))),AND(AI10<>"",ISNA(MATCH(AI10,{"Low","Medium","High","Critical"},0))),AND(AL10<>"",COUNTIF(Lists!$A$3:$A$10,AL10)=0),AND(AO10<>"",ISNA(MATCH(AO10,{"Operational monitoring","Performance review","Formal review"},0))),AND(AP10<>"",ISNA(MATCH(AP10,{"Raised per Monitoring and Review Plan","Not action-capable","Action-capable: raise not yet set"},0)))),"INVALID VALUE — use the dropdown list",IF(AND(AG10="UC-ID specific",OR(AF10="",AF10="None")),"UC-ID REQUIRED",IF(OR(J10="",K10="",Q10="",R10="",T10="",AL10="",J10="Not yet known",K10="Unknown",Q10="Unknown",R10="Unknown",T10="Unknown"),"UNKNOWN TO RESOLVE",IF(AND(K10="Yes",OR(H10="",I10="",M10="",N10="",O10="",P10="",P10="None",X10="")),"BREACH ACTION INCOMPLETE",IF(AND(OR(K10="Yes",Q10="Yes"),AL10="None"),"TRIGGER NOT RECORDED — select the E.4 trigger",IF(AND(OR(AND(AL10<>"",AL10<>"None"),R10="Yes"),AM10=""),"REASSESSMENT / CONSIDERATION REF REQUIRED",IF(AND(OR(R10="Yes",T10="Yes"),U10=""),"GATE LOG EVENT ID REQUIRED",IF(OR(AND(D10<>"",NOT(ISNUMBER(D10))),AND(Y10<>"",NOT(ISNUMBER(Y10))),AND(ISNUMBER(D10),ISNUMBER(Y10),Y10<=D10)),"DATE CHECK — Review and Next Review must be dates, Next after Review",IF(AND(ISNUMBER(AC10),ISNUMBER(AD10),AD10>AC10),"SAMPLE EXCEEDS POPULATION",IF(AND(ISNUMBER(AD10),ISNUMBER(AK10),AD10<AK10),"SAMPLE BELOW TIER MINIMUM",IF(AND(AI10<>"",ISNUMBER(Y10),AO10=""),"REVIEW TYPE REQUIRED: operational, performance or formal (§6.4.4)",IF(AND(ISNUMBER(D10),ISNUMBER(Y10),AI10<>"",Y10-D10>IF(AI10="Critical",31,IF(AI10="High",IF(OR(AO10="Operational monitoring",AO10="Performance review"),31,92),IF(AI10="Medium",IF(AO10="Operational monitoring",31,IF(AO10="Performance review",92,366)),366)))),"NEXT REVIEW EXCEEDS TIER CADENCE",IF(OR(AP10="",AP10="Action-capable: raise not yet set"),"AGENTIC CADENCE RAISE NOT SET (§6.4.4; size to be set by the Council)",IF(AND(Z10="Closed",OR(D10="",E10="",G10="",H10="",I10="",X10="",Y10="",AA10="",AB10="",NOT(ISNUMBER(AC10)),NOT(ISNUMBER(AD10)),AC10<1,AD10<1,AE10="",AG10="",AI10="")),"CLOSURE EVIDENCE MISSING",IF(Z10="Closed","Closure ready for independent review","Open / review"))))))))))))))))) | AJ10: =IF(AI10="","",IF(AO10="Operational monitoring",IF(AI10="Low","Routine operational monitoring by the Service Owner",IF(AI10="Medium","Monthly","Continuous (logged at least monthly)")),IF(AO10="Performance review",IF(AI10="Critical","At least monthly",IF(AI10="High","Monthly",IF(AI10="Medium","Quarterly","Annual"))),IF(AI10="Critical","Continuous monitoring; formal review at least monthly",IF(AI10="High","Quarterly","Annual"))))) | AK10: =IF(OR(AI10="",NOT(ISNUMBER(AC10))),"",IF(OR(AI10="Critical",AI10="High"),MIN(AC10,MAX(30,ROUNDUP(0.05*AC10,0))),IF(AI10="Medium",MIN(AC10,20),MIN(AC10,10))))
AH11: =IF(COUNTA(A11:AG11,AI11,AL11:AP11)=0,"",IF(TRIM(A11)="","AIR-ID REQUIRED",IF(OR(AND(K11<>"",ISNA(MATCH(K11,{"Yes","No","Unknown"},0))),AND(Q11<>"",ISNA(MATCH(Q11,{"Yes","No","Unknown"},0))),AND(R11<>"",ISNA(MATCH(R11,{"Yes","No","Unknown"},0))),AND(T11<>"",ISNA(MATCH(T11,{"Yes","No","Unknown"},0))),AND(J11<>"",ISNA(MATCH(J11,{"Improving","Stable","Deteriorating","New / Baseline","Not yet known"},0))),AND(Z11<>"",ISNA(MATCH(Z11,{"Open","Reviewed","Action Open","Escalated","Closed"},0))),AND(AG11<>"",ISNA(MATCH(AG11,{"UC-ID specific","Shared system baseline"},0))),AND(AI11<>"",ISNA(MATCH(AI11,{"Low","Medium","High","Critical"},0))),AND(AL11<>"",COUNTIF(Lists!$A$3:$A$10,AL11)=0),AND(AO11<>"",ISNA(MATCH(AO11,{"Operational monitoring","Performance review","Formal review"},0))),AND(AP11<>"",ISNA(MATCH(AP11,{"Raised per Monitoring and Review Plan","Not action-capable","Action-capable: raise not yet set"},0)))),"INVALID VALUE — use the dropdown list",IF(AND(AG11="UC-ID specific",OR(AF11="",AF11="None")),"UC-ID REQUIRED",IF(OR(J11="",K11="",Q11="",R11="",T11="",AL11="",J11="Not yet known",K11="Unknown",Q11="Unknown",R11="Unknown",T11="Unknown"),"UNKNOWN TO RESOLVE",IF(AND(K11="Yes",OR(H11="",I11="",M11="",N11="",O11="",P11="",P11="None",X11="")),"BREACH ACTION INCOMPLETE",IF(AND(OR(K11="Yes",Q11="Yes"),AL11="None"),"TRIGGER NOT RECORDED — select the E.4 trigger",IF(AND(OR(AND(AL11<>"",AL11<>"None"),R11="Yes"),AM11=""),"REASSESSMENT / CONSIDERATION REF REQUIRED",IF(AND(OR(R11="Yes",T11="Yes"),U11=""),"GATE LOG EVENT ID REQUIRED",IF(OR(AND(D11<>"",NOT(ISNUMBER(D11))),AND(Y11<>"",NOT(ISNUMBER(Y11))),AND(ISNUMBER(D11),ISNUMBER(Y11),Y11<=D11)),"DATE CHECK — Review and Next Review must be dates, Next after Review",IF(AND(ISNUMBER(AC11),ISNUMBER(AD11),AD11>AC11),"SAMPLE EXCEEDS POPULATION",IF(AND(ISNUMBER(AD11),ISNUMBER(AK11),AD11<AK11),"SAMPLE BELOW TIER MINIMUM",IF(AND(AI11<>"",ISNUMBER(Y11),AO11=""),"REVIEW TYPE REQUIRED: operational, performance or formal (§6.4.4)",IF(AND(ISNUMBER(D11),ISNUMBER(Y11),AI11<>"",Y11-D11>IF(AI11="Critical",31,IF(AI11="High",IF(OR(AO11="Operational monitoring",AO11="Performance review"),31,92),IF(AI11="Medium",IF(AO11="Operational monitoring",31,IF(AO11="Performance review",92,366)),366)))),"NEXT REVIEW EXCEEDS TIER CADENCE",IF(OR(AP11="",AP11="Action-capable: raise not yet set"),"AGENTIC CADENCE RAISE NOT SET (§6.4.4; size to be set by the Council)",IF(AND(Z11="Closed",OR(D11="",E11="",G11="",H11="",I11="",X11="",Y11="",AA11="",AB11="",NOT(ISNUMBER(AC11)),NOT(ISNUMBER(AD11)),AC11<1,AD11<1,AE11="",AG11="",AI11="")),"CLOSURE EVIDENCE MISSING",IF(Z11="Closed","Closure ready for independent review","Open / review"))))))))))))))))) | AJ11: =IF(AI11="","",IF(AO11="Operational monitoring",IF(AI11="Low","Routine operational monitoring by the Service Owner",IF(AI11="Medium","Monthly","Continuous (logged at least monthly)")),IF(AO11="Performance review",IF(AI11="Critical","At least monthly",IF(AI11="High","Monthly",IF(AI11="Medium","Quarterly","Annual"))),IF(AI11="Critical","Continuous monitoring; formal review at least monthly",IF(AI11="High","Quarterly","Annual"))))) | AK11: =IF(OR(AI11="",NOT(ISNUMBER(AC11))),"",IF(OR(AI11="Critical",AI11="High"),MIN(AC11,MAX(30,ROUNDUP(0.05*AC11,0))),IF(AI11="Medium",MIN(AC11,20),MIN(AC11,10))))
AH12: =IF(COUNTA(A12:AG12,AI12,AL12:AP12)=0,"",IF(TRIM(A12)="","AIR-ID REQUIRED",IF(OR(AND(K12<>"",ISNA(MATCH(K12,{"Yes","No","Unknown"},0))),AND(Q12<>"",ISNA(MATCH(Q12,{"Yes","No","Unknown"},0))),AND(R12<>"",ISNA(MATCH(R12,{"Yes","No","Unknown"},0))),AND(T12<>"",ISNA(MATCH(T12,{"Yes","No","Unknown"},0))),AND(J12<>"",ISNA(MATCH(J12,{"Improving","Stable","Deteriorating","New / Baseline","Not yet known"},0))),AND(Z12<>"",ISNA(MATCH(Z12,{"Open","Reviewed","Action Open","Escalated","Closed"},0))),AND(AG12<>"",ISNA(MATCH(AG12,{"UC-ID specific","Shared system baseline"},0))),AND(AI12<>"",ISNA(MATCH(AI12,{"Low","Medium","High","Critical"},0))),AND(AL12<>"",COUNTIF(Lists!$A$3:$A$10,AL12)=0),AND(AO12<>"",ISNA(MATCH(AO12,{"Operational monitoring","Performance review","Formal review"},0))),AND(AP12<>"",ISNA(MATCH(AP12,{"Raised per Monitoring and Review Plan","Not action-capable","Action-capable: raise not yet set"},0)))),"INVALID VALUE — use the dropdown list",IF(AND(AG12="UC-ID specific",OR(AF12="",AF12="None")),"UC-ID REQUIRED",IF(OR(J12="",K12="",Q12="",R12="",T12="",AL12="",J12="Not yet known",K12="Unknown",Q12="Unknown",R12="Unknown",T12="Unknown"),"UNKNOWN TO RESOLVE",IF(AND(K12="Yes",OR(H12="",I12="",M12="",N12="",O12="",P12="",P12="None",X12="")),"BREACH ACTION INCOMPLETE",IF(AND(OR(K12="Yes",Q12="Yes"),AL12="None"),"TRIGGER NOT RECORDED — select the E.4 trigger",IF(AND(OR(AND(AL12<>"",AL12<>"None"),R12="Yes"),AM12=""),"REASSESSMENT / CONSIDERATION REF REQUIRED",IF(AND(OR(R12="Yes",T12="Yes"),U12=""),"GATE LOG EVENT ID REQUIRED",IF(OR(AND(D12<>"",NOT(ISNUMBER(D12))),AND(Y12<>"",NOT(ISNUMBER(Y12))),AND(ISNUMBER(D12),ISNUMBER(Y12),Y12<=D12)),"DATE CHECK — Review and Next Review must be dates, Next after Review",IF(AND(ISNUMBER(AC12),ISNUMBER(AD12),AD12>AC12),"SAMPLE EXCEEDS POPULATION",IF(AND(ISNUMBER(AD12),ISNUMBER(AK12),AD12<AK12),"SAMPLE BELOW TIER MINIMUM",IF(AND(AI12<>"",ISNUMBER(Y12),AO12=""),"REVIEW TYPE REQUIRED: operational, performance or formal (§6.4.4)",IF(AND(ISNUMBER(D12),ISNUMBER(Y12),AI12<>"",Y12-D12>IF(AI12="Critical",31,IF(AI12="High",IF(OR(AO12="Operational monitoring",AO12="Performance review"),31,92),IF(AI12="Medium",IF(AO12="Operational monitoring",31,IF(AO12="Performance review",92,366)),366)))),"NEXT REVIEW EXCEEDS TIER CADENCE",IF(OR(AP12="",AP12="Action-capable: raise not yet set"),"AGENTIC CADENCE RAISE NOT SET (§6.4.4; size to be set by the Council)",IF(AND(Z12="Closed",OR(D12="",E12="",G12="",H12="",I12="",X12="",Y12="",AA12="",AB12="",NOT(ISNUMBER(AC12)),NOT(ISNUMBER(AD12)),AC12<1,AD12<1,AE12="",AG12="",AI12="")),"CLOSURE EVIDENCE MISSING",IF(Z12="Closed","Closure ready for independent review","Open / review"))))))))))))))))) | AJ12: =IF(AI12="","",IF(AO12="Operational monitoring",IF(AI12="Low","Routine operational monitoring by the Service Owner",IF(AI12="Medium","Monthly","Continuous (logged at least monthly)")),IF(AO12="Performance review",IF(AI12="Critical","At least monthly",IF(AI12="High","Monthly",IF(AI12="Medium","Quarterly","Annual"))),IF(AI12="Critical","Continuous monitoring; formal review at least monthly",IF(AI12="High","Quarterly","Annual"))))) | AK12: =IF(OR(AI12="",NOT(ISNUMBER(AC12))),"",IF(OR(AI12="Critical",AI12="High"),MIN(AC12,MAX(30,ROUNDUP(0.05*AC12,0))),IF(AI12="Medium",MIN(AC12,20),MIN(AC12,10))))
AH13: =IF(COUNTA(A13:AG13,AI13,AL13:AP13)=0,"",IF(TRIM(A13)="","AIR-ID REQUIRED",IF(OR(AND(K13<>"",ISNA(MATCH(K13,{"Yes","No","Unknown"},0))),AND(Q13<>"",ISNA(MATCH(Q13,{"Yes","No","Unknown"},0))),AND(R13<>"",ISNA(MATCH(R13,{"Yes","No","Unknown"},0))),AND(T13<>"",ISNA(MATCH(T13,{"Yes","No","Unknown"},0))),AND(J13<>"",ISNA(MATCH(J13,{"Improving","Stable","Deteriorating","New / Baseline","Not yet known"},0))),AND(Z13<>"",ISNA(MATCH(Z13,{"Open","Reviewed","Action Open","Escalated","Closed"},0))),AND(AG13<>"",ISNA(MATCH(AG13,{"UC-ID specific","Shared system baseline"},0))),AND(AI13<>"",ISNA(MATCH(AI13,{"Low","Medium","High","Critical"},0))),AND(AL13<>"",COUNTIF(Lists!$A$3:$A$10,AL13)=0),AND(AO13<>"",ISNA(MATCH(AO13,{"Operational monitoring","Performance review","Formal review"},0))),AND(AP13<>"",ISNA(MATCH(AP13,{"Raised per Monitoring and Review Plan","Not action-capable","Action-capable: raise not yet set"},0)))),"INVALID VALUE — use the dropdown list",IF(AND(AG13="UC-ID specific",OR(AF13="",AF13="None")),"UC-ID REQUIRED",IF(OR(J13="",K13="",Q13="",R13="",T13="",AL13="",J13="Not yet known",K13="Unknown",Q13="Unknown",R13="Unknown",T13="Unknown"),"UNKNOWN TO RESOLVE",IF(AND(K13="Yes",OR(H13="",I13="",M13="",N13="",O13="",P13="",P13="None",X13="")),"BREACH ACTION INCOMPLETE",IF(AND(OR(K13="Yes",Q13="Yes"),AL13="None"),"TRIGGER NOT RECORDED — select the E.4 trigger",IF(AND(OR(AND(AL13<>"",AL13<>"None"),R13="Yes"),AM13=""),"REASSESSMENT / CONSIDERATION REF REQUIRED",IF(AND(OR(R13="Yes",T13="Yes"),U13=""),"GATE LOG EVENT ID REQUIRED",IF(OR(AND(D13<>"",NOT(ISNUMBER(D13))),AND(Y13<>"",NOT(ISNUMBER(Y13))),AND(ISNUMBER(D13),ISNUMBER(Y13),Y13<=D13)),"DATE CHECK — Review and Next Review must be dates, Next after Review",IF(AND(ISNUMBER(AC13),ISNUMBER(AD13),AD13>AC13),"SAMPLE EXCEEDS POPULATION",IF(AND(ISNUMBER(AD13),ISNUMBER(AK13),AD13<AK13),"SAMPLE BELOW TIER MINIMUM",IF(AND(AI13<>"",ISNUMBER(Y13),AO13=""),"REVIEW TYPE REQUIRED: operational, performance or formal (§6.4.4)",IF(AND(ISNUMBER(D13),ISNUMBER(Y13),AI13<>"",Y13-D13>IF(AI13="Critical",31,IF(AI13="High",IF(OR(AO13="Operational monitoring",AO13="Performance review"),31,92),IF(AI13="Medium",IF(AO13="Operational monitoring",31,IF(AO13="Performance review",92,366)),366)))),"NEXT REVIEW EXCEEDS TIER CADENCE",IF(OR(AP13="",AP13="Action-capable: raise not yet set"),"AGENTIC CADENCE RAISE NOT SET (§6.4.4; size to be set by the Council)",IF(AND(Z13="Closed",OR(D13="",E13="",G13="",H13="",I13="",X13="",Y13="",AA13="",AB13="",NOT(ISNUMBER(AC13)),NOT(ISNUMBER(AD13)),AC13<1,AD13<1,AE13="",AG13="",AI13="")),"CLOSURE EVIDENCE MISSING",IF(Z13="Closed","Closure ready for independent review","Open / review"))))))))))))))))) | AJ13: =IF(AI13="","",IF(AO13="Operational monitoring",IF(AI13="Low","Routine operational monitoring by the Service Owner",IF(AI13="Medium","Monthly","Continuous (logged at least monthly)")),IF(AO13="Performance review",IF(AI13="Critical","At least monthly",IF(AI13="High","Monthly",IF(AI13="Medium","Quarterly","Annual"))),IF(AI13="Critical","Continuous monitoring; formal review at least monthly",IF(AI13="High","Quarterly","Annual"))))) | AK13: =IF(OR(AI13="",NOT(ISNUMBER(AC13))),"",IF(OR(AI13="Critical",AI13="High"),MIN(AC13,MAX(30,ROUNDUP(0.05*AC13,0))),IF(AI13="Medium",MIN(AC13,20),MIN(AC13,10))))
AH14: =IF(COUNTA(A14:AG14,AI14,AL14:AP14)=0,"",IF(TRIM(A14)="","AIR-ID REQUIRED",IF(OR(AND(K14<>"",ISNA(MATCH(K14,{"Yes","No","Unknown"},0))),AND(Q14<>"",ISNA(MATCH(Q14,{"Yes","No","Unknown"},0))),AND(R14<>"",ISNA(MATCH(R14,{"Yes","No","Unknown"},0))),AND(T14<>"",ISNA(MATCH(T14,{"Yes","No","Unknown"},0))),AND(J14<>"",ISNA(MATCH(J14,{"Improving","Stable","Deteriorating","New / Baseline","Not yet known"},0))),AND(Z14<>"",ISNA(MATCH(Z14,{"Open","Reviewed","Action Open","Escalated","Closed"},0))),AND(AG14<>"",ISNA(MATCH(AG14,{"UC-ID specific","Shared system baseline"},0))),AND(AI14<>"",ISNA(MATCH(AI14,{"Low","Medium","High","Critical"},0))),AND(AL14<>"",COUNTIF(Lists!$A$3:$A$10,AL14)=0),AND(AO14<>"",ISNA(MATCH(AO14,{"Operational monitoring","Performance review","Formal review"},0))),AND(AP14<>"",ISNA(MATCH(AP14,{"Raised per Monitoring and Review Plan","Not action-capable","Action-capable: raise not yet set"},0)))),"INVALID VALUE — use the dropdown list",IF(AND(AG14="UC-ID specific",OR(AF14="",AF14="None")),"UC-ID REQUIRED",IF(OR(J14="",K14="",Q14="",R14="",T14="",AL14="",J14="Not yet known",K14="Unknown",Q14="Unknown",R14="Unknown",T14="Unknown"),"UNKNOWN TO RESOLVE",IF(AND(K14="Yes",OR(H14="",I14="",M14="",N14="",O14="",P14="",P14="None",X14="")),"BREACH ACTION INCOMPLETE",IF(AND(OR(K14="Yes",Q14="Yes"),AL14="None"),"TRIGGER NOT RECORDED — select the E.4 trigger",IF(AND(OR(AND(AL14<>"",AL14<>"None"),R14="Yes"),AM14=""),"REASSESSMENT / CONSIDERATION REF REQUIRED",IF(AND(OR(R14="Yes",T14="Yes"),U14=""),"GATE LOG EVENT ID REQUIRED",IF(OR(AND(D14<>"",NOT(ISNUMBER(D14))),AND(Y14<>"",NOT(ISNUMBER(Y14))),AND(ISNUMBER(D14),ISNUMBER(Y14),Y14<=D14)),"DATE CHECK — Review and Next Review must be dates, Next after Review",IF(AND(ISNUMBER(AC14),ISNUMBER(AD14),AD14>AC14),"SAMPLE EXCEEDS POPULATION",IF(AND(ISNUMBER(AD14),ISNUMBER(AK14),AD14<AK14),"SAMPLE BELOW TIER MINIMUM",IF(AND(AI14<>"",ISNUMBER(Y14),AO14=""),"REVIEW TYPE REQUIRED: operational, performance or formal (§6.4.4)",IF(AND(ISNUMBER(D14),ISNUMBER(Y14),AI14<>"",Y14-D14>IF(AI14="Critical",31,IF(AI14="High",IF(OR(AO14="Operational monitoring",AO14="Performance review"),31,92),IF(AI14="Medium",IF(AO14="Operational monitoring",31,IF(AO14="Performance review",92,366)),366)))),"NEXT REVIEW EXCEEDS TIER CADENCE",IF(OR(AP14="",AP14="Action-capable: raise not yet set"),"AGENTIC CADENCE RAISE NOT SET (§6.4.4; size to be set by the Council)",IF(AND(Z14="Closed",OR(D14="",E14="",G14="",H14="",I14="",X14="",Y14="",AA14="",AB14="",NOT(ISNUMBER(AC14)),NOT(ISNUMBER(AD14)),AC14<1,AD14<1,AE14="",AG14="",AI14="")),"CLOSURE EVIDENCE MISSING",IF(Z14="Closed","Closure ready for independent review","Open / review"))))))))))))))))) | AJ14: =IF(AI14="","",IF(AO14="Operational monitoring",IF(AI14="Low","Routine operational monitoring by the Service Owner",IF(AI14="Medium","Monthly","Continuous (logged at least monthly)")),IF(AO14="Performance review",IF(AI14="Critical","At least monthly",IF(AI14="High","Monthly",IF(AI14="Medium","Quarterly","Annual"))),IF(AI14="Critical","Continuous monitoring; formal review at least monthly",IF(AI14="High","Quarterly","Annual"))))) | AK14: =IF(OR(AI14="",NOT(ISNUMBER(AC14))),"",IF(OR(AI14="Critical",AI14="High"),MIN(AC14,MAX(30,ROUNDUP(0.05*AC14,0))),IF(AI14="Medium",MIN(AC14,20),MIN(AC14,10))))
AH15: =IF(COUNTA(A15:AG15,AI15,AL15:AP15)=0,"",IF(TRIM(A15)="","AIR-ID REQUIRED",IF(OR(AND(K15<>"",ISNA(MATCH(K15,{"Yes","No","Unknown"},0))),AND(Q15<>"",ISNA(MATCH(Q15,{"Yes","No","Unknown"},0))),AND(R15<>"",ISNA(MATCH(R15,{"Yes","No","Unknown"},0))),AND(T15<>"",ISNA(MATCH(T15,{"Yes","No","Unknown"},0))),AND(J15<>"",ISNA(MATCH(J15,{"Improving","Stable","Deteriorating","New / Baseline","Not yet known"},0))),AND(Z15<>"",ISNA(MATCH(Z15,{"Open","Reviewed","Action Open","Escalated","Closed"},0))),AND(AG15<>"",ISNA(MATCH(AG15,{"UC-ID specific","Shared system baseline"},0))),AND(AI15<>"",ISNA(MATCH(AI15,{"Low","Medium","High","Critical"},0))),AND(AL15<>"",COUNTIF(Lists!$A$3:$A$10,AL15)=0),AND(AO15<>"",ISNA(MATCH(AO15,{"Operational monitoring","Performance review","Formal review"},0))),AND(AP15<>"",ISNA(MATCH(AP15,{"Raised per Monitoring and Review Plan","Not action-capable","Action-capable: raise not yet set"},0)))),"INVALID VALUE — use the dropdown list",IF(AND(AG15="UC-ID specific",OR(AF15="",AF15="None")),"UC-ID REQUIRED",IF(OR(J15="",K15="",Q15="",R15="",T15="",AL15="",J15="Not yet known",K15="Unknown",Q15="Unknown",R15="Unknown",T15="Unknown"),"UNKNOWN TO RESOLVE",IF(AND(K15="Yes",OR(H15="",I15="",M15="",N15="",O15="",P15="",P15="None",X15="")),"BREACH ACTION INCOMPLETE",IF(AND(OR(K15="Yes",Q15="Yes"),AL15="None"),"TRIGGER NOT RECORDED — select the E.4 trigger",IF(AND(OR(AND(AL15<>"",AL15<>"None"),R15="Yes"),AM15=""),"REASSESSMENT / CONSIDERATION REF REQUIRED",IF(AND(OR(R15="Yes",T15="Yes"),U15=""),"GATE LOG EVENT ID REQUIRED",IF(OR(AND(D15<>"",NOT(ISNUMBER(D15))),AND(Y15<>"",NOT(ISNUMBER(Y15))),AND(ISNUMBER(D15),ISNUMBER(Y15),Y15<=D15)),"DATE CHECK — Review and Next Review must be dates, Next after Review",IF(AND(ISNUMBER(AC15),ISNUMBER(AD15),AD15>AC15),"SAMPLE EXCEEDS POPULATION",IF(AND(ISNUMBER(AD15),ISNUMBER(AK15),AD15<AK15),"SAMPLE BELOW TIER MINIMUM",IF(AND(AI15<>"",ISNUMBER(Y15),AO15=""),"REVIEW TYPE REQUIRED: operational, performance or formal (§6.4.4)",IF(AND(ISNUMBER(D15),ISNUMBER(Y15),AI15<>"",Y15-D15>IF(AI15="Critical",31,IF(AI15="High",IF(OR(AO15="Operational monitoring",AO15="Performance review"),31,92),IF(AI15="Medium",IF(AO15="Operational monitoring",31,IF(AO15="Performance review",92,366)),366)))),"NEXT REVIEW EXCEEDS TIER CADENCE",IF(OR(AP15="",AP15="Action-capable: raise not yet set"),"AGENTIC CADENCE RAISE NOT SET (§6.4.4; size to be set by the Council)",IF(AND(Z15="Closed",OR(D15="",E15="",G15="",H15="",I15="",X15="",Y15="",AA15="",AB15="",NOT(ISNUMBER(AC15)),NOT(ISNUMBER(AD15)),AC15<1,AD15<1,AE15="",AG15="",AI15="")),"CLOSURE EVIDENCE MISSING",IF(Z15="Closed","Closure ready for independent review","Open / review"))))))))))))))))) | AJ15: =IF(AI15="","",IF(AO15="Operational monitoring",IF(AI15="Low","Routine operational monitoring by the Service Owner",IF(AI15="Medium","Monthly","Continuous (logged at least monthly)")),IF(AO15="Performance review",IF(AI15="Critical","At least monthly",IF(AI15="High","Monthly",IF(AI15="Medium","Quarterly","Annual"))),IF(AI15="Critical","Continuous monitoring; formal review at least monthly",IF(AI15="High","Quarterly","Annual"))))) | AK15: =IF(OR(AI15="",NOT(ISNUMBER(AC15))),"",IF(OR(AI15="Critical",AI15="High"),MIN(AC15,MAX(30,ROUNDUP(0.05*AC15,0))),IF(AI15="Medium",MIN(AC15,20),MIN(AC15,10))))
AH16: =IF(COUNTA(A16:AG16,AI16,AL16:AP16)=0,"",IF(TRIM(A16)="","AIR-ID REQUIRED",IF(OR(AND(K16<>"",ISNA(MATCH(K16,{"Yes","No","Unknown"},0))),AND(Q16<>"",ISNA(MATCH(Q16,{"Yes","No","Unknown"},0))),AND(R16<>"",ISNA(MATCH(R16,{"Yes","No","Unknown"},0))),AND(T16<>"",ISNA(MATCH(T16,{"Yes","No","Unknown"},0))),AND(J16<>"",ISNA(MATCH(J16,{"Improving","Stable","Deteriorating","New / Baseline","Not yet known"},0))),AND(Z16<>"",ISNA(MATCH(Z16,{"Open","Reviewed","Action Open","Escalated","Closed"},0))),AND(AG16<>"",ISNA(MATCH(AG16,{"UC-ID specific","Shared system baseline"},0))),AND(AI16<>"",ISNA(MATCH(AI16,{"Low","Medium","High","Critical"},0))),AND(AL16<>"",COUNTIF(Lists!$A$3:$A$10,AL16)=0),AND(AO16<>"",ISNA(MATCH(AO16,{"Operational monitoring","Performance review","Formal review"},0))),AND(AP16<>"",ISNA(MATCH(AP16,{"Raised per Monitoring and Review Plan","Not action-capable","Action-capable: raise not yet set"},0)))),"INVALID VALUE — use the dropdown list",IF(AND(AG16="UC-ID specific",OR(AF16="",AF16="None")),"UC-ID REQUIRED",IF(OR(J16="",K16="",Q16="",R16="",T16="",AL16="",J16="Not yet known",K16="Unknown",Q16="Unknown",R16="Unknown",T16="Unknown"),"UNKNOWN TO RESOLVE",IF(AND(K16="Yes",OR(H16="",I16="",M16="",N16="",O16="",P16="",P16="None",X16="")),"BREACH ACTION INCOMPLETE",IF(AND(OR(K16="Yes",Q16="Yes"),AL16="None"),"TRIGGER NOT RECORDED — select the E.4 trigger",IF(AND(OR(AND(AL16<>"",AL16<>"None"),R16="Yes"),AM16=""),"REASSESSMENT / CONSIDERATION REF REQUIRED",IF(AND(OR(R16="Yes",T16="Yes"),U16=""),"GATE LOG EVENT ID REQUIRED",IF(OR(AND(D16<>"",NOT(ISNUMBER(D16))),AND(Y16<>"",NOT(ISNUMBER(Y16))),AND(ISNUMBER(D16),ISNUMBER(Y16),Y16<=D16)),"DATE CHECK — Review and Next Review must be dates, Next after Review",IF(AND(ISNUMBER(AC16),ISNUMBER(AD16),AD16>AC16),"SAMPLE EXCEEDS POPULATION",IF(AND(ISNUMBER(AD16),ISNUMBER(AK16),AD16<AK16),"SAMPLE BELOW TIER MINIMUM",IF(AND(AI16<>"",ISNUMBER(Y16),AO16=""),"REVIEW TYPE REQUIRED: operational, performance or formal (§6.4.4)",IF(AND(ISNUMBER(D16),ISNUMBER(Y16),AI16<>"",Y16-D16>IF(AI16="Critical",31,IF(AI16="High",IF(OR(AO16="Operational monitoring",AO16="Performance review"),31,92),IF(AI16="Medium",IF(AO16="Operational monitoring",31,IF(AO16="Performance review",92,366)),366)))),"NEXT REVIEW EXCEEDS TIER CADENCE",IF(OR(AP16="",AP16="Action-capable: raise not yet set"),"AGENTIC CADENCE RAISE NOT SET (§6.4.4; size to be set by the Council)",IF(AND(Z16="Closed",OR(D16="",E16="",G16="",H16="",I16="",X16="",Y16="",AA16="",AB16="",NOT(ISNUMBER(AC16)),NOT(ISNUMBER(AD16)),AC16<1,AD16<1,AE16="",AG16="",AI16="")),"CLOSURE EVIDENCE MISSING",IF(Z16="Closed","Closure ready for independent review","Open / review"))))))))))))))))) | AJ16: =IF(AI16="","",IF(AO16="Operational monitoring",IF(AI16="Low","Routine operational monitoring by the Service Owner",IF(AI16="Medium","Monthly","Continuous (logged at least monthly)")),IF(AO16="Performance review",IF(AI16="Critical","At least monthly",IF(AI16="High","Monthly",IF(AI16="Medium","Quarterly","Annual"))),IF(AI16="Critical","Continuous monitoring; formal review at least monthly",IF(AI16="High","Quarterly","Annual"))))) | AK16: =IF(OR(AI16="",NOT(ISNUMBER(AC16))),"",IF(OR(AI16="Critical",AI16="High"),MIN(AC16,MAX(30,ROUNDUP(0.05*AC16,0))),IF(AI16="Medium",MIN(AC16,20),MIN(AC16,10))))
... AH2000: =IF(COUNTA(A2000:AG2000,AI2000,AL2000:AP2000)=0,"",IF(TRIM(A2000)="","AIR-ID REQUIRED",IF(OR(AND(K2000<>"",ISNA(MATCH(K2000,{"Yes","No","Unknown"},0))),AND(Q2000<>"",ISNA(MATCH(Q2000,{"Yes","No","Unknown"},0))),AND(R2000<>"",ISNA(MATCH(R2000,{"Yes","No","Unknown"},0))),AND(T2000<>"",ISNA(MATCH(T2000,{"Yes","No","Unknown"},0))),AND(J2000<>"",ISNA(MATCH(J2000,{"Improving","Stable","Deteriorating","New / Baseline","Not yet known"},0))),AND(Z2000<>"",ISNA(MATCH(Z2000,{"Open","Reviewed","Action Open","Escalated","Closed"},0))),AND(AG2000<>"",ISNA(MATCH(AG2000,{"UC-ID specific","Shared system baseline"},0))),AND(AI2000<>"",ISNA(MATCH(AI2000,{"Low","Medium","High","Critical"},0))),AND(AL2000<>"",COUNTIF(Lists!$A$3:$A$10,AL2000)=0),AND(AO2000<>"",ISNA(MATCH(AO2000,{"Operational monitoring","Performance review","Formal review"},0))),AND(AP2000<>"",ISNA(MATCH(AP2000,{"Raised per Monitoring and Review Plan","Not action-capable","Action-capable: raise not yet set"},0)))),"INVALID VALUE — use the dropdown list",IF(AND(AG2000="UC-ID specific",OR(AF2000="",AF2000="None")),"UC-ID REQUIRED",IF(OR(J2000="",K2000="",Q2000="",R2000="",T2000="",AL2000="",J2000="Not yet known",K2000="Unknown",Q2000="Unknown",R2000="Unknown",T2000="Unknown"),"UNKNOWN TO RESOLVE",IF(AND(K2000="Yes",OR(H2000="",I2000="",M2000="",N2000="",O2000="",P2000="",P2000="None",X2000="")),"BREACH ACTION INCOMPLETE",IF(AND(OR(K2000="Yes",Q2000="Yes"),AL2000="None"),"TRIGGER NOT RECORDED — select the E.4 trigger",IF(AND(OR(AND(AL2000<>"",AL2000<>"None"),R2000="Yes"),AM2000=""),"REASSESSMENT / CONSIDERATION REF REQUIRED",IF(AND(OR(R2000="Yes",T2000="Yes"),U2000=""),"GATE LOG EVENT ID REQUIRED",IF(OR(AND(D2000<>"",NOT(ISNUMBER(D2000))),AND(Y2000<>"",NOT(ISNUMBER(Y2000))),AND(ISNUMBER(D2000),ISNUMBER(Y2000),Y2000<=D2000)),"DATE CHECK — Review and Next Review must be dates, Next after Review",IF(AND(ISNUMBER(AC2000),ISNUMBER(AD2000),AD2000>AC2000),"SAMPLE EXCEEDS POPULATION",IF(AND(ISNUMBER(AD2000),ISNUMBER(AK2000),AD2000<AK2000),"SAMPLE BELOW TIER MINIMUM",IF(AND(AI2000<>"",ISNUMBER(Y2000),AO2000=""),"REVIEW TYPE REQUIRED: operational, performance or formal (§6.4.4)",IF(AND(ISNUMBER(D2000),ISNUMBER(Y2000),AI2000<>"",Y2000-D2000>IF(AI2000="Critical",31,IF(AI2000="High",IF(OR(AO2000="Operational monitoring",AO2000="Performance review"),31,92),IF(AI2000="Medium",IF(AO2000="Operational monitoring",31,IF(AO2000="Performance review",92,366)),366)))),"NEXT REVIEW EXCEEDS TIER CADENCE",IF(OR(AP2000="",AP2000="Action-capable: raise not yet set"),"AGENTIC CADENCE RAISE NOT SET (§6.4.4; size to be set by the Council)",IF(AND(Z2000="Closed",OR(D2000="",E2000="",G2000="",H2000="",I2000="",X2000="",Y2000="",AA2000="",AB2000="",NOT(ISNUMBER(AC2000)),NOT(ISNUMBER(AD2000)),AC2000<1,AD2000<1,AE2000="",AG2000="",AI2000="")),"CLOSURE EVIDENCE MISSING",IF(Z2000="Closed","Closure ready for independent review","Open / review"))))))))))))))))) | AJ2000: =IF(AI2000="","",IF(AO2000="Operational monitoring",IF(AI2000="Low","Routine operational monitoring by the Service Owner",IF(AI2000="Medium","Monthly","Continuous (logged at least monthly)")),IF(AO2000="Performance review",IF(AI2000="Critical","At least monthly",IF(AI2000="High","Monthly",IF(AI2000="Medium","Quarterly","Annual"))),IF(AI2000="Critical","Continuous monitoring; formal review at least monthly",IF(AI2000="High","Quarterly","Annual"))))) | AK2000: =IF(OR(AI2000="",NOT(ISNUMBER(AC2000))),"",IF(OR(AI2000="Critical",AI2000="High"),MIN(AC2000,MAX(30,ROUNDUP(0.05*AC2000,0))),IF(AI2000="Medium",MIN(AC2000,20),MIN(AC2000,10))))

Sheet Sampling Method
A1: AIG-OPS-02 — Sampling Method for Post-Deployment Monitoring
A2: AIG-OPS-02 Annex · v1.6 draft · Draft for Council review · OFFICIAL · Defines how and where monitoring samples are drawn so each result in the Monitoring Log is valid, comparable and reproducible. Aligns to ISO/IEC 42001:2023 clause 9.1 and Playbook §6.4.
A3: Status: draft design. Sample sizes and windows below are illustrative defaults, to be confirmed per system at adoption from actual decision volumes; nothing is yet operating. The selection basis and source population must be recorded for every review in the Monitoring Log (columns AA to AE).
A5: Principles — how and where samples are drawn
A6: Source (where) | B6: Samples are drawn only from the system's authoritative record of decisions or outputs — the system of record named for that AIR-ID (for example the case management system, the model's own decision or output log, or the source dataset). Not from a convenience extract, a screenshot set, or the supplier's own summary. Name the exact source per system and record it in the Monitoring Log 'Sample Source / Population of Record' column.
A7: Population (what the sample represents) | B7: The population is every in-scope decision or output the system produced in the review window. Fix the window and any inclusion or exclusion (for example live decisions only, excluding test traffic) before drawing, and record the population size so the coverage of the sample is visible on the face of the record.
A8: Selection basis (how) | B8: State one reproducible basis per review: full population (census) where volumes allow; simple random; stratified random across the segments that matter (decision type and, for fairness, the protected-characteristic groups held in the equality record); or risk-weighted / targeted for a specific concern. For any random draw, record enough to reproduce it (the method or seed, and the date or range drawn).
A9: High-impact decisions | B9: Whatever the sampled metric, review 100% of the highest-impact decision types for the tier (for example refusals, removals, escalations, or any fully automated adverse decision). Sampling reduces effort on routine outcomes; it never dilutes scrutiny of the decisions that harm a resident if they are wrong.
A10: Sample size | B10: Treat the tier minimums below as a floor. Where a stated confidence level is required — for example to evidence a fairness threshold — set the size by a proportion / confidence calculation on the population instead, and record that basis. If the population in the window is at or below the minimum, review the whole population.
A11: Traceability | B11: Every Monitoring Log result must carry its Sample Source, Selection Basis, Population Size, Sample Size and Sampling Window (columns AA to AE). A metric with no recorded sample is not evidence, and cannot be relied on at internal audit (9.2) or management review (9.3).
A13: Sample plan and minimum cadence by risk tier (per UC-ID; cadence per the Playbook §6.4.4 controlled minimum cadence table)
A14: Risk Tier | B14: Tier band (residual) | C14: Default selection basis | D14: Minimum sample per review | E14: Minimum cadence by review type (§6.4.4) | F14: Low-volume rule
A15: Critical | B15: 16 to 25 | C15: Stratified random, plus 100% of adverse or fully automated decisions | D15: Greater of 30 decisions or 5% of the window's population | E15: Operational monitoring: continuous. Performance review: at least monthly. Formal review: continuous monitoring with a formal review at least monthly. | F15: Census if population is at or below the minimum
A16: High | B16: 11 to 15 | C16: Stratified random | D16: Greater of 30 decisions or 5% of the window's population | E16: Operational monitoring: continuous. Performance review: monthly. Formal review: quarterly. | F16: Census if population is at or below the minimum
A17: Medium | B17: 6 to 10 | C17: Simple random | D17: 20 decisions | E17: Operational monitoring: monthly. Performance review: quarterly. Formal review: annual. | F17: Census if population is 20 or fewer
A18: Low | B18: 1 to 5 | C18: Random spot-check or exception-based | D18: 10 decisions | E18: Operational monitoring: routine, by the Service Owner. Performance review: annual. Formal review: annual. | F18: Census if population is 10 or fewer
A19: Bands match the Risk Assessment Worksheet (AIG-ASS-02) and Playbook §4.4.3 and §4.4.8 (residual = inherent × control ÷ 5; tiers 1–5 / 6–10 / 11–15 / 16–25). Minimum cadences per UC-ID follow the Playbook §6.4.4 table by review type (operational monitoring, performance review, formal review); formal review: Low and Medium annual, High quarterly, Critical continuous monitoring with at least monthly formal review. The plan may increase frequency but never reduce it below the tier minimum (Appendix E.2). Record the tier in Monitoring Log column AI and the review type in column AO; the log derives the cadence for that review type (AJ) and minimum sample (AK) and flags a shortfall. Continuous monitoring is logged at least monthly. Record column AP on every row (“Not action-capable” where the use cannot act; a blank AP is flagged). For an action-capable use, record in column AP whether the Monitoring and Review Plan has raised the cadence (§6.4.4: agentic capability raises and never lowers it); the size of the raise is to be set by the Council (Proposed — for Council confirmation). Minimum sample sizes are illustrative defaults; confirm each per system at adoption. Fairness sampling must stratify on the groups recorded in the Equality Impact Assessment (AIG-ASS-06).

Sheet Instructions
A1: AIG-OPS-02 — Operating Rules
A3: Purpose | B3: Create auditable evidence that each live AI system is actually monitored against approved metrics and thresholds.
A4: Record key | B4: Every entry must carry the same AIR-ID used in the AI Register and other governance artefacts.
A5: Minimum monitoring | B5: Use proportionate metrics. Higher-risk systems should normally consider performance, fairness/bias, drift, error/failure, human oversight/override, complaints/challenges, privacy/security and benefits/outcomes where relevant.
A6: Mandatory reassessment triggers | B6: Documented consideration of risk reassessment is required where monitoring identifies an approved UC-ID threshold breach; material change to the model, data, supplier, purpose, user population or autonomous authority; a significant complaint/challenge pattern; a material incident or near miss; adverse human-override trends; control failure; or a legal/regulatory change affecting a use. (Playbook Appendix E.4, verbatim.) Record the trigger in Monitoring Log column AL and the reassessment or documented-consideration ref in AM.
A7: Threshold breach rule | B7: A breach must not be closed only as an operational fix. Record whether reassessment is required, recalculate residual risk where appropriate, and consider re-entry to the relevant governance gate.
A8: Escalation | B8: Use Incident Report (AIG-OPS-03) and/or CAPA (AIG-AIMS-08) where applicable. Record formal governance decisions/events in Gate Log (AIG-DEC-04).
A9: Register relationship | B9: AI Register (AIG-INV-04) remains the current-state portfolio record, not the monitoring history. Update Monitoring in place, Last review date, Next review and status there when monitoring changes the current governance position.
A10: Dashboard relationship | B10: Portfolio reporting should include overdue monitoring, high/critical systems without current monitoring evidence, systems outside approved thresholds, and systems requiring reassessment.
A11: Retirement | B11: Confirm service withdrawal, access/interface removal, supplier access disposition, data/model/log retention, closure/transfer of open actions, Register status update, final governance review and lessons learned.
A12: Sampling method | B12: Draw every sampled metric per the Sampling Method sheet: from the system's authoritative record of decisions or outputs, on a stated selection basis (census / simple random / stratified), with high-impact decisions reviewed in full. Record Sample Source, Selection Basis, Population Size, Sample Size and Sampling Window (log columns AA to AE) for each result.
A13: Imported technical evidence | B13: If imported technical evidence is used, cite its verified AIG-INV-04 Evidence ID and dated snapshot in Evidence Location (column X). The monitoring owner still reviews the metric, sampling, threshold and action. Missing or stale imported evidence is not a passing result; otherwise use the established controlled evidence reference.
A14: Agentic applicability | B14: For every action-capable agent, set proportionate named metric owners, thresholds, review windows, source of truth and escalation response before live use. Risk tier affects cadence and depth, not whether applicable action controls exist.
... A23: Closure control | B23: Use the Monitoring Log closure/evidence check in column AH. A row needs an AIR-ID and controlled list values. Blank or Unknown answers for Trend, Threshold Breach?, Material Change?, Risk Reassessment Required?, Governance Escalation? or the E.4 trigger show UNKNOWN TO RESOLVE. A breach needs threshold, result, named action, owner, due date, incident/CAPA reference and evidence; any trigger needs a reassessment or consideration ref; reassessment or escalation needs the AIG-DEC-04 Event ID. The check also tests date order, sample ≤ population, the tier minimum sample and the tier cadence for the review type in column AO (§6.4.4: operational monitoring, performance review or formal review), and flags an action-capable use whose agentic cadence raise is not yet set (column AP). Column AP is required on every row: the log identifies an action-capable use only from AP, so a blank AP is treated as a raise not yet set; choose “Not action-capable” where the use cannot act. “Closure ready for independent review” is a prompt to check the underlying source; it is not delegated approval.
A25: Example row (illustrative only — not part of the log)
A26: AIR-ID | B26: AIR-EXAMPLE
A27: AI System / Service | B27: Example only — delete before use
A28: Monitoring Period | B28: 2026-Q3
A29: Monitoring Owner | B29: Service Owner
A30: Metric Category | B30: Performance
A31: Metric / Indicator | B31: Accuracy
A32: Approved Threshold / Tolerance | B32: ≥ 92%
A33: Actual Result | B33: 93.6%
A34: Trend | B34: Stable
A35: Threshold Breach? | B35: No
A36: Severity | B36: Low
A37: Action / Decision | B37: Continue monitoring
... A47: Selection Basis | B47: Stratified random
A48: Population Size | B48: 1240
A49: Sample Size Reviewed | B49: 60
A50: Sampling Window | B50: Quarter (2026-Q3)
A51: Review type (§6.4.4) | B51: Performance review
A52: Agentic cadence raise applied? | B52: Not action-capable

Sheet INTEGRATION INV-04 DEC-04
A1: AIG-OPS-02 — PROPOSED AIG-INV-04/AIG-DEC-04 INTEGRATION NOTES
A2: NOT APPROVED — additive integration annex only; existing workbook content and formulas are retained unchanged. AIG-INV-04 (AI Register) and AIG-DEC-04 (Gate Log) are themselves proposed designs: until the Council approves their adoption and migration, the Council’s existing records remain authoritative and the AIG-INV-04/AIG-DEC-04 joins below are design references only. No live system, event, evidence, approval or Council decision is asserted.
A4: Contract area | B4: Authoritative key / authority | C4: Link / required handling and trigger
A5: System key / authority | B5: AIG-INV-04 AI Register is the system-level source and permanent AIR-ID is the join key for every Monitoring Log entry. AIG-OPS-02 is controlled post-deployment evidence, not the system register. | C5: Use exact AIR-ID to link incident, complaint, control, material-change and monitoring evidence. Do not substitute names or create a parallel system key.
A6: Mandatory reassessment triggers | B6: Documented consideration of risk reassessment is required where monitoring identifies an approved UC-ID threshold breach; material change to the model, data, supplier, purpose, user population or autonomous authority; a significant complaint/challenge pattern; a material incident or near miss; adverse human-override trends; control failure; or a legal/regulatory change affecting a use. (Playbook Appendix E.4, verbatim.) | C6: Record the monitoring/incident/complaint/control/change evidence and date; notify accountable owner; reassess current risks and assurance in the applicable AIG-INV-04 Assessment summary. State decision, rationale, owner and evidence reference—do not close as an operational fix alone.
