Workbook

Sheet Summary
A1: The Council — AIMS Roles, Competence, Awareness and Communications Plan
A2: AIG-AIMS-04 · v1.3 draft · Draft for Council review · OFFICIAL · ISO/IEC 42001:2023
A3: Purpose: operationalise accountable AIMS roles, required competence, learning and internal/external communications without changing Council delegations or specialist authority.
A4: Status statement: all appointments, deputies, authority mappings, competence requirements, training modules and communications are proposed. No individual is confirmed competent, trained or authorised until the Council approves the design and retains evidence.
A6: Document control | B6: Controlled value | D6: Role readiness | G6: Competence and learning readiness
A7: Document ID | B7: AIG-AIMS-04 | D7: Measure | E7: Result | G7: Measure | H7: Result
A8: Version | B8: 1.3 draft | D8: Defined role/body records | E8: =COUNTA('Role Accountability'!$A$7:$A$26) | G8: Role groups mapped | H8: =COUNTA('Competence Matrix'!$A$7:$A$19)
A9: Status | B9: Draft for Council review | D9: Appointments confirmed | E9: =COUNTIF('Role Accountability'!$J$7:$J$26,"Confirmed") | G9: Current assessments complete | H9: =COUNTIF('Competence Matrix'!$N$7:$N$19,"Assessed - competent")+COUNTIF('Competence Matrix'!$N$7:$N$19,"Assessed - gap")
A10: Document owner | B10: AI Governance Lead | D10: Deputies recorded | E10: =COUNTIF('Role Accountability'!$I$7:$I$26,"?*") | G10: Open competence gaps (assessed gap / expired) | H10: =COUNTIF('Competence Matrix'!$N$7:$N$19,"Assessed - gap")+COUNTIF('Competence Matrix'!$N$7:$N$19,"Expired / reassess")
A11: Approving authority | B11: To be confirmed under Council delegations | D11: Appointment evidence recorded | E11: =COUNTIF('Role Accountability'!$K$7:$K$26,"?*") | G11: Learning modules designed | H11: =COUNTA('Learning Plan'!$A$7:$A$18)
A12: Effective date | B12: Pending formal approval | D12: Roles reviewed | E12: =COUNT('Role Accountability'!$N$7:$N$26) | G12: Approved / active modules | H12: =COUNTIF('Learning Plan'!$J$7:$J$18,"Approved")+COUNTIF('Learning Plan'!$J$7:$J$18,"Active")
A13: Review frequency | B13: At least annually and on material change | D13: Role records QA complete | E13: =COUNTIF('Role Accountability'!$R$7:$R$26,"Complete") | G13: Average completion | H13: =AVERAGE('Learning Plan'!$O$7:$O$18)
A14: Primary authority source | B14: AIG-GOV-06 Terms of Reference; approved Council delegations prevail | G14: Learning records QA complete | H14: =COUNTIF('Learning Plan'!$U$7:$U$18,"Complete")
A15: Implementation source | B15: AIG-AIMS-03 IMP-05 and IMP-09
A16: Classification | B16: OFFICIAL | D16: Communications readiness | G16: Important control distinction
D17: Measure | E17: Result | G17: 1. A role description does not appoint a person.
D18: Communication activities | E18: =COUNTA('Communications Plan'!$A$7:$A$19) | G18: 2. Training completion does not by itself prove competence.
D19: Approved / active | E19: =COUNTIF('Communications Plan'!$K$7:$K$19,"Approved")+COUNTIF('Communications Plan'!$K$7:$K$19,"Active") | G19: 3. Competence does not itself confer delegated authority.
D20: Issued / completed | E20: =COUNTIF('Communications Plan'!$K$7:$K$19,"Issued")+COUNTIF('Communications Plan'!$K$7:$K$19,"Complete") | G20: 4. Communication activity needs retained evidence and an effectiveness measure.
D21: Target dates recorded | E21: =COUNT('Communications Plan'!$L$7:$L$19) | G21: 5. AIG-GOV-06 and approved Council delegations remain the authority source.
D22: Last-issued dates recorded | E22: =COUNT('Communications Plan'!$M$7:$M$19) | G22: 6. Specialist/statutory functions retain their existing authority.
D23: Communication QA complete | E23: =COUNTIF('Communications Plan'!$R$7:$R$19,"Complete") | G23: 7. Draft entries must not be represented as operating controls.
A26: Controlled implementation sequence
A27: 1. Approve the Terms of Reference, delegations, retained specialist authority and the role design in this workbook.
A28: 2. Name role holders and deputies; retain appointment, conflict and authority evidence.
A29: 3. Confirm target populations, required competency profiles, resources and assessment methods.
A30: 4. Approve learning content, delivery owners, dates, accessibility, pass criteria and LMS/evidence arrangements.
A31: 5. Assess role holders; record competence conclusions, gaps, supervised practice and remedial actions.
A32: 6. Approve and issue communications in sequence with AIMS adoption and operational rollout.
A33: 7. Review training, communication and role effectiveness using incidents, audit, performance and stakeholder feedback.
A35: Version | B35: Date | C35: Change | G35: Author / owner
A36: 1.0 draft | B36: 46241 | C36: Initial AIMS role-accountability, competence, learning, awareness and communications design aligned to AIG-GOV-06, AIG-OPS-01 and AIG-AIMS-03. | G36: AI Governance Lead
A37: 1.1 draft | B37: 28 September 2026 | C37: Make role-accountability QA colours match exact statuses.
A38: 1.2 draft | B38: 29 September 2026 | C38: QA remediation — applied findings QA-218, QA-220, QA-238, QA-240, QA-241, QA-251, QA-255, QA-280, QA-282, QA-284, QA-291 and decision D2 role names (see QA change log). | G38: AI Governance Lead
A39: 1.3 draft | B39: 12 October 2026 | C39: v3.9.10: Role Accountability adds ROL-20 Data Steward, who maintains data quality, lineage and the Information Asset Register link (AIG-INV-04 column AA) on behalf of the Data Owner. Summary counts extended to the new row. Proposed — for Council confirmation. | G39: AI Governance Lead

Sheet Role Accountability
A1: The Council — AIMS Role Accountability and Appointment Register
A2: AIG-AIMS-04 · v1.3 draft · Draft for Council review · OFFICIAL · ISO/IEC 42001:2023
A3: Purpose: define proposed accountability, responsibilities, authority boundaries, interfaces, competence and appointment evidence for AIMS roles and bodies.
A4: Current position: role descriptions are proposed design only. Complete named appointment, deputy, evidence and review fields only after formal authority is confirmed; approved Council delegations and specialist responsibilities prevail.
A6: Role ID | B6: Role / body | C6: AIMS layer | D6: Purpose / accountability | E6: Key responsibilities | F6: Decision / approval authority | G6: Consultation / escalation | H6: Named appointee | I6: Deputy | J6: Appointment status | K6: Appointment evidence | L6: Required competency level | M6: Training pathway | N6: Review date | O6: Related suite references | P6: ISO / SoA links | Q6: Role record / source | R6: Record QA
A7: ROL-01 | B7: Executive Sponsor | C7: Strategic oversight | D7: Senior accountability, sponsorship and resources for the AIMS. | E7: Champion responsible AI; secure adoption and resources; hold leadership to account; resolve strategic barriers; receive escalations and management-review outputs. | F7: Sponsors formal adoption and decisions reserved under Council delegations; does not replace statutory or specialist authority. | G7: Escalate critical matters to Executive Leadership and the AI Assurance Board; consult Monitoring Officer, SIRO, DPO and other control owners. | J7: Proposed | L7: Level 5 — AI Governance Leader | M7: TRN-01, TRN-03, TRN-09, TRN-10 | O7: AIG-GOV-02, AIG-OPS-05, AIG-OPS-06, AIG-GOV-06, AIG-AIMS-01, AIG-AIMS-03 | P7: ISO 5.1, 5.3, 7.1; A.2.2, A.3.2 | Q7: AIG-GOV-06 proposed governance; Playbook roles | R7: =IF(AND(A7<>"",B7<>"",C7<>"",D7<>"",E7<>"",F7<>"",G7<>"",J7<>"",L7<>"",M7<>"",O7<>"",P7<>"",Q7<>""),IF(J7="Proposed","Complete",IF(AND(H7<>"",K7<>"",N7<>""),"Complete","Appointment evidence incomplete")),"Incomplete")
A8: ROL-02 | B8: AI Assurance Board | C8: Strategic oversight | D8: Collective strategic oversight and higher-risk decision-making. | E8: Provide assurance and endorsement on strategic direction and higher-risk cases; oversee risk, performance, exceptions and improvement; sponsor management review and assurance responses. | F8: Proposed: Assurance and endorsement of high-risk cases, with approval remaining with the relevant delivery forum under delegation; Critical escalated to Executive Sponsor/Leadership, subject to approved Terms of Reference and delegations. | G8: Receives Working Group recommendations and critical escalations; refers specialist matters to the relevant accountable function. | J8: Proposed | L8: Level 5 — AI Governance Leader | M8: TRN-01, TRN-09, TRN-10 | O8: AIG-DEC-03, AIG-OPS-05, AIG-OPS-06, AIG-GOV-06, AIG-AIMS-01, AIG-AIMS-03 | P8: ISO 5.1, 5.3, 9.3; A.3.2 | Q8: AIG-GOV-06 Terms of Reference | R8: =IF(AND(A8<>"",B8<>"",C8<>"",D8<>"",E8<>"",F8<>"",G8<>"",J8<>"",L8<>"",M8<>"",O8<>"",P8<>"",Q8<>""),IF(J8="Proposed","Complete",IF(AND(H8<>"",K8<>"",N8<>""),"Complete","Appointment evidence incomplete")),"Incomplete")
A9: ROL-03 | B9: AI Governance Working Group | C9: Operational governance | D9: Cross-functional coordination, triage and medium-risk assurance. | E9: Coordinate intake, AGPI, register and assessments; scrutinise evidence; assure and recommend on medium-risk cases; recommend high/critical decisions; track conditions and actions. | F9: Proposed: Assurance and recommendation on medium-risk cases, with approval remaining with the relevant delivery forum under delegation; recommends High/Critical decisions. | G9: Escalates High to the Board and Critical to Board/Executive Sponsor; involves control functions whenever their authority is engaged. | J9: Proposed | L9: Level 4 — AI Specialist | M9: TRN-01, TRN-04, TRN-05, TRN-09, TRN-10 | O9: AIG-INV-03, AIG-INV-04, AIG-ASS-01, AIG-ASS-02, AIG-ASS-03 and AIG-ASS-04, AIG-DEC-03, AIG-GOV-06, AIG-AIMS-03 | P9: ISO 5.3, 8.1; A.3.2 | Q9: AIG-GOV-06 Terms of Reference | R9: =IF(AND(A9<>"",B9<>"",C9<>"",D9<>"",E9<>"",F9<>"",G9<>"",J9<>"",L9<>"",M9<>"",O9<>"",P9<>"",Q9<>""),IF(J9="Proposed","Complete",IF(AND(H9<>"",K9<>"",N9<>""),"Complete","Appointment evidence incomplete")),"Incomplete")
A10: ROL-04 | B10: AI Assurance Board Chair | C10: Strategic and operational interface | D10: Lead the Council’s AI direction and chair strategic governance. | E10: Set direction; chair the Board; sponsor coherent prioritisation; ensure decisions and escalations reach the correct authority; promote capability and responsible innovation. | F10: Chairing and recommendation authority only until delegations and Terms of Reference are formally approved. Chair to be confirmed by the Council (proposed: Executive Sponsor). | G10: Works with Executive Sponsor and AI Governance Lead; escalates authority, resource and systemic-risk issues. | J10: Proposed | L10: Level 5 — AI Governance Leader | M10: TRN-01, TRN-03, TRN-09, TRN-10 | O10: AIG-GOV-02, AIG-OPS-05, AIG-OPS-06, AIG-GOV-06, AIG-AIMS-01 | P10: ISO 5.1, 5.3, 7.4; A.3.2 | Q10: Playbook governance roles; AIG-GOV-06 | R10: =IF(AND(A10<>"",B10<>"",C10<>"",D10<>"",E10<>"",F10<>"",G10<>"",J10<>"",L10<>"",M10<>"",O10<>"",P10<>"",Q10<>""),IF(J10="Proposed","Complete",IF(AND(H10<>"",K10<>"",N10<>""),"Complete","Appointment evidence incomplete")),"Incomplete")
A11: ROL-05 | B11: AI Governance Lead | C11: AIMS management | D11: Operate and continually improve the AIMS on behalf of accountable leadership. | E11: Maintain scope, policy, SoA, registers, triage, governance workflow, metrics, evidence, training design, reporting, audits, management review and corrective actions. | F11: Process administration and recommendation authority; no independent power to approve cases or accept risk outside confirmed delegation. | G11: Escalates material risks, overdue actions, exceptions and evidence gaps to the relevant owner, Working Group, Board or Executive Sponsor. | J11: Proposed | L11: Level 5 — AI Governance Leader | M11: TRN-01 to TRN-12 as applicable | O11: AIG-GOV-01 to AIG-GOV-03, AIG-GOV-06, AIG-INV-01, AIG-INV-03, AIG-INV-04, AIG-ASS-01 to AIG-ASS-11, AIG-DEC-03, AIG-OPS-01, AIG-OPS-03, AIG-OPS-05, AIG-OPS-06, AIG-AIMS-01 to AIG-AIMS-04 | P11: ISO 4.4, 5.3, 7.2-7.5, 9-10; A.3.2 | Q11: Playbook roles; AIG-GOV-06 and AIG-AIMS-03 IMP-05/IMP-09 | R11: =IF(AND(A11<>"",B11<>"",C11<>"",D11<>"",E11<>"",F11<>"",G11<>"",J11<>"",L11<>"",M11<>"",O11<>"",P11<>"",Q11<>""),IF(J11="Proposed","Complete",IF(AND(H11<>"",K11<>"",N11<>""),"Complete","Appointment evidence incomplete")),"Incomplete")
A12: ROL-06 | B12: Governance Secretariat | C12: Operational governance | D12: Maintain reliable governance records and action tracking. | E12: Schedule meetings; manage agendas, papers, conflicts, minutes, decisions, conditions, action logs and links to the AI Register and its Evidence index. | F12: Administrative control only; cannot approve cases, close conditions or vary recorded decisions without authorised instruction. | G12: Escalates missing papers, overdue actions, conflicts and decision-record inconsistencies to the Chair and AI Governance Lead. | J12: Proposed | L12: Level 2 — AI User / Practitioner | M12: TRN-01, TRN-04, TRN-09 | O12: AIG-INV-04, AIG-DEC-03, AIG-OPS-05, AIG-GOV-06 | P12: ISO 7.5; A.3.2, A.6.2.3 | Q12: AIG-GOV-06 secretariat responsibilities | R12: =IF(AND(A12<>"",B12<>"",C12<>"",D12<>"",E12<>"",F12<>"",G12<>"",J12<>"",L12<>"",M12<>"",O12<>"",P12<>"",Q12<>""),IF(J12="Proposed","Complete",IF(AND(H12<>"",K12<>"",N12<>""),"Complete","Appointment evidence incomplete")),"Incomplete")
A13: ROL-07 | B13: Service Owner | C13: Service accountability | D13: Accountable owner for service outcomes and proportionate governance of an AI use. | E13: Register the use; ensure assessments and controls; own risk and benefits; resource human oversight; approve operational procedures; monitor performance; report incidents and material change. | F13: Proposed: Low-risk decision by the officer or forum with confirmed delegation (Service Owner/Service Manager only if delegated), recorded in AIG-DEC-03 or approved minutes; the AI Register records the reference. Cannot override specialist or higher-tier controls. | G13: Escalates Medium/High/Critical cases and unresolved specialist findings; consults users and affected groups proportionately. | J13: Proposed | L13: Level 3 — AI Owner / Manager | M13: TRN-01, TRN-03, TRN-04, TRN-05, TRN-10 | O13: AIG-INV-03, AIG-INV-04, AIG-ASS-01, AIG-ASS-02, AIG-ASS-03, AIG-ASS-04, AIG-ASS-05, AIG-ASS-06 and AIG-ASS-07, AIG-DEC-03, AIG-OPS-03, AIG-OPS-01 | P13: ISO 5.3, 8.1; A.5.4, A.9.2 | Q13: Playbook Service Owner; AIG-GOV-06 decision rights | R13: =IF(AND(A13<>"",B13<>"",C13<>"",D13<>"",E13<>"",F13<>"",G13<>"",J13<>"",L13<>"",M13<>"",O13<>"",P13<>"",Q13<>""),IF(J13="Proposed","Complete",IF(AND(H13<>"",K13<>"",N13<>""),"Complete","Appointment evidence incomplete")),"Incomplete")
A14: ROL-08 | B14: AI System Owner / Operational Lead | C14: Operational delivery | D14: Day-to-day accountability for safe, controlled system operation. | E14: Maintain operating instructions, oversight, monitoring, access, logs, changes, thresholds, incidents, continuity and retirement evidence; keep the Service Owner informed. | F14: Operational action within approved limits; may pause or invoke rollback where authorised by the deployment/incident plan. | G14: Escalates threshold breaches, unapproved change, incidents, complaints and control failure to Service Owner and relevant specialists. | J14: Proposed | L14: Level 3 — AI Owner / Manager | M14: TRN-01, TRN-02, TRN-04, TRN-10, TRN-11 | O14: AIG-INV-04, AIG-ASS-09, AIG-OPS-03, AIG-ASS-11, AIG-OPS-01 | P14: ISO 8.1, 9.1; A.6.2.6-A.6.2.8, A.9.2 | Q14: Playbook lifecycle; AIG-OPS-01 rollout roles | R14: =IF(AND(A14<>"",B14<>"",C14<>"",D14<>"",E14<>"",F14<>"",G14<>"",J14<>"",L14<>"",M14<>"",O14<>"",P14<>"",Q14<>""),IF(J14="Proposed","Complete",IF(AND(H14<>"",K14<>"",N14<>""),"Complete","Appointment evidence incomplete")),"Incomplete")
A15: ROL-09 | B15: Product / Technical Delivery Lead | C15: Technical delivery | D15: Ensure technical design, testing, release and change evidence meets approved requirements. | E15: Document system design; perform verification/validation; manage environments and release; implement monitoring, security and rollback controls; disclose limitations and dependencies. | F15: Technical recommendation and release execution within approved change and deployment authority; no governance risk acceptance. | G15: Escalates failed tests, limitations, security issues, drift and material change to System/Service Owner and governance functions. | J15: Proposed | L15: Level 4 — AI Specialist | M15: TRN-01, TRN-02, TRN-05, TRN-07, TRN-11 | O15: AIG-ASS-02, AIG-ASS-09, AIG-ASS-11, AIG-OPS-01 | P15: ISO 8.1; A.6.2.2-A.6.2.8, A.7.2-A.7.6 | Q15: AIG-OPS-01 technical/delivery role; Model Card | R15: =IF(AND(A15<>"",B15<>"",C15<>"",D15<>"",E15<>"",F15<>"",G15<>"",J15<>"",L15<>"",M15<>"",O15<>"",P15<>"",Q15<>""),IF(J15="Proposed","Complete",IF(AND(H15<>"",K15<>"",N15<>""),"Complete","Appointment evidence incomplete")),"Incomplete")
A16: ROL-10 | B16: Data Owner / Data Governance | C16: Specialist control | D16: Authorise and assure appropriate data use, quality and stewardship. | E16: Confirm data ownership, provenance, lawful/approved access, quality, representativeness, lineage, retention and monitoring; resolve data-control exceptions. | F16: Retains data-governance authority under Council policy; can withhold data approval where requirements are unmet. | G16: Escalates material data risks to Service Owner, DPO/IG, SIRO and governance bodies as appropriate. | J16: Proposed | L16: Level 4 — AI Specialist | M16: TRN-01, TRN-05, TRN-06, TRN-11 | O16: AIG-ASS-02, AIG-ASS-04, AIG-ASS-05, AIG-ASS-09 | P16: ISO 5.3, 8.1; A.4.3, A.7.2-A.7.6 | Q16: Playbook data roles and lifecycle controls | R16: =IF(AND(A16<>"",B16<>"",C16<>"",D16<>"",E16<>"",F16<>"",G16<>"",J16<>"",L16<>"",M16<>"",O16<>"",P16<>"",Q16<>""),IF(J16="Proposed","Complete",IF(AND(H16<>"",K16<>"",N16<>""),"Complete","Appointment evidence incomplete")),"Incomplete")
A17: ROL-11 | B17: DPO / Information Governance | C17: Specialist control | D17: Provide independent data-protection and information-governance advice and assurance. | E17: Determine DPIA needs; advise on lawful basis, transparency, rights, minimisation, retention, sharing and high-risk processing; maintain statutory escalation where applicable. | F17: Retains statutory/professional authority; governance bodies cannot waive legal data-protection requirements. | G17: Escalates unresolved high privacy risk through statutory and Council routes; consults Legal, SIRO, Security and affected services. | J17: Proposed | L17: Level 4 — AI Specialist | M17: TRN-01, TRN-05, TRN-06, TRN-10 | O17: AIG-ASS-04, AIG-ASS-05, AIG-ASS-08, AIG-OPS-03, AIG-GOV-06 | P17: ISO 5.3, 7.4; A.5.2-A.5.5, A.7 | Q17: Playbook DPO role; AIG-GOV-06 retained authority | R17: =IF(AND(A17<>"",B17<>"",C17<>"",D17<>"",E17<>"",F17<>"",G17<>"",J17<>"",L17<>"",M17<>"",O17<>"",P17<>"",Q17<>""),IF(J17="Proposed","Complete",IF(AND(H17<>"",K17<>"",N17<>""),"Complete","Appointment evidence incomplete")),"Incomplete")
A18: ROL-12 | B18: SIRO / Information Risk | C18: Strategic specialist control | D18: Oversee material information risk and assurance. | E18: Advise on information risk appetite, ownership, escalation and assurance; sponsor resolution of systemic or critical information risks. | F18: Retains information-risk authority under Council governance and approved risk delegations. | G18: Escalates material information risks to Executive Leadership and appropriate governance bodies. | J18: Proposed | L18: Level 5 — AI Governance Leader | M18: TRN-01, TRN-07, TRN-09, TRN-10 | O18: AIG-ASS-11, AIG-GOV-06, AIG-AIMS-01, AIG-AIMS-03 | P18: ISO 5.1, 5.3, 6.1; A.3.2 | Q18: Playbook SIRO role; AIG-GOV-06 membership | R18: =IF(AND(A18<>"",B18<>"",C18<>"",D18<>"",E18<>"",F18<>"",G18<>"",J18<>"",L18<>"",M18<>"",O18<>"",P18<>"",Q18<>""),IF(J18="Proposed","Complete",IF(AND(H18<>"",K18<>"",N18<>""),"Complete","Appointment evidence incomplete")),"Incomplete")
... A26: ROL-20 | B26: Data Steward | C26: Service accountability | D26: Look after the quality, meaning and day-to-day use of the data an AI system relies on, on behalf of the Data Owner. | E26: Maintain data definitions and quality checks; keep data lineage and provenance records current; check that data used by AI matches the approved purpose; keep the Information Asset Register entry and the AI Register Information asset reference (AIG-INV-04 column AA) aligned; raise data quality or misuse issues. | F26: No authority to approve AI use or new uses of data; recommends to the Data Owner and Service Owner. | G26: Escalate to the Data Owner, Service Owner, DPO or Information Governance as applicable. | J26: Proposed | L26: Level 3 — AI Owner / Manager | M26: TRN-01, TRN-03, TRN-04, TRN-05, TRN-10 | O26: AIG-GOV-02 §5.6 and Appendix A.2; AIG-INV-04 column AA; AIG-ASS-05; AIG-ASS-09 | P26: ISO 5.3, 7.2; A.7.4, A.7.5 | Q26: Proposed v3.9.10 data governance role (Proposed — for Council confirmation) | R26: =IF(AND(A26<>"",B26<>"",C26<>"",D26<>"",E26<>"",F26<>"",G26<>"",J26<>"",L26<>"",M26<>"",O26<>"",P26<>"",Q26<>""),IF(J26="Proposed","Complete",IF(AND(H26<>"",K26<>"",N26<>""),"Complete","Appointment evidence incomplete")),"Incomplete")

Sheet Competence Matrix
A1: The Council — AIMS Competence Matrix and Assessment Record
A2: AIG-AIMS-04 · v1.3 draft · Draft for Council review · OFFICIAL · ISO/IEC 42001:2023
A3: Purpose: define required role-group competence across the Playbook domains and control assessment, gaps, remedial action and evidence.
A4: Current position: proficiency numbers are required levels, not current scores. Every group is marked Not assessed until named people are assessed using approved methods and evidence; training attendance alone is insufficient.
A6: Group ID | B6: Role group | C6: Playbook competency level | D6: AI literacy | E6: Governance / accountability | F6: Risk | G6: Responsible AI | H6: Data / IG | I6: Security / resilience | J6: Operational application | K6: Leadership / oversight | L6: Evidence / assessment method | M6: Assessment frequency | N6: Current assessment status | O6: Current result | P6: Gap / remedial action | Q6: Owner | R6: Due date | S6: Evidence location | T6: Related objectives / risks / learning | U6: Record QA
A7: CMP-01 | B7: All employees | C7: Level 1 — AI Awareness | D7: 1 | E7: 1 | F7: 1 | G7: 1 | H7: 1 | I7: 1 | J7: 1 | K7: 1 | L7: Completion plus short knowledge check | M7: At induction; refresh at least annually | N7: Not assessed | P7: Assess the target population and completion baseline once the programme is approved. | Q7: HR / L&D with AI Governance Lead | T7: OBJ-08; R-05; IMP-09; TRN-01 | U7: =IF(AND(A7<>"",B7<>"",C7<>"",D7<>"",E7<>"",F7<>"",G7<>"",H7<>"",I7<>"",J7<>"",K7<>"",L7<>"",M7<>"",N7<>"",P7<>"",Q7<>"",T7<>""),IF(N7="Not assessed","Complete",IF(AND(O7<>"",R7<>"",S7<>""),"Complete","Assessment evidence incomplete")),"Incomplete")
A8: CMP-02 | B8: Regular AI users / practitioners | C8: Level 2 — AI User / Practitioner | D8: 2 | E8: 2 | F8: 2 | G8: 2 | H8: 2 | I8: 2 | J8: 3 | K8: 1 | L8: Scenario-based knowledge check and supervisor observation | M8: Before approved use; annual refresh and on material change | N8: Not assessed | P8: Identify the user population and validate practice against approved instructions. | Q8: Service Owner / Line Manager | T8: OBJ-04, OBJ-05; R-05; TRN-01, TRN-02 | U8: =IF(AND(A8<>"",B8<>"",C8<>"",D8<>"",E8<>"",F8<>"",G8<>"",H8<>"",I8<>"",J8<>"",K8<>"",L8<>"",M8<>"",N8<>"",P8<>"",Q8<>"",T8<>""),IF(N8="Not assessed","Complete",IF(AND(O8<>"",R8<>"",S8<>""),"Complete","Assessment evidence incomplete")),"Incomplete")
A9: CMP-03 | B9: Managers of AI-using staff | C9: Level 3 — AI Owner / Manager | D9: 2 | E9: 3 | F9: 3 | G9: 3 | H9: 2 | I9: 2 | J9: 3 | K9: 3 | L9: Manager module, scenario exercise and management review | M9: On appointment; annual refresh | N9: Not assessed | P9: Confirm which managers supervise AI use and assess governance decision capability. | Q9: Directorate Leadership / HR-L&D | T9: OBJ-08; R-04, R-05; TRN-03 | U9: =IF(AND(A9<>"",B9<>"",C9<>"",D9<>"",E9<>"",F9<>"",G9<>"",H9<>"",I9<>"",J9<>"",K9<>"",L9<>"",M9<>"",N9<>"",P9<>"",Q9<>"",T9<>""),IF(N9="Not assessed","Complete",IF(AND(O9<>"",R9<>"",S9<>""),"Complete","Assessment evidence incomplete")),"Incomplete")
A10: CMP-04 | B10: Service Owners | C10: Level 3 — AI Owner / Manager | D10: 3 | E10: 4 | F10: 4 | G10: 4 | H10: 3 | I10: 3 | J10: 4 | K10: 4 | L10: Case-based assessment using a real governance submission | M10: Before approval authority; annual and after control failure | N10: Not assessed | P10: Assess named Service Owners after appointment; remediate any lifecycle or accountability gap. | Q10: AI Governance Lead / Directorate Leadership | T10: OBJ-02 to OBJ-08; R-04, R-05; IMP-05, IMP-09 | U10: =IF(AND(A10<>"",B10<>"",C10<>"",D10<>"",E10<>"",F10<>"",G10<>"",H10<>"",I10<>"",J10<>"",K10<>"",L10<>"",M10<>"",N10<>"",P10<>"",Q10<>"",T10<>""),IF(N10="Not assessed","Complete",IF(AND(O10<>"",R10<>"",S10<>""),"Complete","Assessment evidence incomplete")),"Incomplete")
A11: CMP-05 | B11: AI System Owners / Operational Leads | C11: Level 3 — AI Owner / Manager | D11: 3 | E11: 3 | F11: 4 | G11: 3 | H11: 3 | I11: 4 | J11: 4 | K11: 3 | L11: Operational simulation, threshold/rollback exercise and record review | M11: Before go-live; at least annually and on material change | N11: Not assessed | P11: Validate monitoring, escalation, incident and change-control competence for each live system. | Q11: Service Owner / AI Governance Lead | T11: OBJ-04, OBJ-07; R-05, R-11, R-12; TRN-04, TRN-10, TRN-11 | U11: =IF(AND(A11<>"",B11<>"",C11<>"",D11<>"",E11<>"",F11<>"",G11<>"",H11<>"",I11<>"",J11<>"",K11<>"",L11<>"",M11<>"",N11<>"",P11<>"",Q11<>"",T11<>""),IF(N11="Not assessed","Complete",IF(AND(O11<>"",R11<>"",S11<>""),"Complete","Assessment evidence incomplete")),"Incomplete")
A12: CMP-06 | B12: Product / Technical / Data Science specialists | C12: Level 4 — AI Specialist | D12: 4 | E12: 3 | F12: 4 | G12: 4 | H12: 3 | I12: 4 | J12: 4 | K12: 2 | L12: Technical portfolio, test evidence, peer review and scenario exercise | M12: Before technical authority; annual CPD review | N12: Not assessed | P12: Map required disciplines to each system and confirm specialist depth, peer review and succession. | Q12: Technical Leadership / Service Owner | T12: OBJ-04; R-05, R-07, R-10, R-11; TRN-07, TRN-11 | U12: =IF(AND(A12<>"",B12<>"",C12<>"",D12<>"",E12<>"",F12<>"",G12<>"",H12<>"",I12<>"",J12<>"",K12<>"",L12<>"",M12<>"",N12<>"",P12<>"",Q12<>"",T12<>""),IF(N12="Not assessed","Complete",IF(AND(O12<>"",R12<>"",S12<>""),"Complete","Assessment evidence incomplete")),"Incomplete")
A13: CMP-07 | B13: Data, privacy and information-governance specialists | C13: Level 4 — AI Specialist | D13: 3 | E13: 4 | F13: 4 | G13: 4 | H13: 4 | I13: 3 | J13: 3 | K13: 3 | L13: Professional evidence, case review and challenge exercise | M13: On assignment; annual CPD review | N13: Not assessed | P13: Validate AI-specific application of professional expertise and access to external advice. | Q13: Relevant Function Head | T13: OBJ-03, OBJ-04; R-05, R-07; TRN-05, TRN-06 | U13: =IF(AND(A13<>"",B13<>"",C13<>"",D13<>"",E13<>"",F13<>"",G13<>"",H13<>"",I13<>"",J13<>"",K13<>"",L13<>"",M13<>"",N13<>"",P13<>"",Q13<>"",T13<>""),IF(N13="Not assessed","Complete",IF(AND(O13<>"",R13<>"",S13<>""),"Complete","Assessment evidence incomplete")),"Incomplete")
A14: CMP-08 | B14: Cyber Security specialists | C14: Level 4 — AI Specialist | D14: 3 | E14: 3 | F14: 4 | G14: 3 | H14: 3 | I14: 4 | J14: 3 | K14: 3 | L14: Threat-model review, technical exercise and professional evidence | M14: On assignment; annual CPD review and threat change | N14: Not assessed | P14: Validate AI-specific threat, misuse, resilience and supplier-security competence. | Q14: Head of Cyber Security | T14: OBJ-04, OBJ-07; R-05, R-10, R-12; TRN-07, TRN-10, TRN-11 | U14: =IF(AND(A14<>"",B14<>"",C14<>"",D14<>"",E14<>"",F14<>"",G14<>"",H14<>"",I14<>"",J14<>"",K14<>"",L14<>"",M14<>"",N14<>"",P14<>"",Q14<>"",T14<>""),IF(N14="Not assessed","Complete",IF(AND(O14<>"",R14<>"",S14<>""),"Complete","Assessment evidence incomplete")),"Incomplete")
A15: CMP-09 | B15: Legal, equality, human-rights and safeguarding specialists | C15: Level 4 — AI Specialist | D15: 3 | E15: 4 | F15: 4 | G15: 4 | H15: 3 | I15: 2 | J15: 3 | K15: 3 | L15: Professional evidence and cross-functional case challenge | M15: On assignment; annual CPD review and legal change | N15: Not assessed | P15: Validate AI-specific public-law, equality, rights and safeguarding capability. | Q15: Relevant Function Head | T15: OBJ-03, OBJ-05; R-05, R-06, R-08, R-13; TRN-05 | U15: =IF(AND(A15<>"",B15<>"",C15<>"",D15<>"",E15<>"",F15<>"",G15<>"",H15<>"",I15<>"",J15<>"",K15<>"",L15<>"",M15<>"",N15<>"",P15<>"",Q15<>"",T15<>""),IF(N15="Not assessed","Complete",IF(AND(O15<>"",R15<>"",S15<>""),"Complete","Assessment evidence incomplete")),"Incomplete")
A16: CMP-10 | B16: Procurement, commercial and contract owners | C16: Level 3 — AI Owner / Manager | D16: 3 | E16: 3 | F16: 4 | G16: 3 | H16: 3 | I16: 3 | J16: 4 | K16: 3 | L16: Supplier case assessment and contract-control review | M16: Before material AI procurement; annual refresh | N16: Not assessed | P16: Validate early governance triggering, due diligence, clauses, evidence rights and exit competence. | Q16: Head of Procurement / AI Governance Lead | T16: OBJ-06; R-05, R-09, R-15; TRN-08 | U16: =IF(AND(A16<>"",B16<>"",C16<>"",D16<>"",E16<>"",F16<>"",G16<>"",H16<>"",I16<>"",J16<>"",K16<>"",L16<>"",M16<>"",N16<>"",P16<>"",Q16<>"",T16<>""),IF(N16="Not assessed","Complete",IF(AND(O16<>"",R16<>"",S16<>""),"Complete","Assessment evidence incomplete")),"Incomplete")
A17: CMP-11 | B17: Governance Secretariat and Working Group members | C17: Level 4 — AI Specialist | D17: 3 | E17: 4 | F17: 4 | G17: 4 | H17: 3 | I17: 3 | J17: 4 | K17: 3 | L17: Induction, calibrated case exercise and decision-record sample | M17: Before participation; annual calibration | N17: Not assessed | P17: Assess consistent triage, evidence challenge, conflicts, decisions and escalation. | Q17: AI Governance Lead / Working Group Chair | T17: OBJ-02, OBJ-08; R-03 to R-05; TRN-04, TRN-09 | U17: =IF(AND(A17<>"",B17<>"",C17<>"",D17<>"",E17<>"",F17<>"",G17<>"",H17<>"",I17<>"",J17<>"",K17<>"",L17<>"",M17<>"",N17<>"",P17<>"",Q17<>"",T17<>""),IF(N17="Not assessed","Complete",IF(AND(O17<>"",R17<>"",S17<>""),"Complete","Assessment evidence incomplete")),"Incomplete")
A18: CMP-12 | B18: AI Assurance Board and Executive Sponsor | C18: Level 5 — AI Governance Leader | D18: 3 | E18: 4 | F18: 4 | G18: 4 | H18: 3 | I18: 3 | J18: 3 | K18: 4 | L18: Board induction, strategic scenario and management-review evaluation | M18: Before decision authority; annual update | N18: Not assessed | P18: Confirm leadership understanding of accountability, risk acceptance, resources and management review. | Q18: AI Governance Lead | T18: OBJ-08; R-01, R-04, R-05; TRN-09, TRN-10 | U18: =IF(AND(A18<>"",B18<>"",C18<>"",D18<>"",E18<>"",F18<>"",G18<>"",H18<>"",I18<>"",J18<>"",K18<>"",L18<>"",M18<>"",N18<>"",P18<>"",Q18<>"",T18<>""),IF(N18="Not assessed","Complete",IF(AND(O18<>"",R18<>"",S18<>""),"Complete","Assessment evidence incomplete")),"Incomplete")
A19: CMP-13 | B19: AI Governance Lead and Internal Audit | C19: Level 5 / Level 4 specialist | D19: 4 | E19: 4 | F19: 4 | G19: 4 | H19: 4 | I19: 4 | J19: 4 | K19: 4 | L19: Advanced AIMS assessment, audit/implementation evidence and independent review | M19: On appointment; annual CPD and external-change review | N19: Not assessed | P19: Confirm sufficient ISO/IEC 42001, audit, regulatory and practical governance capability; obtain expert support for gaps. | Q19: Executive Sponsor / Head of Internal Audit | T19: OBJ-08; R-05, R-14; IMP-05, IMP-09, IMP-14; TRN-12 | U19: =IF(AND(A19<>"",B19<>"",C19<>"",D19<>"",E19<>"",F19<>"",G19<>"",H19<>"",I19<>"",J19<>"",K19<>"",L19<>"",M19<>"",N19<>"",P19<>"",Q19<>"",T19<>""),IF(N19="Not assessed","Complete",IF(AND(O19<>"",R19<>"",S19<>""),"Complete","Assessment evidence incomplete")),"Incomplete")

Sheet Learning Plan
A1: The Council — AIMS Learning and Awareness Plan
A2: AIG-AIMS-04 · v1.3 draft · Draft for Council review · OFFICIAL · ISO/IEC 42001:2023
A3: Purpose: define role-based learning, timing, outcomes, delivery, completion, assessment and effectiveness evidence required to support competent AIMS operation.
A4: Current position: modules and targets are proposed designs. No delivery, completion or effectiveness is claimed; approve audience, content, accessibility, dates, pass criteria, ownership and evidence before launch.
A6: Module ID | B6: Module | C6: Audience | D6: Competency level | E6: Requirement | F6: Trigger / deadline | G6: Learning outcomes | H6: Delivery method | I6: Owner | J6: Status | K6: Planned date | L6: Recurrence | M6: Assessment / effectiveness | N6: Completion target | O6: Completion rate | P6: Evidence location | Q6: Review date | R6: Related objectives / risks / actions | S6: ISO / SoA links | T6: Decision / design note | U6: Record QA
A7: TRN-01 | B7: AI Awareness | C7: All employees, agency workers and relevant contractors | D7: Level 1 | E7: Mandatory | F7: At induction and before Council AI use | G7: Recognise AI; understand Council principles, registration, acceptable use, data handling, human accountability and concern routes. | H7: Accessible e-learning with short knowledge check | I7: HR / L&D with AI Governance Lead | J7: Draft design | L7: At least annually | M7: Completion, pass score, feedback and incident trend | N7: 1 | O7: 0 | R7: OBJ-08; R-05; IMP-09 | S7: ISO 7.2-7.3; A.3.3, A.4.6 | T7: Confirm target population, pass score, accessibility and LMS reporting. | U7: =IF(AND(A7<>"",B7<>"",C7<>"",D7<>"",E7<>"",F7<>"",G7<>"",H7<>"",I7<>"",J7<>"",L7<>"",M7<>"",ISNUMBER(N7),ISNUMBER(O7),R7<>"",S7<>"",T7<>""),IF(J7="Draft design","Complete",IF(AND(K7<>"",P7<>"",Q7<>""),"Complete","Delivery evidence incomplete")),"Incomplete")
A8: TRN-02 | B8: Approved AI Use, Acceptable Use and Data Handling | C8: Regular AI users and practitioners | D8: Level 2 | E8: Mandatory for AI users | F8: Before access to an approved AI system | G8: Apply approved instructions; protect information; verify outputs; maintain human responsibility; report errors, incidents and suspected unregistered use. | H8: System-linked e-learning plus local briefing | I8: Service Owner / Information Governance | J8: Draft design | L8: Annual and on instruction change | M8: Knowledge check, observed practice, user error and incident data | N8: 1 | O8: 0 | R8: OBJ-04, OBJ-05; R-05, R-10; CMP-02 | S8: ISO 7.2-7.3, 8.1; A.4.6, A.9.2 | T8: Link access provisioning to completion where technically and lawfully appropriate. | U8: =IF(AND(A8<>"",B8<>"",C8<>"",D8<>"",E8<>"",F8<>"",G8<>"",H8<>"",I8<>"",J8<>"",L8<>"",M8<>"",ISNUMBER(N8),ISNUMBER(O8),R8<>"",S8<>"",T8<>""),IF(J8="Draft design","Complete",IF(AND(K8<>"",P8<>"",Q8<>""),"Complete","Delivery evidence incomplete")),"Incomplete")
A9: TRN-03 | B9: AI Governance for Managers | C9: Managers of staff who use, commission or oversee AI | D9: Level 3 | E9: Mandatory for in-scope managers | F9: On appointment or before supervisory responsibility | G9: Recognise governance triggers; assign owners; prevent shadow AI; support oversight, challenge, escalation and staff capability. | H9: Workshop or facilitated e-learning with scenarios | I9: AI Governance Lead / HR-L&D | J9: Draft design | L9: At least annually | M9: Scenario score, manager confidence, registration and escalation trends | N9: 1 | O9: 0 | R9: OBJ-01, OBJ-08; R-02, R-05; CMP-03 | S9: ISO 5.3, 7.2-7.3; A.4.6, A.9.2 | T9: Confirm manager population and appointment timeframe. | U9: =IF(AND(A9<>"",B9<>"",C9<>"",D9<>"",E9<>"",F9<>"",G9<>"",H9<>"",I9<>"",J9<>"",L9<>"",M9<>"",ISNUMBER(N9),ISNUMBER(O9),R9<>"",S9<>"",T9<>""),IF(J9="Draft design","Complete",IF(AND(K9<>"",P9<>"",Q9<>""),"Complete","Delivery evidence incomplete")),"Incomplete")
A10: TRN-04 | B10: Service and System Owner Lifecycle Governance | C10: Service Owners, System Owners, operational leads and secretariat | D10: Level 3 | E10: Mandatory for assigned owners | F10: Before ownership or approval authority | G10: Operate intake, AGPI, assessments, decision records, conditions, monitoring, material change, evidence, incidents and retirement. | H10: Facilitated case-based workshop using suite artefacts | I10: AI Governance Lead | J10: Draft design | L10: Annual calibration and on process change | M10: Completed case, evidence-quality review and governance rework rate | N10: 1 | O10: 0 | R10: OBJ-01, OBJ-02, OBJ-04; R-03 to R-05; IMP-05, IMP-09 | S10: ISO 5.3, 7.2, 8.1; A.3.2, A.6.2, A.9.2 | T10: Use representative Council cases and record assessor conclusions. | U10: =IF(AND(A10<>"",B10<>"",C10<>"",D10<>"",E10<>"",F10<>"",G10<>"",H10<>"",I10<>"",J10<>"",L10<>"",M10<>"",ISNUMBER(N10),ISNUMBER(O10),R10<>"",S10<>"",T10<>""),IF(J10="Draft design","Complete",IF(AND(K10<>"",P10<>"",Q10<>""),"Complete","Delivery evidence incomplete")),"Incomplete")
A11: TRN-05 | B11: Responsible AI and Impact Assessment | C11: Owners, governance members, legal/equality/rights/safeguarding and engagement roles | D11: Levels 3-4 | E11: Mandatory where role applies | F11: Before assessing or approving potentially material impacts | G11: Identify people and societal impacts; apply Responsible AI, DPIA, equality and human-rights assessments; plan participation, mitigation and monitoring. | H11: Cross-functional workshop and case challenge | I11: AI Governance Lead with specialist functions | J11: Draft design | L11: Annual and on material legal/process change | M11: Assessment sample quality, challenge outcomes, action closure and complaints | N11: 1 | O11: 0 | R11: OBJ-03, OBJ-05; R-06, R-08, R-13; CMP-04, CMP-07, CMP-09 | S11: ISO 4.2, 6.1, 8.1; A.5.2-A.5.5, A.8.2-A.8.5 | T11: Specialist functions define required depth and sign-off. | U11: =IF(AND(A11<>"",B11<>"",C11<>"",D11<>"",E11<>"",F11<>"",G11<>"",H11<>"",I11<>"",J11<>"",L11<>"",M11<>"",ISNUMBER(N11),ISNUMBER(O11),R11<>"",S11<>"",T11<>""),IF(J11="Draft design","Complete",IF(AND(K11<>"",P11<>"",Q11<>""),"Complete","Delivery evidence incomplete")),"Incomplete")
A12: TRN-06 | B12: Data Protection, Information Governance and Data Quality | C12: Owners, practitioners, data and IG roles | D12: Levels 2-4 | E12: Mandatory / role-based | F12: Before relevant data processing or approval | G12: Apply lawful/approved data use, minimisation, transparency, rights, provenance, quality, representativeness, retention and sharing controls. | H12: Role-based modules plus case clinics | I12: DPO / Information Governance / Data Governance | J12: Draft design | L12: Annual and on material change | M12: Assessment quality, data exceptions, DPIA outcomes and audit findings | N12: 1 | O12: 0 | R12: OBJ-03, OBJ-04; R-07, R-13; CMP-02, CMP-07 | S12: ISO 7.2, 8.1; A.4.3, A.5, A.7 | T12: Integrate with existing mandatory information-governance learning. | U12: =IF(AND(A12<>"",B12<>"",C12<>"",D12<>"",E12<>"",F12<>"",G12<>"",H12<>"",I12<>"",J12<>"",L12<>"",M12<>"",ISNUMBER(N12),ISNUMBER(O12),R12<>"",S12<>"",T12<>""),IF(J12="Draft design","Complete",IF(AND(K12<>"",P12<>"",Q12<>""),"Complete","Delivery evidence incomplete")),"Incomplete")
A13: TRN-07 | B13: AI Security, Misuse and Resilience | C13: Technical, security, owner and incident roles | D13: Levels 3-4 | E13: Mandatory for relevant roles | F13: Before design approval, security review or operational ownership | G13: Address AI-specific threats, access, logging, misuse, vulnerabilities, supplier controls, resilience, monitoring and secure rollback. | H13: Technical workshop, threat modelling and tabletop exercise | I13: Cyber Security | J13: Draft design | L13: Annual and on threat/material system change | M13: Threat-model quality, exercise outcomes, findings and incident trends | N13: 1 | O13: 0 | R13: OBJ-04, OBJ-07; R-10, R-12; CMP-05, CMP-06, CMP-08 | S13: ISO 7.2, 8.1; A.4.4-A.4.5, A.6.2.4-A.6.2.8 | T13: Align to corporate security training and incident processes. | U13: =IF(AND(A13<>"",B13<>"",C13<>"",D13<>"",E13<>"",F13<>"",G13<>"",H13<>"",I13<>"",J13<>"",L13<>"",M13<>"",ISNUMBER(N13),ISNUMBER(O13),R13<>"",S13<>"",T13<>""),IF(J13="Draft design","Complete",IF(AND(K13<>"",P13<>"",Q13<>""),"Complete","Delivery evidence incomplete")),"Incomplete")
A14: TRN-08 | B14: AI Procurement, Supplier Assurance and Contract Controls | C14: Procurement, commercial, Legal, Service Owners and contract managers | D14: Levels 3-4 | E14: Mandatory for material AI sourcing | F14: Before market engagement, contract, renewal or material change | G14: Trigger governance early; conduct due diligence; specify evidence, change, incident, performance, audit, continuity and exit obligations. | H14: Procurement clinic and supplier-case assessment | I14: Procurement / Legal / AI Governance Lead | J14: Draft design | L14: Annual and on template/legal change | M14: Supplier case quality, clause exceptions, findings, change notices and exit readiness | N14: 1 | O14: 0 | R14: OBJ-06; R-09, R-10, R-15; CMP-10 | S14: ISO 7.2, 8.1; A.10.2-A.10.4 | T14: Embed triggers into procurement guidance and assurance gates. | U14: =IF(AND(A14<>"",B14<>"",C14<>"",D14<>"",E14<>"",F14<>"",G14<>"",H14<>"",I14<>"",J14<>"",L14<>"",M14<>"",ISNUMBER(N14),ISNUMBER(O14),R14<>"",S14<>"",T14<>""),IF(J14="Draft design","Complete",IF(AND(K14<>"",P14<>"",Q14<>""),"Complete","Delivery evidence incomplete")),"Incomplete")
A15: TRN-09 | B15: Governance Decision-Maker Induction and Calibration | C15: Executive Sponsor, Board, Working Group, chairs and secretariat | D15: Levels 4-5 | E15: Mandatory before governance participation | F15: Before first meeting or decision | G15: Understand mandate, delegations, conflicts, evidence expectations, risk tiering, specialist authority, decision recording, escalation and management review. | H15: Induction pack, facilitated case calibration and annual update | I15: AI Governance Lead | J15: Draft design | L15: Annual and on Terms of Reference/delegation change | M15: Attendance, calibration consistency, decision-record quality and rework | N15: 1 | O15: 0 | R15: OBJ-02, OBJ-08; R-01, R-03 to R-05; IMP-05 | S15: ISO 5.1, 5.3, 7.2-7.4, 9.3; A.3.2 | T15: Do not grant decision authority solely through training; formal appointment is also required. | U15: =IF(AND(A15<>"",B15<>"",C15<>"",D15<>"",E15<>"",F15<>"",G15<>"",H15<>"",I15<>"",J15<>"",L15<>"",M15<>"",ISNUMBER(N15),ISNUMBER(O15),R15<>"",S15<>"",T15<>""),IF(J15="Draft design","Complete",IF(AND(K15<>"",P15<>"",Q15<>""),"Complete","Delivery evidence incomplete")),"Incomplete")
A16: TRN-10 | B16: AI Incident, Concern, Complaint and Tabletop Response | C16: Owners, governance, security, DPO, Legal, communications and complaints roles | D16: Levels 2-5 | E16: Mandatory where role applies | F16: Before go-live or incident-response duty | G16: Triage and contain; notify; preserve evidence; communicate; investigate root cause; manage complaints/redress; verify corrective-action effectiveness. | H16: Cross-functional tabletop using AIG-OPS-03 | I16: Incident Lead / AI Governance Lead | J16: Draft design | L16: At least annually and after material incident | M16: Exercise results, response time, missed hand-offs, action closure and recurrence | N16: 1 | O16: 0 | R16: OBJ-05, OBJ-07; R-08, R-12; IMP-13 | S16: ISO 7.2-7.4, 10.2; A.3.3, A.8.3-A.8.4 | T16: Align severity and notification with Council incident frameworks. | U16: =IF(AND(A16<>"",B16<>"",C16<>"",D16<>"",E16<>"",F16<>"",G16<>"",H16<>"",I16<>"",J16<>"",L16<>"",M16<>"",ISNUMBER(N16),ISNUMBER(O16),R16<>"",S16<>"",T16<>""),IF(J16="Draft design","Complete",IF(AND(K16<>"",P16<>"",Q16<>""),"Complete","Delivery evidence incomplete")),"Incomplete")
A17: TRN-11 | B17: Technical Verification, Validation, Monitoring and Change | C17: Technical leads, data scientists, System Owners and reviewers | D17: Level 4 | E17: Mandatory for technical authority | F17: Before testing, release, monitoring or material-change decisions | G17: Define acceptance criteria; test limitations and affected groups; monitor drift/performance; maintain traceability; trigger change control and rollback. | H17: Technical lab, peer review and evidence assessment | I17: Technical Leadership / AI Governance Lead | J17: Draft design | L17: Annual CPD and on material technology change | M17: Test/evidence sample quality, threshold breaches, change and incident trends | N17: 1 | O17: 0 | R17: OBJ-04; R-07, R-10, R-11; CMP-05, CMP-06 | S17: ISO 7.2, 8.1, 9.1; A.6.2.5-A.6.2.8, A.7 | T17: Tailor depth to system risk and technical role. | U17: =IF(AND(A17<>"",B17<>"",C17<>"",D17<>"",E17<>"",F17<>"",G17<>"",H17<>"",I17<>"",J17<>"",L17<>"",M17<>"",ISNUMBER(N17),ISNUMBER(O17),R17<>"",S17<>"",T17<>""),IF(J17="Draft design","Complete",IF(AND(K17<>"",P17<>"",Q17<>""),"Complete","Delivery evidence incomplete")),"Incomplete")
A18: TRN-12 | B18: Advanced AIMS Implementation and Independent Assurance | C18: AI Governance Lead, nominated deputies and Internal Audit | D18: Levels 4-5 | E18: Mandatory for AIMS/audit leads | F18: Before leading implementation or independent audit | G18: Apply ISO/IEC 42001 requirements; maintain scope, SoA, objectives, risks and evidence; plan audits and management review; manage nonconformity and improvement. | H18: Advanced practitioner course, supervised application and independent review | I18: Executive Sponsor / Head of Internal Audit | J18: Draft design | L18: Annual CPD and standards change | M18: Practical work product, audit quality, finding consistency and improvement outcomes | N18: 1 | O18: 0 | R18: OBJ-08; R-05, R-14; IMP-02, IMP-14, IMP-15 | S18: ISO clauses 4-10; Annex A | T18: Confirm independence and avoid self-audit of controls operated by the same individual. | U18: =IF(AND(A18<>"",B18<>"",C18<>"",D18<>"",E18<>"",F18<>"",G18<>"",H18<>"",I18<>"",J18<>"",L18<>"",M18<>"",ISNUMBER(N18),ISNUMBER(O18),R18<>"",S18<>"",T18<>""),IF(J18="Draft design","Complete",IF(AND(K18<>"",P18<>"",Q18<>""),"Complete","Delivery evidence incomplete")),"Incomplete")

Sheet Communications Plan
A1: The Council — AIMS Communications Plan
A2: AIG-AIMS-04 · v1.3 draft · Draft for Council review · OFFICIAL · ISO/IEC 42001:2023
A3: Purpose: control AIMS messages, audiences, ownership, channels, triggers, accessibility, evidence and effectiveness for internal and external interested parties.
A4: Current position: all activities are draft designs. Approve the message, sender, audience, timing, accessibility, confidentiality and evidence before issue; retain actual publication and effectiveness records.
A6: Communication ID | B6: Objective / core message | C6: Audience / interested party | D6: Owner | E6: Sender / approver | F6: Channel | G6: Timing / trigger | H6: Frequency | I6: Accessibility / consultation | J6: Required record / evidence | K6: Status | L6: Target date | M6: Last issued | N6: Effectiveness measure | O6: Related objectives / risks / actions | P6: ISO / SoA links | Q6: Decision / design note | R6: Record QA
A7: COM-01 | B7: Formal leadership adoption: explain scope, mandate, accountable ownership, delegations, resources and effective date. | C7: Executive Leadership, governance bodies, control-function heads and directorate leadership | D7: Executive Sponsor | E7: Adopting authority / corporate communications | F7: Formal decision, leadership briefing and controlled publication | G7: On approval of the AIMS and any material governance change | H7: Once, then on material change | I7: Accessible summary; opportunity for questions and recorded specialist consultation | J7: Approval record, published message, audience list, questions/actions | K7: Draft design | N7: Receipt, leadership understanding, unresolved questions and assigned actions | O7: OBJ-08; R-01, R-04; IMP-01, IMP-03, IMP-05 | P7: ISO 5.1-5.3, 7.3-7.4; A.2.2, A.3.2 | Q7: Must not describe draft documents as approved or operational. | R7: =IF(AND(A7<>"",B7<>"",C7<>"",D7<>"",E7<>"",F7<>"",G7<>"",H7<>"",I7<>"",J7<>"",K7<>"",N7<>"",O7<>"",P7<>"",Q7<>""),IF(K7="Draft design","Complete",IF(AND(L7<>"",M7<>""),"Complete","Issue evidence incomplete")),"Incomplete")
A8: COM-02 | B8: All-staff awareness: approved AI use, registration, acceptable-use rules, human responsibility and routes for concerns. | C8: All employees, agency workers and relevant contractors | D8: AI Governance Lead / HR-L&D | E8: Executive Sponsor / Internal Communications | F8: Intranet, staff bulletin, learning campaign and manager cascade | G8: At launch; induction; major policy or risk change | H8: Annual campaign plus triggered updates | I8: Accessible formats, plain language and feedback route | J8: Published content, audience/reach data, learning link and FAQs | K8: Draft design | N8: Reach, learning completion, knowledge score, registrations and reported shadow AI | O8: OBJ-01, OBJ-08; R-02, R-05; IMP-06, IMP-09 | P8: ISO 7.3-7.4; A.3.3, A.4.6, A.9.2 | Q8: Align with AIG-INV-01 staff guide and approved policy. | R8: =IF(AND(A8<>"",B8<>"",C8<>"",D8<>"",E8<>"",F8<>"",G8<>"",H8<>"",I8<>"",J8<>"",K8<>"",N8<>"",O8<>"",P8<>"",Q8<>""),IF(K8="Draft design","Complete",IF(AND(L8<>"",M8<>""),"Complete","Issue evidence incomplete")),"Incomplete")
A9: COM-03 | B9: Manager and owner briefing: governance triggers, accountability, approval tiers, evidence and escalation. | C9: Managers, Service Owners, System Owners and delivery leads | D9: AI Governance Lead | E9: AI Governance Lead / Directorate Leadership | F9: Briefing session, manager toolkit and office hours | G9: Before ownership or supervisory duty; at launch | H9: At least annually and on process change | I9: Scenario-led, role-specific and available in accessible formats | J9: Attendance, toolkit version, questions, actions and competence assessment | K9: Draft design | N9: Attendance, scenario results, registration timeliness and governance rework | O9: OBJ-02, OBJ-08; R-03 to R-05; IMP-05, IMP-09 | P9: ISO 5.3, 7.2-7.4; A.3.2, A.4.6 | Q9: Coordinate with TRN-03 and TRN-04. | R9: =IF(AND(A9<>"",B9<>"",C9<>"",D9<>"",E9<>"",F9<>"",G9<>"",H9<>"",I9<>"",J9<>"",K9<>"",N9<>"",O9<>"",P9<>"",Q9<>""),IF(K9="Draft design","Complete",IF(AND(L9<>"",M9<>""),"Complete","Issue evidence incomplete")),"Incomplete")
A10: COM-04 | B10: AI Register and intake guidance: when and how to register, expected response, status meanings and support route. | C10: Council staff, project teams, procurement, suppliers working through Council teams | D10: AI Governance Lead | E10: AI Governance Working Group Chair | F10: Intranet guidance, intake form, drop-in clinics and project templates | G10: At launch; new project/procurement; form/process change | H10: Continuous availability; quarterly reminder during implementation | I10: Accessible form and guidance; assisted route for users who need it | J10: Published version, usage data, enquiries, response times and form changes | K10: Draft design | N10: Registration volume/completeness, abandoned requests, response time and user feedback | O10: OBJ-01, OBJ-02; R-02, R-03; IMP-06, IMP-07 | P10: ISO 7.4, 8.1; A.4.2, A.8.5, A.9.2 | Q10: Use one AI Register ID across all evidence. | R10: =IF(AND(A10<>"",B10<>"",C10<>"",D10<>"",E10<>"",F10<>"",G10<>"",H10<>"",I10<>"",J10<>"",K10<>"",N10<>"",O10<>"",P10<>"",Q10<>""),IF(K10="Draft design","Complete",IF(AND(L10<>"",M10<>""),"Complete","Issue evidence incomplete")),"Incomplete")
A11: COM-05 | B11: Governance body induction and decision protocol: mandate, evidence, conflicts, specialist authority and decision records. | C11: Executive Sponsor, Board, Working Group, secretariat and regular advisers | D11: AI Governance Lead | E11: AI Governance Lead / relevant Chair | F11: Induction pack, calibrated case workshop and meeting standing items | G11: Before participation and on appointment/delegation change | H11: Annual calibration plus triggered update | I11: Materials issued early; conflicts and accessibility needs captured | J11: Attendance, declarations, calibration result, minutes and updated pack | K11: Draft design | N11: Decision consistency, evidence quality, conflicts handled and rework | O11: OBJ-02, OBJ-08; R-01, R-03, R-04; IMP-05 | P11: ISO 5.3, 7.2-7.4; A.3.2 | Q11: Training does not itself confer decision authority. | R11: =IF(AND(A11<>"",B11<>"",C11<>"",D11<>"",E11<>"",F11<>"",G11<>"",H11<>"",I11<>"",J11<>"",K11<>"",N11<>"",O11<>"",P11<>"",Q11<>""),IF(K11="Draft design","Complete",IF(AND(L11<>"",M11<>""),"Complete","Issue evidence incomplete")),"Incomplete")
A12: COM-06 | B12: Specialist-control integration: confirm retained authority, hand-offs, service levels, evidence and escalation. | C12: DPO/IG, SIRO, Security, Legal, Procurement, Data, Equality, Human Rights, Safeguarding, Audit | D12: AI Governance Lead | E12: Executive Sponsor / relevant Function Heads | F12: Cross-functional workshop, operating agreement and process maps | G12: Before AIMS activation and on material organisational change | H12: At least annually | I12: Allow specialist functions to document constraints and resourcing needs | J12: Agreed interfaces, action log, service expectations and escalation records | K12: Draft design | N12: Hand-off failures, overdue reviews, disputed authority and resource actions | O12: OBJ-02, OBJ-08; R-04, R-05; IMP-05 | P12: ISO 5.3, 7.1, 7.4; A.3.2 | Q12: AIG-GOV-06 states specialist functions retain their authority. | R12: =IF(AND(A12<>"",B12<>"",C12<>"",D12<>"",E12<>"",F12<>"",G12<>"",H12<>"",I12<>"",J12<>"",K12<>"",N12<>"",O12<>"",P12<>"",Q12<>""),IF(K12="Draft design","Complete",IF(AND(L12<>"",M12<>""),"Complete","Issue evidence incomplete")),"Incomplete")
A13: COM-07 | B13: Supplier and market communication: disclose Council AI governance, due-diligence evidence, contract, change, incident and exit expectations. | C13: Bidders, suppliers, partners, contract owners and procurement teams | D13: Procurement / Contract Owner | E13: Legal / authorised procurement approver | F13: Procurement documents, contracts, supplier briefings and review meetings | G13: Before market engagement; contract/renewal; material supplier change | H13: Per procurement and scheduled supplier review | I13: Proportionate to market and procurement law; accessible supplier route for clarification | J13: Issued requirements, questions, due diligence, clauses, exceptions and review minutes | K13: Draft design | N13: Compliance, exceptions, evidence timeliness, unnotified change and exit readiness | O13: OBJ-06; R-09, R-10, R-15; IMP-10 | P13: ISO 7.4, 8.1; A.10.2-A.10.4 | Q13: Do not disclose sensitive security detail outside approved channels. | R13: =IF(AND(A13<>"",B13<>"",C13<>"",D13<>"",E13<>"",F13<>"",G13<>"",H13<>"",I13<>"",J13<>"",K13<>"",N13<>"",O13<>"",P13<>"",Q13<>""),IF(K13="Draft design","Complete",IF(AND(L13<>"",M13<>""),"Complete","Issue evidence incomplete")),"Incomplete")
A14: COM-08 | B14: Live-system operational communication: approved purpose, limits, instructions, oversight, thresholds, escalation and rollback. | C14: Authorised users, supervisors, support teams and operational owners | D14: AI System Owner / Service Owner | E14: Service Owner and relevant control owners | F14: Operating procedure, user briefing, in-product guidance and release notice | G14: Before go-live/access; material change; threshold or incident response | H14: At every release/change plus periodic refresh | I14: Role-specific, accessible and tested with representative users | J14: Approved instructions, attendance/acknowledgement, release record and user feedback | K14: Draft design | N14: Instruction comprehension, user error, overrides, incidents and support demand | O14: OBJ-04, OBJ-05, OBJ-07; R-08, R-10, R-11 | P14: ISO 7.3-7.4, 8.1; A.6.2.6-A.6.2.8, A.9.2 | Q14: Link to AIG-ASS-09 Model Card and AIG-OPS-01 rollout evidence. | R14: =IF(AND(A14<>"",B14<>"",C14<>"",D14<>"",E14<>"",F14<>"",G14<>"",H14<>"",I14<>"",J14<>"",K14<>"",N14<>"",O14<>"",P14<>"",Q14<>""),IF(K14="Draft design","Complete",IF(AND(L14<>"",M14<>""),"Complete","Issue evidence incomplete")),"Incomplete")
A15: COM-09 | B15: Resident/service-user transparency: explain relevant AI use, purpose, human role, significant limits, data/rights, accessibility, contact and redress. | C15: Residents, service users, communities and affected groups | D15: Service Owner / Communications | E15: Authorised service owner with DPO/Legal/specialist review | F15: Service pages, notices, letters, assisted channels and engagement sessions | G15: Before applicable use; material purpose/impact change; emerging concern | H15: Continuous availability and periodic review | I15: Plain language, accessible formats, language/assisted routes and proportionate affected-group testing | J15: Approved content, accessibility/user testing, consultation, publication and change records | K15: Draft design | N15: Understanding, accessibility findings, contact/complaint themes and resulting service changes | O15: OBJ-03, OBJ-05; R-06, R-08, R-13 | P15: ISO 4.2, 7.4; A.5.4, A.8.2-A.8.5 | Q15: Apply proportionality; legal/privacy notices remain subject to specialist approval. | R15: =IF(AND(A15<>"",B15<>"",C15<>"",D15<>"",E15<>"",F15<>"",G15<>"",H15<>"",I15<>"",J15<>"",K15<>"",N15<>"",O15<>"",P15<>"",Q15<>""),IF(K15="Draft design","Complete",IF(AND(L15<>"",M15<>""),"Complete","Issue evidence incomplete")),"Incomplete")
A16: COM-10 | B16: Urgent incident and risk communication: what happened, containment, affected parties, actions, contact and update cadence. | C16: Incident team, leadership, regulators/partners where required, staff, residents and media as applicable | D16: Incident Lead | E16: Authorised incident/corporate communications owner with specialist clearance | F16: Secure incident channels, notifications, service updates and holding statements | G16: Severity-based trigger under approved incident plan | H16: As required until closure | I16: Protect confidentiality; use accessible/public channels where affected people need timely information | J16: Incident log, approvals, notifications, message versions, receipt and follow-up | K16: Draft design | N16: Notification timeliness, accuracy, reach, misinformation, complaints and lessons learned | O16: OBJ-05, OBJ-07; R-08, R-12; IMP-13 | P16: ISO 7.4, 10.2; A.3.3, A.8.3-A.8.4 | Q16: Align severity, notification and legal duties with corporate processes. | R16: =IF(AND(A16<>"",B16<>"",C16<>"",D16<>"",E16<>"",F16<>"",G16<>"",H16<>"",I16<>"",J16<>"",K16<>"",N16<>"",O16<>"",P16<>"",Q16<>""),IF(K16="Draft design","Complete",IF(AND(L16<>"",M16<>""),"Complete","Issue evidence incomplete")),"Incomplete")
A17: COM-11 | B17: AIMS performance and assurance reporting: objectives, risk, inventory, control effectiveness, incidents, learning, audit and actions. | C17: Working Group, Board, Executive Sponsor, leadership and assurance committees | D17: AI Governance Lead | E17: Relevant Chair / Executive Sponsor | F17: Dashboard, governance report, management-review pack and audit updates | G17: Approved reporting calendar; material exception; management review | H17: Monthly during implementation; at least quarterly thereafter | I17: Clear definitions, data-quality notes, exceptions and decision requests | J17: Controlled report, source data, minutes, decisions and action log | K17: Draft design | N17: Data completeness/accuracy, decisions made, overdue actions and trend response | O17: OBJ-01 to OBJ-08; R-14; IMP-12, IMP-14, IMP-15 | P17: ISO 9.1-9.3, 10.1; A.8.5 | Q17: Do not imply control effectiveness without operating evidence. | R17: =IF(AND(A17<>"",B17<>"",C17<>"",D17<>"",E17<>"",F17<>"",G17<>"",H17<>"",I17<>"",J17<>"",K17<>"",N17<>"",O17<>"",P17<>"",Q17<>""),IF(K17="Draft design","Complete",IF(AND(L17<>"",M17<>""),"Complete","Issue evidence incomplete")),"Incomplete")
