Workbook

Sheet READ ME
A1: AIG-DEC-04 | Using the separate Gate Log
A3: Status | B3: Draft for Council review — unpopulated design draft; not adopted policy or an operational replacement.
A4: Plan ≠ event | B4: Gate plan is prospective. Only a dated Gate events row says a gate occurred. A plan cannot grant approval.
A5: Event ≠ authority | B5: An assurance opinion or review may be logged without being an approval. Record the delegated decision-maker and authoritative AIG-DEC-03 decision or approved-minutes reference for a decision event.
A6: Conditions | B6: Keep each condition as its own row linked to a dated Decision event (Outcome ‘Progress with condition’, ‘Re-authorise’ or ‘Resume’); record the action, owner, due date, state, verifier/date and closure evidence or waiver authority. Overdue is derived from the due date, never typed.
A7: Join to AIG-INV-04 | B7: Use the same controlled AIR-ID as the AIG-INV-04 Register. There are no fragile external-workbook formulas; reconcile AIG-INV-04 current status and latest Event ID to the actual AIG-DEC-04 event and decision record.
A8: Separate system map | B8: The proposed standalone Capabilities and System Map links use cases, capabilities and components to controlled AIR-IDs. It is not this Gate Log, the AIG-DEC-01 governance Gate Map or an approval source. No gate is proved by a map link.
A9: Before migration | B9: Agree field dispositions with the owners of the Council's existing (pre-suite) gate and decision logs, split legacy multi-condition cells without losing meaning, reconcile event IDs and actual delegations, test with controlled records in Excel, approve cutover and archive sources. None were migrated here.
A10: Priority override | B10: A priority override is its own Event type. Record the delegated decision-maker and the AIG-DEC-03 or approved-minutes reference; the priority before and after, reason and Assurance update reference live in that record. Leave Outcome blank or No decision: an override changes governance attention, not progress through a gate.
A11: Change 29 Sep 2026 | B11: Added Event type “Priority override” and its row check, so the override route in AIG-ASS-01 and Playbook Annex G.4 has a controlled home.
A12: One outcome per UC-ID | B12: AIG-DEC-03 (or approved minutes) is the authoritative decision record, one outcome per UC-ID. Log one Gate events row per UC-ID: where one meeting decides several uses, enter a row for each (Event ID with a suffix, e.g. EVT-0012-a, EVT-0012-b) with that use's own outcome. A row listing several UC-IDs is flagged by the Row check.
A13: Controlled lists | B13: Gate / forum uses the AIG-DEC-01 gates on the Lists sheet (configure forum names locally). Event types include Intake / registration; outcomes include Suspend, Decommission, Re-authorise and Resume (lifts a precautionary pause; allowed only in the event straight after the pause for the same use). The Lists sheet maps each outcome to the AIG-DEC-03 outcome vocabulary and each condition state to AIG-DEC-03 and the UC-ID current view.
A14: Evidence, source and time | B14: Gate events carry Time, Source and Evidence ID(s) (AIG-INV-04 Evidence index) and the event-time lifecycle stage (columns R–U). Conditions carry Verified by / date and, for monitoring conditions, the AIG-OPS-02 evidence ref needed before closure.
... A21: Change 3 Oct 2026 | B21: v3.9.8: column X (screening considered), Outcome Resume (Lists row 16) and locked row-check columns. See Document Control.

Sheet Gate plan
A1: AIG-DEC-04 / GATE PLAN — WHAT IS EXPECTED
A2: Prospective requirements only. A plan is not evidence that a gate happened or that a use was approved. | K2: Gate plans are prospective requirements, never approval. State whether the planned gate concerns named UC-ID(s) or a shared system baseline. The duplicate check keys on AIR-ID + UC-ID scope + gate: each use of a system has its own plan rows, and a system-level row (blank UC-ID) counts separately.
A3: Plan ID | B3: AIR-ID | C3: Gate / forum | D3: Trigger / stage | E3: Requirement | F3: Basis / triage ref | G3: Target date | H3: Responsible role | I3: Plan state | J3: N-A / waiver rationale and authority ref | K3: UC-ID scope(s) (blank only for explicit system baseline) | L3: Decision scope (UC-ID specific / Shared system baseline) | M3: Row check
M4: =IF(COUNTA(A4:L4)=0,"",IF(A4="","Plan ID missing",IF(COUNTIF($A$4:$A$353,A4)>1,"Duplicate Plan ID",IF(B4="","AIR-ID missing",IF(C4="","Gate / forum missing",IF(AND(I4="Planned",COUNTIFS($B$4:$B$353,B4,$C$4:$C$353,C4,$K$4:$K$353,K4&"",$I$4:$I$353,"Planned")>1),"More than one active plan for this AIR-ID, UC-ID scope and gate",IF(AND(E4="Not applicable",J4=""),"Not applicable needs rationale and authority ref",IF(AND(E4="Required",F4=""),"Required gate needs basis / triage ref",IF(L4="","Decision scope missing",IF(AND(L4="UC-ID specific",K4=""),"UC-ID required",IF(AND(L4="Shared system baseline",K4<>""),"Remove UC-ID or correct scope",IF(AND(G4<>"",NOT(ISNUMBER(G4))),"Target date is not a date",IF(E4="","Requirement missing",IF(I4="","Plan state missing","Check against source"))))))))))))))
M5: =IF(COUNTA(A5:L5)=0,"",IF(A5="","Plan ID missing",IF(COUNTIF($A$4:$A$353,A5)>1,"Duplicate Plan ID",IF(B5="","AIR-ID missing",IF(C5="","Gate / forum missing",IF(AND(I5="Planned",COUNTIFS($B$4:$B$353,B5,$C$4:$C$353,C5,$K$4:$K$353,K5&"",$I$4:$I$353,"Planned")>1),"More than one active plan for this AIR-ID, UC-ID scope and gate",IF(AND(E5="Not applicable",J5=""),"Not applicable needs rationale and authority ref",IF(AND(E5="Required",F5=""),"Required gate needs basis / triage ref",IF(L5="","Decision scope missing",IF(AND(L5="UC-ID specific",K5=""),"UC-ID required",IF(AND(L5="Shared system baseline",K5<>""),"Remove UC-ID or correct scope",IF(AND(G5<>"",NOT(ISNUMBER(G5))),"Target date is not a date",IF(E5="","Requirement missing",IF(I5="","Plan state missing","Check against source"))))))))))))))
M6: =IF(COUNTA(A6:L6)=0,"",IF(A6="","Plan ID missing",IF(COUNTIF($A$4:$A$353,A6)>1,"Duplicate Plan ID",IF(B6="","AIR-ID missing",IF(C6="","Gate / forum missing",IF(AND(I6="Planned",COUNTIFS($B$4:$B$353,B6,$C$4:$C$353,C6,$K$4:$K$353,K6&"",$I$4:$I$353,"Planned")>1),"More than one active plan for this AIR-ID, UC-ID scope and gate",IF(AND(E6="Not applicable",J6=""),"Not applicable needs rationale and authority ref",IF(AND(E6="Required",F6=""),"Required gate needs basis / triage ref",IF(L6="","Decision scope missing",IF(AND(L6="UC-ID specific",K6=""),"UC-ID required",IF(AND(L6="Shared system baseline",K6<>""),"Remove UC-ID or correct scope",IF(AND(G6<>"",NOT(ISNUMBER(G6))),"Target date is not a date",IF(E6="","Requirement missing",IF(I6="","Plan state missing","Check against source"))))))))))))))
M7: =IF(COUNTA(A7:L7)=0,"",IF(A7="","Plan ID missing",IF(COUNTIF($A$4:$A$353,A7)>1,"Duplicate Plan ID",IF(B7="","AIR-ID missing",IF(C7="","Gate / forum missing",IF(AND(I7="Planned",COUNTIFS($B$4:$B$353,B7,$C$4:$C$353,C7,$K$4:$K$353,K7&"",$I$4:$I$353,"Planned")>1),"More than one active plan for this AIR-ID, UC-ID scope and gate",IF(AND(E7="Not applicable",J7=""),"Not applicable needs rationale and authority ref",IF(AND(E7="Required",F7=""),"Required gate needs basis / triage ref",IF(L7="","Decision scope missing",IF(AND(L7="UC-ID specific",K7=""),"UC-ID required",IF(AND(L7="Shared system baseline",K7<>""),"Remove UC-ID or correct scope",IF(AND(G7<>"",NOT(ISNUMBER(G7))),"Target date is not a date",IF(E7="","Requirement missing",IF(I7="","Plan state missing","Check against source"))))))))))))))
M8: =IF(COUNTA(A8:L8)=0,"",IF(A8="","Plan ID missing",IF(COUNTIF($A$4:$A$353,A8)>1,"Duplicate Plan ID",IF(B8="","AIR-ID missing",IF(C8="","Gate / forum missing",IF(AND(I8="Planned",COUNTIFS($B$4:$B$353,B8,$C$4:$C$353,C8,$K$4:$K$353,K8&"",$I$4:$I$353,"Planned")>1),"More than one active plan for this AIR-ID, UC-ID scope and gate",IF(AND(E8="Not applicable",J8=""),"Not applicable needs rationale and authority ref",IF(AND(E8="Required",F8=""),"Required gate needs basis / triage ref",IF(L8="","Decision scope missing",IF(AND(L8="UC-ID specific",K8=""),"UC-ID required",IF(AND(L8="Shared system baseline",K8<>""),"Remove UC-ID or correct scope",IF(AND(G8<>"",NOT(ISNUMBER(G8))),"Target date is not a date",IF(E8="","Requirement missing",IF(I8="","Plan state missing","Check against source"))))))))))))))
M9: =IF(COUNTA(A9:L9)=0,"",IF(A9="","Plan ID missing",IF(COUNTIF($A$4:$A$353,A9)>1,"Duplicate Plan ID",IF(B9="","AIR-ID missing",IF(C9="","Gate / forum missing",IF(AND(I9="Planned",COUNTIFS($B$4:$B$353,B9,$C$4:$C$353,C9,$K$4:$K$353,K9&"",$I$4:$I$353,"Planned")>1),"More than one active plan for this AIR-ID, UC-ID scope and gate",IF(AND(E9="Not applicable",J9=""),"Not applicable needs rationale and authority ref",IF(AND(E9="Required",F9=""),"Required gate needs basis / triage ref",IF(L9="","Decision scope missing",IF(AND(L9="UC-ID specific",K9=""),"UC-ID required",IF(AND(L9="Shared system baseline",K9<>""),"Remove UC-ID or correct scope",IF(AND(G9<>"",NOT(ISNUMBER(G9))),"Target date is not a date",IF(E9="","Requirement missing",IF(I9="","Plan state missing","Check against source"))))))))))))))
M10: =IF(COUNTA(A10:L10)=0,"",IF(A10="","Plan ID missing",IF(COUNTIF($A$4:$A$353,A10)>1,"Duplicate Plan ID",IF(B10="","AIR-ID missing",IF(C10="","Gate / forum missing",IF(AND(I10="Planned",COUNTIFS($B$4:$B$353,B10,$C$4:$C$353,C10,$K$4:$K$353,K10&"",$I$4:$I$353,"Planned")>1),"More than one active plan for this AIR-ID, UC-ID scope and gate",IF(AND(E10="Not applicable",J10=""),"Not applicable needs rationale and authority ref",IF(AND(E10="Required",F10=""),"Required gate needs basis / triage ref",IF(L10="","Decision scope missing",IF(AND(L10="UC-ID specific",K10=""),"UC-ID required",IF(AND(L10="Shared system baseline",K10<>""),"Remove UC-ID or correct scope",IF(AND(G10<>"",NOT(ISNUMBER(G10))),"Target date is not a date",IF(E10="","Requirement missing",IF(I10="","Plan state missing","Check against source"))))))))))))))
M11: =IF(COUNTA(A11:L11)=0,"",IF(A11="","Plan ID missing",IF(COUNTIF($A$4:$A$353,A11)>1,"Duplicate Plan ID",IF(B11="","AIR-ID missing",IF(C11="","Gate / forum missing",IF(AND(I11="Planned",COUNTIFS($B$4:$B$353,B11,$C$4:$C$353,C11,$K$4:$K$353,K11&"",$I$4:$I$353,"Planned")>1),"More than one active plan for this AIR-ID, UC-ID scope and gate",IF(AND(E11="Not applicable",J11=""),"Not applicable needs rationale and authority ref",IF(AND(E11="Required",F11=""),"Required gate needs basis / triage ref",IF(L11="","Decision scope missing",IF(AND(L11="UC-ID specific",K11=""),"UC-ID required",IF(AND(L11="Shared system baseline",K11<>""),"Remove UC-ID or correct scope",IF(AND(G11<>"",NOT(ISNUMBER(G11))),"Target date is not a date",IF(E11="","Requirement missing",IF(I11="","Plan state missing","Check against source"))))))))))))))
M12: =IF(COUNTA(A12:L12)=0,"",IF(A12="","Plan ID missing",IF(COUNTIF($A$4:$A$353,A12)>1,"Duplicate Plan ID",IF(B12="","AIR-ID missing",IF(C12="","Gate / forum missing",IF(AND(I12="Planned",COUNTIFS($B$4:$B$353,B12,$C$4:$C$353,C12,$K$4:$K$353,K12&"",$I$4:$I$353,"Planned")>1),"More than one active plan for this AIR-ID, UC-ID scope and gate",IF(AND(E12="Not applicable",J12=""),"Not applicable needs rationale and authority ref",IF(AND(E12="Required",F12=""),"Required gate needs basis / triage ref",IF(L12="","Decision scope missing",IF(AND(L12="UC-ID specific",K12=""),"UC-ID required",IF(AND(L12="Shared system baseline",K12<>""),"Remove UC-ID or correct scope",IF(AND(G12<>"",NOT(ISNUMBER(G12))),"Target date is not a date",IF(E12="","Requirement missing",IF(I12="","Plan state missing","Check against source"))))))))))))))
M13: =IF(COUNTA(A13:L13)=0,"",IF(A13="","Plan ID missing",IF(COUNTIF($A$4:$A$353,A13)>1,"Duplicate Plan ID",IF(B13="","AIR-ID missing",IF(C13="","Gate / forum missing",IF(AND(I13="Planned",COUNTIFS($B$4:$B$353,B13,$C$4:$C$353,C13,$K$4:$K$353,K13&"",$I$4:$I$353,"Planned")>1),"More than one active plan for this AIR-ID, UC-ID scope and gate",IF(AND(E13="Not applicable",J13=""),"Not applicable needs rationale and authority ref",IF(AND(E13="Required",F13=""),"Required gate needs basis / triage ref",IF(L13="","Decision scope missing",IF(AND(L13="UC-ID specific",K13=""),"UC-ID required",IF(AND(L13="Shared system baseline",K13<>""),"Remove UC-ID or correct scope",IF(AND(G13<>"",NOT(ISNUMBER(G13))),"Target date is not a date",IF(E13="","Requirement missing",IF(I13="","Plan state missing","Check against source"))))))))))))))
M14: =IF(COUNTA(A14:L14)=0,"",IF(A14="","Plan ID missing",IF(COUNTIF($A$4:$A$353,A14)>1,"Duplicate Plan ID",IF(B14="","AIR-ID missing",IF(C14="","Gate / forum missing",IF(AND(I14="Planned",COUNTIFS($B$4:$B$353,B14,$C$4:$C$353,C14,$K$4:$K$353,K14&"",$I$4:$I$353,"Planned")>1),"More than one active plan for this AIR-ID, UC-ID scope and gate",IF(AND(E14="Not applicable",J14=""),"Not applicable needs rationale and authority ref",IF(AND(E14="Required",F14=""),"Required gate needs basis / triage ref",IF(L14="","Decision scope missing",IF(AND(L14="UC-ID specific",K14=""),"UC-ID required",IF(AND(L14="Shared system baseline",K14<>""),"Remove UC-ID or correct scope",IF(AND(G14<>"",NOT(ISNUMBER(G14))),"Target date is not a date",IF(E14="","Requirement missing",IF(I14="","Plan state missing","Check against source"))))))))))))))
M15: =IF(COUNTA(A15:L15)=0,"",IF(A15="","Plan ID missing",IF(COUNTIF($A$4:$A$353,A15)>1,"Duplicate Plan ID",IF(B15="","AIR-ID missing",IF(C15="","Gate / forum missing",IF(AND(I15="Planned",COUNTIFS($B$4:$B$353,B15,$C$4:$C$353,C15,$K$4:$K$353,K15&"",$I$4:$I$353,"Planned")>1),"More than one active plan for this AIR-ID, UC-ID scope and gate",IF(AND(E15="Not applicable",J15=""),"Not applicable needs rationale and authority ref",IF(AND(E15="Required",F15=""),"Required gate needs basis / triage ref",IF(L15="","Decision scope missing",IF(AND(L15="UC-ID specific",K15=""),"UC-ID required",IF(AND(L15="Shared system baseline",K15<>""),"Remove UC-ID or correct scope",IF(AND(G15<>"",NOT(ISNUMBER(G15))),"Target date is not a date",IF(E15="","Requirement missing",IF(I15="","Plan state missing","Check against source"))))))))))))))
... M353: =IF(COUNTA(A353:L353)=0,"",IF(A353="","Plan ID missing",IF(COUNTIF($A$4:$A$353,A353)>1,"Duplicate Plan ID",IF(B353="","AIR-ID missing",IF(C353="","Gate / forum missing",IF(AND(I353="Planned",COUNTIFS($B$4:$B$353,B353,$C$4:$C$353,C353,$K$4:$K$353,K353&"",$I$4:$I$353,"Planned")>1),"More than one active plan for this AIR-ID, UC-ID scope and gate",IF(AND(E353="Not applicable",J353=""),"Not applicable needs rationale and authority ref",IF(AND(E353="Required",F353=""),"Required gate needs basis / triage ref",IF(L353="","Decision scope missing",IF(AND(L353="UC-ID specific",K353=""),"UC-ID required",IF(AND(L353="Shared system baseline",K353<>""),"Remove UC-ID or correct scope",IF(AND(G353<>"",NOT(ISNUMBER(G353))),"Target date is not a date",IF(E353="","Requirement missing",IF(I353="","Plan state missing","Check against source"))))))))))))))

Sheet Gate events
A1: AIG-DEC-04 / GATE EVENTS — WHAT ACTUALLY HAPPENED
A2: One dated occurrence per row. An assurance opinion is not a delegated approval. Decision events need the authoritative AIG-DEC-03 decision or approved-minutes reference. | O2: One dated event row per UC-ID (split multi-use decisions into suffixed Event IDs). UC-ID specific scope is mandatory for use approval; a shared baseline event is not UC approval. A precautionary pause (Playbook §4.7.17) is containment, not a decision: Event type “Precautionary pause (containment)”, Outcome “Paused — pending decision”, no AIG-DEC-03 ref needed; record the AIG-OPS-03 incident ref (V) and the follow-up decision due date (W). To lift the pause with the approval unchanged, record a Decision with Outcome “Resume” in a later row for the same AIR-ID and UC-ID (AIG-DEC-03 ref needed; new conditions go on Conditions rows).
A3: Event ID | B3: AIR-ID | C3: Plan ID (if any) | D3: Gate / forum | E3: Event type | F3: Date | G3: Outcome | H3: Decision-maker / role | I3: AIG-DEC-03 / minutes ref | J3: Assurance opinion ref | K3: Technical snapshot / as-at ref | L3: Next gate / action | M3: Recorded by | N3: Row check | O3: UC-ID(s) covered by this dated event | P3: Decision scope (UC-ID specific / Shared system baseline) | Q3: Decision-scope completeness prompt | R3: Time (hh:mm) | S3: Source (minutes / decision record / system) | T3: Evidence ID(s) (AIG-INV-04 Evidence index) | U3: Event-time lifecycle stage | V3: Incident ref (AIG-OPS-03), precautionary pause | W3: Follow-up decision due date (precautionary pause) | X3: Screening considered by the decision-maker (Yes / No)
N4: =IF(COUNTA(A4:M4,O4:P4,R4:X4)=0,"",IF(OR(A4="",B4="",F4=""),"Event ID, AIR-ID or date missing",IF(COUNTIF($A$4:$A$553,A4)>1,"Duplicate Event ID",IF(E4="","Event type missing",IF(OR(NOT(ISNUMBER(F4)),F4>TODAY()),"Date is not a real date or is in the future",IF(AND(C4<>"",COUNTIF('Gate plan'!$A$4:$A$353,C4)=0),"Plan ID not found in Gate plan",IF(AND(C4<>"",COUNTIFS('Gate plan'!$A$4:$A$353,C4,'Gate plan'!$B$4:$B$353,B4)=0),"Plan AIR-ID differs from event",IF(D4="","Gate / forum missing",IF(AND(E4="Precautionary pause (containment)",G4<>"Paused — pending decision"),"Precautionary pause: Outcome must be Paused, pending decision",IF(AND(E4="Precautionary pause (containment)",V4=""),"Precautionary pause: AIG-OPS-03 incident ref missing",IF(AND(E4="Precautionary pause (containment)",NOT(ISNUMBER(W4))),"Precautionary pause: follow-up decision due date missing",IF(AND(G4="Paused — pending decision",E4<>"Precautionary pause (containment)"),"Paused, pending decision is only for a Precautionary pause event",IF(AND(E4="Decision",OR(G4="",H4="",I4="")),"Outcome / delegation / decision ref missing",IF(AND(E4="Decision",NOT(OR(G4="Progress",G4="Progress with condition",G4="Return for evidence",G4="Pause",G4="Stop",G4="Suspend",G4="Decommission",G4="Re-authorise",G4="Resume"))),"Decision event needs a decision outcome",IF(AND(E4="Priority override",OR(H4="",I4="")),"Decision-maker / AIG-DEC-03 ref missing",IF(AND(E4="Priority override",G4<>"",G4<>"No decision"),"Priority override: Outcome blank or No decision",IF(AND(E4<>"Decision",OR(G4="Progress",G4="Progress with condition",G4="Return for evidence",G4="Pause",G4="Stop",G4="Suspend",G4="Decommission",G4="Re-authorise",G4="Resume")),"Outcome implies decision",IF(OR(ISNUMBER(SEARCH(",",O4)),ISNUMBER(SEARCH(";",O4))),"One UC-ID per event row — split this event",IF(AND(E4="Decision",OR(Q4="UC-ID REQUIRED",Q4="Decision scope missing",Q4="REMOVE UC-ID OR CORRECT SCOPE")),"Decision scope missing",IF(AND(G4="Progress with condition",COUNTIF(Conditions!$B$4:$B$553,A4)=0),"Progress with condition needs at least one Conditions row",IF(AND(C4<>"",COUNTIFS('Gate plan'!$A$4:$A$353,C4,'Gate plan'!$C$4:$C$353,D4)=0),"Plan gate differs from event gate",IF(AND(C4<>"",O4<>"",COUNTIFS('Gate plan'!$A$4:$A$353,C4,'Gate plan'!$K$4:$K$353,"<>")>0,COUNTIFS('Gate plan'!$A$4:$A$353,C4,'Gate plan'!$K$4:$K$353,O4)=0),"Plan UC-ID differs from event UC-ID",IF(AND(E4="Assurance opinion",J4=""),"Assurance opinion ref missing",IF(AND(G4="Opinion only",E4<>"Assurance opinion",E4<>"Review only"),"Opinion only is for Assurance opinion or Review only events",IF(AND(G4="No decision",E4<>"Review only",E4<>"Priority override",E4<>"Intake / registration"),"No decision is for Review only, Priority override or Intake / registration events",IF(OR(ISNUMBER(SEARCH(" ",TRIM(O4))),ISNUMBER(SEARCH("/",O4))),"One UC-ID per event row: split this event",IF(AND(E4="Precautionary pause (containment)",ISNUMBER(W4),ISNUMBER(F4),W4<F4),"Follow-up decision due date is before the pause",IF(AND(G4="Resume",IFERROR(LOOKUP(2,1/(($B$3:B3=B4)*($O$3:O3=O4)),$G$3:G3),"")<>"Paused — pending decision"),"Resume is only for the event straight after a Precautionary pause on the same AIR-ID and UC-ID (in an earlier row)",IF(AND(E4="Decision",OR(G4="Progress",G4="Progress with condition",G4="Re-authorise",G4="Resume"),X4<>"Yes"),"Decision-maker has not confirmed the screening was considered (column X)","Check against source"))))))))))))))))))))))))))))) | Q4: =IF(A4="","",IF(E4<>"Decision","",IF(P4="UC-ID specific",IF(O4="","UC-ID REQUIRED","Check source decision for each UC-ID"),IF(P4="Shared system baseline",IF(O4<>"","REMOVE UC-ID OR CORRECT SCOPE","Baseline only — NOT UC approval"),"Decision scope missing"))))
N5: =IF(COUNTA(A5:M5,O5:P5,R5:X5)=0,"",IF(OR(A5="",B5="",F5=""),"Event ID, AIR-ID or date missing",IF(COUNTIF($A$4:$A$553,A5)>1,"Duplicate Event ID",IF(E5="","Event type missing",IF(OR(NOT(ISNUMBER(F5)),F5>TODAY()),"Date is not a real date or is in the future",IF(AND(C5<>"",COUNTIF('Gate plan'!$A$4:$A$353,C5)=0),"Plan ID not found in Gate plan",IF(AND(C5<>"",COUNTIFS('Gate plan'!$A$4:$A$353,C5,'Gate plan'!$B$4:$B$353,B5)=0),"Plan AIR-ID differs from event",IF(D5="","Gate / forum missing",IF(AND(E5="Precautionary pause (containment)",G5<>"Paused — pending decision"),"Precautionary pause: Outcome must be Paused, pending decision",IF(AND(E5="Precautionary pause (containment)",V5=""),"Precautionary pause: AIG-OPS-03 incident ref missing",IF(AND(E5="Precautionary pause (containment)",NOT(ISNUMBER(W5))),"Precautionary pause: follow-up decision due date missing",IF(AND(G5="Paused — pending decision",E5<>"Precautionary pause (containment)"),"Paused, pending decision is only for a Precautionary pause event",IF(AND(E5="Decision",OR(G5="",H5="",I5="")),"Outcome / delegation / decision ref missing",IF(AND(E5="Decision",NOT(OR(G5="Progress",G5="Progress with condition",G5="Return for evidence",G5="Pause",G5="Stop",G5="Suspend",G5="Decommission",G5="Re-authorise",G5="Resume"))),"Decision event needs a decision outcome",IF(AND(E5="Priority override",OR(H5="",I5="")),"Decision-maker / AIG-DEC-03 ref missing",IF(AND(E5="Priority override",G5<>"",G5<>"No decision"),"Priority override: Outcome blank or No decision",IF(AND(E5<>"Decision",OR(G5="Progress",G5="Progress with condition",G5="Return for evidence",G5="Pause",G5="Stop",G5="Suspend",G5="Decommission",G5="Re-authorise",G5="Resume")),"Outcome implies decision",IF(OR(ISNUMBER(SEARCH(",",O5)),ISNUMBER(SEARCH(";",O5))),"One UC-ID per event row — split this event",IF(AND(E5="Decision",OR(Q5="UC-ID REQUIRED",Q5="Decision scope missing",Q5="REMOVE UC-ID OR CORRECT SCOPE")),"Decision scope missing",IF(AND(G5="Progress with condition",COUNTIF(Conditions!$B$4:$B$553,A5)=0),"Progress with condition needs at least one Conditions row",IF(AND(C5<>"",COUNTIFS('Gate plan'!$A$4:$A$353,C5,'Gate plan'!$C$4:$C$353,D5)=0),"Plan gate differs from event gate",IF(AND(C5<>"",O5<>"",COUNTIFS('Gate plan'!$A$4:$A$353,C5,'Gate plan'!$K$4:$K$353,"<>")>0,COUNTIFS('Gate plan'!$A$4:$A$353,C5,'Gate plan'!$K$4:$K$353,O5)=0),"Plan UC-ID differs from event UC-ID",IF(AND(E5="Assurance opinion",J5=""),"Assurance opinion ref missing",IF(AND(G5="Opinion only",E5<>"Assurance opinion",E5<>"Review only"),"Opinion only is for Assurance opinion or Review only events",IF(AND(G5="No decision",E5<>"Review only",E5<>"Priority override",E5<>"Intake / registration"),"No decision is for Review only, Priority override or Intake / registration events",IF(OR(ISNUMBER(SEARCH(" ",TRIM(O5))),ISNUMBER(SEARCH("/",O5))),"One UC-ID per event row: split this event",IF(AND(E5="Precautionary pause (containment)",ISNUMBER(W5),ISNUMBER(F5),W5<F5),"Follow-up decision due date is before the pause",IF(AND(G5="Resume",IFERROR(LOOKUP(2,1/(($B$3:B4=B5)*($O$3:O4=O5)),$G$3:G4),"")<>"Paused — pending decision"),"Resume is only for the event straight after a Precautionary pause on the same AIR-ID and UC-ID (in an earlier row)",IF(AND(E5="Decision",OR(G5="Progress",G5="Progress with condition",G5="Re-authorise",G5="Resume"),X5<>"Yes"),"Decision-maker has not confirmed the screening was considered (column X)","Check against source"))))))))))))))))))))))))))))) | Q5: =IF(A5="","",IF(E5<>"Decision","",IF(P5="UC-ID specific",IF(O5="","UC-ID REQUIRED","Check source decision for each UC-ID"),IF(P5="Shared system baseline",IF(O5<>"","REMOVE UC-ID OR CORRECT SCOPE","Baseline only — NOT UC approval"),"Decision scope missing"))))
N6: =IF(COUNTA(A6:M6,O6:P6,R6:X6)=0,"",IF(OR(A6="",B6="",F6=""),"Event ID, AIR-ID or date missing",IF(COUNTIF($A$4:$A$553,A6)>1,"Duplicate Event ID",IF(E6="","Event type missing",IF(OR(NOT(ISNUMBER(F6)),F6>TODAY()),"Date is not a real date or is in the future",IF(AND(C6<>"",COUNTIF('Gate plan'!$A$4:$A$353,C6)=0),"Plan ID not found in Gate plan",IF(AND(C6<>"",COUNTIFS('Gate plan'!$A$4:$A$353,C6,'Gate plan'!$B$4:$B$353,B6)=0),"Plan AIR-ID differs from event",IF(D6="","Gate / forum missing",IF(AND(E6="Precautionary pause (containment)",G6<>"Paused — pending decision"),"Precautionary pause: Outcome must be Paused, pending decision",IF(AND(E6="Precautionary pause (containment)",V6=""),"Precautionary pause: AIG-OPS-03 incident ref missing",IF(AND(E6="Precautionary pause (containment)",NOT(ISNUMBER(W6))),"Precautionary pause: follow-up decision due date missing",IF(AND(G6="Paused — pending decision",E6<>"Precautionary pause (containment)"),"Paused, pending decision is only for a Precautionary pause event",IF(AND(E6="Decision",OR(G6="",H6="",I6="")),"Outcome / delegation / decision ref missing",IF(AND(E6="Decision",NOT(OR(G6="Progress",G6="Progress with condition",G6="Return for evidence",G6="Pause",G6="Stop",G6="Suspend",G6="Decommission",G6="Re-authorise",G6="Resume"))),"Decision event needs a decision outcome",IF(AND(E6="Priority override",OR(H6="",I6="")),"Decision-maker / AIG-DEC-03 ref missing",IF(AND(E6="Priority override",G6<>"",G6<>"No decision"),"Priority override: Outcome blank or No decision",IF(AND(E6<>"Decision",OR(G6="Progress",G6="Progress with condition",G6="Return for evidence",G6="Pause",G6="Stop",G6="Suspend",G6="Decommission",G6="Re-authorise",G6="Resume")),"Outcome implies decision",IF(OR(ISNUMBER(SEARCH(",",O6)),ISNUMBER(SEARCH(";",O6))),"One UC-ID per event row — split this event",IF(AND(E6="Decision",OR(Q6="UC-ID REQUIRED",Q6="Decision scope missing",Q6="REMOVE UC-ID OR CORRECT SCOPE")),"Decision scope missing",IF(AND(G6="Progress with condition",COUNTIF(Conditions!$B$4:$B$553,A6)=0),"Progress with condition needs at least one Conditions row",IF(AND(C6<>"",COUNTIFS('Gate plan'!$A$4:$A$353,C6,'Gate plan'!$C$4:$C$353,D6)=0),"Plan gate differs from event gate",IF(AND(C6<>"",O6<>"",COUNTIFS('Gate plan'!$A$4:$A$353,C6,'Gate plan'!$K$4:$K$353,"<>")>0,COUNTIFS('Gate plan'!$A$4:$A$353,C6,'Gate plan'!$K$4:$K$353,O6)=0),"Plan UC-ID differs from event UC-ID",IF(AND(E6="Assurance opinion",J6=""),"Assurance opinion ref missing",IF(AND(G6="Opinion only",E6<>"Assurance opinion",E6<>"Review only"),"Opinion only is for Assurance opinion or Review only events",IF(AND(G6="No decision",E6<>"Review only",E6<>"Priority override",E6<>"Intake / registration"),"No decision is for Review only, Priority override or Intake / registration events",IF(OR(ISNUMBER(SEARCH(" ",TRIM(O6))),ISNUMBER(SEARCH("/",O6))),"One UC-ID per event row: split this event",IF(AND(E6="Precautionary pause (containment)",ISNUMBER(W6),ISNUMBER(F6),W6<F6),"Follow-up decision due date is before the pause",IF(AND(G6="Resume",IFERROR(LOOKUP(2,1/(($B$3:B5=B6)*($O$3:O5=O6)),$G$3:G5),"")<>"Paused — pending decision"),"Resume is only for the event straight after a Precautionary pause on the same AIR-ID and UC-ID (in an earlier row)",IF(AND(E6="Decision",OR(G6="Progress",G6="Progress with condition",G6="Re-authorise",G6="Resume"),X6<>"Yes"),"Decision-maker has not confirmed the screening was considered (column X)","Check against source"))))))))))))))))))))))))))))) | Q6: =IF(A6="","",IF(E6<>"Decision","",IF(P6="UC-ID specific",IF(O6="","UC-ID REQUIRED","Check source decision for each UC-ID"),IF(P6="Shared system baseline",IF(O6<>"","REMOVE UC-ID OR CORRECT SCOPE","Baseline only — NOT UC approval"),"Decision scope missing"))))
N7: =IF(COUNTA(A7:M7,O7:P7,R7:X7)=0,"",IF(OR(A7="",B7="",F7=""),"Event ID, AIR-ID or date missing",IF(COUNTIF($A$4:$A$553,A7)>1,"Duplicate Event ID",IF(E7="","Event type missing",IF(OR(NOT(ISNUMBER(F7)),F7>TODAY()),"Date is not a real date or is in the future",IF(AND(C7<>"",COUNTIF('Gate plan'!$A$4:$A$353,C7)=0),"Plan ID not found in Gate plan",IF(AND(C7<>"",COUNTIFS('Gate plan'!$A$4:$A$353,C7,'Gate plan'!$B$4:$B$353,B7)=0),"Plan AIR-ID differs from event",IF(D7="","Gate / forum missing",IF(AND(E7="Precautionary pause (containment)",G7<>"Paused — pending decision"),"Precautionary pause: Outcome must be Paused, pending decision",IF(AND(E7="Precautionary pause (containment)",V7=""),"Precautionary pause: AIG-OPS-03 incident ref missing",IF(AND(E7="Precautionary pause (containment)",NOT(ISNUMBER(W7))),"Precautionary pause: follow-up decision due date missing",IF(AND(G7="Paused — pending decision",E7<>"Precautionary pause (containment)"),"Paused, pending decision is only for a Precautionary pause event",IF(AND(E7="Decision",OR(G7="",H7="",I7="")),"Outcome / delegation / decision ref missing",IF(AND(E7="Decision",NOT(OR(G7="Progress",G7="Progress with condition",G7="Return for evidence",G7="Pause",G7="Stop",G7="Suspend",G7="Decommission",G7="Re-authorise",G7="Resume"))),"Decision event needs a decision outcome",IF(AND(E7="Priority override",OR(H7="",I7="")),"Decision-maker / AIG-DEC-03 ref missing",IF(AND(E7="Priority override",G7<>"",G7<>"No decision"),"Priority override: Outcome blank or No decision",IF(AND(E7<>"Decision",OR(G7="Progress",G7="Progress with condition",G7="Return for evidence",G7="Pause",G7="Stop",G7="Suspend",G7="Decommission",G7="Re-authorise",G7="Resume")),"Outcome implies decision",IF(OR(ISNUMBER(SEARCH(",",O7)),ISNUMBER(SEARCH(";",O7))),"One UC-ID per event row — split this event",IF(AND(E7="Decision",OR(Q7="UC-ID REQUIRED",Q7="Decision scope missing",Q7="REMOVE UC-ID OR CORRECT SCOPE")),"Decision scope missing",IF(AND(G7="Progress with condition",COUNTIF(Conditions!$B$4:$B$553,A7)=0),"Progress with condition needs at least one Conditions row",IF(AND(C7<>"",COUNTIFS('Gate plan'!$A$4:$A$353,C7,'Gate plan'!$C$4:$C$353,D7)=0),"Plan gate differs from event gate",IF(AND(C7<>"",O7<>"",COUNTIFS('Gate plan'!$A$4:$A$353,C7,'Gate plan'!$K$4:$K$353,"<>")>0,COUNTIFS('Gate plan'!$A$4:$A$353,C7,'Gate plan'!$K$4:$K$353,O7)=0),"Plan UC-ID differs from event UC-ID",IF(AND(E7="Assurance opinion",J7=""),"Assurance opinion ref missing",IF(AND(G7="Opinion only",E7<>"Assurance opinion",E7<>"Review only"),"Opinion only is for Assurance opinion or Review only events",IF(AND(G7="No decision",E7<>"Review only",E7<>"Priority override",E7<>"Intake / registration"),"No decision is for Review only, Priority override or Intake / registration events",IF(OR(ISNUMBER(SEARCH(" ",TRIM(O7))),ISNUMBER(SEARCH("/",O7))),"One UC-ID per event row: split this event",IF(AND(E7="Precautionary pause (containment)",ISNUMBER(W7),ISNUMBER(F7),W7<F7),"Follow-up decision due date is before the pause",IF(AND(G7="Resume",IFERROR(LOOKUP(2,1/(($B$3:B6=B7)*($O$3:O6=O7)),$G$3:G6),"")<>"Paused — pending decision"),"Resume is only for the event straight after a Precautionary pause on the same AIR-ID and UC-ID (in an earlier row)",IF(AND(E7="Decision",OR(G7="Progress",G7="Progress with condition",G7="Re-authorise",G7="Resume"),X7<>"Yes"),"Decision-maker has not confirmed the screening was considered (column X)","Check against source"))))))))))))))))))))))))))))) | Q7: =IF(A7="","",IF(E7<>"Decision","",IF(P7="UC-ID specific",IF(O7="","UC-ID REQUIRED","Check source decision for each UC-ID"),IF(P7="Shared system baseline",IF(O7<>"","REMOVE UC-ID OR CORRECT SCOPE","Baseline only — NOT UC approval"),"Decision scope missing"))))
N8: =IF(COUNTA(A8:M8,O8:P8,R8:X8)=0,"",IF(OR(A8="",B8="",F8=""),"Event ID, AIR-ID or date missing",IF(COUNTIF($A$4:$A$553,A8)>1,"Duplicate Event ID",IF(E8="","Event type missing",IF(OR(NOT(ISNUMBER(F8)),F8>TODAY()),"Date is not a real date or is in the future",IF(AND(C8<>"",COUNTIF('Gate plan'!$A$4:$A$353,C8)=0),"Plan ID not found in Gate plan",IF(AND(C8<>"",COUNTIFS('Gate plan'!$A$4:$A$353,C8,'Gate plan'!$B$4:$B$353,B8)=0),"Plan AIR-ID differs from event",IF(D8="","Gate / forum missing",IF(AND(E8="Precautionary pause (containment)",G8<>"Paused — pending decision"),"Precautionary pause: Outcome must be Paused, pending decision",IF(AND(E8="Precautionary pause (containment)",V8=""),"Precautionary pause: AIG-OPS-03 incident ref missing",IF(AND(E8="Precautionary pause (containment)",NOT(ISNUMBER(W8))),"Precautionary pause: follow-up decision due date missing",IF(AND(G8="Paused — pending decision",E8<>"Precautionary pause (containment)"),"Paused, pending decision is only for a Precautionary pause event",IF(AND(E8="Decision",OR(G8="",H8="",I8="")),"Outcome / delegation / decision ref missing",IF(AND(E8="Decision",NOT(OR(G8="Progress",G8="Progress with condition",G8="Return for evidence",G8="Pause",G8="Stop",G8="Suspend",G8="Decommission",G8="Re-authorise",G8="Resume"))),"Decision event needs a decision outcome",IF(AND(E8="Priority override",OR(H8="",I8="")),"Decision-maker / AIG-DEC-03 ref missing",IF(AND(E8="Priority override",G8<>"",G8<>"No decision"),"Priority override: Outcome blank or No decision",IF(AND(E8<>"Decision",OR(G8="Progress",G8="Progress with condition",G8="Return for evidence",G8="Pause",G8="Stop",G8="Suspend",G8="Decommission",G8="Re-authorise",G8="Resume")),"Outcome implies decision",IF(OR(ISNUMBER(SEARCH(",",O8)),ISNUMBER(SEARCH(";",O8))),"One UC-ID per event row — split this event",IF(AND(E8="Decision",OR(Q8="UC-ID REQUIRED",Q8="Decision scope missing",Q8="REMOVE UC-ID OR CORRECT SCOPE")),"Decision scope missing",IF(AND(G8="Progress with condition",COUNTIF(Conditions!$B$4:$B$553,A8)=0),"Progress with condition needs at least one Conditions row",IF(AND(C8<>"",COUNTIFS('Gate plan'!$A$4:$A$353,C8,'Gate plan'!$C$4:$C$353,D8)=0),"Plan gate differs from event gate",IF(AND(C8<>"",O8<>"",COUNTIFS('Gate plan'!$A$4:$A$353,C8,'Gate plan'!$K$4:$K$353,"<>")>0,COUNTIFS('Gate plan'!$A$4:$A$353,C8,'Gate plan'!$K$4:$K$353,O8)=0),"Plan UC-ID differs from event UC-ID",IF(AND(E8="Assurance opinion",J8=""),"Assurance opinion ref missing",IF(AND(G8="Opinion only",E8<>"Assurance opinion",E8<>"Review only"),"Opinion only is for Assurance opinion or Review only events",IF(AND(G8="No decision",E8<>"Review only",E8<>"Priority override",E8<>"Intake / registration"),"No decision is for Review only, Priority override or Intake / registration events",IF(OR(ISNUMBER(SEARCH(" ",TRIM(O8))),ISNUMBER(SEARCH("/",O8))),"One UC-ID per event row: split this event",IF(AND(E8="Precautionary pause (containment)",ISNUMBER(W8),ISNUMBER(F8),W8<F8),"Follow-up decision due date is before the pause",IF(AND(G8="Resume",IFERROR(LOOKUP(2,1/(($B$3:B7=B8)*($O$3:O7=O8)),$G$3:G7),"")<>"Paused — pending decision"),"Resume is only for the event straight after a Precautionary pause on the same AIR-ID and UC-ID (in an earlier row)",IF(AND(E8="Decision",OR(G8="Progress",G8="Progress with condition",G8="Re-authorise",G8="Resume"),X8<>"Yes"),"Decision-maker has not confirmed the screening was considered (column X)","Check against source"))))))))))))))))))))))))))))) | Q8: =IF(A8="","",IF(E8<>"Decision","",IF(P8="UC-ID specific",IF(O8="","UC-ID REQUIRED","Check source decision for each UC-ID"),IF(P8="Shared system baseline",IF(O8<>"","REMOVE UC-ID OR CORRECT SCOPE","Baseline only — NOT UC approval"),"Decision scope missing"))))
N9: =IF(COUNTA(A9:M9,O9:P9,R9:X9)=0,"",IF(OR(A9="",B9="",F9=""),"Event ID, AIR-ID or date missing",IF(COUNTIF($A$4:$A$553,A9)>1,"Duplicate Event ID",IF(E9="","Event type missing",IF(OR(NOT(ISNUMBER(F9)),F9>TODAY()),"Date is not a real date or is in the future",IF(AND(C9<>"",COUNTIF('Gate plan'!$A$4:$A$353,C9)=0),"Plan ID not found in Gate plan",IF(AND(C9<>"",COUNTIFS('Gate plan'!$A$4:$A$353,C9,'Gate plan'!$B$4:$B$353,B9)=0),"Plan AIR-ID differs from event",IF(D9="","Gate / forum missing",IF(AND(E9="Precautionary pause (containment)",G9<>"Paused — pending decision"),"Precautionary pause: Outcome must be Paused, pending decision",IF(AND(E9="Precautionary pause (containment)",V9=""),"Precautionary pause: AIG-OPS-03 incident ref missing",IF(AND(E9="Precautionary pause (containment)",NOT(ISNUMBER(W9))),"Precautionary pause: follow-up decision due date missing",IF(AND(G9="Paused — pending decision",E9<>"Precautionary pause (containment)"),"Paused, pending decision is only for a Precautionary pause event",IF(AND(E9="Decision",OR(G9="",H9="",I9="")),"Outcome / delegation / decision ref missing",IF(AND(E9="Decision",NOT(OR(G9="Progress",G9="Progress with condition",G9="Return for evidence",G9="Pause",G9="Stop",G9="Suspend",G9="Decommission",G9="Re-authorise",G9="Resume"))),"Decision event needs a decision outcome",IF(AND(E9="Priority override",OR(H9="",I9="")),"Decision-maker / AIG-DEC-03 ref missing",IF(AND(E9="Priority override",G9<>"",G9<>"No decision"),"Priority override: Outcome blank or No decision",IF(AND(E9<>"Decision",OR(G9="Progress",G9="Progress with condition",G9="Return for evidence",G9="Pause",G9="Stop",G9="Suspend",G9="Decommission",G9="Re-authorise",G9="Resume")),"Outcome implies decision",IF(OR(ISNUMBER(SEARCH(",",O9)),ISNUMBER(SEARCH(";",O9))),"One UC-ID per event row — split this event",IF(AND(E9="Decision",OR(Q9="UC-ID REQUIRED",Q9="Decision scope missing",Q9="REMOVE UC-ID OR CORRECT SCOPE")),"Decision scope missing",IF(AND(G9="Progress with condition",COUNTIF(Conditions!$B$4:$B$553,A9)=0),"Progress with condition needs at least one Conditions row",IF(AND(C9<>"",COUNTIFS('Gate plan'!$A$4:$A$353,C9,'Gate plan'!$C$4:$C$353,D9)=0),"Plan gate differs from event gate",IF(AND(C9<>"",O9<>"",COUNTIFS('Gate plan'!$A$4:$A$353,C9,'Gate plan'!$K$4:$K$353,"<>")>0,COUNTIFS('Gate plan'!$A$4:$A$353,C9,'Gate plan'!$K$4:$K$353,O9)=0),"Plan UC-ID differs from event UC-ID",IF(AND(E9="Assurance opinion",J9=""),"Assurance opinion ref missing",IF(AND(G9="Opinion only",E9<>"Assurance opinion",E9<>"Review only"),"Opinion only is for Assurance opinion or Review only events",IF(AND(G9="No decision",E9<>"Review only",E9<>"Priority override",E9<>"Intake / registration"),"No decision is for Review only, Priority override or Intake / registration events",IF(OR(ISNUMBER(SEARCH(" ",TRIM(O9))),ISNUMBER(SEARCH("/",O9))),"One UC-ID per event row: split this event",IF(AND(E9="Precautionary pause (containment)",ISNUMBER(W9),ISNUMBER(F9),W9<F9),"Follow-up decision due date is before the pause",IF(AND(G9="Resume",IFERROR(LOOKUP(2,1/(($B$3:B8=B9)*($O$3:O8=O9)),$G$3:G8),"")<>"Paused — pending decision"),"Resume is only for the event straight after a Precautionary pause on the same AIR-ID and UC-ID (in an earlier row)",IF(AND(E9="Decision",OR(G9="Progress",G9="Progress with condition",G9="Re-authorise",G9="Resume"),X9<>"Yes"),"Decision-maker has not confirmed the screening was considered (column X)","Check against source"))))))))))))))))))))))))))))) | Q9: =IF(A9="","",IF(E9<>"Decision","",IF(P9="UC-ID specific",IF(O9="","UC-ID REQUIRED","Check source decision for each UC-ID"),IF(P9="Shared system baseline",IF(O9<>"","REMOVE UC-ID OR CORRECT SCOPE","Baseline only — NOT UC approval"),"Decision scope missing"))))
N10: =IF(COUNTA(A10:M10,O10:P10,R10:X10)=0,"",IF(OR(A10="",B10="",F10=""),"Event ID, AIR-ID or date missing",IF(COUNTIF($A$4:$A$553,A10)>1,"Duplicate Event ID",IF(E10="","Event type missing",IF(OR(NOT(ISNUMBER(F10)),F10>TODAY()),"Date is not a real date or is in the future",IF(AND(C10<>"",COUNTIF('Gate plan'!$A$4:$A$353,C10)=0),"Plan ID not found in Gate plan",IF(AND(C10<>"",COUNTIFS('Gate plan'!$A$4:$A$353,C10,'Gate plan'!$B$4:$B$353,B10)=0),"Plan AIR-ID differs from event",IF(D10="","Gate / forum missing",IF(AND(E10="Precautionary pause (containment)",G10<>"Paused — pending decision"),"Precautionary pause: Outcome must be Paused, pending decision",IF(AND(E10="Precautionary pause (containment)",V10=""),"Precautionary pause: AIG-OPS-03 incident ref missing",IF(AND(E10="Precautionary pause (containment)",NOT(ISNUMBER(W10))),"Precautionary pause: follow-up decision due date missing",IF(AND(G10="Paused — pending decision",E10<>"Precautionary pause (containment)"),"Paused, pending decision is only for a Precautionary pause event",IF(AND(E10="Decision",OR(G10="",H10="",I10="")),"Outcome / delegation / decision ref missing",IF(AND(E10="Decision",NOT(OR(G10="Progress",G10="Progress with condition",G10="Return for evidence",G10="Pause",G10="Stop",G10="Suspend",G10="Decommission",G10="Re-authorise",G10="Resume"))),"Decision event needs a decision outcome",IF(AND(E10="Priority override",OR(H10="",I10="")),"Decision-maker / AIG-DEC-03 ref missing",IF(AND(E10="Priority override",G10<>"",G10<>"No decision"),"Priority override: Outcome blank or No decision",IF(AND(E10<>"Decision",OR(G10="Progress",G10="Progress with condition",G10="Return for evidence",G10="Pause",G10="Stop",G10="Suspend",G10="Decommission",G10="Re-authorise",G10="Resume")),"Outcome implies decision",IF(OR(ISNUMBER(SEARCH(",",O10)),ISNUMBER(SEARCH(";",O10))),"One UC-ID per event row — split this event",IF(AND(E10="Decision",OR(Q10="UC-ID REQUIRED",Q10="Decision scope missing",Q10="REMOVE UC-ID OR CORRECT SCOPE")),"Decision scope missing",IF(AND(G10="Progress with condition",COUNTIF(Conditions!$B$4:$B$553,A10)=0),"Progress with condition needs at least one Conditions row",IF(AND(C10<>"",COUNTIFS('Gate plan'!$A$4:$A$353,C10,'Gate plan'!$C$4:$C$353,D10)=0),"Plan gate differs from event gate",IF(AND(C10<>"",O10<>"",COUNTIFS('Gate plan'!$A$4:$A$353,C10,'Gate plan'!$K$4:$K$353,"<>")>0,COUNTIFS('Gate plan'!$A$4:$A$353,C10,'Gate plan'!$K$4:$K$353,O10)=0),"Plan UC-ID differs from event UC-ID",IF(AND(E10="Assurance opinion",J10=""),"Assurance opinion ref missing",IF(AND(G10="Opinion only",E10<>"Assurance opinion",E10<>"Review only"),"Opinion only is for Assurance opinion or Review only events",IF(AND(G10="No decision",E10<>"Review only",E10<>"Priority override",E10<>"Intake / registration"),"No decision is for Review only, Priority override or Intake / registration events",IF(OR(ISNUMBER(SEARCH(" ",TRIM(O10))),ISNUMBER(SEARCH("/",O10))),"One UC-ID per event row: split this event",IF(AND(E10="Precautionary pause (containment)",ISNUMBER(W10),ISNUMBER(F10),W10<F10),"Follow-up decision due date is before the pause",IF(AND(G10="Resume",IFERROR(LOOKUP(2,1/(($B$3:B9=B10)*($O$3:O9=O10)),$G$3:G9),"")<>"Paused — pending decision"),"Resume is only for the event straight after a Precautionary pause on the same AIR-ID and UC-ID (in an earlier row)",IF(AND(E10="Decision",OR(G10="Progress",G10="Progress with condition",G10="Re-authorise",G10="Resume"),X10<>"Yes"),"Decision-maker has not confirmed the screening was considered (column X)","Check against source"))))))))))))))))))))))))))))) | Q10: =IF(A10="","",IF(E10<>"Decision","",IF(P10="UC-ID specific",IF(O10="","UC-ID REQUIRED","Check source decision for each UC-ID"),IF(P10="Shared system baseline",IF(O10<>"","REMOVE UC-ID OR CORRECT SCOPE","Baseline only — NOT UC approval"),"Decision scope missing"))))
N11: =IF(COUNTA(A11:M11,O11:P11,R11:X11)=0,"",IF(OR(A11="",B11="",F11=""),"Event ID, AIR-ID or date missing",IF(COUNTIF($A$4:$A$553,A11)>1,"Duplicate Event ID",IF(E11="","Event type missing",IF(OR(NOT(ISNUMBER(F11)),F11>TODAY()),"Date is not a real date or is in the future",IF(AND(C11<>"",COUNTIF('Gate plan'!$A$4:$A$353,C11)=0),"Plan ID not found in Gate plan",IF(AND(C11<>"",COUNTIFS('Gate plan'!$A$4:$A$353,C11,'Gate plan'!$B$4:$B$353,B11)=0),"Plan AIR-ID differs from event",IF(D11="","Gate / forum missing",IF(AND(E11="Precautionary pause (containment)",G11<>"Paused — pending decision"),"Precautionary pause: Outcome must be Paused, pending decision",IF(AND(E11="Precautionary pause (containment)",V11=""),"Precautionary pause: AIG-OPS-03 incident ref missing",IF(AND(E11="Precautionary pause (containment)",NOT(ISNUMBER(W11))),"Precautionary pause: follow-up decision due date missing",IF(AND(G11="Paused — pending decision",E11<>"Precautionary pause (containment)"),"Paused, pending decision is only for a Precautionary pause event",IF(AND(E11="Decision",OR(G11="",H11="",I11="")),"Outcome / delegation / decision ref missing",IF(AND(E11="Decision",NOT(OR(G11="Progress",G11="Progress with condition",G11="Return for evidence",G11="Pause",G11="Stop",G11="Suspend",G11="Decommission",G11="Re-authorise",G11="Resume"))),"Decision event needs a decision outcome",IF(AND(E11="Priority override",OR(H11="",I11="")),"Decision-maker / AIG-DEC-03 ref missing",IF(AND(E11="Priority override",G11<>"",G11<>"No decision"),"Priority override: Outcome blank or No decision",IF(AND(E11<>"Decision",OR(G11="Progress",G11="Progress with condition",G11="Return for evidence",G11="Pause",G11="Stop",G11="Suspend",G11="Decommission",G11="Re-authorise",G11="Resume")),"Outcome implies decision",IF(OR(ISNUMBER(SEARCH(",",O11)),ISNUMBER(SEARCH(";",O11))),"One UC-ID per event row — split this event",IF(AND(E11="Decision",OR(Q11="UC-ID REQUIRED",Q11="Decision scope missing",Q11="REMOVE UC-ID OR CORRECT SCOPE")),"Decision scope missing",IF(AND(G11="Progress with condition",COUNTIF(Conditions!$B$4:$B$553,A11)=0),"Progress with condition needs at least one Conditions row",IF(AND(C11<>"",COUNTIFS('Gate plan'!$A$4:$A$353,C11,'Gate plan'!$C$4:$C$353,D11)=0),"Plan gate differs from event gate",IF(AND(C11<>"",O11<>"",COUNTIFS('Gate plan'!$A$4:$A$353,C11,'Gate plan'!$K$4:$K$353,"<>")>0,COUNTIFS('Gate plan'!$A$4:$A$353,C11,'Gate plan'!$K$4:$K$353,O11)=0),"Plan UC-ID differs from event UC-ID",IF(AND(E11="Assurance opinion",J11=""),"Assurance opinion ref missing",IF(AND(G11="Opinion only",E11<>"Assurance opinion",E11<>"Review only"),"Opinion only is for Assurance opinion or Review only events",IF(AND(G11="No decision",E11<>"Review only",E11<>"Priority override",E11<>"Intake / registration"),"No decision is for Review only, Priority override or Intake / registration events",IF(OR(ISNUMBER(SEARCH(" ",TRIM(O11))),ISNUMBER(SEARCH("/",O11))),"One UC-ID per event row: split this event",IF(AND(E11="Precautionary pause (containment)",ISNUMBER(W11),ISNUMBER(F11),W11<F11),"Follow-up decision due date is before the pause",IF(AND(G11="Resume",IFERROR(LOOKUP(2,1/(($B$3:B10=B11)*($O$3:O10=O11)),$G$3:G10),"")<>"Paused — pending decision"),"Resume is only for the event straight after a Precautionary pause on the same AIR-ID and UC-ID (in an earlier row)",IF(AND(E11="Decision",OR(G11="Progress",G11="Progress with condition",G11="Re-authorise",G11="Resume"),X11<>"Yes"),"Decision-maker has not confirmed the screening was considered (column X)","Check against source"))))))))))))))))))))))))))))) | Q11: =IF(A11="","",IF(E11<>"Decision","",IF(P11="UC-ID specific",IF(O11="","UC-ID REQUIRED","Check source decision for each UC-ID"),IF(P11="Shared system baseline",IF(O11<>"","REMOVE UC-ID OR CORRECT SCOPE","Baseline only — NOT UC approval"),"Decision scope missing"))))
N12: =IF(COUNTA(A12:M12,O12:P12,R12:X12)=0,"",IF(OR(A12="",B12="",F12=""),"Event ID, AIR-ID or date missing",IF(COUNTIF($A$4:$A$553,A12)>1,"Duplicate Event ID",IF(E12="","Event type missing",IF(OR(NOT(ISNUMBER(F12)),F12>TODAY()),"Date is not a real date or is in the future",IF(AND(C12<>"",COUNTIF('Gate plan'!$A$4:$A$353,C12)=0),"Plan ID not found in Gate plan",IF(AND(C12<>"",COUNTIFS('Gate plan'!$A$4:$A$353,C12,'Gate plan'!$B$4:$B$353,B12)=0),"Plan AIR-ID differs from event",IF(D12="","Gate / forum missing",IF(AND(E12="Precautionary pause (containment)",G12<>"Paused — pending decision"),"Precautionary pause: Outcome must be Paused, pending decision",IF(AND(E12="Precautionary pause (containment)",V12=""),"Precautionary pause: AIG-OPS-03 incident ref missing",IF(AND(E12="Precautionary pause (containment)",NOT(ISNUMBER(W12))),"Precautionary pause: follow-up decision due date missing",IF(AND(G12="Paused — pending decision",E12<>"Precautionary pause (containment)"),"Paused, pending decision is only for a Precautionary pause event",IF(AND(E12="Decision",OR(G12="",H12="",I12="")),"Outcome / delegation / decision ref missing",IF(AND(E12="Decision",NOT(OR(G12="Progress",G12="Progress with condition",G12="Return for evidence",G12="Pause",G12="Stop",G12="Suspend",G12="Decommission",G12="Re-authorise",G12="Resume"))),"Decision event needs a decision outcome",IF(AND(E12="Priority override",OR(H12="",I12="")),"Decision-maker / AIG-DEC-03 ref missing",IF(AND(E12="Priority override",G12<>"",G12<>"No decision"),"Priority override: Outcome blank or No decision",IF(AND(E12<>"Decision",OR(G12="Progress",G12="Progress with condition",G12="Return for evidence",G12="Pause",G12="Stop",G12="Suspend",G12="Decommission",G12="Re-authorise",G12="Resume")),"Outcome implies decision",IF(OR(ISNUMBER(SEARCH(",",O12)),ISNUMBER(SEARCH(";",O12))),"One UC-ID per event row — split this event",IF(AND(E12="Decision",OR(Q12="UC-ID REQUIRED",Q12="Decision scope missing",Q12="REMOVE UC-ID OR CORRECT SCOPE")),"Decision scope missing",IF(AND(G12="Progress with condition",COUNTIF(Conditions!$B$4:$B$553,A12)=0),"Progress with condition needs at least one Conditions row",IF(AND(C12<>"",COUNTIFS('Gate plan'!$A$4:$A$353,C12,'Gate plan'!$C$4:$C$353,D12)=0),"Plan gate differs from event gate",IF(AND(C12<>"",O12<>"",COUNTIFS('Gate plan'!$A$4:$A$353,C12,'Gate plan'!$K$4:$K$353,"<>")>0,COUNTIFS('Gate plan'!$A$4:$A$353,C12,'Gate plan'!$K$4:$K$353,O12)=0),"Plan UC-ID differs from event UC-ID",IF(AND(E12="Assurance opinion",J12=""),"Assurance opinion ref missing",IF(AND(G12="Opinion only",E12<>"Assurance opinion",E12<>"Review only"),"Opinion only is for Assurance opinion or Review only events",IF(AND(G12="No decision",E12<>"Review only",E12<>"Priority override",E12<>"Intake / registration"),"No decision is for Review only, Priority override or Intake / registration events",IF(OR(ISNUMBER(SEARCH(" ",TRIM(O12))),ISNUMBER(SEARCH("/",O12))),"One UC-ID per event row: split this event",IF(AND(E12="Precautionary pause (containment)",ISNUMBER(W12),ISNUMBER(F12),W12<F12),"Follow-up decision due date is before the pause",IF(AND(G12="Resume",IFERROR(LOOKUP(2,1/(($B$3:B11=B12)*($O$3:O11=O12)),$G$3:G11),"")<>"Paused — pending decision"),"Resume is only for the event straight after a Precautionary pause on the same AIR-ID and UC-ID (in an earlier row)",IF(AND(E12="Decision",OR(G12="Progress",G12="Progress with condition",G12="Re-authorise",G12="Resume"),X12<>"Yes"),"Decision-maker has not confirmed the screening was considered (column X)","Check against source"))))))))))))))))))))))))))))) | Q12: =IF(A12="","",IF(E12<>"Decision","",IF(P12="UC-ID specific",IF(O12="","UC-ID REQUIRED","Check source decision for each UC-ID"),IF(P12="Shared system baseline",IF(O12<>"","REMOVE UC-ID OR CORRECT SCOPE","Baseline only — NOT UC approval"),"Decision scope missing"))))
N13: =IF(COUNTA(A13:M13,O13:P13,R13:X13)=0,"",IF(OR(A13="",B13="",F13=""),"Event ID, AIR-ID or date missing",IF(COUNTIF($A$4:$A$553,A13)>1,"Duplicate Event ID",IF(E13="","Event type missing",IF(OR(NOT(ISNUMBER(F13)),F13>TODAY()),"Date is not a real date or is in the future",IF(AND(C13<>"",COUNTIF('Gate plan'!$A$4:$A$353,C13)=0),"Plan ID not found in Gate plan",IF(AND(C13<>"",COUNTIFS('Gate plan'!$A$4:$A$353,C13,'Gate plan'!$B$4:$B$353,B13)=0),"Plan AIR-ID differs from event",IF(D13="","Gate / forum missing",IF(AND(E13="Precautionary pause (containment)",G13<>"Paused — pending decision"),"Precautionary pause: Outcome must be Paused, pending decision",IF(AND(E13="Precautionary pause (containment)",V13=""),"Precautionary pause: AIG-OPS-03 incident ref missing",IF(AND(E13="Precautionary pause (containment)",NOT(ISNUMBER(W13))),"Precautionary pause: follow-up decision due date missing",IF(AND(G13="Paused — pending decision",E13<>"Precautionary pause (containment)"),"Paused, pending decision is only for a Precautionary pause event",IF(AND(E13="Decision",OR(G13="",H13="",I13="")),"Outcome / delegation / decision ref missing",IF(AND(E13="Decision",NOT(OR(G13="Progress",G13="Progress with condition",G13="Return for evidence",G13="Pause",G13="Stop",G13="Suspend",G13="Decommission",G13="Re-authorise",G13="Resume"))),"Decision event needs a decision outcome",IF(AND(E13="Priority override",OR(H13="",I13="")),"Decision-maker / AIG-DEC-03 ref missing",IF(AND(E13="Priority override",G13<>"",G13<>"No decision"),"Priority override: Outcome blank or No decision",IF(AND(E13<>"Decision",OR(G13="Progress",G13="Progress with condition",G13="Return for evidence",G13="Pause",G13="Stop",G13="Suspend",G13="Decommission",G13="Re-authorise",G13="Resume")),"Outcome implies decision",IF(OR(ISNUMBER(SEARCH(",",O13)),ISNUMBER(SEARCH(";",O13))),"One UC-ID per event row — split this event",IF(AND(E13="Decision",OR(Q13="UC-ID REQUIRED",Q13="Decision scope missing",Q13="REMOVE UC-ID OR CORRECT SCOPE")),"Decision scope missing",IF(AND(G13="Progress with condition",COUNTIF(Conditions!$B$4:$B$553,A13)=0),"Progress with condition needs at least one Conditions row",IF(AND(C13<>"",COUNTIFS('Gate plan'!$A$4:$A$353,C13,'Gate plan'!$C$4:$C$353,D13)=0),"Plan gate differs from event gate",IF(AND(C13<>"",O13<>"",COUNTIFS('Gate plan'!$A$4:$A$353,C13,'Gate plan'!$K$4:$K$353,"<>")>0,COUNTIFS('Gate plan'!$A$4:$A$353,C13,'Gate plan'!$K$4:$K$353,O13)=0),"Plan UC-ID differs from event UC-ID",IF(AND(E13="Assurance opinion",J13=""),"Assurance opinion ref missing",IF(AND(G13="Opinion only",E13<>"Assurance opinion",E13<>"Review only"),"Opinion only is for Assurance opinion or Review only events",IF(AND(G13="No decision",E13<>"Review only",E13<>"Priority override",E13<>"Intake / registration"),"No decision is for Review only, Priority override or Intake / registration events",IF(OR(ISNUMBER(SEARCH(" ",TRIM(O13))),ISNUMBER(SEARCH("/",O13))),"One UC-ID per event row: split this event",IF(AND(E13="Precautionary pause (containment)",ISNUMBER(W13),ISNUMBER(F13),W13<F13),"Follow-up decision due date is before the pause",IF(AND(G13="Resume",IFERROR(LOOKUP(2,1/(($B$3:B12=B13)*($O$3:O12=O13)),$G$3:G12),"")<>"Paused — pending decision"),"Resume is only for the event straight after a Precautionary pause on the same AIR-ID and UC-ID (in an earlier row)",IF(AND(E13="Decision",OR(G13="Progress",G13="Progress with condition",G13="Re-authorise",G13="Resume"),X13<>"Yes"),"Decision-maker has not confirmed the screening was considered (column X)","Check against source"))))))))))))))))))))))))))))) | Q13: =IF(A13="","",IF(E13<>"Decision","",IF(P13="UC-ID specific",IF(O13="","UC-ID REQUIRED","Check source decision for each UC-ID"),IF(P13="Shared system baseline",IF(O13<>"","REMOVE UC-ID OR CORRECT SCOPE","Baseline only — NOT UC approval"),"Decision scope missing"))))
N14: =IF(COUNTA(A14:M14,O14:P14,R14:X14)=0,"",IF(OR(A14="",B14="",F14=""),"Event ID, AIR-ID or date missing",IF(COUNTIF($A$4:$A$553,A14)>1,"Duplicate Event ID",IF(E14="","Event type missing",IF(OR(NOT(ISNUMBER(F14)),F14>TODAY()),"Date is not a real date or is in the future",IF(AND(C14<>"",COUNTIF('Gate plan'!$A$4:$A$353,C14)=0),"Plan ID not found in Gate plan",IF(AND(C14<>"",COUNTIFS('Gate plan'!$A$4:$A$353,C14,'Gate plan'!$B$4:$B$353,B14)=0),"Plan AIR-ID differs from event",IF(D14="","Gate / forum missing",IF(AND(E14="Precautionary pause (containment)",G14<>"Paused — pending decision"),"Precautionary pause: Outcome must be Paused, pending decision",IF(AND(E14="Precautionary pause (containment)",V14=""),"Precautionary pause: AIG-OPS-03 incident ref missing",IF(AND(E14="Precautionary pause (containment)",NOT(ISNUMBER(W14))),"Precautionary pause: follow-up decision due date missing",IF(AND(G14="Paused — pending decision",E14<>"Precautionary pause (containment)"),"Paused, pending decision is only for a Precautionary pause event",IF(AND(E14="Decision",OR(G14="",H14="",I14="")),"Outcome / delegation / decision ref missing",IF(AND(E14="Decision",NOT(OR(G14="Progress",G14="Progress with condition",G14="Return for evidence",G14="Pause",G14="Stop",G14="Suspend",G14="Decommission",G14="Re-authorise",G14="Resume"))),"Decision event needs a decision outcome",IF(AND(E14="Priority override",OR(H14="",I14="")),"Decision-maker / AIG-DEC-03 ref missing",IF(AND(E14="Priority override",G14<>"",G14<>"No decision"),"Priority override: Outcome blank or No decision",IF(AND(E14<>"Decision",OR(G14="Progress",G14="Progress with condition",G14="Return for evidence",G14="Pause",G14="Stop",G14="Suspend",G14="Decommission",G14="Re-authorise",G14="Resume")),"Outcome implies decision",IF(OR(ISNUMBER(SEARCH(",",O14)),ISNUMBER(SEARCH(";",O14))),"One UC-ID per event row — split this event",IF(AND(E14="Decision",OR(Q14="UC-ID REQUIRED",Q14="Decision scope missing",Q14="REMOVE UC-ID OR CORRECT SCOPE")),"Decision scope missing",IF(AND(G14="Progress with condition",COUNTIF(Conditions!$B$4:$B$553,A14)=0),"Progress with condition needs at least one Conditions row",IF(AND(C14<>"",COUNTIFS('Gate plan'!$A$4:$A$353,C14,'Gate plan'!$C$4:$C$353,D14)=0),"Plan gate differs from event gate",IF(AND(C14<>"",O14<>"",COUNTIFS('Gate plan'!$A$4:$A$353,C14,'Gate plan'!$K$4:$K$353,"<>")>0,COUNTIFS('Gate plan'!$A$4:$A$353,C14,'Gate plan'!$K$4:$K$353,O14)=0),"Plan UC-ID differs from event UC-ID",IF(AND(E14="Assurance opinion",J14=""),"Assurance opinion ref missing",IF(AND(G14="Opinion only",E14<>"Assurance opinion",E14<>"Review only"),"Opinion only is for Assurance opinion or Review only events",IF(AND(G14="No decision",E14<>"Review only",E14<>"Priority override",E14<>"Intake / registration"),"No decision is for Review only, Priority override or Intake / registration events",IF(OR(ISNUMBER(SEARCH(" ",TRIM(O14))),ISNUMBER(SEARCH("/",O14))),"One UC-ID per event row: split this event",IF(AND(E14="Precautionary pause (containment)",ISNUMBER(W14),ISNUMBER(F14),W14<F14),"Follow-up decision due date is before the pause",IF(AND(G14="Resume",IFERROR(LOOKUP(2,1/(($B$3:B13=B14)*($O$3:O13=O14)),$G$3:G13),"")<>"Paused — pending decision"),"Resume is only for the event straight after a Precautionary pause on the same AIR-ID and UC-ID (in an earlier row)",IF(AND(E14="Decision",OR(G14="Progress",G14="Progress with condition",G14="Re-authorise",G14="Resume"),X14<>"Yes"),"Decision-maker has not confirmed the screening was considered (column X)","Check against source"))))))))))))))))))))))))))))) | Q14: =IF(A14="","",IF(E14<>"Decision","",IF(P14="UC-ID specific",IF(O14="","UC-ID REQUIRED","Check source decision for each UC-ID"),IF(P14="Shared system baseline",IF(O14<>"","REMOVE UC-ID OR CORRECT SCOPE","Baseline only — NOT UC approval"),"Decision scope missing"))))
