Workbook

Sheet Dashboard
A1: The Council — AI Governance Dashboard
A2: Controlled point-in-time snapshot. Use-specific measures are counted by UC-ID; AIR-ID (system) counts are labelled as such and never imply UC-ID approval. Each figure displays only when its source, as-at date and checker are recorded (see Measure definitions). UC-ID counts are manually reconciled to the UC-ID current view; no automatic cross-workbook synchronisation.
A4: Reporting period | B4: =IF(ISBLANK('Controlled Inputs'!B4),"",'Controlled Inputs'!B4) | D4: Prepared by | E4: =IF(ISBLANK('Controlled Inputs'!B8),"",'Controlled Inputs'!B8)
A5: Data as at | B5: =IF(ISBLANK('Controlled Inputs'!B5),"",'Controlled Inputs'!B5) | D5: Checked by | E5: =IF(ISBLANK('Controlled Inputs'!B9),"",'Controlled Inputs'!B9)
A6: Indicator | B6: Current period | C6: Previous period | D6: Trend | E6: RAG | F6: Notes / commentary
A7: AIR-IDs with ≥1 authorised UC-ID in operation | B7: =IF(OR(ISBLANK('Controlled Inputs'!B13),OR('Controlled Inputs'!E13="",'Controlled Inputs'!F13="",'Controlled Inputs'!G13="")),"",'Controlled Inputs'!B13) | C7: =IF(OR(ISBLANK('Controlled Inputs'!C13),OR('Controlled Inputs'!E13="",'Controlled Inputs'!F13="",'Controlled Inputs'!G13="")),"",'Controlled Inputs'!C13) | D7: =IF(OR(NOT(ISNUMBER(B7)),NOT(ISNUMBER(C7))),"",IF(B7>C7,"Up",IF(B7<C7,"Down","Flat"))) | E7: =IF(ISBLANK('Controlled Inputs'!D13),"",'Controlled Inputs'!D13) | F7: =IF(AND(NOT(ISBLANK('Controlled Inputs'!B13)),OR('Controlled Inputs'!E13="",'Controlled Inputs'!F13="",'Controlled Inputs'!G13="")),"Withheld — source, as-at or checker missing",IF(ISBLANK('Controlled Inputs'!H13),"",'Controlled Inputs'!H13))
A8: UC-IDs awaiting a delegated decision | B8: =IF(OR(ISBLANK('Controlled Inputs'!B14),OR('Controlled Inputs'!E14="",'Controlled Inputs'!F14="",'Controlled Inputs'!G14="")),"",'Controlled Inputs'!B14) | C8: =IF(OR(ISBLANK('Controlled Inputs'!C14),OR('Controlled Inputs'!E14="",'Controlled Inputs'!F14="",'Controlled Inputs'!G14="")),"",'Controlled Inputs'!C14) | D8: =IF(OR(NOT(ISNUMBER(B8)),NOT(ISNUMBER(C8))),"",IF(B8>C8,"Up",IF(B8<C8,"Down","Flat"))) | E8: =IF(ISBLANK('Controlled Inputs'!D14),"",'Controlled Inputs'!D14) | F8: =IF(AND(NOT(ISBLANK('Controlled Inputs'!B14)),OR('Controlled Inputs'!E14="",'Controlled Inputs'!F14="",'Controlled Inputs'!G14="")),"Withheld — source, as-at or checker missing",IF(ISBLANK('Controlled Inputs'!H14),"",'Controlled Inputs'!H14))
A9: Open incidents | B9: =IF(OR(ISBLANK('Controlled Inputs'!B15),OR('Controlled Inputs'!E15="",'Controlled Inputs'!F15="",'Controlled Inputs'!G15="")),"",'Controlled Inputs'!B15) | C9: =IF(OR(ISBLANK('Controlled Inputs'!C15),OR('Controlled Inputs'!E15="",'Controlled Inputs'!F15="",'Controlled Inputs'!G15="")),"",'Controlled Inputs'!C15) | D9: =IF(OR(NOT(ISNUMBER(B9)),NOT(ISNUMBER(C9))),"",IF(B9>C9,"Up",IF(B9<C9,"Down","Flat"))) | E9: =IF(ISBLANK('Controlled Inputs'!D15),"",'Controlled Inputs'!D15) | F9: =IF(AND(NOT(ISBLANK('Controlled Inputs'!B15)),OR('Controlled Inputs'!E15="",'Controlled Inputs'!F15="",'Controlled Inputs'!G15="")),"Withheld — source, as-at or checker missing",IF(ISBLANK('Controlled Inputs'!H15),"",'Controlled Inputs'!H15))
A10: Assurance activities completed | B10: =IF(OR(ISBLANK('Controlled Inputs'!B16),OR('Controlled Inputs'!E16="",'Controlled Inputs'!F16="",'Controlled Inputs'!G16="")),"",'Controlled Inputs'!B16) | C10: =IF(OR(ISBLANK('Controlled Inputs'!C16),OR('Controlled Inputs'!E16="",'Controlled Inputs'!F16="",'Controlled Inputs'!G16="")),"",'Controlled Inputs'!C16) | D10: =IF(OR(NOT(ISNUMBER(B10)),NOT(ISNUMBER(C10))),"",IF(B10>C10,"Up",IF(B10<C10,"Down","Flat"))) | E10: =IF(ISBLANK('Controlled Inputs'!D16),"",'Controlled Inputs'!D16) | F10: =IF(AND(NOT(ISBLANK('Controlled Inputs'!B16)),OR('Controlled Inputs'!E16="",'Controlled Inputs'!F16="",'Controlled Inputs'!G16="")),"Withheld — source, as-at or checker missing",IF(ISBLANK('Controlled Inputs'!H16),"",'Controlled Inputs'!H16))
A11: Outstanding governance actions | B11: =IF(OR(ISBLANK('Controlled Inputs'!B17),OR('Controlled Inputs'!E17="",'Controlled Inputs'!F17="",'Controlled Inputs'!G17="")),"",'Controlled Inputs'!B17) | C11: =IF(OR(ISBLANK('Controlled Inputs'!C17),OR('Controlled Inputs'!E17="",'Controlled Inputs'!F17="",'Controlled Inputs'!G17="")),"",'Controlled Inputs'!C17) | D11: =IF(OR(NOT(ISNUMBER(B11)),NOT(ISNUMBER(C11))),"",IF(B11>C11,"Up",IF(B11<C11,"Down","Flat"))) | E11: =IF(ISBLANK('Controlled Inputs'!D17),"",'Controlled Inputs'!D17) | F11: =IF(AND(NOT(ISBLANK('Controlled Inputs'!B17)),OR('Controlled Inputs'!E17="",'Controlled Inputs'!F17="",'Controlled Inputs'!G17="")),"Withheld — source, as-at or checker missing",IF(ISBLANK('Controlled Inputs'!H17),"",'Controlled Inputs'!H17))
A12: Compliance status (% compliant) | B12: =IF(OR(ISBLANK('Controlled Inputs'!B18),OR('Controlled Inputs'!E18="",'Controlled Inputs'!F18="",'Controlled Inputs'!G18="")),"",'Controlled Inputs'!B18) | C12: =IF(OR(ISBLANK('Controlled Inputs'!C18),OR('Controlled Inputs'!E18="",'Controlled Inputs'!F18="",'Controlled Inputs'!G18="")),"",'Controlled Inputs'!C18) | D12: =IF(OR(NOT(ISNUMBER(B12)),NOT(ISNUMBER(C12))),"",IF(B12>C12,"Up",IF(B12<C12,"Down","Flat"))) | E12: =IF(ISBLANK('Controlled Inputs'!D18),"",'Controlled Inputs'!D18) | F12: =IF(AND(NOT(ISBLANK('Controlled Inputs'!B18)),OR('Controlled Inputs'!E18="",'Controlled Inputs'!F18="",'Controlled Inputs'!G18="")),"Withheld — source, as-at or checker missing",IF(ISBLANK('Controlled Inputs'!H18),"",'Controlled Inputs'!H18))
A13: Benefits realisation measures | B13: =IF(OR(ISBLANK('Controlled Inputs'!B19),OR('Controlled Inputs'!E19="",'Controlled Inputs'!F19="",'Controlled Inputs'!G19="")),"",'Controlled Inputs'!B19) | C13: =IF(OR(ISBLANK('Controlled Inputs'!C19),OR('Controlled Inputs'!E19="",'Controlled Inputs'!F19="",'Controlled Inputs'!G19="")),"",'Controlled Inputs'!C19) | D13: =IF(OR(NOT(ISNUMBER(B13)),NOT(ISNUMBER(C13))),"",IF(B13>C13,"Up",IF(B13<C13,"Down","Flat"))) | E13: =IF(ISBLANK('Controlled Inputs'!D19),"",'Controlled Inputs'!D19) | F13: =IF(AND(NOT(ISBLANK('Controlled Inputs'!B19)),OR('Controlled Inputs'!E19="",'Controlled Inputs'!F19="",'Controlled Inputs'!G19="")),"Withheld — source, as-at or checker missing",IF(ISBLANK('Controlled Inputs'!H19),"",'Controlled Inputs'!H19))
A14: Training and capability indicators | B14: =IF(OR(ISBLANK('Controlled Inputs'!B20),OR('Controlled Inputs'!E20="",'Controlled Inputs'!F20="",'Controlled Inputs'!G20="")),"",'Controlled Inputs'!B20) | C14: =IF(OR(ISBLANK('Controlled Inputs'!C20),OR('Controlled Inputs'!E20="",'Controlled Inputs'!F20="",'Controlled Inputs'!G20="")),"",'Controlled Inputs'!C20) | D14: =IF(OR(NOT(ISNUMBER(B14)),NOT(ISNUMBER(C14))),"",IF(B14>C14,"Up",IF(B14<C14,"Down","Flat"))) | E14: =IF(ISBLANK('Controlled Inputs'!D20),"",'Controlled Inputs'!D20) | F14: =IF(AND(NOT(ISBLANK('Controlled Inputs'!B20)),OR('Controlled Inputs'!E20="",'Controlled Inputs'!F20="",'Controlled Inputs'!G20="")),"Withheld — source, as-at or checker missing",IF(ISBLANK('Controlled Inputs'!H20),"",'Controlled Inputs'!H20))
A16: UC-ID risk classification distribution (effective tier per UC-ID)
A17: Risk tier | B17: Number of UC-IDs | C17: Share of UC-IDs
A18: Critical | B18: =IF(ISBLANK('Controlled Inputs'!B24),"",'Controlled Inputs'!B24) | C18: =IF(OR(NOT(ISNUMBER(B18)),NOT(ISNUMBER($B$23)),$B$23=0),"",B18/$B$23)
A19: High | B19: =IF(ISBLANK('Controlled Inputs'!B25),"",'Controlled Inputs'!B25) | C19: =IF(OR(NOT(ISNUMBER(B19)),NOT(ISNUMBER($B$23)),$B$23=0),"",B19/$B$23)
A20: Medium | B20: =IF(ISBLANK('Controlled Inputs'!B26),"",'Controlled Inputs'!B26) | C20: =IF(OR(NOT(ISNUMBER(B20)),NOT(ISNUMBER($B$23)),$B$23=0),"",B20/$B$23)
A21: Low | B21: =IF(ISBLANK('Controlled Inputs'!B27),"",'Controlled Inputs'!B27) | C21: =IF(OR(NOT(ISNUMBER(B21)),NOT(ISNUMBER($B$23)),$B$23=0),"",B21/$B$23)
A22: Unclassified / assessment incomplete | B22: =IF(ISBLANK('Controlled Inputs'!B28),"",'Controlled Inputs'!B28) | C22: =IF(OR(NOT(ISNUMBER(B22)),NOT(ISNUMBER($B$23)),$B$23=0),"",B22/$B$23)
A23: Total UC-IDs | B23: =IF(COUNT(B18:B22)=0,"",SUM(B18:B22))
A24: Reconciliation control
A25: Check | B25: Extract rows | C25: Dashboard total | D25: Difference | E25: Status | F25: Source extract ID
A26: UC-ID count | B26: =IF(ISBLANK('Controlled Inputs'!B31),"",'Controlled Inputs'!B31) | C26: =IF(NOT(ISNUMBER(B26)),"",B23) | D26: =IF(OR(NOT(ISNUMBER(B26)),NOT(ISNUMBER(C26))),"",C26-B26) | E26: ='Controlled Inputs'!E31 | F26: =IF(ISBLANK('Controlled Inputs'!B6),"",'Controlled Inputs'!B6)
A28: Release control: do not circulate this dashboard until the source extract is identified, the data cut is recorded, the checker is named and the UC-ID reconciliation status is Reconciled. A blank count is not zero: enter 0 for an empty tier.
A30: Post-deployment live-risk indicators
A31: Indicator | B31: Current period | C31: Previous period | D31: Trend | E31: RAG | F31: Notes / commentary
A32: UC-IDs with overdue reviews | B32: =IF(OR(ISBLANK('Controlled Inputs'!B35),OR('Controlled Inputs'!E35="",'Controlled Inputs'!F35="",'Controlled Inputs'!G35="")),"",'Controlled Inputs'!B35) | C32: =IF(OR(ISBLANK('Controlled Inputs'!C35),OR('Controlled Inputs'!E35="",'Controlled Inputs'!F35="",'Controlled Inputs'!G35="")),"",'Controlled Inputs'!C35) | D32: =IF(OR(NOT(ISNUMBER(B32)),NOT(ISNUMBER(C32))),"",IF(B32>C32,"Up",IF(B32<C32,"Down","Flat"))) | E32: =IF(ISBLANK('Controlled Inputs'!D35),"",'Controlled Inputs'!D35) | F32: =IF(AND(NOT(ISBLANK('Controlled Inputs'!B35)),OR('Controlled Inputs'!E35="",'Controlled Inputs'!F35="",'Controlled Inputs'!G35="")),"Withheld — source, as-at or checker missing",IF(ISBLANK('Controlled Inputs'!H35),"",'Controlled Inputs'!H35))
A33: High/Critical UC-IDs without current monitoring evidence | B33: =IF(OR(ISBLANK('Controlled Inputs'!B36),OR('Controlled Inputs'!E36="",'Controlled Inputs'!F36="",'Controlled Inputs'!G36="")),"",'Controlled Inputs'!B36) | C33: =IF(OR(ISBLANK('Controlled Inputs'!C36),OR('Controlled Inputs'!E36="",'Controlled Inputs'!F36="",'Controlled Inputs'!G36="")),"",'Controlled Inputs'!C36) | D33: =IF(OR(NOT(ISNUMBER(B33)),NOT(ISNUMBER(C33))),"",IF(B33>C33,"Up",IF(B33<C33,"Down","Flat"))) | E33: =IF(ISBLANK('Controlled Inputs'!D36),"",'Controlled Inputs'!D36) | F33: =IF(AND(NOT(ISBLANK('Controlled Inputs'!B36)),OR('Controlled Inputs'!E36="",'Controlled Inputs'!F36="",'Controlled Inputs'!G36="")),"Withheld — source, as-at or checker missing",IF(ISBLANK('Controlled Inputs'!H36),"",'Controlled Inputs'!H36))
A34: UC-IDs outside approved performance, fairness or drift thresholds | B34: =IF(OR(ISBLANK('Controlled Inputs'!B37),OR('Controlled Inputs'!E37="",'Controlled Inputs'!F37="",'Controlled Inputs'!G37="")),"",'Controlled Inputs'!B37) | C34: =IF(OR(ISBLANK('Controlled Inputs'!C37),OR('Controlled Inputs'!E37="",'Controlled Inputs'!F37="",'Controlled Inputs'!G37="")),"",'Controlled Inputs'!C37) | D34: =IF(OR(NOT(ISNUMBER(B34)),NOT(ISNUMBER(C34))),"",IF(B34>C34,"Up",IF(B34<C34,"Down","Flat"))) | E34: =IF(ISBLANK('Controlled Inputs'!D37),"",'Controlled Inputs'!D37) | F34: =IF(AND(NOT(ISBLANK('Controlled Inputs'!B37)),OR('Controlled Inputs'!E37="",'Controlled Inputs'!F37="",'Controlled Inputs'!G37="")),"Withheld — source, as-at or checker missing",IF(ISBLANK('Controlled Inputs'!H37),"",'Controlled Inputs'!H37))
A35: UC-IDs requiring reassessment after breach or material change | B35: =IF(OR(ISBLANK('Controlled Inputs'!B38),OR('Controlled Inputs'!E38="",'Controlled Inputs'!F38="",'Controlled Inputs'!G38="")),"",'Controlled Inputs'!B38) | C35: =IF(OR(ISBLANK('Controlled Inputs'!C38),OR('Controlled Inputs'!E38="",'Controlled Inputs'!F38="",'Controlled Inputs'!G38="")),"",'Controlled Inputs'!C38) | D35: =IF(OR(NOT(ISNUMBER(B35)),NOT(ISNUMBER(C35))),"",IF(B35>C35,"Up",IF(B35<C35,"Down","Flat"))) | E35: =IF(ISBLANK('Controlled Inputs'!D38),"",'Controlled Inputs'!D38) | F35: =IF(AND(NOT(ISBLANK('Controlled Inputs'!B38)),OR('Controlled Inputs'!E38="",'Controlled Inputs'!F38="",'Controlled Inputs'!G38="")),"Withheld — source, as-at or checker missing",IF(ISBLANK('Controlled Inputs'!H38),"",'Controlled Inputs'!H38))
A36: Open High/Critical post-deployment risks | B36: =IF(OR(ISBLANK('Controlled Inputs'!B39),OR('Controlled Inputs'!E39="",'Controlled Inputs'!F39="",'Controlled Inputs'!G39="")),"",'Controlled Inputs'!B39) | C36: =IF(OR(ISBLANK('Controlled Inputs'!C39),OR('Controlled Inputs'!E39="",'Controlled Inputs'!F39="",'Controlled Inputs'!G39="")),"",'Controlled Inputs'!C39) | D36: =IF(OR(NOT(ISNUMBER(B36)),NOT(ISNUMBER(C36))),"",IF(B36>C36,"Up",IF(B36<C36,"Down","Flat"))) | E36: =IF(ISBLANK('Controlled Inputs'!D39),"",'Controlled Inputs'!D39) | F36: =IF(AND(NOT(ISBLANK('Controlled Inputs'!B39)),OR('Controlled Inputs'!E39="",'Controlled Inputs'!F39="",'Controlled Inputs'!G39="")),"Withheld — source, as-at or checker missing",IF(ISBLANK('Controlled Inputs'!H39),"",'Controlled Inputs'!H39))
A39: Use-specific decision snapshot
A40: Systems with system-baseline status Approved (NOT use approvals) | B40: =IF(ISBLANK('Controlled Inputs'!B42),"",'Controlled Inputs'!B42) | C40: =IF(ISBLANK('Controlled Inputs'!C42),"",'Controlled Inputs'!C42) | D40: =IF(OR(NOT(ISNUMBER(B40)),NOT(ISNUMBER(C40))),"",IF(B40>C40,"Up",IF(B40<C40,"Down","Flat"))) | E40: =IF(ISBLANK('Controlled Inputs'!D42),"",'Controlled Inputs'!D42) | F40: =IF(ISBLANK('Controlled Inputs'!H42),"",'Controlled Inputs'!H42)
A41: UC-IDs in reconciled snapshot | B41: =IF(OR(ISBLANK('Controlled Inputs'!B43),'Controlled Inputs'!B49<>"Reconciled"),"",'Controlled Inputs'!B43) | C41: =IF(OR(ISBLANK('Controlled Inputs'!C43),'Controlled Inputs'!B49<>"Reconciled"),"",'Controlled Inputs'!C43) | D41: =IF(OR(NOT(ISNUMBER(B41)),NOT(ISNUMBER(C41))),"",IF(B41>C41,"Up",IF(B41<C41,"Down","Flat"))) | E41: =IF(ISBLANK('Controlled Inputs'!D43),"",'Controlled Inputs'!D43) | F41: =IF(ISBLANK('Controlled Inputs'!H43),"",'Controlled Inputs'!H43)
A42: UC-IDs with UC-specific unconditional Approved decision | B42: =IF(OR(ISBLANK('Controlled Inputs'!B44),'Controlled Inputs'!B49<>"Reconciled"),"",'Controlled Inputs'!B44) | C42: =IF(OR(ISBLANK('Controlled Inputs'!C44),'Controlled Inputs'!B49<>"Reconciled"),"",'Controlled Inputs'!C44) | D42: =IF(OR(NOT(ISNUMBER(B42)),NOT(ISNUMBER(C42))),"",IF(B42>C42,"Up",IF(B42<C42,"Down","Flat"))) | E42: =IF(ISBLANK('Controlled Inputs'!D44),"",'Controlled Inputs'!D44) | F42: =IF(ISBLANK('Controlled Inputs'!H44),"",'Controlled Inputs'!H44)
A43: UC-IDs with Approved with conditions (not unconditional) | B43: =IF(OR(ISBLANK('Controlled Inputs'!B45),'Controlled Inputs'!B49<>"Reconciled"),"",'Controlled Inputs'!B45) | C43: =IF(OR(ISBLANK('Controlled Inputs'!C45),'Controlled Inputs'!B49<>"Reconciled"),"",'Controlled Inputs'!C45) | D43: =IF(OR(NOT(ISNUMBER(B43)),NOT(ISNUMBER(C43))),"",IF(B43>C43,"Up",IF(B43<C43,"Down","Flat"))) | E43: =IF(ISBLANK('Controlled Inputs'!D45),"",'Controlled Inputs'!D45) | F43: =IF(ISBLANK('Controlled Inputs'!H45),"",'Controlled Inputs'!H45)
A44: UC-IDs not currently approved: Pending / Deferred / Rejected / Suspended / Retired / expired / not yet effective | B44: =IF(OR(ISBLANK('Controlled Inputs'!B46),'Controlled Inputs'!B49<>"Reconciled"),"",'Controlled Inputs'!B46) | C44: =IF(OR(ISBLANK('Controlled Inputs'!C46),'Controlled Inputs'!B49<>"Reconciled"),"",'Controlled Inputs'!C46) | D44: =IF(OR(NOT(ISNUMBER(B44)),NOT(ISNUMBER(C44))),"",IF(B44>C44,"Up",IF(B44<C44,"Down","Flat"))) | E44: =IF(ISBLANK('Controlled Inputs'!D46),"",'Controlled Inputs'!D46) | F44: =IF(ISBLANK('Controlled Inputs'!H46),"",'Controlled Inputs'!H46)
A45: UC-IDs Unknown / Unverified / Conflict / missing source or date | B45: =IF(OR(ISBLANK('Controlled Inputs'!B47),'Controlled Inputs'!B49<>"Reconciled"),"",'Controlled Inputs'!B47) | C45: =IF(OR(ISBLANK('Controlled Inputs'!C47),'Controlled Inputs'!B49<>"Reconciled"),"",'Controlled Inputs'!C47) | D45: =IF(OR(NOT(ISNUMBER(B45)),NOT(ISNUMBER(C45))),"",IF(B45>C45,"Up",IF(B45<C45,"Down","Flat"))) | E45: =IF(ISBLANK('Controlled Inputs'!D47),"",'Controlled Inputs'!D47) | F45: =IF(ISBLANK('Controlled Inputs'!H47),"",'Controlled Inputs'!H47)
A46: Systems with ≥1 unapproved, conditional or unknown use | B46: =IF(OR(ISBLANK('Controlled Inputs'!B48),'Controlled Inputs'!B49<>"Reconciled"),"",'Controlled Inputs'!B48) | C46: =IF(OR(ISBLANK('Controlled Inputs'!C48),'Controlled Inputs'!B49<>"Reconciled"),"",'Controlled Inputs'!C48) | D46: =IF(OR(NOT(ISNUMBER(B46)),NOT(ISNUMBER(C46))),"",IF(B46>C46,"Up",IF(B46<C46,"Down","Flat"))) | E46: =IF(ISBLANK('Controlled Inputs'!D48),"",'Controlled Inputs'!D48) | F46: =IF(ISBLANK('Controlled Inputs'!H48),"",'Controlled Inputs'!H48)
...

Sheet Controlled Inputs
A1: The Council — Dashboard Controlled Inputs
A2: Enter or paste point-in-time figures here, not on the Dashboard. Each metric must identify its source record, data cut and checker; a figure without them is withheld from the Dashboard. See the Measure definitions sheet. A blank is not zero.
A4: Reporting period
A5: Data as at
A6: Source extract ID
A7: Source register filename / version
A8: Prepared by
A9: Checked by
A10: Check date
A12: Indicator | B12: Current period | C12: Previous period | D12: RAG | E12: Source record / file | F12: Source data as at | G12: Reconciled / checked by | H12: Notes
A13: AIR-IDs with ≥1 authorised UC-ID in operation
A14: UC-IDs awaiting a delegated decision
A15: Open incidents
A16: Assurance activities completed
A17: Outstanding governance actions
A18: Compliance status (% compliant)
A19: Benefits realisation measures
A20: Training and capability indicators
A22: UC-ID risk classification distribution (count each UC-ID once, at its effective tier, from the UC-ID current view)
A23: Risk tier | B23: Current count (UC-IDs) | C23: Previous count | D23: Source record / file | E23: Source data as at | F23: Reconciled / checked by
A24: Critical
A25: High
A26: Medium
A27: Low
A28: Unclassified / assessment incomplete
A29: Portfolio reconciliation
A30: Check | B30: Source extract rows (UC-IDs) | C30: Tier distribution total | D30: Difference | E30: Status | F30: Checked by
A31: UC-ID count | C31: =IF(COUNT(B24:B28)=0,"",SUM(B24:B28)) | D31: =IF(OR(B31="",C31=""),"",C31-B31) | E31: =IF(B31="","Incomplete",IF(COUNT(B24:B28)<5,"Incomplete — enter 0 for an empty tier (blank is not zero)",IF(D31<>0,"Investigate",IF(OR($B$5="",$B$6="",$B$9="",$B$10="",COUNTBLANK(D24:F28)>0),"Source verification required","Reconciled")))) | F31: =IF(B9="","",B9)
A33: Post-deployment live-risk indicators
A34: Indicator | B34: Current period | C34: Previous period | D34: RAG | E34: Source record / file | F34: Source data as at | G34: Reconciled / checked by | H34: Notes
A35: UC-IDs with overdue reviews
A36: High/Critical UC-IDs without current monitoring evidence
A37: UC-IDs outside approved performance, fairness or drift thresholds
A38: UC-IDs requiring reassessment after breach or material change
A39: Open High/Critical post-deployment risks
A40: Manually reconciled UC-ID snapshot: source evidence and independent check required before counts display. System baseline remains separate.
A41: Indicator | B41: Current period | C41: Previous period | D41: RAG | E41: Source file / view and reconciliation cut-off | F41: Source as at | G41: Independent reconciler | H41: Notes / exceptions
A42: Systems with system-baseline status Approved (NOT use approvals)
A43: UC-IDs in reconciled snapshot
A44: UC-IDs with UC-specific unconditional Approved decision
...

Sheet Measure definitions
A1: AIG-OPS-06 — Measure definitions (controlled with this workbook, v1.4 draft)
A2: Each Dashboard figure must match this definition. Counts are taken at the Controlled Inputs ‘Data as at’ cut from the named source. A blank means not supplied and is never treated as zero. RAG criteria are proposed defaults for Council confirmation.
A4: Ref | B4: Dashboard indicator | C4: What is counted (numerator) | D4: Population / denominator | E4: Unit | F4: Source record and date field | G4: Blank handling | H4: RAG criteria (Proposed — for Council confirmation) | I4: Playbook ref
A5: M01 | B5: AIR-IDs with ≥1 authorised UC-ID in operation | C5: AIR-IDs (systems) with at least one UC-ID whose current delegated decision authorises operation | D5: All AIR-IDs in AIG-INV-04 | E5: Count of AIR-IDs | F5: AIG-INV-04 AI Register (Operational Status) + UC-ID current view; as-at cut | G5: Blank = not supplied | H5: Not RAG-rated (context measure) | I5: §6.9.7; AIG-OPS-05
A6: M02 | B6: UC-IDs awaiting a delegated decision | C6: UC-IDs with a completed assessment and no recorded delegated decision (Pending) | D6: All UC-IDs in the UC-ID current view | E6: Count of UC-IDs | F6: UC-ID current view (Decision outcome = Pending); AIG-DEC-04 Gate plan target dates | G6: Blank = not supplied | H6: Red: any waiting > 60 days; Amber: any waiting 30–60 days; Green: none > 30 days | I6: §6.9.7
A7: M03 | B7: Open incidents | C7: Incident records not formally closed | D7: All AIG-OPS-03 incident records | E7: Count of incidents | F7: AIG-OPS-03 incident log (status, report date) | G7: Blank = not supplied | H7: Red: any open High/Critical incident; Amber: any other open incident; Green: none | I7: §6.6; D8
A8: M04 | B8: Assurance activities completed | C8: Planned assurance activities completed in the period | D8: Assurance activities planned for the period | E8: Count (state n of N in Notes) | F8: AIMS monitoring plan / AIG-DEC-04 Gate plan (Plan state) | G8: Blank = not supplied | H8: Green ≥ 90% of plan; Amber 75–89%; Red < 75% | I8: §6.9
A9: M05 | B9: Outstanding governance actions | C9: Open AIG-DEC-04 conditions and AIMS actions past due at the as-at cut (Overdue derived, not typed) | D9: All open conditions and actions | E9: Count | F9: AIG-DEC-04 Conditions (State, Due date); AIG-AIMS-08 | G9: Blank = not supplied | H9: Red: any High/Critical UC-ID affected; Amber: any other UC-ID affected; Green: none | I9: Annex G.2
A10: M06 | B10: Compliance status (% compliant) | C10: Controls or requirements assessed as compliant | D10: Controls or requirements assessed in the period | E10: Percentage 0–100 (enter 85 for 85%) | F10: AIG-AIMS-06 conformity register; AIG-ASS-03 checklist results | G10: Blank = not supplied; not assessed ≠ compliant | H10: Green ≥ 95; Amber 85–94; Red < 85 | I10: §6.9
A11: M07 | B11: Benefits realisation measures | C11: UC-IDs meeting their approved benefit measure | D11: UC-IDs with an approved benefit measure | E11: Count (state n of N in Notes) | F11: AIG-OPS-02 Monitoring Log (Metric Category = Benefits / Outcomes) | G11: Blank = not supplied | H11: Green ≥ 80%; Amber 60–79%; Red < 60% | I11: §6.4
A12: M08 | B12: Training and capability indicators | C12: Staff in AI roles with required training current | D12: Staff in AI roles (AIG-AIMS-04) | E12: Percentage 0–100 | F12: AIG-AIMS-04 competence records | G12: Blank = not supplied | H12: Green ≥ 90; Amber 75–89; Red < 75 | I12: §5; ISO/IEC 42001 7.2
A13: M09 | B13: UC-ID risk classification distribution | C13: UC-IDs by effective governance tier (Critical/High/Medium/Low) plus Unclassified | D13: All UC-IDs in the UC-ID current view | E13: Count of UC-IDs | F13: UC-ID current view (Risk tier), from AIG-ASS-02 | G13: Enter 0 for an empty tier; a blank tier count stops reconciliation | H13: Not RAG-rated | I13: §4.4.8; §6.9.7
A14: M10 | B14: UC-IDs with overdue reviews | C14: UC-IDs whose next review date is before the as-at cut | D14: All UC-IDs in operation | E14: Count of UC-IDs | F14: AIG-OPS-02 Monitoring Log (Next Review Date, Risk tier) | G14: Blank = not supplied | H14: Red: any High/Critical UC-ID affected; Amber: any other UC-ID affected; Green: none | I14: E.6; D3 cadences
A15: M11 | B15: High/Critical UC-IDs without current monitoring evidence | C15: High/Critical UC-IDs with no monitoring row inside the tier cadence (High quarterly; Critical monthly formal review) | D15: High/Critical UC-IDs in operation | E15: Count of UC-IDs | F15: AIG-OPS-02 Monitoring Log (Review Date, Risk tier) | G15: Blank = not supplied | H15: Red: any; Green: none | I15: E.6; D3
... A21: M17 | B21: Assessor consistency (moderation-sample tier agreement) | C21: Moderation-sample assessments where the second assessor's tier matches the original | D21: Medium and Low assessments in the quarter's moderation sample (second assessor does not see the original scores) | E21: Percentage 0–100 | F21: Moderation sample records (original and second-assessor tiers, AIG-ASS-02); AIG-AIMS-10 M-17 | G21: Blank = not supplied; no sample is not full agreement | H21: Target and RAG criteria set by the Council; any whole-band difference is reviewed by the AI Governance Working Group (Proposed — for Council confirmation) | I21: Assessor consistency (Playbook §4.4.9); AIG-AIMS-10 M-17

Sheet Document Control
A1: AIG-OPS-06 — Document Control
A2: Controlled working template. Draft for Council review; not Council-adopted and not effective until formally approved.
A4: Field | B4: Controlled value
A5: Document ID | B5: AIG-OPS-06
A6: Artefact | B6: AI Governance Dashboard
A7: Version | B7: 1.4 draft
A8: Status | B8: Draft for Council review
A9: Document owner | B9: AI Governance Lead
A10: Approving body | B10: Competent Council authority under Constitution and Scheme of Delegation; AI Assurance Board provides assurance where applicable
A11: Approval date | B11: Not yet approved
A12: Effective date | B12: Not yet effective
A13: Next review date | B13: To be set on approval: 12 months after effective date or sooner following material change
A15: Change history
A16: Version | B16: Date | C16: Change | D16: Author / owner
A17: 1.0 draft | B17: 6 August 2026 | C17: Step 4.3 spreadsheet QA controls and document-control baseline established. | D17: AI Governance Lead
A18: 1.1 draft | B18: 6 August 2026 | C18: Formula guard added so blank portfolio totals display blank rather than an error. | D18: AI Governance Lead
A19: 1.2 draft | B19: Not recorded in source | C19: Not recorded in source (placeholder added during QA remediation so the history is continuous). | D19: Not recorded in source
A20: 1.3 draft | B20: 29 September 2026 | C20: QA remediation — applied findings QA-102, QA-212, QA-218, QA-237, QA-240, QA-251, QA-273, QA-274, QA-275, QA-280, QA-286, QA-291 (see QA change log). | D20: AI Governance Lead
A21: 1.4 draft | B21: 30 September 2026 | C21: v3.9: added proposed indicators M16 (largest dependency concentration, from AIG-INV-05; AIG-AIMS-10 M-16) and M17 (assessor consistency; AIG-AIMS-10 M-17): Controlled Inputs rows 72 to 75, Dashboard rows 48 to 52 with the same release control (withheld until source, as-at and checker are recorded) and Measure definitions rows 20 to 21. Proposed — for Council confirmation. | D21: AI Governance Lead
A22: Classification: OFFICIAL. Approval, effective and review dates must be completed by the document owner following formal governance approval.

Sheet INTEGRATION INV-04 DEC-04
A1: AIG-OPS-06 — PROPOSED AIG-INV-04/AIG-DEC-04 INTEGRATION NOTES
A2: NOT APPROVED — additive integration annex only; existing workbook content and formulas are retained unchanged. AIG-INV-04 (AI Register) and AIG-DEC-04 (Gate Log) are themselves proposed designs: until the Council approves their adoption and migration, the Council’s existing records remain authoritative and the AIG-INV-04/AIG-DEC-04 joins below are design references only. No live system, event, evidence, approval or Council decision is asserted.
A4: Contract area | B4: Authoritative key / authority | C4: Link / required handling and trigger
A5: Portfolio authority / key | B5: AIG-INV-04 AI Register is the proposed system-level source; AIR-ID is the permanent join key. AIG-OPS-06 is a point-in-time reporting snapshot, not a competing register. | C5: Use the AIG-INV-04 source filename/version, extract ID, reconciliation date, reporting period and data-as-at cut in Controlled Inputs. Keep source row counts and checker evidence.
A6: AIG-INV-04 AI Register and Assessment summary extract | B6: Reconcile the extract to AIG-INV-04 AI Register and the associated Assessment summary for the same AIR-ID population and data cut. Include relevant lifecycle/approval, risk and assurance indicators only after source validation. | C6: Identify the AIG-INV-04 filename/version and extract ID; record source data-as-at, preparer, independent checker and check date. Preserve source references per indicator and reconcile count totals before reporting.
A7: AIG-DEC-04 gate plan / events / conditions | B7: For gate coverage, use AIG-DEC-04 Gate plan (requirements and state), Gate events (dated decisions), and Conditions (open/resolved/overdue obligations) for the same AIR-ID and snapshot cut. Gate Map is a derived aid, not primary evidence. | C7: Reconcile each extract and its version/data cut to the AIG-INV-04 snapshot; retain query/extract reference, cut time, row counts, preparer/checker and reconciliation outcome. Distinguish planned gates from final events and open conditions.
A8: Dashboard reporting contract | B8: Dashboard figures are controlled-input snapshot values and formulas remain unchanged. Every figure must identify the source record/file, source data-as-at and who reconciled it. | C8: Do not report unreconciled or mixed-cut values. If AIG-INV-04/AIG-DEC-04 data are missing, stale or inconsistent, flag/investigate in Notes and withhold a reconciled claim; never infer gate completion from a plan.
A9: Change and refresh | B9: A refreshed dashboard is a new dated extract/snapshot; preserve prior cut and source/version identifiers for auditability. | C9: Re-run the reconciliation when AIG-INV-04 AI Register/Assessment summary or AIG-DEC-04 plans/events/conditions change; record the new extract ID, reporting period, data cut and independent check.

Sheet STANDARDS SCOPE QA
A1: PROPOSED QA INDEX — NOT APPROVED. A source reference does not establish applicability or compliance. See AIG-AIMS-05 and AIG-AIMS-13; owners must validate the current source, case-specific scope, control evidence and adopted status.
A2: Requirement ID | B2: Instrument / edition | C2: Conditional scope / relevance | D2: Source URL | E2: Owner validation status
A3: REQ-036 | B3: Algorithmic Transparency Recording Standard (ATRS) | C3: Central-government mandatory scope is distinct from proposed local-authority adoption. | D3: https://www.gov.uk/government/publications/guidance-for-organisations-using-the-algorithmic-transparency-recording-standard/algorithmic-transparency-recording-standard-guidance-for-public-sector-bodies | E3: Specialist validation required
A4: REQ-040 | B4: ISO/IEC 42001:2023 Artificial intelligence management system | C4: Proposed management-system design mapping; licensed clause review and adoption needed. | D4: https://www.iso.org/standard/42001 | E4: Specialist validation required

Sheet MAP & SPLIT CONTRACT
A1: AIG-OPS-06 / PROPOSED THREE-ARTEFACT SOURCE CONTRACT
A3: Status | B3: PROPOSED INTEGRATION DESIGN ONLY. This sheet does not amend the artefact's native assessment, decision authority, data or formulas.
A4: Role of this file | B4: Estate dashboard: Source counts from a dated AIG-INV-04 extract, gate events/conditions from a separate dated AIG-DEC-04 extract, and map coverage only from confirmed, QA-clean map links. Label each extract/version/as-at; never infer approval from map counts.
A5: AIG-INV-04 source | B5: Separate AIG-INV-04 AI Register: official AIR-ID, current position, in-file Assessment summary/Evidence index. Reconcile against authoritative AIG-INV-04 before using a copied value.
A6: AIG-DEC-04 source | B6: Separate AIG-DEC-04 Gate Log: prospective Gate plan, dated Gate events, event-linked Conditions. A planned gate is not a decision. A decision requires AIG-DEC-03 or approved minutes and proper delegation.
A7: Map source | B7: Proposed standalone Capabilities and System Map (candidate catalogue ID AIG-INV-05): UC/CAP and component relationship pointers. Edge ID is not an approval or permission; AIG-AGT-04/AIG-AGT-05 remain sources of agent scope/authority.
A8: Data exchange | B8: Use controlled AIR-ID across files. Where applicable reference exact Event ID, Condition ID, Evidence ID, AG-ID and Edge ID. Record source file/version/as-at with imported or quoted evidence; no live cross-workbook formula is assumed.
A9: Change trigger | B9: New or expanded system/tool access, or a material model, data, interface, purpose or agent change: log the map change, obtain owner reassessment and escalate to the proper AIG-DEC-04 gate/AIG-DEC-03 decision when required.
A10: Validation before use | B10: The INTEGRATION INV-04 DEC-04 tab in this workbook is current supporting design guidance (not historical) and holds the detailed join notes. Controlled owners must reconcile real records, validate values and formulas in Excel, and approve migration/cutover; existing Council records remain unchanged until then.
