Workbook

Sheet Summary
A1: The Council — Agent Record (Agentic System Bill of Materials, ASBOM)
A2: AIG-AGT-04 · v0.7 working draft · Draft for Council review · OFFICIAL · ISO/IEC 42001:2023 · OWASP 2026-aligned
A3: Purpose: the core per-agent record of the agentic layer. One agent, one row on Agent Record, keyed to the permanent AIR-ID plus the agent’s AG-ID; every child sheet carries both keys. The Capability Vector, Components (bill of materials) and Authority & Delegations sheets add the detail an agent's row cannot hold. The AI Register (AIG-INV-04) becomes the portfolio index that points here. Governs the authority envelope (what the agent can do), not the intended use.
A4: Controlled identifier status | B4: AIG-AGT-04 (controlled identifier; formal Council adoption pending)
A6: Field | B6: Controlled value
A7: Document ID | B7: AIG-AGT-04
A8: Version | B8: 0.7 working draft
A9: Status | B9: Draft for Council review; nothing evidenced until operated
A10: Owner | B10: AI Governance Lead; operational and technical owners retain delivery responsibilities
A11: Date | B11: 16 October 2026
A12: Built to | B12: Agentic AI Governance Design Principles (AIG-AGT-01; core principle + five invariants)
A13: Source | B13: OWASP Top 10 for Agentic Applications 2026 (ASI01-ASI10); OWASP Agent Control Standard (1 Sep 2026)
A14: Relationship | B14: AI Register (AIG-INV-04) indexes this; Authority & Delegations feeds the Agent Authority Graph; Agentic Triage records the assessed autonomy level and Agency Tier; the permitted autonomy level is granted at Gate 6 (go-live) by the delegated decision (AIG-DEC-03); each agency tier sets a minimum risk-tier pathway (Gate Map AIG-DEC-01, Agentic pathway)
A15: Classification | B15: OFFICIAL
A17: Change history
A18: Version | B18: Date — change
A19: 0.2 working draft | B19: 25 September 2026 — working draft (history entry reconstructed during QA remediation).
A20: 0.3 working draft | B20: 29 September 2026 — QA remediation — applied findings QA-053, QA-057, QA-094, QA-127, QA-128, QA-129, QA-210, QA-226, QA-227, QA-228, QA-233, QA-234, QA-235, QA-240, QA-251, QA-252, QA-272, QA-280, QA-284, QA-288, QA-291, QA-292 (see QA change log). AG-ID added to every child sheet; ASBOM record version, agency profile, tier floor, pathway and oversight fields added; lists realigned and wired to validations. v3.7 alignment (no version change): permitted autonomy granted at Gate 6; governing pathway = higher of risk-tier pathway and agency-tier minimum (AIG-DEC-01 Agentic pathway); equivalent-control authorisation evidenced at Gate 2 and re-confirmed at Gate 6; “Production gate” label renamed “Production requirement (checked at Gate 6)”.
A21: 0.4 working draft | B21: 30 September 2026 — v3.9.2: Record QA (Agent Record BI) now requires each Required runtime control to be Evidenced (Implemented and Evidenced) or to carry an authorised, time-bounded compensating control (Compensating Control and Expiry / Review), before an Approved/Active agent shows OK; “Implemented” alone no longer passes (Playbook F.7.8; scenario finding W-01). The Agent Record AIR-ID check now uses the AI Register (AIG-INV-04) rule (AIR- plus four characters, warning), so IDs accepted by the Register are accepted here (T-10). Follow-up from the v3.9.2 re-test (NEW-01): a compensating control passes only while its Expiry / Review date is on or after today; an expired (or non-date) Expiry / Review shows “compensating control expired, re-authorise”. See QA change log.
A22: 0.5 working draft | B22: 1 October 2026 — v3.9.4: Field Guidance adds a line on log retention: record the retention period and its basis in Notes (column AD): the DPIA reference, or the records retention schedule class agreed with the records manager where there is no DPIA; in line with Playbook §4.7.12 and AIG-ASS-11 Section 4; no field, header, list or validation changed. Proposed — for Council confirmation.
A23: 0.6 working draft | B23: 4 October 2026 — v3.9.9: proportionate ASBOM. New column BL shows the record level each agent needs (Core; Core plus features; Full at T3 and above, with financial authority or while the tier is unassessed). The core record includes the Agency Profile row. Field Guidance lists the core fields and the sheets each feature switches on, and allows “Not disclosed by supplier” for supplier-side detail but never for a core field. Record QA checks the core fields and the level’s sheets before go-live; the Runtime Controls template no longer defaults all ten controls to Required (set per AIG-ASS-11). Proposed — for Council confirmation.
A24: 0.7 working draft | B24: 16 October 2026 — v3.9.11 / Playbook 19.9.23: new Platform Agent Inventory sheet for agents built on an approved platform (Playbook Appendix F.8), with lists PlatformAgentClass, PlatformAgentAudience and LGATier and a Field Guidance line. Its columns match the Multi-Board Triage tool’s platform agent screening download. No existing sheet, field, formula or validation changed. Proposed — for Council confirmation.

Sheet Agent Record
A1: Agent Record — one row per agent
A2: Keyed to the permanent AIR-ID. Agent authority is an envelope, not blanket approval of every UC-ID. Record authorised UC-ID scope and its delegated decision reference; action records must carry the UC-ID actually invoked.
A3: One agent per row. Every agent that can act needs at least the core record (the core columns are listed on Field Guidance). Column BL shows the level this agent needs: Core; Core plus features (persistence, memory, tool discovery or credential access, and delegation each switch on their own sheets); or Full at T3 and above, with financial authority or while the tier is unassessed (every sheet, including Capability Vector, Components, all ten Runtime Controls and the Authority Graph). “Not disclosed by supplier” is allowed for supplier-side detail, never for a core field. Fail safe: where autonomy, authority or containment is unclear, classify at the higher tier until assessed. | AY3: Stable, unique per-agent key; keep linked to parent AIR-ID. See INTEGRATION INV-04 DEC-04. | BJ3: Permitted autonomy is granted per UC-ID by the delegated decision (AIG-DEC-03), never inferred from the assessed level (QA-053).
A4: AIR-ID | B4: Agent Name | C4: Approved Purpose (mandate) | D4: Prohibited Purposes | E4: Decisions never delegated | F4: Max acceptable consequence | G4: Accountable Executive | H4: Business Owner | I4: Operator / Platform | J4: Environment (stage) | K4: Jurisdiction | L4: Assessed autonomy level (triage; not permission) | M4: Agency Tier | N4: AGPI Priority (from AIG-INV-04) | O4: Persistence? | P4: Memory Type | Q4: Can delegate? | R4: Financial Authority (limit) | S4: Permission Scope (summary) | T4: Identity / credential provenance | U4: Suspension mechanism | V4: Termination mechanism | W4: Kill-switch tested? | X4: Rollback capability? | Y4: Evaluation / red-team status | Z4: Date authorised | AA4: Authority expiry / next reauthorisation | AB4: Governance Approval Status | AC4: Operational Status | AD4: Notes | AE4: Memory Read Scope | AF4: Memory Write Scope | AG4: Memory Retention / Deletion | AH4: Memory Provenance | AI4: Memory Isolation / Poisoning Control | AJ4: Model Routing / Fallback | AK4: Frontier Model? | AL4: Max Delegation Depth | AM4: Recursion Allowed? | AN4: Max Concurrent Sub-agents | AO4: Runtime Control State | AP4: Containment Test Date | AQ4: Time to Containment | AR4: Action Record Available? | AS4: Human Oversight Mode | AT4: Reversibility Class | AU4: Compensating Action | AV4: Budget / Transaction Ceiling | AW4: Agent Creation Authority | AX4: Self-Modification Authority | AY4: AG-ID | AZ4: UC-ID(s) within this authority envelope (reference only) | BA4: Use-specific delegated decision / gate reference(s) | BB4: ASBOM record version | BC4: ASBOM version effective date | BD4: Exposure | BE4: Agency profile ref (Agency Profile sheet — the record) | BF4: Mandatory tier floor applied (trigger) | BG4: Governing pathway (higher of risk-tier pathway and agency-tier minimum) | BH4: Oversight mode rationale | BI4: Record QA | BJ4: Permitted autonomy level (granted at Gate 6) | BK4: Permitted autonomy decision ref (AIG-DEC-03) | BL4: Record level required (Core / Core plus features / Full)
A5: AIR-EXAMPLE | B5: Example — delete before use | C5: Draft supplier invoices for human approval | D5: Making payments; changing bank details | E5: Any payment release | F5: Material financial loss if wrong | G5: Director of Finance | H5: AP Team Lead | I5: AI platform | J5: Pre-production / test | K5: England | L5: A2 bounded execution | M5: T2 bounded agent | N5: Priority 3 | O5: No | P5: Context | Q5: No | R5: No | S5: Read AP mailbox; draft only | T5: Platform service identity AP-047 | U5: Disable tool + revoke token in console | V5: Delete service identity | W5: Yes | X5: Yes | Y5: Pre-deployment eval passed; red-team pending | Z5: 46280 | AA5: 46461 | AB5: Pending | AC5: Not live | AD5: Example row — delete before use. Kill-switch test 2026-09-10 recorded in Containment Test Date. | AE5: Required at Full level or where the feature applies — complete before production | AF5: Required at Full level or where the feature applies — complete before production | AG5: Required at Full level or where the feature applies — complete before production | AH5: Required at Full level or where the feature applies — complete before production | AI5: Required at Full level or where the feature applies — complete before production | AJ5: Required at Full level or where the feature applies — complete before production | AK5: No | AL5: Required at Full level or where the feature applies — complete before production | AM5: No | AN5: Required at Full level or where the feature applies — complete before production | AO5: Designed | AP5: 46275 | AQ5: Required at Full level or where the feature applies — complete before production | AR5: Required at Full level or where the feature applies — complete before production | AS5: Pre-action approval | AT5: Fully reversible | AU5: Required at Full level or where the feature applies — complete before production | AV5: Required at Full level or where the feature applies — complete before production | AW5: Required at Full level or where the feature applies — complete before production | AX5: Required at Full level or where the feature applies — complete before production | AY5: AG-EXAMPLE | AZ5: UC-EXAMPLE | BA5: AIG-DEC-03 reference (example) | BB5: 0.1 | BC5: 46280 | BD5: Internal | BE5: Agency Profile, AG-EXAMPLE | BF5: None triggered | BG5: Medium (risk-tier pathway Medium; T2 agency-tier minimum Medium): agentic controls review at Gate 2 | BH5: Drafts only; every payment-related action needs per-action human approval (D7). | BI5: =IF(A5="","",IF(AY5="","AG-ID missing",IF(COUNTIF($AY$5:$AY$203,AY5)>1,"Duplicate AG-ID",IF(AND(OR(AB5="Approved",AB5="Approved with conditions",AC5="Active"),OR(B5="",C5="",H5="",I5="",M5="",S5="",T5="",U5="",X5="",AA5="",AZ5="",BE5="")),"Core record incomplete: name, purpose, owner, platform, agency tier and profile ref, permission scope, credentials, how to stop it, how to undo it, UC-IDs and review date are needed before go-live",IF(AND(OR(AB5="Approved",AB5="Approved with conditions",AC5="Active"),COUNTIF('Agency Profile'!$B$5:$B$203,AY5)=0),"Agency Profile row missing: record the five agency scores behind the tier",IF(AND(OR(AB5="Approved",AB5="Approved with conditions",AC5="Active"),OR(B5="Not disclosed by supplier",C5="Not disclosed by supplier",H5="Not disclosed by supplier",I5="Not disclosed by supplier",M5="Not disclosed by supplier",S5="Not disclosed by supplier",T5="Not disclosed by supplier",U5="Not disclosed by supplier",X5="Not disclosed by supplier",AA5="Not disclosed by supplier",AZ5="Not disclosed by supplier",BE5="Not disclosed by supplier",AS5="Not disclosed by supplier",BJ5="Not disclosed by supplier")),"A core field says Not disclosed by supplier: the Council must answer the core fields itself",IF(AND(OR(AB5="Approved",AB5="Approved with conditions",AC5="Active"),BL5="Full",OR(COUNTIF('Capability Vector'!$B$5:$B$203,AY5)=0,COUNTIF(Components!$B$5:$B$303,AY5)=0,COUNTIFS('Runtime Controls'!$B$5:$B$303,AY5,'Runtime Controls'!$E$5:$E$303,"<>")<10)),"Full ASBOM (T3 and above, financial authority or tier not assessed): Capability Vector, Components and all ten Runtime Controls rows with Required State set are needed",IF(AND(OR(AB5="Approved",AB5="Approved with conditions",AC5="Active"),OR(Q5="Yes",BL5="Full"),COUNTIF('Authority & Delegations'!$C$5:$C$303,AY5)=0),"Delegation or Full level: add Authority & Delegations rows (they feed the Authority Graph)",IF(AND(OR(AB5="Approved",AB5="Approved with conditions",AC5="Active"),Q5="Yes",COUNTIF('Multi-Agent Controls'!$B$5:$B$303,AY5)=0),"Delegation: add a Multi-Agent Controls row",IF(AND(OR(AB5="Approved",AB5="Approved with conditions",AC5="Active"),O5="Yes",COUNTIF('Runtime Controls'!$B$5:$B$303,AY5)=0),"Persistence: add Runtime Controls rows for how it is stopped and contained",IF(AND(OR(AB5="Approved",AB5="Approved with conditions",AC5="Active"),OR(P5="Working memory",P5="Retrieved knowledge",P5="Persistent memory"),COUNTIF('Memory Controls'!$B$5:$B$303,AY5)=0),"Memory: add a Memory Controls row for each memory store",IF(AND(OR(AB5="Approved",AB5="Approved with conditions",AC5="Active"),COUNTIFS('Capability Vector'!$B$5:$B$203,AY5,'Capability Vector'!$P$5:$P$203,"Yes")+COUNTIFS('Capability Vector'!$B$5:$B$203,AY5,'Capability Vector'!$P$5:$P$203,"Scoped")+COUNTIFS('Capability Vector'!$B$5:$B$203,AY5,'Capability Vector'!$R$5:$R$203,"Yes")+COUNTIFS('Capability Vector'!$B$5:$B$203,AY5,'Capability Vector'!$R$5:$R$203,"Scoped")>0,OR(COUNTIF('Tool Authority Registry'!$B$5:$B$303,AY5)=0,COUNTIF('Interface Register'!$B$5:$B$303,AY5)=0)),"Tool discovery or credential access: add Tool Authority Registry and Interface Register rows",IF(AND(OR(AB5="Approved",AB5="Approved with conditions"),AC5="Active",COUNTIFS('Runtime Controls'!$B$5:$B$303,AY5,'Runtime Controls'!$E$5:$E$303,"Required",'Runtime Controls'!$F$5:$F$303,"<>Evidenced",'Runtime Controls'!$M$5:$M$303,"")+COUNTIFS('Runtime Controls'!$B$5:$B$303,AY5,'Runtime Controls'!$E$5:$E$303,"Required",'Runtime Controls'!$F$5:$F$303,"<>Evidenced",'Runtime Controls'!$M$5:$M$303,"<>",'Runtime Controls'!$L$5:$L$303,"")>0),"Production requirement (Gate 6): required control not Implemented and Evidenced, and no time-bounded compensating control (F.7.8)",IF(AND(OR(AB5="Approved",AB5="Approved with conditions"),AC5="Active",COUNTIFS('Runtime Controls'!$B$5:$B$303,AY5,'Runtime Controls'!$E$5:$E$303,"Required",'Runtime Controls'!$F$5:$F$303,"<>Evidenced",'Runtime Controls'!$M$5:$M$303,"<>",'Runtime Controls'!$L$5:$L$303,"<>")-COUNTIFS('Runtime Controls'!$B$5:$B$303,AY5,'Runtime Controls'!$E$5:$E$303,"Required",'Runtime Controls'!$F$5:$F$303,"<>Evidenced",'Runtime Controls'!$M$5:$M$303,"<>",'Runtime Controls'!$L$5:$L$303,">="&TODAY())>0),"Production requirement (Gate 6): compensating control expired, re-authorise (Expiry / Review must be a date on or after today; F.7.8)",IF(OR(AS5="",BB5=""),"Oversight mode or ASBOM version missing",IF(AND(AC5="Active",BA5=""),"Active without use-specific decision ref (F.7.8)",IF(AND(BJ5<>"",BK5=""),"Permitted autonomy decision ref missing",IF(AND(AC5="Active",BJ5=""),"Active without permitted autonomy level","OK")))))))))))))))))) | BJ5: A2 bounded execution | BK5: AIG-DEC-03 reference (example) | BL5: =IF(A5="","",IF(OR(M5="",LEFT(M5,2)="T3",LEFT(M5,2)="T4",LEFT(M5,2)="T5",AND(R5<>"",R5<>"No",R5<>"None",R5<>"0",R5<>"N/A")),"Full",IF(OR(O5="Yes",Q5="Yes",P5="Working memory",P5="Retrieved knowledge",P5="Persistent memory",COUNTIFS('Capability Vector'!$B$5:$B$203,AY5,'Capability Vector'!$P$5:$P$203,"Yes")+COUNTIFS('Capability Vector'!$B$5:$B$203,AY5,'Capability Vector'!$P$5:$P$203,"Scoped")+COUNTIFS('Capability Vector'!$B$5:$B$203,AY5,'Capability Vector'!$R$5:$R$203,"Yes")+COUNTIFS('Capability Vector'!$B$5:$B$203,AY5,'Capability Vector'!$R$5:$R$203,"Scoped")>0),"Core plus features","Core")))
BI6: =IF(A6="","",IF(AY6="","AG-ID missing",IF(COUNTIF($AY$5:$AY$203,AY6)>1,"Duplicate AG-ID",IF(AND(OR(AB6="Approved",AB6="Approved with conditions",AC6="Active"),OR(B6="",C6="",H6="",I6="",M6="",S6="",T6="",U6="",X6="",AA6="",AZ6="",BE6="")),"Core record incomplete: name, purpose, owner, platform, agency tier and profile ref, permission scope, credentials, how to stop it, how to undo it, UC-IDs and review date are needed before go-live",IF(AND(OR(AB6="Approved",AB6="Approved with conditions",AC6="Active"),COUNTIF('Agency Profile'!$B$5:$B$203,AY6)=0),"Agency Profile row missing: record the five agency scores behind the tier",IF(AND(OR(AB6="Approved",AB6="Approved with conditions",AC6="Active"),OR(B6="Not disclosed by supplier",C6="Not disclosed by supplier",H6="Not disclosed by supplier",I6="Not disclosed by supplier",M6="Not disclosed by supplier",S6="Not disclosed by supplier",T6="Not disclosed by supplier",U6="Not disclosed by supplier",X6="Not disclosed by supplier",AA6="Not disclosed by supplier",AZ6="Not disclosed by supplier",BE6="Not disclosed by supplier",AS6="Not disclosed by supplier",BJ6="Not disclosed by supplier")),"A core field says Not disclosed by supplier: the Council must answer the core fields itself",IF(AND(OR(AB6="Approved",AB6="Approved with conditions",AC6="Active"),BL6="Full",OR(COUNTIF('Capability Vector'!$B$5:$B$203,AY6)=0,COUNTIF(Components!$B$5:$B$303,AY6)=0,COUNTIFS('Runtime Controls'!$B$5:$B$303,AY6,'Runtime Controls'!$E$5:$E$303,"<>")<10)),"Full ASBOM (T3 and above, financial authority or tier not assessed): Capability Vector, Components and all ten Runtime Controls rows with Required State set are needed",IF(AND(OR(AB6="Approved",AB6="Approved with conditions",AC6="Active"),OR(Q6="Yes",BL6="Full"),COUNTIF('Authority & Delegations'!$C$5:$C$303,AY6)=0),"Delegation or Full level: add Authority & Delegations rows (they feed the Authority Graph)",IF(AND(OR(AB6="Approved",AB6="Approved with conditions",AC6="Active"),Q6="Yes",COUNTIF('Multi-Agent Controls'!$B$5:$B$303,AY6)=0),"Delegation: add a Multi-Agent Controls row",IF(AND(OR(AB6="Approved",AB6="Approved with conditions",AC6="Active"),O6="Yes",COUNTIF('Runtime Controls'!$B$5:$B$303,AY6)=0),"Persistence: add Runtime Controls rows for how it is stopped and contained",IF(AND(OR(AB6="Approved",AB6="Approved with conditions",AC6="Active"),OR(P6="Working memory",P6="Retrieved knowledge",P6="Persistent memory"),COUNTIF('Memory Controls'!$B$5:$B$303,AY6)=0),"Memory: add a Memory Controls row for each memory store",IF(AND(OR(AB6="Approved",AB6="Approved with conditions",AC6="Active"),COUNTIFS('Capability Vector'!$B$5:$B$203,AY6,'Capability Vector'!$P$5:$P$203,"Yes")+COUNTIFS('Capability Vector'!$B$5:$B$203,AY6,'Capability Vector'!$P$5:$P$203,"Scoped")+COUNTIFS('Capability Vector'!$B$5:$B$203,AY6,'Capability Vector'!$R$5:$R$203,"Yes")+COUNTIFS('Capability Vector'!$B$5:$B$203,AY6,'Capability Vector'!$R$5:$R$203,"Scoped")>0,OR(COUNTIF('Tool Authority Registry'!$B$5:$B$303,AY6)=0,COUNTIF('Interface Register'!$B$5:$B$303,AY6)=0)),"Tool discovery or credential access: add Tool Authority Registry and Interface Register rows",IF(AND(OR(AB6="Approved",AB6="Approved with conditions"),AC6="Active",COUNTIFS('Runtime Controls'!$B$5:$B$303,AY6,'Runtime Controls'!$E$5:$E$303,"Required",'Runtime Controls'!$F$5:$F$303,"<>Evidenced",'Runtime Controls'!$M$5:$M$303,"")+COUNTIFS('Runtime Controls'!$B$5:$B$303,AY6,'Runtime Controls'!$E$5:$E$303,"Required",'Runtime Controls'!$F$5:$F$303,"<>Evidenced",'Runtime Controls'!$M$5:$M$303,"<>",'Runtime Controls'!$L$5:$L$303,"")>0),"Production requirement (Gate 6): required control not Implemented and Evidenced, and no time-bounded compensating control (F.7.8)",IF(AND(OR(AB6="Approved",AB6="Approved with conditions"),AC6="Active",COUNTIFS('Runtime Controls'!$B$5:$B$303,AY6,'Runtime Controls'!$E$5:$E$303,"Required",'Runtime Controls'!$F$5:$F$303,"<>Evidenced",'Runtime Controls'!$M$5:$M$303,"<>",'Runtime Controls'!$L$5:$L$303,"<>")-COUNTIFS('Runtime Controls'!$B$5:$B$303,AY6,'Runtime Controls'!$E$5:$E$303,"Required",'Runtime Controls'!$F$5:$F$303,"<>Evidenced",'Runtime Controls'!$M$5:$M$303,"<>",'Runtime Controls'!$L$5:$L$303,">="&TODAY())>0),"Production requirement (Gate 6): compensating control expired, re-authorise (Expiry / Review must be a date on or after today; F.7.8)",IF(OR(AS6="",BB6=""),"Oversight mode or ASBOM version missing",IF(AND(AC6="Active",BA6=""),"Active without use-specific decision ref (F.7.8)",IF(AND(BJ6<>"",BK6=""),"Permitted autonomy decision ref missing",IF(AND(AC6="Active",BJ6=""),"Active without permitted autonomy level","OK")))))))))))))))))) | BL6: =IF(A6="","",IF(OR(M6="",LEFT(M6,2)="T3",LEFT(M6,2)="T4",LEFT(M6,2)="T5",AND(R6<>"",R6<>"No",R6<>"None",R6<>"0",R6<>"N/A")),"Full",IF(OR(O6="Yes",Q6="Yes",P6="Working memory",P6="Retrieved knowledge",P6="Persistent memory",COUNTIFS('Capability Vector'!$B$5:$B$203,AY6,'Capability Vector'!$P$5:$P$203,"Yes")+COUNTIFS('Capability Vector'!$B$5:$B$203,AY6,'Capability Vector'!$P$5:$P$203,"Scoped")+COUNTIFS('Capability Vector'!$B$5:$B$203,AY6,'Capability Vector'!$R$5:$R$203,"Yes")+COUNTIFS('Capability Vector'!$B$5:$B$203,AY6,'Capability Vector'!$R$5:$R$203,"Scoped")>0),"Core plus features","Core")))
BI7: =IF(A7="","",IF(AY7="","AG-ID missing",IF(COUNTIF($AY$5:$AY$203,AY7)>1,"Duplicate AG-ID",IF(AND(OR(AB7="Approved",AB7="Approved with conditions",AC7="Active"),OR(B7="",C7="",H7="",I7="",M7="",S7="",T7="",U7="",X7="",AA7="",AZ7="",BE7="")),"Core record incomplete: name, purpose, owner, platform, agency tier and profile ref, permission scope, credentials, how to stop it, how to undo it, UC-IDs and review date are needed before go-live",IF(AND(OR(AB7="Approved",AB7="Approved with conditions",AC7="Active"),COUNTIF('Agency Profile'!$B$5:$B$203,AY7)=0),"Agency Profile row missing: record the five agency scores behind the tier",IF(AND(OR(AB7="Approved",AB7="Approved with conditions",AC7="Active"),OR(B7="Not disclosed by supplier",C7="Not disclosed by supplier",H7="Not disclosed by supplier",I7="Not disclosed by supplier",M7="Not disclosed by supplier",S7="Not disclosed by supplier",T7="Not disclosed by supplier",U7="Not disclosed by supplier",X7="Not disclosed by supplier",AA7="Not disclosed by supplier",AZ7="Not disclosed by supplier",BE7="Not disclosed by supplier",AS7="Not disclosed by supplier",BJ7="Not disclosed by supplier")),"A core field says Not disclosed by supplier: the Council must answer the core fields itself",IF(AND(OR(AB7="Approved",AB7="Approved with conditions",AC7="Active"),BL7="Full",OR(COUNTIF('Capability Vector'!$B$5:$B$203,AY7)=0,COUNTIF(Components!$B$5:$B$303,AY7)=0,COUNTIFS('Runtime Controls'!$B$5:$B$303,AY7,'Runtime Controls'!$E$5:$E$303,"<>")<10)),"Full ASBOM (T3 and above, financial authority or tier not assessed): Capability Vector, Components and all ten Runtime Controls rows with Required State set are needed",IF(AND(OR(AB7="Approved",AB7="Approved with conditions",AC7="Active"),OR(Q7="Yes",BL7="Full"),COUNTIF('Authority & Delegations'!$C$5:$C$303,AY7)=0),"Delegation or Full level: add Authority & Delegations rows (they feed the Authority Graph)",IF(AND(OR(AB7="Approved",AB7="Approved with conditions",AC7="Active"),Q7="Yes",COUNTIF('Multi-Agent Controls'!$B$5:$B$303,AY7)=0),"Delegation: add a Multi-Agent Controls row",IF(AND(OR(AB7="Approved",AB7="Approved with conditions",AC7="Active"),O7="Yes",COUNTIF('Runtime Controls'!$B$5:$B$303,AY7)=0),"Persistence: add Runtime Controls rows for how it is stopped and contained",IF(AND(OR(AB7="Approved",AB7="Approved with conditions",AC7="Active"),OR(P7="Working memory",P7="Retrieved knowledge",P7="Persistent memory"),COUNTIF('Memory Controls'!$B$5:$B$303,AY7)=0),"Memory: add a Memory Controls row for each memory store",IF(AND(OR(AB7="Approved",AB7="Approved with conditions",AC7="Active"),COUNTIFS('Capability Vector'!$B$5:$B$203,AY7,'Capability Vector'!$P$5:$P$203,"Yes")+COUNTIFS('Capability Vector'!$B$5:$B$203,AY7,'Capability Vector'!$P$5:$P$203,"Scoped")+COUNTIFS('Capability Vector'!$B$5:$B$203,AY7,'Capability Vector'!$R$5:$R$203,"Yes")+COUNTIFS('Capability Vector'!$B$5:$B$203,AY7,'Capability Vector'!$R$5:$R$203,"Scoped")>0,OR(COUNTIF('Tool Authority Registry'!$B$5:$B$303,AY7)=0,COUNTIF('Interface Register'!$B$5:$B$303,AY7)=0)),"Tool discovery or credential access: add Tool Authority Registry and Interface Register rows",IF(AND(OR(AB7="Approved",AB7="Approved with conditions"),AC7="Active",COUNTIFS('Runtime Controls'!$B$5:$B$303,AY7,'Runtime Controls'!$E$5:$E$303,"Required",'Runtime Controls'!$F$5:$F$303,"<>Evidenced",'Runtime Controls'!$M$5:$M$303,"")+COUNTIFS('Runtime Controls'!$B$5:$B$303,AY7,'Runtime Controls'!$E$5:$E$303,"Required",'Runtime Controls'!$F$5:$F$303,"<>Evidenced",'Runtime Controls'!$M$5:$M$303,"<>",'Runtime Controls'!$L$5:$L$303,"")>0),"Production requirement (Gate 6): required control not Implemented and Evidenced, and no time-bounded compensating control (F.7.8)",IF(AND(OR(AB7="Approved",AB7="Approved with conditions"),AC7="Active",COUNTIFS('Runtime Controls'!$B$5:$B$303,AY7,'Runtime Controls'!$E$5:$E$303,"Required",'Runtime Controls'!$F$5:$F$303,"<>Evidenced",'Runtime Controls'!$M$5:$M$303,"<>",'Runtime Controls'!$L$5:$L$303,"<>")-COUNTIFS('Runtime Controls'!$B$5:$B$303,AY7,'Runtime Controls'!$E$5:$E$303,"Required",'Runtime Controls'!$F$5:$F$303,"<>Evidenced",'Runtime Controls'!$M$5:$M$303,"<>",'Runtime Controls'!$L$5:$L$303,">="&TODAY())>0),"Production requirement (Gate 6): compensating control expired, re-authorise (Expiry / Review must be a date on or after today; F.7.8)",IF(OR(AS7="",BB7=""),"Oversight mode or ASBOM version missing",IF(AND(AC7="Active",BA7=""),"Active without use-specific decision ref (F.7.8)",IF(AND(BJ7<>"",BK7=""),"Permitted autonomy decision ref missing",IF(AND(AC7="Active",BJ7=""),"Active without permitted autonomy level","OK")))))))))))))))))) | BL7: =IF(A7="","",IF(OR(M7="",LEFT(M7,2)="T3",LEFT(M7,2)="T4",LEFT(M7,2)="T5",AND(R7<>"",R7<>"No",R7<>"None",R7<>"0",R7<>"N/A")),"Full",IF(OR(O7="Yes",Q7="Yes",P7="Working memory",P7="Retrieved knowledge",P7="Persistent memory",COUNTIFS('Capability Vector'!$B$5:$B$203,AY7,'Capability Vector'!$P$5:$P$203,"Yes")+COUNTIFS('Capability Vector'!$B$5:$B$203,AY7,'Capability Vector'!$P$5:$P$203,"Scoped")+COUNTIFS('Capability Vector'!$B$5:$B$203,AY7,'Capability Vector'!$R$5:$R$203,"Yes")+COUNTIFS('Capability Vector'!$B$5:$B$203,AY7,'Capability Vector'!$R$5:$R$203,"Scoped")>0),"Core plus features","Core")))
BI8: =IF(A8="","",IF(AY8="","AG-ID missing",IF(COUNTIF($AY$5:$AY$203,AY8)>1,"Duplicate AG-ID",IF(AND(OR(AB8="Approved",AB8="Approved with conditions",AC8="Active"),OR(B8="",C8="",H8="",I8="",M8="",S8="",T8="",U8="",X8="",AA8="",AZ8="",BE8="")),"Core record incomplete: name, purpose, owner, platform, agency tier and profile ref, permission scope, credentials, how to stop it, how to undo it, UC-IDs and review date are needed before go-live",IF(AND(OR(AB8="Approved",AB8="Approved with conditions",AC8="Active"),COUNTIF('Agency Profile'!$B$5:$B$203,AY8)=0),"Agency Profile row missing: record the five agency scores behind the tier",IF(AND(OR(AB8="Approved",AB8="Approved with conditions",AC8="Active"),OR(B8="Not disclosed by supplier",C8="Not disclosed by supplier",H8="Not disclosed by supplier",I8="Not disclosed by supplier",M8="Not disclosed by supplier",S8="Not disclosed by supplier",T8="Not disclosed by supplier",U8="Not disclosed by supplier",X8="Not disclosed by supplier",AA8="Not disclosed by supplier",AZ8="Not disclosed by supplier",BE8="Not disclosed by supplier",AS8="Not disclosed by supplier",BJ8="Not disclosed by supplier")),"A core field says Not disclosed by supplier: the Council must answer the core fields itself",IF(AND(OR(AB8="Approved",AB8="Approved with conditions",AC8="Active"),BL8="Full",OR(COUNTIF('Capability Vector'!$B$5:$B$203,AY8)=0,COUNTIF(Components!$B$5:$B$303,AY8)=0,COUNTIFS('Runtime Controls'!$B$5:$B$303,AY8,'Runtime Controls'!$E$5:$E$303,"<>")<10)),"Full ASBOM (T3 and above, financial authority or tier not assessed): Capability Vector, Components and all ten Runtime Controls rows with Required State set are needed",IF(AND(OR(AB8="Approved",AB8="Approved with conditions",AC8="Active"),OR(Q8="Yes",BL8="Full"),COUNTIF('Authority & Delegations'!$C$5:$C$303,AY8)=0),"Delegation or Full level: add Authority & Delegations rows (they feed the Authority Graph)",IF(AND(OR(AB8="Approved",AB8="Approved with conditions",AC8="Active"),Q8="Yes",COUNTIF('Multi-Agent Controls'!$B$5:$B$303,AY8)=0),"Delegation: add a Multi-Agent Controls row",IF(AND(OR(AB8="Approved",AB8="Approved with conditions",AC8="Active"),O8="Yes",COUNTIF('Runtime Controls'!$B$5:$B$303,AY8)=0),"Persistence: add Runtime Controls rows for how it is stopped and contained",IF(AND(OR(AB8="Approved",AB8="Approved with conditions",AC8="Active"),OR(P8="Working memory",P8="Retrieved knowledge",P8="Persistent memory"),COUNTIF('Memory Controls'!$B$5:$B$303,AY8)=0),"Memory: add a Memory Controls row for each memory store",IF(AND(OR(AB8="Approved",AB8="Approved with conditions",AC8="Active"),COUNTIFS('Capability Vector'!$B$5:$B$203,AY8,'Capability Vector'!$P$5:$P$203,"Yes")+COUNTIFS('Capability Vector'!$B$5:$B$203,AY8,'Capability Vector'!$P$5:$P$203,"Scoped")+COUNTIFS('Capability Vector'!$B$5:$B$203,AY8,'Capability Vector'!$R$5:$R$203,"Yes")+COUNTIFS('Capability Vector'!$B$5:$B$203,AY8,'Capability Vector'!$R$5:$R$203,"Scoped")>0,OR(COUNTIF('Tool Authority Registry'!$B$5:$B$303,AY8)=0,COUNTIF('Interface Register'!$B$5:$B$303,AY8)=0)),"Tool discovery or credential access: add Tool Authority Registry and Interface Register rows",IF(AND(OR(AB8="Approved",AB8="Approved with conditions"),AC8="Active",COUNTIFS('Runtime Controls'!$B$5:$B$303,AY8,'Runtime Controls'!$E$5:$E$303,"Required",'Runtime Controls'!$F$5:$F$303,"<>Evidenced",'Runtime Controls'!$M$5:$M$303,"")+COUNTIFS('Runtime Controls'!$B$5:$B$303,AY8,'Runtime Controls'!$E$5:$E$303,"Required",'Runtime Controls'!$F$5:$F$303,"<>Evidenced",'Runtime Controls'!$M$5:$M$303,"<>",'Runtime Controls'!$L$5:$L$303,"")>0),"Production requirement (Gate 6): required control not Implemented and Evidenced, and no time-bounded compensating control (F.7.8)",IF(AND(OR(AB8="Approved",AB8="Approved with conditions"),AC8="Active",COUNTIFS('Runtime Controls'!$B$5:$B$303,AY8,'Runtime Controls'!$E$5:$E$303,"Required",'Runtime Controls'!$F$5:$F$303,"<>Evidenced",'Runtime Controls'!$M$5:$M$303,"<>",'Runtime Controls'!$L$5:$L$303,"<>")-COUNTIFS('Runtime Controls'!$B$5:$B$303,AY8,'Runtime Controls'!$E$5:$E$303,"Required",'Runtime Controls'!$F$5:$F$303,"<>Evidenced",'Runtime Controls'!$M$5:$M$303,"<>",'Runtime Controls'!$L$5:$L$303,">="&TODAY())>0),"Production requirement (Gate 6): compensating control expired, re-authorise (Expiry / Review must be a date on or after today; F.7.8)",IF(OR(AS8="",BB8=""),"Oversight mode or ASBOM version missing",IF(AND(AC8="Active",BA8=""),"Active without use-specific decision ref (F.7.8)",IF(AND(BJ8<>"",BK8=""),"Permitted autonomy decision ref missing",IF(AND(AC8="Active",BJ8=""),"Active without permitted autonomy level","OK")))))))))))))))))) | BL8: =IF(A8="","",IF(OR(M8="",LEFT(M8,2)="T3",LEFT(M8,2)="T4",LEFT(M8,2)="T5",AND(R8<>"",R8<>"No",R8<>"None",R8<>"0",R8<>"N/A")),"Full",IF(OR(O8="Yes",Q8="Yes",P8="Working memory",P8="Retrieved knowledge",P8="Persistent memory",COUNTIFS('Capability Vector'!$B$5:$B$203,AY8,'Capability Vector'!$P$5:$P$203,"Yes")+COUNTIFS('Capability Vector'!$B$5:$B$203,AY8,'Capability Vector'!$P$5:$P$203,"Scoped")+COUNTIFS('Capability Vector'!$B$5:$B$203,AY8,'Capability Vector'!$R$5:$R$203,"Yes")+COUNTIFS('Capability Vector'!$B$5:$B$203,AY8,'Capability Vector'!$R$5:$R$203,"Scoped")>0),"Core plus features","Core")))
BI9: =IF(A9="","",IF(AY9="","AG-ID missing",IF(COUNTIF($AY$5:$AY$203,AY9)>1,"Duplicate AG-ID",IF(AND(OR(AB9="Approved",AB9="Approved with conditions",AC9="Active"),OR(B9="",C9="",H9="",I9="",M9="",S9="",T9="",U9="",X9="",AA9="",AZ9="",BE9="")),"Core record incomplete: name, purpose, owner, platform, agency tier and profile ref, permission scope, credentials, how to stop it, how to undo it, UC-IDs and review date are needed before go-live",IF(AND(OR(AB9="Approved",AB9="Approved with conditions",AC9="Active"),COUNTIF('Agency Profile'!$B$5:$B$203,AY9)=0),"Agency Profile row missing: record the five agency scores behind the tier",IF(AND(OR(AB9="Approved",AB9="Approved with conditions",AC9="Active"),OR(B9="Not disclosed by supplier",C9="Not disclosed by supplier",H9="Not disclosed by supplier",I9="Not disclosed by supplier",M9="Not disclosed by supplier",S9="Not disclosed by supplier",T9="Not disclosed by supplier",U9="Not disclosed by supplier",X9="Not disclosed by supplier",AA9="Not disclosed by supplier",AZ9="Not disclosed by supplier",BE9="Not disclosed by supplier",AS9="Not disclosed by supplier",BJ9="Not disclosed by supplier")),"A core field says Not disclosed by supplier: the Council must answer the core fields itself",IF(AND(OR(AB9="Approved",AB9="Approved with conditions",AC9="Active"),BL9="Full",OR(COUNTIF('Capability Vector'!$B$5:$B$203,AY9)=0,COUNTIF(Components!$B$5:$B$303,AY9)=0,COUNTIFS('Runtime Controls'!$B$5:$B$303,AY9,'Runtime Controls'!$E$5:$E$303,"<>")<10)),"Full ASBOM (T3 and above, financial authority or tier not assessed): Capability Vector, Components and all ten Runtime Controls rows with Required State set are needed",IF(AND(OR(AB9="Approved",AB9="Approved with conditions",AC9="Active"),OR(Q9="Yes",BL9="Full"),COUNTIF('Authority & Delegations'!$C$5:$C$303,AY9)=0),"Delegation or Full level: add Authority & Delegations rows (they feed the Authority Graph)",IF(AND(OR(AB9="Approved",AB9="Approved with conditions",AC9="Active"),Q9="Yes",COUNTIF('Multi-Agent Controls'!$B$5:$B$303,AY9)=0),"Delegation: add a Multi-Agent Controls row",IF(AND(OR(AB9="Approved",AB9="Approved with conditions",AC9="Active"),O9="Yes",COUNTIF('Runtime Controls'!$B$5:$B$303,AY9)=0),"Persistence: add Runtime Controls rows for how it is stopped and contained",IF(AND(OR(AB9="Approved",AB9="Approved with conditions",AC9="Active"),OR(P9="Working memory",P9="Retrieved knowledge",P9="Persistent memory"),COUNTIF('Memory Controls'!$B$5:$B$303,AY9)=0),"Memory: add a Memory Controls row for each memory store",IF(AND(OR(AB9="Approved",AB9="Approved with conditions",AC9="Active"),COUNTIFS('Capability Vector'!$B$5:$B$203,AY9,'Capability Vector'!$P$5:$P$203,"Yes")+COUNTIFS('Capability Vector'!$B$5:$B$203,AY9,'Capability Vector'!$P$5:$P$203,"Scoped")+COUNTIFS('Capability Vector'!$B$5:$B$203,AY9,'Capability Vector'!$R$5:$R$203,"Yes")+COUNTIFS('Capability Vector'!$B$5:$B$203,AY9,'Capability Vector'!$R$5:$R$203,"Scoped")>0,OR(COUNTIF('Tool Authority Registry'!$B$5:$B$303,AY9)=0,COUNTIF('Interface Register'!$B$5:$B$303,AY9)=0)),"Tool discovery or credential access: add Tool Authority Registry and Interface Register rows",IF(AND(OR(AB9="Approved",AB9="Approved with conditions"),AC9="Active",COUNTIFS('Runtime Controls'!$B$5:$B$303,AY9,'Runtime Controls'!$E$5:$E$303,"Required",'Runtime Controls'!$F$5:$F$303,"<>Evidenced",'Runtime Controls'!$M$5:$M$303,"")+COUNTIFS('Runtime Controls'!$B$5:$B$303,AY9,'Runtime Controls'!$E$5:$E$303,"Required",'Runtime Controls'!$F$5:$F$303,"<>Evidenced",'Runtime Controls'!$M$5:$M$303,"<>",'Runtime Controls'!$L$5:$L$303,"")>0),"Production requirement (Gate 6): required control not Implemented and Evidenced, and no time-bounded compensating control (F.7.8)",IF(AND(OR(AB9="Approved",AB9="Approved with conditions"),AC9="Active",COUNTIFS('Runtime Controls'!$B$5:$B$303,AY9,'Runtime Controls'!$E$5:$E$303,"Required",'Runtime Controls'!$F$5:$F$303,"<>Evidenced",'Runtime Controls'!$M$5:$M$303,"<>",'Runtime Controls'!$L$5:$L$303,"<>")-COUNTIFS('Runtime Controls'!$B$5:$B$303,AY9,'Runtime Controls'!$E$5:$E$303,"Required",'Runtime Controls'!$F$5:$F$303,"<>Evidenced",'Runtime Controls'!$M$5:$M$303,"<>",'Runtime Controls'!$L$5:$L$303,">="&TODAY())>0),"Production requirement (Gate 6): compensating control expired, re-authorise (Expiry / Review must be a date on or after today; F.7.8)",IF(OR(AS9="",BB9=""),"Oversight mode or ASBOM version missing",IF(AND(AC9="Active",BA9=""),"Active without use-specific decision ref (F.7.8)",IF(AND(BJ9<>"",BK9=""),"Permitted autonomy decision ref missing",IF(AND(AC9="Active",BJ9=""),"Active without permitted autonomy level","OK")))))))))))))))))) | BL9: =IF(A9="","",IF(OR(M9="",LEFT(M9,2)="T3",LEFT(M9,2)="T4",LEFT(M9,2)="T5",AND(R9<>"",R9<>"No",R9<>"None",R9<>"0",R9<>"N/A")),"Full",IF(OR(O9="Yes",Q9="Yes",P9="Working memory",P9="Retrieved knowledge",P9="Persistent memory",COUNTIFS('Capability Vector'!$B$5:$B$203,AY9,'Capability Vector'!$P$5:$P$203,"Yes")+COUNTIFS('Capability Vector'!$B$5:$B$203,AY9,'Capability Vector'!$P$5:$P$203,"Scoped")+COUNTIFS('Capability Vector'!$B$5:$B$203,AY9,'Capability Vector'!$R$5:$R$203,"Yes")+COUNTIFS('Capability Vector'!$B$5:$B$203,AY9,'Capability Vector'!$R$5:$R$203,"Scoped")>0),"Core plus features","Core")))
BI10: =IF(A10="","",IF(AY10="","AG-ID missing",IF(COUNTIF($AY$5:$AY$203,AY10)>1,"Duplicate AG-ID",IF(AND(OR(AB10="Approved",AB10="Approved with conditions",AC10="Active"),OR(B10="",C10="",H10="",I10="",M10="",S10="",T10="",U10="",X10="",AA10="",AZ10="",BE10="")),"Core record incomplete: name, purpose, owner, platform, agency tier and profile ref, permission scope, credentials, how to stop it, how to undo it, UC-IDs and review date are needed before go-live",IF(AND(OR(AB10="Approved",AB10="Approved with conditions",AC10="Active"),COUNTIF('Agency Profile'!$B$5:$B$203,AY10)=0),"Agency Profile row missing: record the five agency scores behind the tier",IF(AND(OR(AB10="Approved",AB10="Approved with conditions",AC10="Active"),OR(B10="Not disclosed by supplier",C10="Not disclosed by supplier",H10="Not disclosed by supplier",I10="Not disclosed by supplier",M10="Not disclosed by supplier",S10="Not disclosed by supplier",T10="Not disclosed by supplier",U10="Not disclosed by supplier",X10="Not disclosed by supplier",AA10="Not disclosed by supplier",AZ10="Not disclosed by supplier",BE10="Not disclosed by supplier",AS10="Not disclosed by supplier",BJ10="Not disclosed by supplier")),"A core field says Not disclosed by supplier: the Council must answer the core fields itself",IF(AND(OR(AB10="Approved",AB10="Approved with conditions",AC10="Active"),BL10="Full",OR(COUNTIF('Capability Vector'!$B$5:$B$203,AY10)=0,COUNTIF(Components!$B$5:$B$303,AY10)=0,COUNTIFS('Runtime Controls'!$B$5:$B$303,AY10,'Runtime Controls'!$E$5:$E$303,"<>")<10)),"Full ASBOM (T3 and above, financial authority or tier not assessed): Capability Vector, Components and all ten Runtime Controls rows with Required State set are needed",IF(AND(OR(AB10="Approved",AB10="Approved with conditions",AC10="Active"),OR(Q10="Yes",BL10="Full"),COUNTIF('Authority & Delegations'!$C$5:$C$303,AY10)=0),"Delegation or Full level: add Authority & Delegations rows (they feed the Authority Graph)",IF(AND(OR(AB10="Approved",AB10="Approved with conditions",AC10="Active"),Q10="Yes",COUNTIF('Multi-Agent Controls'!$B$5:$B$303,AY10)=0),"Delegation: add a Multi-Agent Controls row",IF(AND(OR(AB10="Approved",AB10="Approved with conditions",AC10="Active"),O10="Yes",COUNTIF('Runtime Controls'!$B$5:$B$303,AY10)=0),"Persistence: add Runtime Controls rows for how it is stopped and contained",IF(AND(OR(AB10="Approved",AB10="Approved with conditions",AC10="Active"),OR(P10="Working memory",P10="Retrieved knowledge",P10="Persistent memory"),COUNTIF('Memory Controls'!$B$5:$B$303,AY10)=0),"Memory: add a Memory Controls row for each memory store",IF(AND(OR(AB10="Approved",AB10="Approved with conditions",AC10="Active"),COUNTIFS('Capability Vector'!$B$5:$B$203,AY10,'Capability Vector'!$P$5:$P$203,"Yes")+COUNTIFS('Capability Vector'!$B$5:$B$203,AY10,'Capability Vector'!$P$5:$P$203,"Scoped")+COUNTIFS('Capability Vector'!$B$5:$B$203,AY10,'Capability Vector'!$R$5:$R$203,"Yes")+COUNTIFS('Capability Vector'!$B$5:$B$203,AY10,'Capability Vector'!$R$5:$R$203,"Scoped")>0,OR(COUNTIF('Tool Authority Registry'!$B$5:$B$303,AY10)=0,COUNTIF('Interface Register'!$B$5:$B$303,AY10)=0)),"Tool discovery or credential access: add Tool Authority Registry and Interface Register rows",IF(AND(OR(AB10="Approved",AB10="Approved with conditions"),AC10="Active",COUNTIFS('Runtime Controls'!$B$5:$B$303,AY10,'Runtime Controls'!$E$5:$E$303,"Required",'Runtime Controls'!$F$5:$F$303,"<>Evidenced",'Runtime Controls'!$M$5:$M$303,"")+COUNTIFS('Runtime Controls'!$B$5:$B$303,AY10,'Runtime Controls'!$E$5:$E$303,"Required",'Runtime Controls'!$F$5:$F$303,"<>Evidenced",'Runtime Controls'!$M$5:$M$303,"<>",'Runtime Controls'!$L$5:$L$303,"")>0),"Production requirement (Gate 6): required control not Implemented and Evidenced, and no time-bounded compensating control (F.7.8)",IF(AND(OR(AB10="Approved",AB10="Approved with conditions"),AC10="Active",COUNTIFS('Runtime Controls'!$B$5:$B$303,AY10,'Runtime Controls'!$E$5:$E$303,"Required",'Runtime Controls'!$F$5:$F$303,"<>Evidenced",'Runtime Controls'!$M$5:$M$303,"<>",'Runtime Controls'!$L$5:$L$303,"<>")-COUNTIFS('Runtime Controls'!$B$5:$B$303,AY10,'Runtime Controls'!$E$5:$E$303,"Required",'Runtime Controls'!$F$5:$F$303,"<>Evidenced",'Runtime Controls'!$M$5:$M$303,"<>",'Runtime Controls'!$L$5:$L$303,">="&TODAY())>0),"Production requirement (Gate 6): compensating control expired, re-authorise (Expiry / Review must be a date on or after today; F.7.8)",IF(OR(AS10="",BB10=""),"Oversight mode or ASBOM version missing",IF(AND(AC10="Active",BA10=""),"Active without use-specific decision ref (F.7.8)",IF(AND(BJ10<>"",BK10=""),"Permitted autonomy decision ref missing",IF(AND(AC10="Active",BJ10=""),"Active without permitted autonomy level","OK")))))))))))))))))) | BL10: =IF(A10="","",IF(OR(M10="",LEFT(M10,2)="T3",LEFT(M10,2)="T4",LEFT(M10,2)="T5",AND(R10<>"",R10<>"No",R10<>"None",R10<>"0",R10<>"N/A")),"Full",IF(OR(O10="Yes",Q10="Yes",P10="Working memory",P10="Retrieved knowledge",P10="Persistent memory",COUNTIFS('Capability Vector'!$B$5:$B$203,AY10,'Capability Vector'!$P$5:$P$203,"Yes")+COUNTIFS('Capability Vector'!$B$5:$B$203,AY10,'Capability Vector'!$P$5:$P$203,"Scoped")+COUNTIFS('Capability Vector'!$B$5:$B$203,AY10,'Capability Vector'!$R$5:$R$203,"Yes")+COUNTIFS('Capability Vector'!$B$5:$B$203,AY10,'Capability Vector'!$R$5:$R$203,"Scoped")>0),"Core plus features","Core")))
BI11: =IF(A11="","",IF(AY11="","AG-ID missing",IF(COUNTIF($AY$5:$AY$203,AY11)>1,"Duplicate AG-ID",IF(AND(OR(AB11="Approved",AB11="Approved with conditions",AC11="Active"),OR(B11="",C11="",H11="",I11="",M11="",S11="",T11="",U11="",X11="",AA11="",AZ11="",BE11="")),"Core record incomplete: name, purpose, owner, platform, agency tier and profile ref, permission scope, credentials, how to stop it, how to undo it, UC-IDs and review date are needed before go-live",IF(AND(OR(AB11="Approved",AB11="Approved with conditions",AC11="Active"),COUNTIF('Agency Profile'!$B$5:$B$203,AY11)=0),"Agency Profile row missing: record the five agency scores behind the tier",IF(AND(OR(AB11="Approved",AB11="Approved with conditions",AC11="Active"),OR(B11="Not disclosed by supplier",C11="Not disclosed by supplier",H11="Not disclosed by supplier",I11="Not disclosed by supplier",M11="Not disclosed by supplier",S11="Not disclosed by supplier",T11="Not disclosed by supplier",U11="Not disclosed by supplier",X11="Not disclosed by supplier",AA11="Not disclosed by supplier",AZ11="Not disclosed by supplier",BE11="Not disclosed by supplier",AS11="Not disclosed by supplier",BJ11="Not disclosed by supplier")),"A core field says Not disclosed by supplier: the Council must answer the core fields itself",IF(AND(OR(AB11="Approved",AB11="Approved with conditions",AC11="Active"),BL11="Full",OR(COUNTIF('Capability Vector'!$B$5:$B$203,AY11)=0,COUNTIF(Components!$B$5:$B$303,AY11)=0,COUNTIFS('Runtime Controls'!$B$5:$B$303,AY11,'Runtime Controls'!$E$5:$E$303,"<>")<10)),"Full ASBOM (T3 and above, financial authority or tier not assessed): Capability Vector, Components and all ten Runtime Controls rows with Required State set are needed",IF(AND(OR(AB11="Approved",AB11="Approved with conditions",AC11="Active"),OR(Q11="Yes",BL11="Full"),COUNTIF('Authority & Delegations'!$C$5:$C$303,AY11)=0),"Delegation or Full level: add Authority & Delegations rows (they feed the Authority Graph)",IF(AND(OR(AB11="Approved",AB11="Approved with conditions",AC11="Active"),Q11="Yes",COUNTIF('Multi-Agent Controls'!$B$5:$B$303,AY11)=0),"Delegation: add a Multi-Agent Controls row",IF(AND(OR(AB11="Approved",AB11="Approved with conditions",AC11="Active"),O11="Yes",COUNTIF('Runtime Controls'!$B$5:$B$303,AY11)=0),"Persistence: add Runtime Controls rows for how it is stopped and contained",IF(AND(OR(AB11="Approved",AB11="Approved with conditions",AC11="Active"),OR(P11="Working memory",P11="Retrieved knowledge",P11="Persistent memory"),COUNTIF('Memory Controls'!$B$5:$B$303,AY11)=0),"Memory: add a Memory Controls row for each memory store",IF(AND(OR(AB11="Approved",AB11="Approved with conditions",AC11="Active"),COUNTIFS('Capability Vector'!$B$5:$B$203,AY11,'Capability Vector'!$P$5:$P$203,"Yes")+COUNTIFS('Capability Vector'!$B$5:$B$203,AY11,'Capability Vector'!$P$5:$P$203,"Scoped")+COUNTIFS('Capability Vector'!$B$5:$B$203,AY11,'Capability Vector'!$R$5:$R$203,"Yes")+COUNTIFS('Capability Vector'!$B$5:$B$203,AY11,'Capability Vector'!$R$5:$R$203,"Scoped")>0,OR(COUNTIF('Tool Authority Registry'!$B$5:$B$303,AY11)=0,COUNTIF('Interface Register'!$B$5:$B$303,AY11)=0)),"Tool discovery or credential access: add Tool Authority Registry and Interface Register rows",IF(AND(OR(AB11="Approved",AB11="Approved with conditions"),AC11="Active",COUNTIFS('Runtime Controls'!$B$5:$B$303,AY11,'Runtime Controls'!$E$5:$E$303,"Required",'Runtime Controls'!$F$5:$F$303,"<>Evidenced",'Runtime Controls'!$M$5:$M$303,"")+COUNTIFS('Runtime Controls'!$B$5:$B$303,AY11,'Runtime Controls'!$E$5:$E$303,"Required",'Runtime Controls'!$F$5:$F$303,"<>Evidenced",'Runtime Controls'!$M$5:$M$303,"<>",'Runtime Controls'!$L$5:$L$303,"")>0),"Production requirement (Gate 6): required control not Implemented and Evidenced, and no time-bounded compensating control (F.7.8)",IF(AND(OR(AB11="Approved",AB11="Approved with conditions"),AC11="Active",COUNTIFS('Runtime Controls'!$B$5:$B$303,AY11,'Runtime Controls'!$E$5:$E$303,"Required",'Runtime Controls'!$F$5:$F$303,"<>Evidenced",'Runtime Controls'!$M$5:$M$303,"<>",'Runtime Controls'!$L$5:$L$303,"<>")-COUNTIFS('Runtime Controls'!$B$5:$B$303,AY11,'Runtime Controls'!$E$5:$E$303,"Required",'Runtime Controls'!$F$5:$F$303,"<>Evidenced",'Runtime Controls'!$M$5:$M$303,"<>",'Runtime Controls'!$L$5:$L$303,">="&TODAY())>0),"Production requirement (Gate 6): compensating control expired, re-authorise (Expiry / Review must be a date on or after today; F.7.8)",IF(OR(AS11="",BB11=""),"Oversight mode or ASBOM version missing",IF(AND(AC11="Active",BA11=""),"Active without use-specific decision ref (F.7.8)",IF(AND(BJ11<>"",BK11=""),"Permitted autonomy decision ref missing",IF(AND(AC11="Active",BJ11=""),"Active without permitted autonomy level","OK")))))))))))))))))) | BL11: =IF(A11="","",IF(OR(M11="",LEFT(M11,2)="T3",LEFT(M11,2)="T4",LEFT(M11,2)="T5",AND(R11<>"",R11<>"No",R11<>"None",R11<>"0",R11<>"N/A")),"Full",IF(OR(O11="Yes",Q11="Yes",P11="Working memory",P11="Retrieved knowledge",P11="Persistent memory",COUNTIFS('Capability Vector'!$B$5:$B$203,AY11,'Capability Vector'!$P$5:$P$203,"Yes")+COUNTIFS('Capability Vector'!$B$5:$B$203,AY11,'Capability Vector'!$P$5:$P$203,"Scoped")+COUNTIFS('Capability Vector'!$B$5:$B$203,AY11,'Capability Vector'!$R$5:$R$203,"Yes")+COUNTIFS('Capability Vector'!$B$5:$B$203,AY11,'Capability Vector'!$R$5:$R$203,"Scoped")>0),"Core plus features","Core")))
BI12: =IF(A12="","",IF(AY12="","AG-ID missing",IF(COUNTIF($AY$5:$AY$203,AY12)>1,"Duplicate AG-ID",IF(AND(OR(AB12="Approved",AB12="Approved with conditions",AC12="Active"),OR(B12="",C12="",H12="",I12="",M12="",S12="",T12="",U12="",X12="",AA12="",AZ12="",BE12="")),"Core record incomplete: name, purpose, owner, platform, agency tier and profile ref, permission scope, credentials, how to stop it, how to undo it, UC-IDs and review date are needed before go-live",IF(AND(OR(AB12="Approved",AB12="Approved with conditions",AC12="Active"),COUNTIF('Agency Profile'!$B$5:$B$203,AY12)=0),"Agency Profile row missing: record the five agency scores behind the tier",IF(AND(OR(AB12="Approved",AB12="Approved with conditions",AC12="Active"),OR(B12="Not disclosed by supplier",C12="Not disclosed by supplier",H12="Not disclosed by supplier",I12="Not disclosed by supplier",M12="Not disclosed by supplier",S12="Not disclosed by supplier",T12="Not disclosed by supplier",U12="Not disclosed by supplier",X12="Not disclosed by supplier",AA12="Not disclosed by supplier",AZ12="Not disclosed by supplier",BE12="Not disclosed by supplier",AS12="Not disclosed by supplier",BJ12="Not disclosed by supplier")),"A core field says Not disclosed by supplier: the Council must answer the core fields itself",IF(AND(OR(AB12="Approved",AB12="Approved with conditions",AC12="Active"),BL12="Full",OR(COUNTIF('Capability Vector'!$B$5:$B$203,AY12)=0,COUNTIF(Components!$B$5:$B$303,AY12)=0,COUNTIFS('Runtime Controls'!$B$5:$B$303,AY12,'Runtime Controls'!$E$5:$E$303,"<>")<10)),"Full ASBOM (T3 and above, financial authority or tier not assessed): Capability Vector, Components and all ten Runtime Controls rows with Required State set are needed",IF(AND(OR(AB12="Approved",AB12="Approved with conditions",AC12="Active"),OR(Q12="Yes",BL12="Full"),COUNTIF('Authority & Delegations'!$C$5:$C$303,AY12)=0),"Delegation or Full level: add Authority & Delegations rows (they feed the Authority Graph)",IF(AND(OR(AB12="Approved",AB12="Approved with conditions",AC12="Active"),Q12="Yes",COUNTIF('Multi-Agent Controls'!$B$5:$B$303,AY12)=0),"Delegation: add a Multi-Agent Controls row",IF(AND(OR(AB12="Approved",AB12="Approved with conditions",AC12="Active"),O12="Yes",COUNTIF('Runtime Controls'!$B$5:$B$303,AY12)=0),"Persistence: add Runtime Controls rows for how it is stopped and contained",IF(AND(OR(AB12="Approved",AB12="Approved with conditions",AC12="Active"),OR(P12="Working memory",P12="Retrieved knowledge",P12="Persistent memory"),COUNTIF('Memory Controls'!$B$5:$B$303,AY12)=0),"Memory: add a Memory Controls row for each memory store",IF(AND(OR(AB12="Approved",AB12="Approved with conditions",AC12="Active"),COUNTIFS('Capability Vector'!$B$5:$B$203,AY12,'Capability Vector'!$P$5:$P$203,"Yes")+COUNTIFS('Capability Vector'!$B$5:$B$203,AY12,'Capability Vector'!$P$5:$P$203,"Scoped")+COUNTIFS('Capability Vector'!$B$5:$B$203,AY12,'Capability Vector'!$R$5:$R$203,"Yes")+COUNTIFS('Capability Vector'!$B$5:$B$203,AY12,'Capability Vector'!$R$5:$R$203,"Scoped")>0,OR(COUNTIF('Tool Authority Registry'!$B$5:$B$303,AY12)=0,COUNTIF('Interface Register'!$B$5:$B$303,AY12)=0)),"Tool discovery or credential access: add Tool Authority Registry and Interface Register rows",IF(AND(OR(AB12="Approved",AB12="Approved with conditions"),AC12="Active",COUNTIFS('Runtime Controls'!$B$5:$B$303,AY12,'Runtime Controls'!$E$5:$E$303,"Required",'Runtime Controls'!$F$5:$F$303,"<>Evidenced",'Runtime Controls'!$M$5:$M$303,"")+COUNTIFS('Runtime Controls'!$B$5:$B$303,AY12,'Runtime Controls'!$E$5:$E$303,"Required",'Runtime Controls'!$F$5:$F$303,"<>Evidenced",'Runtime Controls'!$M$5:$M$303,"<>",'Runtime Controls'!$L$5:$L$303,"")>0),"Production requirement (Gate 6): required control not Implemented and Evidenced, and no time-bounded compensating control (F.7.8)",IF(AND(OR(AB12="Approved",AB12="Approved with conditions"),AC12="Active",COUNTIFS('Runtime Controls'!$B$5:$B$303,AY12,'Runtime Controls'!$E$5:$E$303,"Required",'Runtime Controls'!$F$5:$F$303,"<>Evidenced",'Runtime Controls'!$M$5:$M$303,"<>",'Runtime Controls'!$L$5:$L$303,"<>")-COUNTIFS('Runtime Controls'!$B$5:$B$303,AY12,'Runtime Controls'!$E$5:$E$303,"Required",'Runtime Controls'!$F$5:$F$303,"<>Evidenced",'Runtime Controls'!$M$5:$M$303,"<>",'Runtime Controls'!$L$5:$L$303,">="&TODAY())>0),"Production requirement (Gate 6): compensating control expired, re-authorise (Expiry / Review must be a date on or after today; F.7.8)",IF(OR(AS12="",BB12=""),"Oversight mode or ASBOM version missing",IF(AND(AC12="Active",BA12=""),"Active without use-specific decision ref (F.7.8)",IF(AND(BJ12<>"",BK12=""),"Permitted autonomy decision ref missing",IF(AND(AC12="Active",BJ12=""),"Active without permitted autonomy level","OK")))))))))))))))))) | BL12: =IF(A12="","",IF(OR(M12="",LEFT(M12,2)="T3",LEFT(M12,2)="T4",LEFT(M12,2)="T5",AND(R12<>"",R12<>"No",R12<>"None",R12<>"0",R12<>"N/A")),"Full",IF(OR(O12="Yes",Q12="Yes",P12="Working memory",P12="Retrieved knowledge",P12="Persistent memory",COUNTIFS('Capability Vector'!$B$5:$B$203,AY12,'Capability Vector'!$P$5:$P$203,"Yes")+COUNTIFS('Capability Vector'!$B$5:$B$203,AY12,'Capability Vector'!$P$5:$P$203,"Scoped")+COUNTIFS('Capability Vector'!$B$5:$B$203,AY12,'Capability Vector'!$R$5:$R$203,"Yes")+COUNTIFS('Capability Vector'!$B$5:$B$203,AY12,'Capability Vector'!$R$5:$R$203,"Scoped")>0),"Core plus features","Core")))
BI13: =IF(A13="","",IF(AY13="","AG-ID missing",IF(COUNTIF($AY$5:$AY$203,AY13)>1,"Duplicate AG-ID",IF(AND(OR(AB13="Approved",AB13="Approved with conditions",AC13="Active"),OR(B13="",C13="",H13="",I13="",M13="",S13="",T13="",U13="",X13="",AA13="",AZ13="",BE13="")),"Core record incomplete: name, purpose, owner, platform, agency tier and profile ref, permission scope, credentials, how to stop it, how to undo it, UC-IDs and review date are needed before go-live",IF(AND(OR(AB13="Approved",AB13="Approved with conditions",AC13="Active"),COUNTIF('Agency Profile'!$B$5:$B$203,AY13)=0),"Agency Profile row missing: record the five agency scores behind the tier",IF(AND(OR(AB13="Approved",AB13="Approved with conditions",AC13="Active"),OR(B13="Not disclosed by supplier",C13="Not disclosed by supplier",H13="Not disclosed by supplier",I13="Not disclosed by supplier",M13="Not disclosed by supplier",S13="Not disclosed by supplier",T13="Not disclosed by supplier",U13="Not disclosed by supplier",X13="Not disclosed by supplier",AA13="Not disclosed by supplier",AZ13="Not disclosed by supplier",BE13="Not disclosed by supplier",AS13="Not disclosed by supplier",BJ13="Not disclosed by supplier")),"A core field says Not disclosed by supplier: the Council must answer the core fields itself",IF(AND(OR(AB13="Approved",AB13="Approved with conditions",AC13="Active"),BL13="Full",OR(COUNTIF('Capability Vector'!$B$5:$B$203,AY13)=0,COUNTIF(Components!$B$5:$B$303,AY13)=0,COUNTIFS('Runtime Controls'!$B$5:$B$303,AY13,'Runtime Controls'!$E$5:$E$303,"<>")<10)),"Full ASBOM (T3 and above, financial authority or tier not assessed): Capability Vector, Components and all ten Runtime Controls rows with Required State set are needed",IF(AND(OR(AB13="Approved",AB13="Approved with conditions",AC13="Active"),OR(Q13="Yes",BL13="Full"),COUNTIF('Authority & Delegations'!$C$5:$C$303,AY13)=0),"Delegation or Full level: add Authority & Delegations rows (they feed the Authority Graph)",IF(AND(OR(AB13="Approved",AB13="Approved with conditions",AC13="Active"),Q13="Yes",COUNTIF('Multi-Agent Controls'!$B$5:$B$303,AY13)=0),"Delegation: add a Multi-Agent Controls row",IF(AND(OR(AB13="Approved",AB13="Approved with conditions",AC13="Active"),O13="Yes",COUNTIF('Runtime Controls'!$B$5:$B$303,AY13)=0),"Persistence: add Runtime Controls rows for how it is stopped and contained",IF(AND(OR(AB13="Approved",AB13="Approved with conditions",AC13="Active"),OR(P13="Working memory",P13="Retrieved knowledge",P13="Persistent memory"),COUNTIF('Memory Controls'!$B$5:$B$303,AY13)=0),"Memory: add a Memory Controls row for each memory store",IF(AND(OR(AB13="Approved",AB13="Approved with conditions",AC13="Active"),COUNTIFS('Capability Vector'!$B$5:$B$203,AY13,'Capability Vector'!$P$5:$P$203,"Yes")+COUNTIFS('Capability Vector'!$B$5:$B$203,AY13,'Capability Vector'!$P$5:$P$203,"Scoped")+COUNTIFS('Capability Vector'!$B$5:$B$203,AY13,'Capability Vector'!$R$5:$R$203,"Yes")+COUNTIFS('Capability Vector'!$B$5:$B$203,AY13,'Capability Vector'!$R$5:$R$203,"Scoped")>0,OR(COUNTIF('Tool Authority Registry'!$B$5:$B$303,AY13)=0,COUNTIF('Interface Register'!$B$5:$B$303,AY13)=0)),"Tool discovery or credential access: add Tool Authority Registry and Interface Register rows",IF(AND(OR(AB13="Approved",AB13="Approved with conditions"),AC13="Active",COUNTIFS('Runtime Controls'!$B$5:$B$303,AY13,'Runtime Controls'!$E$5:$E$303,"Required",'Runtime Controls'!$F$5:$F$303,"<>Evidenced",'Runtime Controls'!$M$5:$M$303,"")+COUNTIFS('Runtime Controls'!$B$5:$B$303,AY13,'Runtime Controls'!$E$5:$E$303,"Required",'Runtime Controls'!$F$5:$F$303,"<>Evidenced",'Runtime Controls'!$M$5:$M$303,"<>",'Runtime Controls'!$L$5:$L$303,"")>0),"Production requirement (Gate 6): required control not Implemented and Evidenced, and no time-bounded compensating control (F.7.8)",IF(AND(OR(AB13="Approved",AB13="Approved with conditions"),AC13="Active",COUNTIFS('Runtime Controls'!$B$5:$B$303,AY13,'Runtime Controls'!$E$5:$E$303,"Required",'Runtime Controls'!$F$5:$F$303,"<>Evidenced",'Runtime Controls'!$M$5:$M$303,"<>",'Runtime Controls'!$L$5:$L$303,"<>")-COUNTIFS('Runtime Controls'!$B$5:$B$303,AY13,'Runtime Controls'!$E$5:$E$303,"Required",'Runtime Controls'!$F$5:$F$303,"<>Evidenced",'Runtime Controls'!$M$5:$M$303,"<>",'Runtime Controls'!$L$5:$L$303,">="&TODAY())>0),"Production requirement (Gate 6): compensating control expired, re-authorise (Expiry / Review must be a date on or after today; F.7.8)",IF(OR(AS13="",BB13=""),"Oversight mode or ASBOM version missing",IF(AND(AC13="Active",BA13=""),"Active without use-specific decision ref (F.7.8)",IF(AND(BJ13<>"",BK13=""),"Permitted autonomy decision ref missing",IF(AND(AC13="Active",BJ13=""),"Active without permitted autonomy level","OK")))))))))))))))))) | BL13: =IF(A13="","",IF(OR(M13="",LEFT(M13,2)="T3",LEFT(M13,2)="T4",LEFT(M13,2)="T5",AND(R13<>"",R13<>"No",R13<>"None",R13<>"0",R13<>"N/A")),"Full",IF(OR(O13="Yes",Q13="Yes",P13="Working memory",P13="Retrieved knowledge",P13="Persistent memory",COUNTIFS('Capability Vector'!$B$5:$B$203,AY13,'Capability Vector'!$P$5:$P$203,"Yes")+COUNTIFS('Capability Vector'!$B$5:$B$203,AY13,'Capability Vector'!$P$5:$P$203,"Scoped")+COUNTIFS('Capability Vector'!$B$5:$B$203,AY13,'Capability Vector'!$R$5:$R$203,"Yes")+COUNTIFS('Capability Vector'!$B$5:$B$203,AY13,'Capability Vector'!$R$5:$R$203,"Scoped")>0),"Core plus features","Core")))
