Workbook

Sheet Summary
A1: The Council — AIMS Applicable Requirements and Change Register
A2: AIG-AIMS-05 · v1.9 draft · Draft for Council review · OFFICIAL · ISO/IEC 42001:2023
A3: Purpose: maintain proposed AIMS requirements, owners, evidence, review and controlled change.
A4: Legal status: desk-review starting point only. Legal Services, the DPO, Monitoring Officer and specialist functions must validate applicability, interpretation, authority, sources and actions before adoption. Existing Council obligations registers remain authoritative.
A6: Document control | B6: Controlled value | D6: Requirements readiness | G6: Change readiness
A7: Document ID | B7: AIG-AIMS-05 | D7: Measure | E7: Result | G7: Measure | H7: Result
A8: Version | B8: 1.9 draft | D8: Desk-reviewed requirements | E8: =COUNTA('Applicable Requirements'!$A$7:$A$64) | G8: Change records | H8: =COUNTA('Change Register'!$A$7:$A$40)
A9: Status | B9: Draft for Council review | D9: Applicable | E9: =COUNTIF('Applicable Requirements'!$F$7:$F$64,"Applicable") | G9: Critical / high | H9: =COUNTIF('Change Register'!$H$7:$H$40,"Critical")+COUNTIF('Change Register'!$H$7:$H$40,"High")
A10: Document owner | B10: AI Governance Lead | D10: Conditional | E10: =COUNTIF('Applicable Requirements'!$F$7:$F$64,"Conditional") | G10: Assessment required | H10: =COUNTIF('Change Register'!$I$7:$I$40,"Assessment required")
A11: Primary specialist owners | B11: Legal Services, DPO, Monitoring Officer and named control functions | D11: Voluntary / proposed adoption | E11: =COUNTIF('Applicable Requirements'!$F$7:$F$64,"Voluntary adopted")+COUNTIF('Applicable Requirements'!$F$7:$F$64,"Proposed adoption") | G11: Monitoring | H11: =COUNTIF('Change Register'!$I$7:$I$40,"Monitoring")
A12: Approving authority | B12: To be confirmed under Council delegations | D12: Specialist validation required | E12: =COUNTIF('Applicable Requirements'!$G$7:$G$64,"Specialist validation required") | G12: Implemented / closed | H12: =COUNTIF('Change Register'!$I$7:$I$40,"Implemented")+COUNTIF('Change Register'!$I$7:$I$40,"Closed")
A13: Effective date | B13: Pending formal approval | D13: Validated | E13: =COUNTIF('Applicable Requirements'!$G$7:$G$64,"Validated") | G13: Target dates recorded | H13: =COUNT('Change Register'!$J$7:$J$40)
A14: Review frequency | B14: Monthly change review; annual full validation; event-driven updates | D14: Reviews due within 90 days | E14: =COUNTIFS('Applicable Requirements'!$R$7:$R$64,">="&TODAY(),'Applicable Requirements'!$R$7:$R$64,"<="&TODAY()+90) | G14: Evidence recorded | H14: =COUNTA('Change Register'!$K$7:$K$40)
A15: Source position | B15: AIG-AIMS-01 section 8; AIG-AIMS-03 IMP-04; official sources verified 2026-08-07 (1-month review items now overdue; see Requirement reviews overdue) | D15: Requirement QA complete | E15: =COUNTIF('Applicable Requirements'!$U$7:$U$64,"Complete") | G15: Change QA complete (not overdue) | H15: =COUNTIF('Change Register'!$O$7:$O$40,"Complete")
A16: Classification | B16: OFFICIAL | D16: Requirement reviews overdue | E16: =COUNTIFS('Applicable Requirements'!$R$7:$R$64,"<"&TODAY()) | G16: Change reviews overdue | H16: =COUNTIFS('Change Register'!$N$7:$N$40,"<"&TODAY())
D18: Monitoring and evidence | G18: Immediate implementation decisions
D19: Measure | E19: Result | G19: 1. Legal, DPO and specialist owners validate all 58 applicability entries.
D20: Horizon channels | E20: =COUNTA('Horizon Scanning'!$A$7:$A$19) | G20: 2. Close the DUAA 2025 gap assessment, including complaints and updated ADM interpretation.
D21: Active channels | E21: =COUNTIF('Horizon Scanning'!$J$7:$J$19,"Active") | G21: 3. Complete EU AI Act territorial/actor screening and apply only where legally in scope.
D22: Completed scans | E22: =COUNT('Horizon Scanning'!$K$7:$K$19) | G22: 4. Formally decide ATRS, ISO/IEC 42001 and related voluntary-standard adoption.
D23: Evidence domains | E23: =COUNTA('Evidence & Review'!$A$7:$A$21) | G23: 5. Populate the authoritative Council policy, Constitution and delegation sources.
D24: Evidence locations recorded | E24: =COUNTA('Evidence & Review'!$J$7:$J$21) | G24: 6. Approve horizon-scanning ownership, cadence, escalation and evidence.
D25: Evidence records complete | E25: =COUNTIF('Evidence & Review'!$O$7:$O$21,"Complete") | G25: 7. Link every live AI Register record to case-specific legal, contract and partnership obligations.
A28: Controlled requirements and change process
A29: 1. Identify an authoritative source or received obligation; record its legal/policy status and date.
A30: 2. Specialist owner validates applicability, interpretation, affected services/systems and any conflict.
A31: 3. Assign an accountable owner, evidence, review frequency and affected AIMS/process/control references.
A32: 4. Assess change significance and urgency; record decision, target, resources and interim risk controls.
A33: 5. Update affected policies, artefacts, contracts, systems, training and communications through approved change control.
A34: 6. Verify implementation and effectiveness; retain evidence and close or continue monitoring.
A35: 7. Feed open changes, overdue reviews, evidence gaps, material changes and trends into risk treatment, audit and AIMS management review.
A37: Version | B37: Date | C37: Change | G37: Author / owner
A38: 1.0 draft | B38: 46241 | C38: Initial applicable-requirements, regulatory-change, horizon-scanning and evidence design aligned to AIG-AIMS-01 and AIG-AIMS-03 IMP-04; official sources checked 2026-08-07. | G38: AI Governance Lead
A39: 1.3 draft | B39: 28 September 2026 | C39: Correct review interval QA, validate positive whole months and make applicability colours exact.
A40: 1.4 draft | B40: 29 September 2026 | C40: QA remediation — applied findings QA-168, QA-218, QA-220, QA-222, QA-223, QA-238, QA-240, QA-241, QA-251, QA-256, QA-257, QA-284, QA-287, QA-291 and decision D9 legal dates (see QA change log). CHG-001 split; CHG-013 added. Integration pass: REQ-052 (DSIT Code of Practice for the Cyber Security of AI, January 2025) and REQ-053 (ETSI EN 304 223, January 2026) added; inventory now 53 entries. | G40: AI Governance Lead
A41: 1.5 draft | B41: 30 September 2026 | C41: v3.9.1: REQ-054 added: Civil Contingencies Act 2004 (Category 1 responder duties, including business continuity arrangements), conditional where an AI use supports a prioritised activity in the Council’s business continuity plans, linked to AIG-OPS-01 section 8 (new business continuity link) and AIG-ASS-08 section 8; added to STANDARDS SCOPE QA, EVD-07, EVD-15 and SCN-01; inventory now 54 entries. Proposed — for Council confirmation. | G41: AI Governance Lead
A42: 1.6 draft | B42: 1 October 2026 | C42: v3.9.3: REQ-055 added: NIST AI 600-1 Artificial Intelligence Risk Management Framework: Generative Artificial Intelligence Profile (July 2024), voluntary guidance (US), reference only, not statutory; relevance: generative AI risk prompts and actions; linked to the Playbook (§4.3, §5.4.3, §5.4.4), the new AIG-AIMS-11 risk domain crosswalk, AIG-ASS-04 and AIG-ASS-11; added to STANDARDS SCOPE QA and EVD-15; inventory now 55 entries; last verified 1 October 2026. Applicable Requirements table filter range corrected to the full table. Proposed — for Council confirmation. | G42: AI Governance Lead
A43: 1.7 draft | B43: 1 October 2026 | C43: v3.9.4: Horizon Scanning SCN-07 widened from ISO only to a standards bodies channel: ISO/IEC JTC 1/SC 42, NIST (AI publications, including the AI RMF and NIST AI 600-1) and ETSI (Securing AI); quarterly; owner AI Governance Lead; any change logged against the linked requirements REQ-041, REQ-042, REQ-053 and REQ-055 (related requirements now REQ-040 to REQ-043, REQ-053, REQ-055; NIST and ETSI source URLs added). REQ-042 required action: validate the AIG-AIMS-11 crosswalk against the Council’s licensed copy of ISO/IEC 42005 before formal adoption (not a pilot blocker). No columns added. Proposed — for Council confirmation. | G43: AI Governance Lead
A44: 1.8 draft | B44: 2 October 2026 | C44: v3.9.5: REQ-056 added: The Data Protection Act 2018 (Code of Practice on Artificial Intelligence and Automated Decision-Making) Regulations 2026 (SI 2026/425), requiring an ICO statutory code of practice on AI and automated decision-making, from regulatory scanner review REG-0001; CHG-014 added; linked to SCN-01, SCN-03 and EVD-01 (inventory now 56 entries). RequirementsChangeTable range also extended to include CHG-012 to CHG-014. Proposed — for Council confirmation. | G44: AI Governance Lead
A45: 1.9 draft | B45: 12 October 2026 | C45: v3.9.10: REQ-057 DAMA-DMBOK (Data Management Body of Knowledge, 2nd Edition Revised) and REQ-058 ISO/IEC 5259 series (data quality for analytics and machine learning) added as voluntary references; the inventory now holds 58 entries. Standards scope QA and evidence coverage (EVD-15) extended. Proposed — for Council confirmation. | G45: AI Governance Lead

Sheet Applicable Requirements
A1: The Council — Applicable Requirements Register
A2: AIG-AIMS-05 · v1.9 draft · Draft for Council review · OFFICIAL · ISO/IEC 42001:2023
A3: Purpose: record authoritative requirements, proposed applicability, validation, ownership, affected processes, evidence, source, review and change decisions for the AIMS scope.
A4: Current position: all 58 entries are desk-reviewed and require competent specialist validation. 'Applicable' does not mean every provision applies to every AI system; case-specific triggers and interpretations must be recorded by authorised Council functions.
A6: Requirement ID | B6: Category | C6: Authority type | D6: Requirement / instrument | E6: Jurisdiction | F6: Proposed applicability | G6: Validation status | H6: Why it applies / trigger | I6: Principal AIMS / AI obligation | J6: Proposed owner | K6: Lifecycle / process | L6: Related suite references | M6: ISO / SoA links | N6: Required compliance evidence | O6: Authoritative source URL / location | P6: Last verified | Q6: Review interval (months) | R6: Next review | S6: Change state | T6: Required action / decision | U6: Record QA
A7: REQ-001 | B7: Data protection and privacy | C7: Legislation | D7: UK General Data Protection Regulation (UK GDPR), as amended | E7: United Kingdom | F7: Applicable | G7: Specialist validation required | H7: Council AI trains on, receives, infers, generates or otherwise processes personal data. | I7: Establish lawful basis and purpose; apply fairness, transparency, minimisation, accuracy, retention, security, accountability, rights, DPIA and processor/controller controls. Interpret automated decision-making together with the DUAA and current ICO guidance. | J7: DPO / Information Governance | K7: Intake; data; design; procurement; deployment; monitoring; incidents; retirement | L7: AIG-INV-03, AIG-ASS-02, AIG-ASS-04, AIG-ASS-05, AIG-ASS-08, AIG-ASS-09, AIG-OPS-03, AIG-OPS-01 | M7: ISO 4.2, 6.1, 8.1; A.5, A.7, A.8 | N7: ROPA; DPIA; privacy information; lawful-basis decision; data map; rights/complaint records; contracts; monitoring | O7: https://www.legislation.gov.uk/eur/2016/679/contents | P7: 46241 | Q7: 3 | R7: =IF(P7="","",IF(OR(NOT(ISNUMBER(P7)),NOT(ISNUMBER(Q7)),Q7<0,Q7<>INT(Q7)),"CHECK DATE / INTERVAL",EDATE(P7,Q7))) | S7: Amended | T7: DPO/Legal to validate current article-level mapping after DUAA amendments and identify every in-scope system. | U7: =IF(AND(A7<>"",B7<>"",C7<>"",D7<>"",E7<>"",F7<>"",G7<>"",H7<>"",I7<>"",J7<>"",K7<>"",L7<>"",M7<>"",N7<>"",O7<>"",P7<>"",AND(ISNUMBER(P7),ISNUMBER(Q7),Q7>0,Q7=INT(Q7),ISNUMBER(R7)),S7<>"",T7<>""),IF(AND(ISNUMBER(R7),R7<TODAY()),"Review overdue","Complete"),"Incomplete")
A8: REQ-002 | B8: Data protection and privacy | C8: Legislation | D8: Data Protection Act 2018, as amended | E8: United Kingdom | F8: Applicable | G8: Specialist validation required | H8: The Council processes general, special-category, criminal-offence and potentially law-enforcement data. | I8: Apply the correct processing regime, conditions and safeguards; retain DPO advice; manage exemptions, enforcement, offences and data-subject rights. Determine Part 3 competent-authority processing case by case. | J8: DPO / Legal Services | K8: Intake; data; DPIA; operations; incidents; complaints | L8: AIG-ASS-02, AIG-ASS-04, AIG-ASS-05, AIG-OPS-03 | M8: ISO 4.2, 6.1, 8.1; A.5, A.7 | N8: Processing-regime decision; condition schedules; DPIA; DPO advice; rights and incident records | O8: https://www.legislation.gov.uk/ukpga/2018/12/contents | P8: 46241 | Q8: 3 | R8: =IF(P8="","",IF(OR(NOT(ISNUMBER(P8)),NOT(ISNUMBER(Q8)),Q8<0,Q8<>INT(Q8)),"CHECK DATE / INTERVAL",EDATE(P8,Q8))) | S8: Amended | T8: DPO/Legal to confirm Part 2/Part 3 applicability, schedules and any service-specific exemptions. | U8: =IF(AND(A8<>"",B8<>"",C8<>"",D8<>"",E8<>"",F8<>"",G8<>"",H8<>"",I8<>"",J8<>"",K8<>"",L8<>"",M8<>"",N8<>"",O8<>"",P8<>"",AND(ISNUMBER(P8),ISNUMBER(Q8),Q8>0,Q8=INT(Q8),ISNUMBER(R8)),S8<>"",T8<>""),IF(AND(ISNUMBER(R8),R8<TODAY()),"Review overdue","Complete"),"Incomplete")
A9: REQ-003 | B9: Data protection and privacy | C9: Legislation | D9: Data (Use and Access) Act 2025 (DUAA) | E9: United Kingdom | F9: Applicable | G9: Specialist validation required | H9: The DUAA amends UK GDPR, DPA 2018 and PECR. The main data-protection amendments, including s.70 (lawfulness and recognised legitimate interests) and s.80 / Sch 6 (UK GDPR Articles 22A to 22D, automated decision-making), commenced on 5 February 2026 (SI 2026/82, reg 2). The s.103 data-protection complaints duty (DPA 2018 s.164A) applies from 19 June 2026 (reg 3) to complaints received on or after that date. | I9: Update privacy, automated-decision, legitimate-interest, research, transfer, cookie/communications and enforcement interpretations as relevant; maintain a compliant data-protection complaints process and current notices/procedures. | J9: DPO / Legal Services / Complaints | K9: AIMS requirements; DPIA; decisions; complaints; policies; training | L9: AIG-ASS-04, AIG-ASS-05, AIG-OPS-05, AIG-OPS-03, AIG-AIMS-04 | M9: ISO 4.2, 7.4, 8.1, 10.2; A.3.3, A.5, A.8 | N9: DUAA gap assessment; updated procedures/notices; complaints route; training; legal advice; change closure | O9: https://www.legislation.gov.uk/uksi/2026/82/contents/made (commencement, primary) ; https://www.legislation.gov.uk/ukpga/2025/18/contents ; https://ico.org.uk/about-the-ico/what-we-do/legislation-we-cover/data-use-and-access-act-2025/ | P9: 46241 | Q9: 1 | R9: =IF(P9="","",IF(OR(NOT(ISNUMBER(P9)),NOT(ISNUMBER(Q9)),Q9<0,Q9<>INT(Q9)),"CHECK DATE / INTERVAL",EDATE(P9,Q9))) | S9: New / commenced | T9: Complete a Council DUAA implementation check, including complaints and current automated-decision safeguards; close CHG-001. | U9: =IF(AND(A9<>"",B9<>"",C9<>"",D9<>"",E9<>"",F9<>"",G9<>"",H9<>"",I9<>"",J9<>"",K9<>"",L9<>"",M9<>"",N9<>"",O9<>"",P9<>"",AND(ISNUMBER(P9),ISNUMBER(Q9),Q9>0,Q9=INT(Q9),ISNUMBER(R9)),S9<>"",T9<>""),IF(AND(ISNUMBER(R9),R9<TODAY()),"Review overdue","Complete"),"Incomplete")
A10: REQ-004 | B10: Data protection and privacy | C10: Legislation | D10: Privacy and Electronic Communications Regulations 2003 (PECR), as amended | E10: United Kingdom | F10: Conditional | G10: Specialist validation required | H10: Triggered by electronic communications, direct marketing, cookies or similar storage/access technologies in AI-enabled services. | I10: Assess consent and information duties, communications rules and cookie/device access; reflect DUAA amendments and ICO guidance. | J10: DPO / Digital / Communications | K10: Service design; web/app; communications; monitoring | L10: AIG-ASS-04, AIG-ASS-05, AIG-ASS-10, AIG-OPS-01 | M10: ISO 4.2, 8.1; A.5.4, A.8.2 | N10: Cookie/technology assessment; consent records; notices; communications approval; supplier configuration | O10: https://www.legislation.gov.uk/uksi/2003/2426/contents | P10: 46241 | Q10: 6 | R10: =IF(P10="","",IF(OR(NOT(ISNUMBER(P10)),NOT(ISNUMBER(Q10)),Q10<0,Q10<>INT(Q10)),"CHECK DATE / INTERVAL",EDATE(P10,Q10))) | S10: Amended | T10: DPO to define PECR triggers for chatbots, analytics, personalisation and AI-enabled communications. | U10: =IF(AND(A10<>"",B10<>"",C10<>"",D10<>"",E10<>"",F10<>"",G10<>"",H10<>"",I10<>"",J10<>"",K10<>"",L10<>"",M10<>"",N10<>"",O10<>"",P10<>"",AND(ISNUMBER(P10),ISNUMBER(Q10),Q10>0,Q10=INT(Q10),ISNUMBER(R10)),S10<>"",T10<>""),IF(AND(ISNUMBER(R10),R10<TODAY()),"Review overdue","Complete"),"Incomplete")
A11: REQ-005 | B11: Equality and non-discrimination | C11: Legislation | D11: Equality Act 2010, including Public Sector Equality Duty section 149 | E11: England, Scotland and Wales | F11: Applicable | G11: Specialist validation required | H11: The Council is a public authority and AI may affect protected groups, access, employment or service outcomes. | I11: Avoid direct/indirect discrimination, harassment and victimisation; make reasonable adjustments; have due regard to eliminating discrimination, advancing equality and fostering good relations throughout procurement, design, use and review. | J11: Equality Lead / Legal Services | K11: Intake; procurement; impact assessment; testing; engagement; monitoring | L11: AIG-ASS-02, AIG-ASS-04, AIG-ASS-06, AIG-ASS-07, AIG-ASS-10, AIG-OPS-05 | M11: ISO 4.2, 6.1, 8.1; A.5.2-A.5.5, A.8 | N11: Equality analysis; EIA; affected-group evidence; accessibility tests; mitigations; monitoring; decision record | O11: https://www.legislation.gov.uk/ukpga/2010/15/section/149 | P11: 46241 | Q11: 6 | R11: =IF(P11="","",IF(OR(NOT(ISNUMBER(P11)),NOT(ISNUMBER(Q11)),Q11<0,Q11<>INT(Q11)),"CHECK DATE / INTERVAL",EDATE(P11,Q11))) | S11: Current | T11: Equality/Legal to validate the PSED evidence standard and approval route for each material AI case. | U11: =IF(AND(A11<>"",B11<>"",C11<>"",D11<>"",E11<>"",F11<>"",G11<>"",H11<>"",I11<>"",J11<>"",K11<>"",L11<>"",M11<>"",N11<>"",O11<>"",P11<>"",AND(ISNUMBER(P11),ISNUMBER(Q11),Q11>0,Q11=INT(Q11),ISNUMBER(R11)),S11<>"",T11<>""),IF(AND(ISNUMBER(R11),R11<TODAY()),"Review overdue","Complete"),"Incomplete")
A12: REQ-006 | B12: Human rights and public law | C12: Legislation | D12: Human Rights Act 1998 | E12: United Kingdom | F12: Applicable | G12: Specialist validation required | H12: It is unlawful for a public authority to act incompatibly with Convention rights; AI may affect privacy, liberty, expression, property, fair procedures or non-discrimination. | I12: Identify engaged rights; assess legality, legitimate aim, necessity and proportionality; provide safeguards, meaningful human review, reasons, challenge and remedy. | J12: Legal Services / Human Rights Lead | K12: Intake; impact assessment; decisions; operations; complaints | L12: AIG-ASS-04, AIG-ASS-07, AIG-ASS-10, AIG-DEC-03, AIG-OPS-03 | M12: ISO 4.2, 6.1, 8.1; A.5, A.8 | N12: Human Rights Assessment; legal advice; proportionality analysis; oversight; explanation; complaint/redress evidence | O12: https://www.legislation.gov.uk/ukpga/1998/42/contents | P12: 46241 | Q12: 6 | R12: =IF(P12="","",IF(OR(NOT(ISNUMBER(P12)),NOT(ISNUMBER(Q12)),Q12<0,Q12<>INT(Q12)),"CHECK DATE / INTERVAL",EDATE(P12,Q12))) | S12: Current | T12: Legal/Human Rights leads to confirm rights triggers and residual-risk acceptance authority. | U12: =IF(AND(A12<>"",B12<>"",C12<>"",D12<>"",E12<>"",F12<>"",G12<>"",H12<>"",I12<>"",J12<>"",K12<>"",L12<>"",M12<>"",N12<>"",O12<>"",P12<>"",AND(ISNUMBER(P12),ISNUMBER(Q12),Q12>0,Q12=INT(Q12),ISNUMBER(R12)),S12<>"",T12<>""),IF(AND(ISNUMBER(R12),R12<TODAY()),"Review overdue","Complete"),"Incomplete")
A13: REQ-007 | B13: Human rights and public law | C13: Public-law requirement | D13: Administrative law, statutory powers, procedural fairness and reasoned decision-making | E13: England / Council functions | F13: Applicable | G13: Specialist validation required | H13: Council decisions must remain within statutory powers and public-law standards even when supported by AI. | I13: Confirm lawful power and proper purpose; consider relevant matters; avoid fettering discretion or irrational outcomes; provide procedurally fair human decision-making, reasons, review and remedy proportionate to impact. | J13: Monitoring Officer / Legal Services | K13: Business case; design; decision workflow; oversight; redress | L13: AIG-ASS-02, AIG-ASS-04, AIG-ASS-07, AIG-ASS-09, AIG-DEC-03, AIG-OPS-03 | M13: ISO 4.2, 5.3, 8.1; A.5.4, A.8.2-A.8.4, A.9.2 | N13: Legal-power analysis; decision policy; human-oversight test; reasons; review/appeal route; sampling | O13: https://www.gov.uk/government/publications/the-judge-over-your-shoulder | P13: 46241 | Q13: 3 | R13: =IF(P13="","",IF(OR(NOT(ISNUMBER(P13)),NOT(ISNUMBER(Q13)),Q13<0,Q13<>INT(Q13)),"CHECK DATE / INTERVAL",EDATE(P13,Q13))) | S13: Current / case-law sensitive | T13: Monitoring Officer/Legal to validate the public-law checklist and system-specific statutory powers. | U13: =IF(AND(A13<>"",B13<>"",C13<>"",D13<>"",E13<>"",F13<>"",G13<>"",H13<>"",I13<>"",J13<>"",K13<>"",L13<>"",M13<>"",N13<>"",O13<>"",P13<>"",AND(ISNUMBER(P13),ISNUMBER(Q13),Q13>0,Q13=INT(Q13),ISNUMBER(R13)),S13<>"",T13<>""),IF(AND(ISNUMBER(R13),R13<TODAY()),"Review overdue","Complete"),"Incomplete")
A14: REQ-008 | B14: Accessibility and inclusion | C14: Legislation | D14: Public Sector Bodies (Websites and Mobile Applications) (No. 2) Accessibility Regulations 2018 | E14: United Kingdom | F14: Conditional | G14: Specialist validation required | H14: Applies where an AI-enabled public website or mobile application is within scope. | I14: Meet accessibility requirements, maintain an accessibility statement, remediate barriers and provide an effective feedback/contact route; integrate with Equality Act reasonable adjustments. | J14: Digital Accessibility Lead / Service Owner | K14: Design; user research; testing; publication; change | L14: AIG-ASS-06, AIG-ASS-07, AIG-ASS-10, AIG-OPS-05, AIG-OPS-01 | M14: ISO 4.2, 8.1; A.5.4, A.8.2-A.8.5 | N14: Accessibility assessment; statement; user testing; defect plan; alternative route; review records | O14: https://www.gov.uk/guidance/accessibility-requirements-for-public-sector-websites-and-apps | P14: 46241 | Q14: 6 | R14: =IF(P14="","",IF(OR(NOT(ISNUMBER(P14)),NOT(ISNUMBER(Q14)),Q14<0,Q14<>INT(Q14)),"CHECK DATE / INTERVAL",EDATE(P14,Q14))) | S14: Current | T14: Define applicability and approved accessibility standard/testing evidence for every public digital interface. | U14: =IF(AND(A14<>"",B14<>"",C14<>"",D14<>"",E14<>"",F14<>"",G14<>"",H14<>"",I14<>"",J14<>"",K14<>"",L14<>"",M14<>"",N14<>"",O14<>"",P14<>"",AND(ISNUMBER(P14),ISNUMBER(Q14),Q14>0,Q14=INT(Q14),ISNUMBER(R14)),S14<>"",T14<>""),IF(AND(ISNUMBER(R14),R14<TODAY()),"Review overdue","Complete"),"Incomplete")
A15: REQ-009 | B15: Information access and records | C15: Legislation | D15: Freedom of Information Act 2000 (FOIA) | E15: England, Wales and Northern Ireland | F15: Applicable | G15: Specialist validation required | H15: The Council is a public authority and recorded AI information may be held by the Council or on its behalf by suppliers. | I15: Identify, retain and retrieve official information; handle requests, publication duties, datasets and exemptions lawfully; ensure supplier-held information and decision records are accessible to the Council. | J15: Information Governance / FOI Lead | K15: Procurement; evidence; operations; transparency; requests; retirement | L15: AIG-INV-04, AIG-ASS-08 to AIG-ASS-10, AIG-DEC-03, AIG-OPS-05, AIG-GOV-06, AIG-OPS-01 | M15: ISO 7.5, 8.1; A.4.2-A.4.5, A.8.5, A.10.2 | N15: Records inventory; retrieval test; contract clauses; disclosure decisions; publication scheme; request logs | O15: https://www.legislation.gov.uk/ukpga/2000/36/contents | P15: 46241 | Q15: 12 | R15: =IF(P15="","",IF(OR(NOT(ISNUMBER(P15)),NOT(ISNUMBER(Q15)),Q15<0,Q15<>INT(Q15)),"CHECK DATE / INTERVAL",EDATE(P15,Q15))) | S15: Current | T15: FOI/IG to map AIMS records and supplier-held evidence to retrieval and exemption processes. | U15: =IF(AND(A15<>"",B15<>"",C15<>"",D15<>"",E15<>"",F15<>"",G15<>"",H15<>"",I15<>"",J15<>"",K15<>"",L15<>"",M15<>"",N15<>"",O15<>"",P15<>"",AND(ISNUMBER(P15),ISNUMBER(Q15),Q15>0,Q15=INT(Q15),ISNUMBER(R15)),S15<>"",T15<>""),IF(AND(ISNUMBER(R15),R15<TODAY()),"Review overdue","Complete"),"Incomplete")
A16: REQ-010 | B16: Information access and records | C16: Legislation | D16: Environmental Information Regulations 2004 (EIR) | E16: United Kingdom | F16: Conditional | G16: Specialist validation required | H16: Triggered where AI information falls within the definition of environmental information, including relevant planning, transport, waste, energy or environmental services. | I16: Identify EIR information; support access, proactive dissemination, exceptions and records retrieval under the correct regime. | J16: Information Governance / EIR Lead | K16: Service design; evidence; transparency; requests | L16: AIG-INV-04, AIG-ASS-10, AIG-OPS-05 | M16: ISO 4.2, 7.5; A.8.5 | N16: Regime decision; searchable records; request log; disclosure/exception decision; publication evidence | O16: https://www.legislation.gov.uk/uksi/2004/3391/contents | P16: 46241 | Q16: 12 | R16: =IF(P16="","",IF(OR(NOT(ISNUMBER(P16)),NOT(ISNUMBER(Q16)),Q16<0,Q16<>INT(Q16)),"CHECK DATE / INTERVAL",EDATE(P16,Q16))) | S16: Current | T16: EIR Lead to define service triggers and align evidence retention with FOIA/EIR handling. | U16: =IF(AND(A16<>"",B16<>"",C16<>"",D16<>"",E16<>"",F16<>"",G16<>"",H16<>"",I16<>"",J16<>"",K16<>"",L16<>"",M16<>"",N16<>"",O16<>"",P16<>"",AND(ISNUMBER(P16),ISNUMBER(Q16),Q16>0,Q16=INT(Q16),ISNUMBER(R16)),S16<>"",T16<>""),IF(AND(ISNUMBER(R16),R16<TODAY()),"Review overdue","Complete"),"Incomplete")
A17: REQ-011 | B17: Information access and records | C17: Statutory code | D17: Section 46 Code of Practice on records management under FOIA | E17: United Kingdom | F17: Applicable | G17: Specialist validation required | H17: The Code applies to public authorities covered by FOIA and supports ordered, retrievable and controlled records. | I17: Maintain governance, policies, responsibilities, retention/disposal, secure custody, retrieval and transfer arrangements for AI and AIMS records, including supplier-held material. | J17: Records Management / Information Governance | K17: Document control; evidence; contracts; retirement | L17: AIG-GOV-01, AIG-INV-04, AIG-ASS-08 to AIG-ASS-11, AIG-DEC-03, AIG-GOV-06, AIG-OPS-01, AIG-OPS-03, AIG-OPS-05, AIG-OPS-06, AIG-AIMS-01 to AIG-AIMS-05 | M17: ISO 7.5, 9.1-9.3, 10.2; A.4.2-A.4.5 | N17: Approved taxonomy; retention schedule; disposal holds; access logs; retrieval sample; transfer/exit evidence | O17: https://ico.org.uk/for-organisations/foi/freedom-of-information-and-environmental-information-regulations/section-46-code-of-practice-records-management/ | P17: 46241 | Q17: 12 | R17: =IF(P17="","",IF(OR(NOT(ISNUMBER(P17)),NOT(ISNUMBER(Q17)),Q17<0,Q17<>INT(Q17)),"CHECK DATE / INTERVAL",EDATE(P17,Q17))) | S17: Current | T17: Records Management to approve AIMS evidence taxonomy, retention and deletion/hold rules. | U17: =IF(AND(A17<>"",B17<>"",C17<>"",D17<>"",E17<>"",F17<>"",G17<>"",H17<>"",I17<>"",J17<>"",K17<>"",L17<>"",M17<>"",N17<>"",O17<>"",P17<>"",AND(ISNUMBER(P17),ISNUMBER(Q17),Q17>0,Q17=INT(Q17),ISNUMBER(R17)),S17<>"",T17<>""),IF(AND(ISNUMBER(R17),R17<TODAY()),"Review overdue","Complete"),"Incomplete")
A18: REQ-012 | B18: Local-government transparency | C18: Statutory code / government requirement | D18: Local Government Transparency Code 2015 | E18: England | F18: Applicable | G18: Specialist validation required | H18: The Code sets mandatory and recommended local-authority publication requirements; AI-related spend, contracts or decisions may be captured. | I18: Map AI procurement, spend, contracts, grants, assets and decision records to required publication; protect lawful exemptions and personal/security information. | J18: Corporate Governance / Transparency Lead | K18: Procurement; reporting; publication; records | L18: AIG-ASS-08, AIG-ASS-10, AIG-OPS-05, AIG-OPS-06 | M18: ISO 4.2, 7.4-7.5; A.8.5, A.10 | N18: Publication mapping; published datasets; exemption decisions; quality checks; update records | O18: https://www.gov.uk/government/publications/local-government-transparency-code-2015/local-government-transparency-code-2015 | P18: 46241 | Q18: 12 | R18: =IF(P18="","",IF(OR(NOT(ISNUMBER(P18)),NOT(ISNUMBER(Q18)),Q18<0,Q18<>INT(Q18)),"CHECK DATE / INTERVAL",EDATE(P18,Q18))) | S18: Current | T18: Transparency Lead to identify which AI/AIMS records fall within mandatory or recommended publication. | U18: =IF(AND(A18<>"",B18<>"",C18<>"",D18<>"",E18<>"",F18<>"",G18<>"",H18<>"",I18<>"",J18<>"",K18<>"",L18<>"",M18<>"",N18<>"",O18<>"",P18<>"",AND(ISNUMBER(P18),ISNUMBER(Q18),Q18>0,Q18=INT(Q18),ISNUMBER(R18)),S18<>"",T18<>""),IF(AND(ISNUMBER(R18),R18<TODAY()),"Review overdue","Complete"),"Incomplete")
A19: REQ-013 | B19: Council governance | C19: Legislation | D19: Local Government Act 1972 (including section 101) and the Council’s constitution and scheme of delegation | E19: England and Wales | F19: Applicable | G19: Specialist validation required | H19: Council functions, meetings, delegations, access to information and records must operate through lawful constitutional arrangements. | I19: Confirm decision-maker, delegation, committee/meeting, record and access requirements; ensure AI governance does not displace statutory or constitutional authority. | J19: Monitoring Officer / Governance | K19: Governance bodies; decisions; delegations; records | L19: AIG-DEC-03, AIG-GOV-06, AIG-AIMS-01, AIG-AIMS-04 | M19: ISO 5.1-5.3, 7.5; A.3.2 | N19: Constitution/delegation reference; Terms of Reference; appointment; minutes; decision and conflict records | O19: https://www.legislation.gov.uk/ukpga/1972/70/contents | Q19: 12 | R19: =IF(P19="","",IF(OR(NOT(ISNUMBER(P19)),NOT(ISNUMBER(Q19)),Q19<0,Q19<>INT(Q19)),"CHECK DATE / INTERVAL",EDATE(P19,Q19))) | S19: Current | T19: Monitoring Officer to validate all governance-body powers, delegations and record/public-access requirements. | U19: =IF(AND(A19<>"",B19<>"",C19<>"",D19<>"",E19<>"",F19<>"",G19<>"",H19<>"",I19<>"",J19<>"",K19<>"",L19<>"",M19<>"",N19<>"",O19<>"",P19<>"",AND(ISNUMBER(P19),ISNUMBER(Q19),Q19>0,Q19=INT(Q19),ISNUMBER(R19)),S19<>"",T19<>""),IF(AND(ISNUMBER(R19),R19<TODAY()),"Review overdue","Complete"),"Incomplete")
A20: REQ-014 | B20: Council governance | C20: Legislation and statutory guidance | D20: Local Government Act 1999 (Best Value Duty) and 2024 statutory guidance | E20: England | F20: Applicable | G20: Specialist validation required | H20: The Council must make arrangements to secure continuous improvement, having regard to economy, efficiency and effectiveness, and to statutory Best Value guidance. | I20: Evidence proportionate business case, value, service outcomes, governance, risk, performance and continuous improvement; avoid treating automation savings as sufficient assurance. | J20: Corporate Leadership / Finance / Performance | K20: Business case; objectives; benefits; monitoring; review | L20: AIG-ASS-02, AIG-OPS-05, AIG-OPS-06, AIG-OPS-01, AIG-AIMS-03 | M20: ISO 5.1, 6.2, 9.1, 10.1 | N20: Business case; option appraisal; benefits baseline; performance/outcome data; review and improvement decisions | O20: https://www.gov.uk/government/publications/best-value-standards-and-intervention-a-statutory-guide-for-best-value-authorities | P20: 46241 | Q20: 12 | R20: =IF(P20="","",IF(OR(NOT(ISNUMBER(P20)),NOT(ISNUMBER(Q20)),Q20<0,Q20<>INT(Q20)),"CHECK DATE / INTERVAL",EDATE(P20,Q20))) | S20: Current | T20: Finance/Performance/Legal to define AI value-for-money and outcome evidence by risk tier. | U20: =IF(AND(A20<>"",B20<>"",C20<>"",D20<>"",E20<>"",F20<>"",G20<>"",H20<>"",I20<>"",J20<>"",K20<>"",L20<>"",M20<>"",N20<>"",O20<>"",P20<>"",AND(ISNUMBER(P20),ISNUMBER(Q20),Q20>0,Q20=INT(Q20),ISNUMBER(R20)),S20<>"",T20<>""),IF(AND(ISNUMBER(R20),R20<TODAY()),"Review overdue","Complete"),"Incomplete")
A21: REQ-015 | B21: Procurement and suppliers | C21: Legislation | D21: Procurement Act 2023 and Procurement Regulations 2024 | E21: England, Wales and Northern Ireland regime as applicable | F21: Applicable | G21: Specialist validation required | H21: New public procurements from 24 February 2025 are governed by the new regime, subject to scope and transitional rules. | I21: Apply procurement objectives, transparency, conflicts, supplier information/exclusion, award, modification and contract-management requirements; embed AI due diligence, evidence, change, incident, audit, resilience and exit controls. | J21: Procurement / Legal / Contract Owner | K21: Discovery; market engagement; procurement; contract; change; exit | L21: AIG-INV-03, AIG-ASS-08, AIG-DEC-03, AIG-ASS-11, AIG-OPS-01 | M21: ISO 4.2, 8.1; A.10.2-A.10.4 | N21: Procurement strategy; notices; conflicts; due diligence; evaluation; contract; KPI/change/exit records | O21: https://www.legislation.gov.uk/ukpga/2023/54/contents | P21: 46241 | Q21: 6 | R21: =IF(P21="","",IF(OR(NOT(ISNUMBER(P21)),NOT(ISNUMBER(Q21)),Q21<0,Q21<>INT(Q21)),"CHECK DATE / INTERVAL",EDATE(P21,Q21))) | S21: Current / commenced | T21: Procurement/Legal to validate AI gates and mandatory terms under the new regime; distinguish legacy procurements. | U21: =IF(AND(A21<>"",B21<>"",C21<>"",D21<>"",E21<>"",F21<>"",G21<>"",H21<>"",I21<>"",J21<>"",K21<>"",L21<>"",M21<>"",N21<>"",O21<>"",P21<>"",AND(ISNUMBER(P21),ISNUMBER(Q21),Q21>0,Q21=INT(Q21),ISNUMBER(R21)),S21<>"",T21<>""),IF(AND(ISNUMBER(R21),R21<TODAY()),"Review overdue","Complete"),"Incomplete")
A22: REQ-016 | B22: Procurement and suppliers | C22: Statutory statement | D22: National Procurement Policy Statement 2025 | E22: England / in-scope contracting authorities | F22: Applicable | G22: Specialist validation required | H22: Section 13 of the Procurement Act requires in-scope contracting authorities to have regard to the NPPS, subject to stated exceptions. | I22: Reflect strategic priorities and public value in AI procurement planning and contract management; retain evidence of regard and relevant decisions. | J22: Procurement / Corporate Leadership | K22: Procurement strategy; business case; award; contract review | L22: AIG-ASS-02, AIG-ASS-08, AIG-DEC-03, AIG-OPS-05 | M22: ISO 4.2, 6.2, 8.1; A.10 | N22: Procurement strategy; decision record; social/economic/environmental considerations; contract performance | O22: https://www.gov.uk/government/publications/national-procurement-policy-statement/ | P22: 46241 | Q22: 6 | R22: =IF(P22="","",IF(OR(NOT(ISNUMBER(P22)),NOT(ISNUMBER(Q22)),Q22<0,Q22<>INT(Q22)),"CHECK DATE / INTERVAL",EDATE(P22,Q22))) | S22: Current | T22: Procurement to confirm applicability/exceptions and evidence required for AI sourcing decisions. | U22: =IF(AND(A22<>"",B22<>"",C22<>"",D22<>"",E22<>"",F22<>"",G22<>"",H22<>"",I22<>"",J22<>"",K22<>"",L22<>"",M22<>"",N22<>"",O22<>"",P22<>"",AND(ISNUMBER(P22),ISNUMBER(Q22),Q22>0,Q22=INT(Q22),ISNUMBER(R22)),S22<>"",T22<>""),IF(AND(ISNUMBER(R22),R22<TODAY()),"Review overdue","Complete"),"Incomplete")
A23: REQ-017 | B23: Procurement and suppliers | C23: Legacy legislation | D23: Public Contracts Regulations 2015 and procurement transitional arrangements | E23: England, Wales and Northern Ireland as applicable | F23: Conditional | G23: Specialist validation required | H23: May continue to govern procurements/contracts commenced under the previous regime. | I23: Identify the governing procurement regime; preserve legacy notice, modification, transparency and contract-management requirements alongside AI controls. | J23: Procurement / Legal | K23: Legacy contract; modification; renewal; exit | L23: AIG-ASS-08, AIG-DEC-03, AIG-ASS-11, AIG-OPS-01 | M23: ISO 4.2, 8.1; A.10 | N23: Regime decision; procurement file; modification/renewal advice; contract and exit evidence | O23: https://www.gov.uk/government/collections/transforming-public-procurement | P23: 46241 | Q23: 6 | R23: =IF(P23="","",IF(OR(NOT(ISNUMBER(P23)),NOT(ISNUMBER(Q23)),Q23<0,Q23<>INT(Q23)),"CHECK DATE / INTERVAL",EDATE(P23,Q23))) | S23: Transitional | T23: Create a contract-level field recording which procurement regime applies and the transition/renewal route. | U23: =IF(AND(A23<>"",B23<>"",C23<>"",D23<>"",E23<>"",F23<>"",G23<>"",H23<>"",I23<>"",J23<>"",K23<>"",L23<>"",M23<>"",N23<>"",O23<>"",P23<>"",AND(ISNUMBER(P23),ISNUMBER(Q23),Q23>0,Q23=INT(Q23),ISNUMBER(R23)),S23<>"",T23<>""),IF(AND(ISNUMBER(R23),R23<TODAY()),"Review overdue","Complete"),"Incomplete")
A24: REQ-018 | B24: Procurement and suppliers | C24: Legislation | D24: Public Services (Social Value) Act 2012 | E24: England and Wales | F24: Conditional | G24: Specialist validation required | H24: Triggered for relevant public-services procurements and pre-procurement consideration, subject to current procurement law and Council policy. | I24: Consider economic, social and environmental wellbeing and proportionate consultation; integrate equality, workforce, community and accessibility outcomes into AI sourcing where applicable. | J24: Procurement / Social Value Lead | K24: Business case; pre-procurement; evaluation; contract monitoring | L24: AIG-ASS-02, AIG-ASS-06 to AIG-ASS-08, AIG-OPS-05 | M24: ISO 4.2, 6.2, 8.1; A.5, A.10 | N24: Social-value assessment; consultation; evaluation; commitments; KPI and benefit evidence | O24: https://www.legislation.gov.uk/ukpga/2012/3/contents | P24: 46241 | Q24: 12 | R24: =IF(P24="","",IF(OR(NOT(ISNUMBER(P24)),NOT(ISNUMBER(Q24)),Q24<0,Q24<>INT(Q24)),"CHECK DATE / INTERVAL",EDATE(P24,Q24))) | S24: Current | T24: Procurement/Social Value Lead to confirm current interaction with the Procurement Act and Council policy. | U24: =IF(AND(A24<>"",B24<>"",C24<>"",D24<>"",E24<>"",F24<>"",G24<>"",H24<>"",I24<>"",J24<>"",K24<>"",L24<>"",M24<>"",N24<>"",O24<>"",P24<>"",AND(ISNUMBER(P24),ISNUMBER(Q24),Q24>0,Q24=INT(Q24),ISNUMBER(R24)),S24<>"",T24<>""),IF(AND(ISNUMBER(R24),R24<TODAY()),"Review overdue","Complete"),"Incomplete")
A25: REQ-019 | B25: Data sharing and public services | C25: Legislation | D25: Digital Economy Act 2017 data-sharing powers and codes | E25: United Kingdom / relevant chapters | F25: Conditional | G25: Specialist validation required | H25: Triggered when a proposed AI data-sharing arrangement relies on a Digital Economy Act power or objective. | I25: Confirm lawful power, objective, participant eligibility, code compliance, security, transparency, data minimisation and information-sharing terms. | J25: Legal / DPO / Information Governance | K25: Data acquisition; partnership; matching; monitoring | L25: AIG-ASS-02, AIG-ASS-05, AIG-ASS-08, AIG-DEC-03 | M25: ISO 4.2, 8.1; A.7, A.10 | N25: Power/eligibility decision; data-sharing agreement; DPIA; code assessment; security and audit records | O25: https://www.legislation.gov.uk/ukpga/2017/30/contents | P25: 46241 | Q25: 12 | R25: =IF(P25="","",IF(OR(NOT(ISNUMBER(P25)),NOT(ISNUMBER(Q25)),Q25<0,Q25<>INT(Q25)),"CHECK DATE / INTERVAL",EDATE(P25,Q25))) | S25: Current | T25: Legal/DPO to validate any proposed reliance and distinguish other statutory data-sharing powers. | U25: =IF(AND(A25<>"",B25<>"",C25<>"",D25<>"",E25<>"",F25<>"",G25<>"",H25<>"",I25<>"",J25<>"",K25<>"",L25<>"",M25<>"",N25<>"",O25<>"",P25<>"",AND(ISNUMBER(P25),ISNUMBER(Q25),Q25>0,Q25=INT(Q25),ISNUMBER(R25)),S25<>"",T25<>""),IF(AND(ISNUMBER(R25),R25<TODAY()),"Review overdue","Complete"),"Incomplete")
A26: REQ-020 | B26: Information access and records | C26: Legislation | D26: Re-use of Public Sector Information Regulations 2015 | E26: United Kingdom | F26: Conditional | G26: Specialist validation required | H26: Triggered where Council information is requested or licensed for re-use, or AI datasets/outputs are made available for re-use. | I26: Assess re-use scope, licensing, charging, non-discrimination, transparency and intellectual-property/data-protection constraints. | J26: Information Governance / Legal / Data | K26: Data publication; open data; licensing; partnerships | L26: AIG-ASS-02, AIG-ASS-08, AIG-ASS-10 | M26: ISO 4.2, 7.4; A.7, A.8.5 | N26: Re-use decision; licence; source/provenance; privacy/IP assessment; publication record | O26: https://www.legislation.gov.uk/uksi/2015/1415/contents | P26: 46241 | Q26: 12 | R26: =IF(P26="","",IF(OR(NOT(ISNUMBER(P26)),NOT(ISNUMBER(Q26)),Q26<0,Q26<>INT(Q26)),"CHECK DATE / INTERVAL",EDATE(P26,Q26))) | S26: Current | T26: Legal/IG to define triggers for AI training datasets, outputs and public/open-data releases. | U26: =IF(AND(A26<>"",B26<>"",C26<>"",D26<>"",E26<>"",F26<>"",G26<>"",H26<>"",I26<>"",J26<>"",K26<>"",L26<>"",M26<>"",N26<>"",O26<>"",P26<>"",AND(ISNUMBER(P26),ISNUMBER(Q26),Q26>0,Q26=INT(Q26),ISNUMBER(R26)),S26<>"",T26<>""),IF(AND(ISNUMBER(R26),R26<TODAY()),"Review overdue","Complete"),"Incomplete")
A27: REQ-021 | B27: Intellectual property and content | C27: Legislation | D27: Copyright, Designs and Patents Act 1988 | E27: United Kingdom | F27: Conditional | G27: Specialist validation required | H27: AI training, prompts, outputs, code, datasets and supplier models may use or generate protected material. | I27: Establish rights, licences, permitted acts, attribution and ownership; control third-party content, output use, open-source terms and supplier indemnity/evidence. | J27: Legal / Procurement / Service Owner | K27: Data acquisition; development; procurement; use; publication; exit | L27: AIG-ASS-02, AIG-ASS-08 to AIG-ASS-10, AIG-OPS-01 | M27: ISO 4.2, 8.1; A.4.3-A.4.5, A.10 | N27: Rights/licence register; provenance; terms; supplier warranty/indemnity; content review; takedown/complaint record | O27: https://www.legislation.gov.uk/ukpga/1988/48/contents | P27: 46241 | Q27: 6 | R27: =IF(P27="","",IF(OR(NOT(ISNUMBER(P27)),NOT(ISNUMBER(Q27)),Q27<0,Q27<>INT(Q27)),"CHECK DATE / INTERVAL",EDATE(P27,Q27))) | S27: Current / policy developing | T27: Legal to establish the approved IP/copyright position for generative AI and monitor government reform. | U27: =IF(AND(A27<>"",B27<>"",C27<>"",D27<>"",E27<>"",F27<>"",G27<>"",H27<>"",I27<>"",J27<>"",K27<>"",L27<>"",M27<>"",N27<>"",O27<>"",P27<>"",AND(ISNUMBER(P27),ISNUMBER(Q27),Q27>0,Q27=INT(Q27),ISNUMBER(R27)),S27<>"",T27<>""),IF(AND(ISNUMBER(R27),R27<TODAY()),"Review overdue","Complete"),"Incomplete")
A28: REQ-022 | B28: Intellectual property and content | C28: Legislation | D28: Copyright and Rights in Databases Regulations 1997 | E28: United Kingdom | F28: Conditional | G28: Specialist validation required | H28: Triggered when AI datasets or data extraction/re-use engage database copyright or database right. | I28: Confirm ownership, substantial extraction/re-utilisation, licences and supplier/customer rights for datasets and derived artefacts. | J28: Legal / Data Owner | K28: Data sourcing; training; evaluation; sharing; exit | L28: AIG-ASS-02, AIG-ASS-08, AIG-ASS-09 | M28: ISO 4.2, 8.1; A.4.3, A.7, A.10 | N28: Dataset licence; provenance; rights assessment; contractual allocation; permitted-use record | O28: https://www.legislation.gov.uk/uksi/1997/3032/contents | P28: 46241 | Q28: 12 | R28: =IF(P28="","",IF(OR(NOT(ISNUMBER(P28)),NOT(ISNUMBER(Q28)),Q28<0,Q28<>INT(Q28)),"CHECK DATE / INTERVAL",EDATE(P28,Q28))) | S28: Current | T28: Include database-right checks in dataset and supplier due diligence where triggered. | U28: =IF(AND(A28<>"",B28<>"",C28<>"",D28<>"",E28<>"",F28<>"",G28<>"",H28<>"",I28<>"",J28<>"",K28<>"",L28<>"",M28<>"",N28<>"",O28<>"",P28<>"",AND(ISNUMBER(P28),ISNUMBER(Q28),Q28>0,Q28=INT(Q28),ISNUMBER(R28)),S28<>"",T28<>""),IF(AND(ISNUMBER(R28),R28<TODAY()),"Review overdue","Complete"),"Incomplete")
A29: REQ-023 | B29: Security and misuse | C29: Legislation | D29: Computer Misuse Act 1990 | E29: United Kingdom | F29: Applicable | G29: Specialist validation required | H29: AI development, testing, agents, integrations and security exercises must not involve unauthorised access or modification. | I29: Authorise access/testing explicitly; apply least privilege, environment separation, logging and supplier controls; escalate suspected offences through security/legal routes. | J29: Cyber Security / Legal | K29: Development; testing; deployment; operations; incident | L29: AIG-ASS-08, AIG-OPS-03, AIG-ASS-11, AIG-OPS-01 | M29: ISO 4.2, 8.1; A.4.4-A.4.5, A.6.2.4-A.6.2.8 | N29: Test authorisation; access records; rules of engagement; logs; incident/legal decisions | O29: https://www.legislation.gov.uk/ukpga/1990/18/contents | P29: 46241 | Q29: 12 | R29: =IF(P29="","",IF(OR(NOT(ISNUMBER(P29)),NOT(ISNUMBER(Q29)),Q29<0,Q29<>INT(Q29)),"CHECK DATE / INTERVAL",EDATE(P29,Q29))) | S29: Current | T29: Security/Legal to define authorisation standards for red teaming, scanning, agentic actions and supplier testing. | U29: =IF(AND(A29<>"",B29<>"",C29<>"",D29<>"",E29<>"",F29<>"",G29<>"",H29<>"",I29<>"",J29<>"",K29<>"",L29<>"",M29<>"",N29<>"",O29<>"",P29<>"",AND(ISNUMBER(P29),ISNUMBER(Q29),Q29>0,Q29=INT(Q29),ISNUMBER(R29)),S29<>"",T29<>""),IF(AND(ISNUMBER(R29),R29<TODAY()),"Review overdue","Complete"),"Incomplete")
A30: REQ-024 | B30: Security and resilience | C30: Legislation | D30: Network and Information Systems Regulations 2018 (NIS Regulations) | E30: United Kingdom | F30: Conditional | G30: Specialist validation required | H30: Applies only if the Council/system is within a regulated operator/digital-service scope or supports an in-scope body/contractual requirement. | I30: Determine status and dependencies; implement proportionate security and incident notification where applicable; reflect supply-chain and service-resilience requirements. | J30: Cyber Security / Legal / Resilience | K30: Scoping; architecture; procurement; operations; incidents | L30: AIG-ASS-08, AIG-OPS-03, AIG-ASS-11, AIG-OPS-01 | M30: ISO 4.2, 8.1; A.4.4, A.6.2.7-A.6.2.8, A.10 | N30: Applicability decision; security assessment; resilience plan; incident process; supplier obligations | O30: https://www.legislation.gov.uk/uksi/2018/506/contents | P30: 46241 | Q30: 6 | R30: =IF(P30="","",IF(OR(NOT(ISNUMBER(P30)),NOT(ISNUMBER(Q30)),Q30<0,Q30<>INT(Q30)),"CHECK DATE / INTERVAL",EDATE(P30,Q30))) | S30: Current / reform sensitive | T30: Security/Legal to confirm applicability and monitor UK cyber-security legislative reform. | U30: =IF(AND(A30<>"",B30<>"",C30<>"",D30<>"",E30<>"",F30<>"",G30<>"",H30<>"",I30<>"",J30<>"",K30<>"",L30<>"",M30<>"",N30<>"",O30<>"",P30<>"",AND(ISNUMBER(P30),ISNUMBER(Q30),Q30>0,Q30=INT(Q30),ISNUMBER(R30)),S30<>"",T30<>""),IF(AND(ISNUMBER(R30),R30<TODAY()),"Review overdue","Complete"),"Incomplete")
A31: REQ-025 | B31: Surveillance and investigatory powers | C31: Legislation and statutory codes | D31: RIPA 2000, Investigatory Powers Act 2016 and Protection of Freedoms Act 2012 / surveillance-camera obligations | E31: United Kingdom / England and Wales as applicable | F31: Conditional | G31: Specialist validation required | H31: Triggered by AI-enabled surveillance, biometrics, covert activity, communications data or investigatory powers. | I31: Confirm lawful authority, necessity, proportionality, authorisation, oversight, retention, transparency and human review; apply relevant codes and commissioner requirements. | J31: Legal / DPO / SIRO / Authorising Officer | K31: Intake; impact assessment; authorisation; deployment; monitoring; incidents | L31: AIG-ASS-02, AIG-ASS-04, AIG-ASS-05, AIG-ASS-07, AIG-ASS-09, AIG-DEC-03, AIG-ASS-11 | M31: ISO 4.2, 6.1, 8.1; A.5, A.7, A.8 | N31: Power/code decision; DPIA/HRA/EIA; authorisation; audit logs; oversight; review and deletion | O31: https://www.legislation.gov.uk/ukpga/2000/23/contents | P31: 46241 | Q31: 3 | R31: =IF(P31="","",IF(OR(NOT(ISNUMBER(P31)),NOT(ISNUMBER(Q31)),Q31<0,Q31<>INT(Q31)),"CHECK DATE / INTERVAL",EDATE(P31,Q31))) | S31: Current / case-sensitive | T31: Legal/DPO to create a specialist trigger and prohibit deployment before required authorisation. | U31: =IF(AND(A31<>"",B31<>"",C31<>"",D31<>"",E31<>"",F31<>"",G31<>"",H31<>"",I31<>"",J31<>"",K31<>"",L31<>"",M31<>"",N31<>"",O31<>"",P31<>"",AND(ISNUMBER(P31),ISNUMBER(Q31),Q31>0,Q31=INT(Q31),ISNUMBER(R31)),S31<>"",T31<>""),IF(AND(ISNUMBER(R31),R31<TODAY()),"Review overdue","Complete"),"Incomplete")
... A50: REQ-044 | B50: Council AI governance | C50: Council policy suite | D50: Council AI Governance Playbook — proposed edition/version and currency to be owner-validated | E50: The Council | F50: Proposed adoption | G50: Specialist validation required | H50: [PROPOSED EDIT — OWNER VALIDATION REQUIRED] Proposed Council-controlled requirement; identify and verify the approved edition/version and currency before adoption. No edition or currency is confirmed by this register. | I50: Approve, control, communicate and operate the suite; assign authority, owners, evidence, exceptions, review and improvement; keep one AI Register ID across the lifecycle. | J50: Executive Sponsor / AI Governance Lead | K50: All AIMS and AI lifecycle processes | L50: 52 purpose-grouped artefacts (see AIG-GOV-03) | M50: ISO clauses 4-10; Annex A | N50: Adoption decision; controlled versions; appointments; case records; metrics; audits; management reviews and improvements | O50: Internal controlled suite — 52 purpose-grouped artefacts (see AIG-GOV-03) | P50: 46241 | Q50: 3 | R50: =IF(P50="","",IF(OR(NOT(ISNUMBER(P50)),NOT(ISNUMBER(Q50)),Q50<0,Q50<>INT(Q50)),"CHECK DATE / INTERVAL",EDATE(P50,Q50))) | S50: Proposed edition/currency — owner validation required | T50: [PROPOSED EDIT — AI Governance Lead/Document Control to validate proposed edition, currency, controlled artefact inventory and adoption route; no current edition/currency asserted. | U50: =IF(AND(A50<>"",B50<>"",C50<>"",D50<>"",E50<>"",F50<>"",G50<>"",H50<>"",I50<>"",J50<>"",K50<>"",L50<>"",M50<>"",N50<>"",O50<>"",P50<>"",AND(ISNUMBER(P50),ISNUMBER(Q50),Q50>0,Q50=INT(Q50),ISNUMBER(R50)),S50<>"",T50<>""),IF(AND(ISNUMBER(R50),R50<TODAY()),"Review overdue","Complete"),"Incomplete")
A51: REQ-045 | B51: Council governance | C51: Council constitution / scheme of delegation | D51: Council Constitution, executive arrangements, schemes of delegation and committee procedure rules | E51: The Council | F51: Applicable | G51: Specialist validation required | H51: These instruments determine lawful authority, reserved decisions, officer/member roles, meetings, conflicts and records. | I51: Validate AIMS bodies, risk acceptance, case approval, exceptions, appointments, conflicts, escalation and records against current constitutional authority. | J51: Monitoring Officer / Governance | K51: AIMS design; appointments; decisions; management review | L51: AIG-DEC-03, AIG-GOV-06, AIG-AIMS-01, AIG-AIMS-04 | M51: ISO 5.1-5.3, 7.5; A.3.2 | N51: Current constitution/delegation references; approved Terms of Reference; appointments; conflicts; minutes/decisions | O51: Current Council Constitution / Scheme of Delegation reference, approved governance records and delegation evidence | Q51: 6 | R51: =IF(P51="","",IF(OR(NOT(ISNUMBER(P51)),NOT(ISNUMBER(Q51)),Q51<0,Q51<>INT(Q51)),"CHECK DATE / INTERVAL",EDATE(P51,Q51))) | S51: Current version to confirm | T51: Monitoring Officer to enter the authoritative titles, versions, links and approved authority mapping from the current approved Constitution and Scheme of Delegation. Committee agendas or reports are working context only, not confirmation of the approved constitution. | U51: =IF(AND(A51<>"",B51<>"",C51<>"",D51<>"",E51<>"",F51<>"",G51<>"",H51<>"",I51<>"",J51<>"",K51<>"",L51<>"",M51<>"",N51<>"",O51<>"",P51<>"",AND(ISNUMBER(P51),ISNUMBER(Q51),Q51>0,Q51=INT(Q51),ISNUMBER(R51)),S51<>"",T51<>""),IF(AND(ISNUMBER(R51),R51<TODAY()),"Review overdue","Complete"),"Incomplete")
A52: REQ-046 | B52: Council information governance | C52: Council policies / standards | D52: Council data protection, information governance, records, retention, information-sharing and FOI/EIR policies | E52: The Council | F52: Applicable | G52: Specialist validation required | H52: Corporate controls apply to AI processing, records, sharing, suppliers, information access and disposal. | I52: Integrate current policy requirements into intake, DPIA, data governance, evidence storage, contracts, access requests, retention and retirement. | J52: DPO / Information Governance / Records Management | K52: Data; evidence; sharing; requests; retirement | L52: AIG-INV-04, AIG-ASS-02, AIG-ASS-04, AIG-ASS-05, AIG-ASS-08 to AIG-ASS-10, AIG-DEC-03, AIG-OPS-03, AIG-OPS-05, AIG-OPS-06, AIG-OPS-01 | M52: ISO 7.5, 8.1; A.4-A.8, A.10 | N52: Current policy references; ROPA/DPIA; data agreements; retention; disclosure and disposal records | O52: Council controlled policy repository — authoritative titles, versions and links to be populated | P52: 46241 | Q52: 6 | R52: =IF(P52="","",IF(OR(NOT(ISNUMBER(P52)),NOT(ISNUMBER(Q52)),Q52<0,Q52<>INT(Q52)),"CHECK DATE / INTERVAL",EDATE(P52,Q52))) | S52: Current version to confirm | T52: Control owners to populate exact policy titles/versions and identify any conflict or duplication with the AIMS. | U52: =IF(AND(A52<>"",B52<>"",C52<>"",D52<>"",E52<>"",F52<>"",G52<>"",H52<>"",I52<>"",J52<>"",K52<>"",L52<>"",M52<>"",N52<>"",O52<>"",P52<>"",AND(ISNUMBER(P52),ISNUMBER(Q52),Q52>0,Q52=INT(Q52),ISNUMBER(R52)),S52<>"",T52<>""),IF(AND(ISNUMBER(R52),R52<TODAY()),"Review overdue","Complete"),"Incomplete")
A53: REQ-047 | B53: Council security and resilience | C53: Council policies / standards | D53: Council cyber security, acceptable use, identity/access, secure development, incident, resilience and business-continuity policies | E53: The Council | F53: Applicable | G53: Specialist validation required | H53: Corporate security and resilience controls apply to AI technology, users, data, suppliers and live services. | I53: Apply approved architecture, access, logging, testing, vulnerability, incident, continuity, backup, recovery and acceptable-use controls; add AI-specific measures where needed. | J53: Cyber Security / Technology / Resilience | K53: Architecture; development; procurement; deployment; operations; incidents | L53: AIG-GOV-02, AIG-ASS-08, AIG-OPS-03, AIG-ASS-11, AIG-OPS-01, AIG-AIMS-04 | M53: ISO 8.1; A.4.4-A.4.5, A.6.2.4-A.6.2.8, A.9.2, A.10 | N53: Current standards; security review; tests; access/logs; incident/BC plans; exercise; supplier evidence | O53: Council controlled security and resilience repository — authoritative titles, versions and links to be populated | P53: 46241 | Q53: 3 | R53: =IF(P53="","",IF(OR(NOT(ISNUMBER(P53)),NOT(ISNUMBER(Q53)),Q53<0,Q53<>INT(Q53)),"CHECK DATE / INTERVAL",EDATE(P53,Q53))) | S53: Current version to confirm | T53: Security/Resilience to populate sources and approve the AI-specific control overlay. | U53: =IF(AND(A53<>"",B53<>"",C53<>"",D53<>"",E53<>"",F53<>"",G53<>"",H53<>"",I53<>"",J53<>"",K53<>"",L53<>"",M53<>"",N53<>"",O53<>"",P53<>"",AND(ISNUMBER(P53),ISNUMBER(Q53),Q53>0,Q53=INT(Q53),ISNUMBER(R53)),S53<>"",T53<>""),IF(AND(ISNUMBER(R53),R53<TODAY()),"Review overdue","Complete"),"Incomplete")
A54: REQ-048 | B54: Council procurement and commercial | C54: Council policies / templates | D54: Council procurement, commercial, contract-management, social-value and financial rules | E54: The Council | F54: Applicable | G54: Specialist validation required | H54: Corporate sourcing and financial controls apply to AI purchases, embedded features, pilots, renewals and supplier changes. | I54: Trigger AI governance early; apply approved routes, financial authority, due diligence, evaluation, clauses, exceptions, KPI, change, audit, continuity and exit controls. | J54: Procurement / Finance / Legal / Contract Owner | K54: Business case; sourcing; contract; monitoring; renewal; exit | L54: AIG-INV-03, AIG-ASS-02, AIG-ASS-08, AIG-DEC-03, AIG-ASS-11, AIG-OPS-01 | M54: ISO 4.2, 8.1; A.10 | N54: Current rules/templates; approvals; due diligence; contract; exception; performance/change/exit evidence | O54: Council controlled procurement and finance repository — authoritative titles, versions and links to be populated | P54: 46241 | Q54: 6 | R54: =IF(P54="","",IF(OR(NOT(ISNUMBER(P54)),NOT(ISNUMBER(Q54)),Q54<0,Q54<>INT(Q54)),"CHECK DATE / INTERVAL",EDATE(P54,Q54))) | S54: Current version to confirm | T54: Procurement/Finance to populate sources and align AIG-ASS-08/AIG-ASS-11/AIG-OPS-01 with mandatory corporate gates. | U54: =IF(AND(A54<>"",B54<>"",C54<>"",D54<>"",E54<>"",F54<>"",G54<>"",H54<>"",I54<>"",J54<>"",K54<>"",L54<>"",M54<>"",N54<>"",O54<>"",P54<>"",AND(ISNUMBER(P54),ISNUMBER(Q54),Q54>0,Q54=INT(Q54),ISNUMBER(R54)),S54<>"",T54<>""),IF(AND(ISNUMBER(R54),R54<TODAY()),"Review overdue","Complete"),"Incomplete")
A55: REQ-049 | B55: Council people and public impact | C55: Council policies / procedures | D55: Council equality, accessibility, HR, workforce consultation, safeguarding, complaints, engagement and communications policies | E55: The Council | F55: Applicable | G55: Specialist validation required | H55: Corporate duties and commitments apply to AI effects on residents, staff, communities, accessibility, safety, participation and redress. | I55: Apply current assessment, consultation, reasonable-adjustment, safeguarding, workforce, complaint, communication and engagement requirements; preserve specialist authority. | J55: Equality / HR / Safeguarding / Complaints / Communications | K55: Impact; workforce; service design; transparency; complaints; incidents | L55: AIG-ASS-04, AIG-ASS-06, AIG-ASS-07, AIG-ASS-10, AIG-OPS-05, AIG-OPS-03, AIG-OPS-01, AIG-AIMS-04 | M55: ISO 4.2, 7.2-7.4, 8.1; A.5, A.8, A.9 | N55: Current policies; assessments; consultation; accessibility; training; notices; complaints and action records | O55: Council controlled people, safeguarding and communications repositories — authoritative titles, versions and links to be populated | P55: 46241 | Q55: 6 | R55: =IF(P55="","",IF(OR(NOT(ISNUMBER(P55)),NOT(ISNUMBER(Q55)),Q55<0,Q55<>INT(Q55)),"CHECK DATE / INTERVAL",EDATE(P55,Q55))) | S55: Current version to confirm | T55: Function owners to populate sources and validate assessment/sign-off and complaint/redress interfaces. | U55: =IF(AND(A55<>"",B55<>"",C55<>"",D55<>"",E55<>"",F55<>"",G55<>"",H55<>"",I55<>"",J55<>"",K55<>"",L55<>"",M55<>"",N55<>"",O55<>"",P55<>"",AND(ISNUMBER(P55),ISNUMBER(Q55),Q55>0,Q55=INT(Q55),ISNUMBER(R55)),S55<>"",T55<>""),IF(AND(ISNUMBER(R55),R55<TODAY()),"Review overdue","Complete"),"Incomplete")
