Workbook

Sheet START HERE
A1: AIG-INV-05 | CAPABILITIES + SYSTEM MAP
A3: Status | B3: Draft for Council review. AIG-INV-05 is the controlled-artefact ID assigned in this proposed suite. This remains an empty draft, not approved, effective or operational. Proposed control designation does not itself confer adoption or approval.
A4: Version | B4: v0.3 proposed design draft (see Document Control); formal version control begins only if adopted.
A5: Owner / custodian | B5: To be confirmed by the competent authority; proposed day-to-day custodianship is shared between the Governance function and authorised service/architecture data owners.
A6: Approving authority | B6: Not yet confirmed. Competent delegated Council authority and publication route must be verified; Governance Lead custody or assurance oversight is not approval.
A7: Approval / effective date | B7: Not approved; no effective date.
A8: Access and retention | B8: Proposed controlled access, confidentiality classification, retention period and disposal route remain to be confirmed before any real system or component records are entered.
A9: Change control | B9: Proposed changes require a dated change record, reason, owner validation, version update and delegated approval where the schema or control rules change. Design changes are recorded on the Document Control sheet; no live data change history is included.
A10: Question it answers | B10: Which outcome-led use cases need which atomic capabilities; which governed AI systems provide them; and which model, data, interface, agent and tool references those systems depend on.
A11: Workflow route | B11: 1. Discover and complete Intake (AIG-INV-03). 2. Governance issues/reconciles the stable AIR-ID in the Register (AIG-INV-04). 3. Complete risk triage and triggered assessments. 4. Record gate plans/events/conditions in AIG-DEC-04; the delegated Council forum decides and records its decision in AIG-DEC-03 or approved minutes. 5. Operate under AIG-OPS-01 and monitor through AIG-OPS-02.
A12: ID rule | B12: AIG-… IDs label suite documents; AIR-ID identifies one governed system and remains stable when documents change. AIG-INV-05 is the controlled-artefact slot in this proposed edition, but its map is descriptive only—not an approval, access grant or decision source.
A13: Read in order | B13: For map work, start with Use cases and Capabilities; enter only AIR-IDs reconciled to AIG-INV-04; record sourced component pointers in Components; link them in Relationships; review the derived System map; track uncertainty in Gaps and actions and changes in Map changes; use Dependency concentration for the whole-portfolio view of shared components and suppliers.
A14: No second Register | B14: AIG-INV-04 remains the authoritative record of AIR-ID, purpose, Service Owner and current status. System map includes only a manually reconciled label/pointer and confirmed relationship counts, not another approval status.
... A21: Dependency concentration | B21: Proposed — for Council confirmation. Whole-portfolio view (Playbook §4.5.8; AIG-AIMS-10 M-16): distinct AIR-IDs relying on each component (confirmed, QA-clean links only) and on each supplier from the controlled AIG-INV-04 extract, with share and a flag against a threshold the Council sets (blank = no flag). Zero is not absence; AIG-INV-04 does not change.

Sheet System map
A1: SYSTEM MAP / CONFIRMED COVERAGE
A2: Enter only official AIR-IDs issued through AIG-INV-04. Labels are a dated snapshot; counts use confirmed, QA-clean links only. Zero means not mapped or unconfirmed, not absent.
A3: AIR-ID (from AIG-INV-04) | B3: System label (AIG-INV-04 snapshot) | C3: AIG-INV-04 source / version | D3: AIG-INV-04 reconciled on | E3: Capabilities | F3: Models | G3: Data assets | H3: Interfaces | I3: Agents | J3: Tools | K3: Proposed links | L3: Links needing review | M3: Review state | N3: Review notes / N-A rationale | O3: Row check
E4: =IF(A4="","",COUNTIFS(Relationships!$B$4:$B$1003,"CAP",Relationships!$E$4:$E$1003,"AIR",Relationships!$F$4:$F$1003,A4,Relationships!$M$4:$M$1003,"Confirmed",Relationships!$N$4:$N$1003,"OK — verify source")) | F4: =IF(A4="","",COUNTIFS(Relationships!$B$4:$B$1003,"AIR",Relationships!$C$4:$C$1003,A4,Relationships!$E$4:$E$1003,"MOD",Relationships!$M$4:$M$1003,"Confirmed",Relationships!$N$4:$N$1003,"OK — verify source")) | G4: =IF(A4="","",COUNTIFS(Relationships!$B$4:$B$1003,"AIR",Relationships!$C$4:$C$1003,A4,Relationships!$E$4:$E$1003,"DATA",Relationships!$M$4:$M$1003,"Confirmed",Relationships!$N$4:$N$1003,"OK — verify source")) | H4: =IF(A4="","",COUNTIFS(Relationships!$B$4:$B$1003,"AIR",Relationships!$C$4:$C$1003,A4,Relationships!$E$4:$E$1003,"IF",Relationships!$M$4:$M$1003,"Confirmed",Relationships!$N$4:$N$1003,"OK — verify source")) | I4: =IF(A4="","",COUNTIFS(Relationships!$B$4:$B$1003,"AIR",Relationships!$C$4:$C$1003,A4,Relationships!$E$4:$E$1003,"AG",Relationships!$M$4:$M$1003,"Confirmed",Relationships!$N$4:$N$1003,"OK — verify source")) | J4: =IF(A4="","",COUNTIFS(Relationships!$B$4:$B$1003,"AIR",Relationships!$C$4:$C$1003,A4,Relationships!$E$4:$E$1003,"TOOL",Relationships!$M$4:$M$1003,"Confirmed",Relationships!$N$4:$N$1003,"OK — verify source")) | K4: =IF(A4="","",COUNTIFS(Relationships!$G$4:$G$1003,A4,Relationships!$M$4:$M$1003,"Proposed")) | L4: =IF(A4="","",COUNTIFS(Relationships!$G$4:$G$1003,A4,Relationships!$A$4:$A$1003,"<>",Relationships!$N$4:$N$1003,"<>OK — verify source")) | O4: =IF(COUNTA(A4:D4,M4:N4)=0,"",IF(A4="","AIR-ID missing",IF(COUNTIF($A$4:$A$203,A4)>1,"Duplicate AIR-ID",IF(OR(B4="",C4="",D4=""),"Label / source / reconciled-on missing",IF(NOT(ISNUMBER(D4)),"Reconciled-on is not a date","OK — verify source")))))
E5: =IF(A5="","",COUNTIFS(Relationships!$B$4:$B$1003,"CAP",Relationships!$E$4:$E$1003,"AIR",Relationships!$F$4:$F$1003,A5,Relationships!$M$4:$M$1003,"Confirmed",Relationships!$N$4:$N$1003,"OK — verify source")) | F5: =IF(A5="","",COUNTIFS(Relationships!$B$4:$B$1003,"AIR",Relationships!$C$4:$C$1003,A5,Relationships!$E$4:$E$1003,"MOD",Relationships!$M$4:$M$1003,"Confirmed",Relationships!$N$4:$N$1003,"OK — verify source")) | G5: =IF(A5="","",COUNTIFS(Relationships!$B$4:$B$1003,"AIR",Relationships!$C$4:$C$1003,A5,Relationships!$E$4:$E$1003,"DATA",Relationships!$M$4:$M$1003,"Confirmed",Relationships!$N$4:$N$1003,"OK — verify source")) | H5: =IF(A5="","",COUNTIFS(Relationships!$B$4:$B$1003,"AIR",Relationships!$C$4:$C$1003,A5,Relationships!$E$4:$E$1003,"IF",Relationships!$M$4:$M$1003,"Confirmed",Relationships!$N$4:$N$1003,"OK — verify source")) | I5: =IF(A5="","",COUNTIFS(Relationships!$B$4:$B$1003,"AIR",Relationships!$C$4:$C$1003,A5,Relationships!$E$4:$E$1003,"AG",Relationships!$M$4:$M$1003,"Confirmed",Relationships!$N$4:$N$1003,"OK — verify source")) | J5: =IF(A5="","",COUNTIFS(Relationships!$B$4:$B$1003,"AIR",Relationships!$C$4:$C$1003,A5,Relationships!$E$4:$E$1003,"TOOL",Relationships!$M$4:$M$1003,"Confirmed",Relationships!$N$4:$N$1003,"OK — verify source")) | K5: =IF(A5="","",COUNTIFS(Relationships!$G$4:$G$1003,A5,Relationships!$M$4:$M$1003,"Proposed")) | L5: =IF(A5="","",COUNTIFS(Relationships!$G$4:$G$1003,A5,Relationships!$A$4:$A$1003,"<>",Relationships!$N$4:$N$1003,"<>OK — verify source")) | O5: =IF(COUNTA(A5:D5,M5:N5)=0,"",IF(A5="","AIR-ID missing",IF(COUNTIF($A$4:$A$203,A5)>1,"Duplicate AIR-ID",IF(OR(B5="",C5="",D5=""),"Label / source / reconciled-on missing",IF(NOT(ISNUMBER(D5)),"Reconciled-on is not a date","OK — verify source")))))
E6: =IF(A6="","",COUNTIFS(Relationships!$B$4:$B$1003,"CAP",Relationships!$E$4:$E$1003,"AIR",Relationships!$F$4:$F$1003,A6,Relationships!$M$4:$M$1003,"Confirmed",Relationships!$N$4:$N$1003,"OK — verify source")) | F6: =IF(A6="","",COUNTIFS(Relationships!$B$4:$B$1003,"AIR",Relationships!$C$4:$C$1003,A6,Relationships!$E$4:$E$1003,"MOD",Relationships!$M$4:$M$1003,"Confirmed",Relationships!$N$4:$N$1003,"OK — verify source")) | G6: =IF(A6="","",COUNTIFS(Relationships!$B$4:$B$1003,"AIR",Relationships!$C$4:$C$1003,A6,Relationships!$E$4:$E$1003,"DATA",Relationships!$M$4:$M$1003,"Confirmed",Relationships!$N$4:$N$1003,"OK — verify source")) | H6: =IF(A6="","",COUNTIFS(Relationships!$B$4:$B$1003,"AIR",Relationships!$C$4:$C$1003,A6,Relationships!$E$4:$E$1003,"IF",Relationships!$M$4:$M$1003,"Confirmed",Relationships!$N$4:$N$1003,"OK — verify source")) | I6: =IF(A6="","",COUNTIFS(Relationships!$B$4:$B$1003,"AIR",Relationships!$C$4:$C$1003,A6,Relationships!$E$4:$E$1003,"AG",Relationships!$M$4:$M$1003,"Confirmed",Relationships!$N$4:$N$1003,"OK — verify source")) | J6: =IF(A6="","",COUNTIFS(Relationships!$B$4:$B$1003,"AIR",Relationships!$C$4:$C$1003,A6,Relationships!$E$4:$E$1003,"TOOL",Relationships!$M$4:$M$1003,"Confirmed",Relationships!$N$4:$N$1003,"OK — verify source")) | K6: =IF(A6="","",COUNTIFS(Relationships!$G$4:$G$1003,A6,Relationships!$M$4:$M$1003,"Proposed")) | L6: =IF(A6="","",COUNTIFS(Relationships!$G$4:$G$1003,A6,Relationships!$A$4:$A$1003,"<>",Relationships!$N$4:$N$1003,"<>OK — verify source")) | O6: =IF(COUNTA(A6:D6,M6:N6)=0,"",IF(A6="","AIR-ID missing",IF(COUNTIF($A$4:$A$203,A6)>1,"Duplicate AIR-ID",IF(OR(B6="",C6="",D6=""),"Label / source / reconciled-on missing",IF(NOT(ISNUMBER(D6)),"Reconciled-on is not a date","OK — verify source")))))
E7: =IF(A7="","",COUNTIFS(Relationships!$B$4:$B$1003,"CAP",Relationships!$E$4:$E$1003,"AIR",Relationships!$F$4:$F$1003,A7,Relationships!$M$4:$M$1003,"Confirmed",Relationships!$N$4:$N$1003,"OK — verify source")) | F7: =IF(A7="","",COUNTIFS(Relationships!$B$4:$B$1003,"AIR",Relationships!$C$4:$C$1003,A7,Relationships!$E$4:$E$1003,"MOD",Relationships!$M$4:$M$1003,"Confirmed",Relationships!$N$4:$N$1003,"OK — verify source")) | G7: =IF(A7="","",COUNTIFS(Relationships!$B$4:$B$1003,"AIR",Relationships!$C$4:$C$1003,A7,Relationships!$E$4:$E$1003,"DATA",Relationships!$M$4:$M$1003,"Confirmed",Relationships!$N$4:$N$1003,"OK — verify source")) | H7: =IF(A7="","",COUNTIFS(Relationships!$B$4:$B$1003,"AIR",Relationships!$C$4:$C$1003,A7,Relationships!$E$4:$E$1003,"IF",Relationships!$M$4:$M$1003,"Confirmed",Relationships!$N$4:$N$1003,"OK — verify source")) | I7: =IF(A7="","",COUNTIFS(Relationships!$B$4:$B$1003,"AIR",Relationships!$C$4:$C$1003,A7,Relationships!$E$4:$E$1003,"AG",Relationships!$M$4:$M$1003,"Confirmed",Relationships!$N$4:$N$1003,"OK — verify source")) | J7: =IF(A7="","",COUNTIFS(Relationships!$B$4:$B$1003,"AIR",Relationships!$C$4:$C$1003,A7,Relationships!$E$4:$E$1003,"TOOL",Relationships!$M$4:$M$1003,"Confirmed",Relationships!$N$4:$N$1003,"OK — verify source")) | K7: =IF(A7="","",COUNTIFS(Relationships!$G$4:$G$1003,A7,Relationships!$M$4:$M$1003,"Proposed")) | L7: =IF(A7="","",COUNTIFS(Relationships!$G$4:$G$1003,A7,Relationships!$A$4:$A$1003,"<>",Relationships!$N$4:$N$1003,"<>OK — verify source")) | O7: =IF(COUNTA(A7:D7,M7:N7)=0,"",IF(A7="","AIR-ID missing",IF(COUNTIF($A$4:$A$203,A7)>1,"Duplicate AIR-ID",IF(OR(B7="",C7="",D7=""),"Label / source / reconciled-on missing",IF(NOT(ISNUMBER(D7)),"Reconciled-on is not a date","OK — verify source")))))
E8: =IF(A8="","",COUNTIFS(Relationships!$B$4:$B$1003,"CAP",Relationships!$E$4:$E$1003,"AIR",Relationships!$F$4:$F$1003,A8,Relationships!$M$4:$M$1003,"Confirmed",Relationships!$N$4:$N$1003,"OK — verify source")) | F8: =IF(A8="","",COUNTIFS(Relationships!$B$4:$B$1003,"AIR",Relationships!$C$4:$C$1003,A8,Relationships!$E$4:$E$1003,"MOD",Relationships!$M$4:$M$1003,"Confirmed",Relationships!$N$4:$N$1003,"OK — verify source")) | G8: =IF(A8="","",COUNTIFS(Relationships!$B$4:$B$1003,"AIR",Relationships!$C$4:$C$1003,A8,Relationships!$E$4:$E$1003,"DATA",Relationships!$M$4:$M$1003,"Confirmed",Relationships!$N$4:$N$1003,"OK — verify source")) | H8: =IF(A8="","",COUNTIFS(Relationships!$B$4:$B$1003,"AIR",Relationships!$C$4:$C$1003,A8,Relationships!$E$4:$E$1003,"IF",Relationships!$M$4:$M$1003,"Confirmed",Relationships!$N$4:$N$1003,"OK — verify source")) | I8: =IF(A8="","",COUNTIFS(Relationships!$B$4:$B$1003,"AIR",Relationships!$C$4:$C$1003,A8,Relationships!$E$4:$E$1003,"AG",Relationships!$M$4:$M$1003,"Confirmed",Relationships!$N$4:$N$1003,"OK — verify source")) | J8: =IF(A8="","",COUNTIFS(Relationships!$B$4:$B$1003,"AIR",Relationships!$C$4:$C$1003,A8,Relationships!$E$4:$E$1003,"TOOL",Relationships!$M$4:$M$1003,"Confirmed",Relationships!$N$4:$N$1003,"OK — verify source")) | K8: =IF(A8="","",COUNTIFS(Relationships!$G$4:$G$1003,A8,Relationships!$M$4:$M$1003,"Proposed")) | L8: =IF(A8="","",COUNTIFS(Relationships!$G$4:$G$1003,A8,Relationships!$A$4:$A$1003,"<>",Relationships!$N$4:$N$1003,"<>OK — verify source")) | O8: =IF(COUNTA(A8:D8,M8:N8)=0,"",IF(A8="","AIR-ID missing",IF(COUNTIF($A$4:$A$203,A8)>1,"Duplicate AIR-ID",IF(OR(B8="",C8="",D8=""),"Label / source / reconciled-on missing",IF(NOT(ISNUMBER(D8)),"Reconciled-on is not a date","OK — verify source")))))
E9: =IF(A9="","",COUNTIFS(Relationships!$B$4:$B$1003,"CAP",Relationships!$E$4:$E$1003,"AIR",Relationships!$F$4:$F$1003,A9,Relationships!$M$4:$M$1003,"Confirmed",Relationships!$N$4:$N$1003,"OK — verify source")) | F9: =IF(A9="","",COUNTIFS(Relationships!$B$4:$B$1003,"AIR",Relationships!$C$4:$C$1003,A9,Relationships!$E$4:$E$1003,"MOD",Relationships!$M$4:$M$1003,"Confirmed",Relationships!$N$4:$N$1003,"OK — verify source")) | G9: =IF(A9="","",COUNTIFS(Relationships!$B$4:$B$1003,"AIR",Relationships!$C$4:$C$1003,A9,Relationships!$E$4:$E$1003,"DATA",Relationships!$M$4:$M$1003,"Confirmed",Relationships!$N$4:$N$1003,"OK — verify source")) | H9: =IF(A9="","",COUNTIFS(Relationships!$B$4:$B$1003,"AIR",Relationships!$C$4:$C$1003,A9,Relationships!$E$4:$E$1003,"IF",Relationships!$M$4:$M$1003,"Confirmed",Relationships!$N$4:$N$1003,"OK — verify source")) | I9: =IF(A9="","",COUNTIFS(Relationships!$B$4:$B$1003,"AIR",Relationships!$C$4:$C$1003,A9,Relationships!$E$4:$E$1003,"AG",Relationships!$M$4:$M$1003,"Confirmed",Relationships!$N$4:$N$1003,"OK — verify source")) | J9: =IF(A9="","",COUNTIFS(Relationships!$B$4:$B$1003,"AIR",Relationships!$C$4:$C$1003,A9,Relationships!$E$4:$E$1003,"TOOL",Relationships!$M$4:$M$1003,"Confirmed",Relationships!$N$4:$N$1003,"OK — verify source")) | K9: =IF(A9="","",COUNTIFS(Relationships!$G$4:$G$1003,A9,Relationships!$M$4:$M$1003,"Proposed")) | L9: =IF(A9="","",COUNTIFS(Relationships!$G$4:$G$1003,A9,Relationships!$A$4:$A$1003,"<>",Relationships!$N$4:$N$1003,"<>OK — verify source")) | O9: =IF(COUNTA(A9:D9,M9:N9)=0,"",IF(A9="","AIR-ID missing",IF(COUNTIF($A$4:$A$203,A9)>1,"Duplicate AIR-ID",IF(OR(B9="",C9="",D9=""),"Label / source / reconciled-on missing",IF(NOT(ISNUMBER(D9)),"Reconciled-on is not a date","OK — verify source")))))
E10: =IF(A10="","",COUNTIFS(Relationships!$B$4:$B$1003,"CAP",Relationships!$E$4:$E$1003,"AIR",Relationships!$F$4:$F$1003,A10,Relationships!$M$4:$M$1003,"Confirmed",Relationships!$N$4:$N$1003,"OK — verify source")) | F10: =IF(A10="","",COUNTIFS(Relationships!$B$4:$B$1003,"AIR",Relationships!$C$4:$C$1003,A10,Relationships!$E$4:$E$1003,"MOD",Relationships!$M$4:$M$1003,"Confirmed",Relationships!$N$4:$N$1003,"OK — verify source")) | G10: =IF(A10="","",COUNTIFS(Relationships!$B$4:$B$1003,"AIR",Relationships!$C$4:$C$1003,A10,Relationships!$E$4:$E$1003,"DATA",Relationships!$M$4:$M$1003,"Confirmed",Relationships!$N$4:$N$1003,"OK — verify source")) | H10: =IF(A10="","",COUNTIFS(Relationships!$B$4:$B$1003,"AIR",Relationships!$C$4:$C$1003,A10,Relationships!$E$4:$E$1003,"IF",Relationships!$M$4:$M$1003,"Confirmed",Relationships!$N$4:$N$1003,"OK — verify source")) | I10: =IF(A10="","",COUNTIFS(Relationships!$B$4:$B$1003,"AIR",Relationships!$C$4:$C$1003,A10,Relationships!$E$4:$E$1003,"AG",Relationships!$M$4:$M$1003,"Confirmed",Relationships!$N$4:$N$1003,"OK — verify source")) | J10: =IF(A10="","",COUNTIFS(Relationships!$B$4:$B$1003,"AIR",Relationships!$C$4:$C$1003,A10,Relationships!$E$4:$E$1003,"TOOL",Relationships!$M$4:$M$1003,"Confirmed",Relationships!$N$4:$N$1003,"OK — verify source")) | K10: =IF(A10="","",COUNTIFS(Relationships!$G$4:$G$1003,A10,Relationships!$M$4:$M$1003,"Proposed")) | L10: =IF(A10="","",COUNTIFS(Relationships!$G$4:$G$1003,A10,Relationships!$A$4:$A$1003,"<>",Relationships!$N$4:$N$1003,"<>OK — verify source")) | O10: =IF(COUNTA(A10:D10,M10:N10)=0,"",IF(A10="","AIR-ID missing",IF(COUNTIF($A$4:$A$203,A10)>1,"Duplicate AIR-ID",IF(OR(B10="",C10="",D10=""),"Label / source / reconciled-on missing",IF(NOT(ISNUMBER(D10)),"Reconciled-on is not a date","OK — verify source")))))
E11: =IF(A11="","",COUNTIFS(Relationships!$B$4:$B$1003,"CAP",Relationships!$E$4:$E$1003,"AIR",Relationships!$F$4:$F$1003,A11,Relationships!$M$4:$M$1003,"Confirmed",Relationships!$N$4:$N$1003,"OK — verify source")) | F11: =IF(A11="","",COUNTIFS(Relationships!$B$4:$B$1003,"AIR",Relationships!$C$4:$C$1003,A11,Relationships!$E$4:$E$1003,"MOD",Relationships!$M$4:$M$1003,"Confirmed",Relationships!$N$4:$N$1003,"OK — verify source")) | G11: =IF(A11="","",COUNTIFS(Relationships!$B$4:$B$1003,"AIR",Relationships!$C$4:$C$1003,A11,Relationships!$E$4:$E$1003,"DATA",Relationships!$M$4:$M$1003,"Confirmed",Relationships!$N$4:$N$1003,"OK — verify source")) | H11: =IF(A11="","",COUNTIFS(Relationships!$B$4:$B$1003,"AIR",Relationships!$C$4:$C$1003,A11,Relationships!$E$4:$E$1003,"IF",Relationships!$M$4:$M$1003,"Confirmed",Relationships!$N$4:$N$1003,"OK — verify source")) | I11: =IF(A11="","",COUNTIFS(Relationships!$B$4:$B$1003,"AIR",Relationships!$C$4:$C$1003,A11,Relationships!$E$4:$E$1003,"AG",Relationships!$M$4:$M$1003,"Confirmed",Relationships!$N$4:$N$1003,"OK — verify source")) | J11: =IF(A11="","",COUNTIFS(Relationships!$B$4:$B$1003,"AIR",Relationships!$C$4:$C$1003,A11,Relationships!$E$4:$E$1003,"TOOL",Relationships!$M$4:$M$1003,"Confirmed",Relationships!$N$4:$N$1003,"OK — verify source")) | K11: =IF(A11="","",COUNTIFS(Relationships!$G$4:$G$1003,A11,Relationships!$M$4:$M$1003,"Proposed")) | L11: =IF(A11="","",COUNTIFS(Relationships!$G$4:$G$1003,A11,Relationships!$A$4:$A$1003,"<>",Relationships!$N$4:$N$1003,"<>OK — verify source")) | O11: =IF(COUNTA(A11:D11,M11:N11)=0,"",IF(A11="","AIR-ID missing",IF(COUNTIF($A$4:$A$203,A11)>1,"Duplicate AIR-ID",IF(OR(B11="",C11="",D11=""),"Label / source / reconciled-on missing",IF(NOT(ISNUMBER(D11)),"Reconciled-on is not a date","OK — verify source")))))
E12: =IF(A12="","",COUNTIFS(Relationships!$B$4:$B$1003,"CAP",Relationships!$E$4:$E$1003,"AIR",Relationships!$F$4:$F$1003,A12,Relationships!$M$4:$M$1003,"Confirmed",Relationships!$N$4:$N$1003,"OK — verify source")) | F12: =IF(A12="","",COUNTIFS(Relationships!$B$4:$B$1003,"AIR",Relationships!$C$4:$C$1003,A12,Relationships!$E$4:$E$1003,"MOD",Relationships!$M$4:$M$1003,"Confirmed",Relationships!$N$4:$N$1003,"OK — verify source")) | G12: =IF(A12="","",COUNTIFS(Relationships!$B$4:$B$1003,"AIR",Relationships!$C$4:$C$1003,A12,Relationships!$E$4:$E$1003,"DATA",Relationships!$M$4:$M$1003,"Confirmed",Relationships!$N$4:$N$1003,"OK — verify source")) | H12: =IF(A12="","",COUNTIFS(Relationships!$B$4:$B$1003,"AIR",Relationships!$C$4:$C$1003,A12,Relationships!$E$4:$E$1003,"IF",Relationships!$M$4:$M$1003,"Confirmed",Relationships!$N$4:$N$1003,"OK — verify source")) | I12: =IF(A12="","",COUNTIFS(Relationships!$B$4:$B$1003,"AIR",Relationships!$C$4:$C$1003,A12,Relationships!$E$4:$E$1003,"AG",Relationships!$M$4:$M$1003,"Confirmed",Relationships!$N$4:$N$1003,"OK — verify source")) | J12: =IF(A12="","",COUNTIFS(Relationships!$B$4:$B$1003,"AIR",Relationships!$C$4:$C$1003,A12,Relationships!$E$4:$E$1003,"TOOL",Relationships!$M$4:$M$1003,"Confirmed",Relationships!$N$4:$N$1003,"OK — verify source")) | K12: =IF(A12="","",COUNTIFS(Relationships!$G$4:$G$1003,A12,Relationships!$M$4:$M$1003,"Proposed")) | L12: =IF(A12="","",COUNTIFS(Relationships!$G$4:$G$1003,A12,Relationships!$A$4:$A$1003,"<>",Relationships!$N$4:$N$1003,"<>OK — verify source")) | O12: =IF(COUNTA(A12:D12,M12:N12)=0,"",IF(A12="","AIR-ID missing",IF(COUNTIF($A$4:$A$203,A12)>1,"Duplicate AIR-ID",IF(OR(B12="",C12="",D12=""),"Label / source / reconciled-on missing",IF(NOT(ISNUMBER(D12)),"Reconciled-on is not a date","OK — verify source")))))
E13: =IF(A13="","",COUNTIFS(Relationships!$B$4:$B$1003,"CAP",Relationships!$E$4:$E$1003,"AIR",Relationships!$F$4:$F$1003,A13,Relationships!$M$4:$M$1003,"Confirmed",Relationships!$N$4:$N$1003,"OK — verify source")) | F13: =IF(A13="","",COUNTIFS(Relationships!$B$4:$B$1003,"AIR",Relationships!$C$4:$C$1003,A13,Relationships!$E$4:$E$1003,"MOD",Relationships!$M$4:$M$1003,"Confirmed",Relationships!$N$4:$N$1003,"OK — verify source")) | G13: =IF(A13="","",COUNTIFS(Relationships!$B$4:$B$1003,"AIR",Relationships!$C$4:$C$1003,A13,Relationships!$E$4:$E$1003,"DATA",Relationships!$M$4:$M$1003,"Confirmed",Relationships!$N$4:$N$1003,"OK — verify source")) | H13: =IF(A13="","",COUNTIFS(Relationships!$B$4:$B$1003,"AIR",Relationships!$C$4:$C$1003,A13,Relationships!$E$4:$E$1003,"IF",Relationships!$M$4:$M$1003,"Confirmed",Relationships!$N$4:$N$1003,"OK — verify source")) | I13: =IF(A13="","",COUNTIFS(Relationships!$B$4:$B$1003,"AIR",Relationships!$C$4:$C$1003,A13,Relationships!$E$4:$E$1003,"AG",Relationships!$M$4:$M$1003,"Confirmed",Relationships!$N$4:$N$1003,"OK — verify source")) | J13: =IF(A13="","",COUNTIFS(Relationships!$B$4:$B$1003,"AIR",Relationships!$C$4:$C$1003,A13,Relationships!$E$4:$E$1003,"TOOL",Relationships!$M$4:$M$1003,"Confirmed",Relationships!$N$4:$N$1003,"OK — verify source")) | K13: =IF(A13="","",COUNTIFS(Relationships!$G$4:$G$1003,A13,Relationships!$M$4:$M$1003,"Proposed")) | L13: =IF(A13="","",COUNTIFS(Relationships!$G$4:$G$1003,A13,Relationships!$A$4:$A$1003,"<>",Relationships!$N$4:$N$1003,"<>OK — verify source")) | O13: =IF(COUNTA(A13:D13,M13:N13)=0,"",IF(A13="","AIR-ID missing",IF(COUNTIF($A$4:$A$203,A13)>1,"Duplicate AIR-ID",IF(OR(B13="",C13="",D13=""),"Label / source / reconciled-on missing",IF(NOT(ISNUMBER(D13)),"Reconciled-on is not a date","OK — verify source")))))
E14: =IF(A14="","",COUNTIFS(Relationships!$B$4:$B$1003,"CAP",Relationships!$E$4:$E$1003,"AIR",Relationships!$F$4:$F$1003,A14,Relationships!$M$4:$M$1003,"Confirmed",Relationships!$N$4:$N$1003,"OK — verify source")) | F14: =IF(A14="","",COUNTIFS(Relationships!$B$4:$B$1003,"AIR",Relationships!$C$4:$C$1003,A14,Relationships!$E$4:$E$1003,"MOD",Relationships!$M$4:$M$1003,"Confirmed",Relationships!$N$4:$N$1003,"OK — verify source")) | G14: =IF(A14="","",COUNTIFS(Relationships!$B$4:$B$1003,"AIR",Relationships!$C$4:$C$1003,A14,Relationships!$E$4:$E$1003,"DATA",Relationships!$M$4:$M$1003,"Confirmed",Relationships!$N$4:$N$1003,"OK — verify source")) | H14: =IF(A14="","",COUNTIFS(Relationships!$B$4:$B$1003,"AIR",Relationships!$C$4:$C$1003,A14,Relationships!$E$4:$E$1003,"IF",Relationships!$M$4:$M$1003,"Confirmed",Relationships!$N$4:$N$1003,"OK — verify source")) | I14: =IF(A14="","",COUNTIFS(Relationships!$B$4:$B$1003,"AIR",Relationships!$C$4:$C$1003,A14,Relationships!$E$4:$E$1003,"AG",Relationships!$M$4:$M$1003,"Confirmed",Relationships!$N$4:$N$1003,"OK — verify source")) | J14: =IF(A14="","",COUNTIFS(Relationships!$B$4:$B$1003,"AIR",Relationships!$C$4:$C$1003,A14,Relationships!$E$4:$E$1003,"TOOL",Relationships!$M$4:$M$1003,"Confirmed",Relationships!$N$4:$N$1003,"OK — verify source")) | K14: =IF(A14="","",COUNTIFS(Relationships!$G$4:$G$1003,A14,Relationships!$M$4:$M$1003,"Proposed")) | L14: =IF(A14="","",COUNTIFS(Relationships!$G$4:$G$1003,A14,Relationships!$A$4:$A$1003,"<>",Relationships!$N$4:$N$1003,"<>OK — verify source")) | O14: =IF(COUNTA(A14:D14,M14:N14)=0,"",IF(A14="","AIR-ID missing",IF(COUNTIF($A$4:$A$203,A14)>1,"Duplicate AIR-ID",IF(OR(B14="",C14="",D14=""),"Label / source / reconciled-on missing",IF(NOT(ISNUMBER(D14)),"Reconciled-on is not a date","OK — verify source")))))
E15: =IF(A15="","",COUNTIFS(Relationships!$B$4:$B$1003,"CAP",Relationships!$E$4:$E$1003,"AIR",Relationships!$F$4:$F$1003,A15,Relationships!$M$4:$M$1003,"Confirmed",Relationships!$N$4:$N$1003,"OK — verify source")) | F15: =IF(A15="","",COUNTIFS(Relationships!$B$4:$B$1003,"AIR",Relationships!$C$4:$C$1003,A15,Relationships!$E$4:$E$1003,"MOD",Relationships!$M$4:$M$1003,"Confirmed",Relationships!$N$4:$N$1003,"OK — verify source")) | G15: =IF(A15="","",COUNTIFS(Relationships!$B$4:$B$1003,"AIR",Relationships!$C$4:$C$1003,A15,Relationships!$E$4:$E$1003,"DATA",Relationships!$M$4:$M$1003,"Confirmed",Relationships!$N$4:$N$1003,"OK — verify source")) | H15: =IF(A15="","",COUNTIFS(Relationships!$B$4:$B$1003,"AIR",Relationships!$C$4:$C$1003,A15,Relationships!$E$4:$E$1003,"IF",Relationships!$M$4:$M$1003,"Confirmed",Relationships!$N$4:$N$1003,"OK — verify source")) | I15: =IF(A15="","",COUNTIFS(Relationships!$B$4:$B$1003,"AIR",Relationships!$C$4:$C$1003,A15,Relationships!$E$4:$E$1003,"AG",Relationships!$M$4:$M$1003,"Confirmed",Relationships!$N$4:$N$1003,"OK — verify source")) | J15: =IF(A15="","",COUNTIFS(Relationships!$B$4:$B$1003,"AIR",Relationships!$C$4:$C$1003,A15,Relationships!$E$4:$E$1003,"TOOL",Relationships!$M$4:$M$1003,"Confirmed",Relationships!$N$4:$N$1003,"OK — verify source")) | K15: =IF(A15="","",COUNTIFS(Relationships!$G$4:$G$1003,A15,Relationships!$M$4:$M$1003,"Proposed")) | L15: =IF(A15="","",COUNTIFS(Relationships!$G$4:$G$1003,A15,Relationships!$A$4:$A$1003,"<>",Relationships!$N$4:$N$1003,"<>OK — verify source")) | O15: =IF(COUNTA(A15:D15,M15:N15)=0,"",IF(A15="","AIR-ID missing",IF(COUNTIF($A$4:$A$203,A15)>1,"Duplicate AIR-ID",IF(OR(B15="",C15="",D15=""),"Label / source / reconciled-on missing",IF(NOT(ISNUMBER(D15)),"Reconciled-on is not a date","OK — verify source")))))
... E203: =IF(A203="","",COUNTIFS(Relationships!$B$4:$B$1003,"CAP",Relationships!$E$4:$E$1003,"AIR",Relationships!$F$4:$F$1003,A203,Relationships!$M$4:$M$1003,"Confirmed",Relationships!$N$4:$N$1003,"OK — verify source")) | F203: =IF(A203="","",COUNTIFS(Relationships!$B$4:$B$1003,"AIR",Relationships!$C$4:$C$1003,A203,Relationships!$E$4:$E$1003,"MOD",Relationships!$M$4:$M$1003,"Confirmed",Relationships!$N$4:$N$1003,"OK — verify source")) | G203: =IF(A203="","",COUNTIFS(Relationships!$B$4:$B$1003,"AIR",Relationships!$C$4:$C$1003,A203,Relationships!$E$4:$E$1003,"DATA",Relationships!$M$4:$M$1003,"Confirmed",Relationships!$N$4:$N$1003,"OK — verify source")) | H203: =IF(A203="","",COUNTIFS(Relationships!$B$4:$B$1003,"AIR",Relationships!$C$4:$C$1003,A203,Relationships!$E$4:$E$1003,"IF",Relationships!$M$4:$M$1003,"Confirmed",Relationships!$N$4:$N$1003,"OK — verify source")) | I203: =IF(A203="","",COUNTIFS(Relationships!$B$4:$B$1003,"AIR",Relationships!$C$4:$C$1003,A203,Relationships!$E$4:$E$1003,"AG",Relationships!$M$4:$M$1003,"Confirmed",Relationships!$N$4:$N$1003,"OK — verify source")) | J203: =IF(A203="","",COUNTIFS(Relationships!$B$4:$B$1003,"AIR",Relationships!$C$4:$C$1003,A203,Relationships!$E$4:$E$1003,"TOOL",Relationships!$M$4:$M$1003,"Confirmed",Relationships!$N$4:$N$1003,"OK — verify source")) | K203: =IF(A203="","",COUNTIFS(Relationships!$G$4:$G$1003,A203,Relationships!$M$4:$M$1003,"Proposed")) | L203: =IF(A203="","",COUNTIFS(Relationships!$G$4:$G$1003,A203,Relationships!$A$4:$A$1003,"<>",Relationships!$N$4:$N$1003,"<>OK — verify source")) | O203: =IF(COUNTA(A203:D203,M203:N203)=0,"",IF(A203="","AIR-ID missing",IF(COUNTIF($A$4:$A$203,A203)>1,"Duplicate AIR-ID",IF(OR(B203="",C203="",D203=""),"Label / source / reconciled-on missing",IF(NOT(ISNUMBER(D203)),"Reconciled-on is not a date","OK — verify source")))))

Sheet Use cases
A1: OUTCOME-LED USE CASES
A2: Use AIG-INV-03 as intake source; keep one distinct outcome/workflow per stable UC-ID linked to one system AIR-ID when issued. Decision and monitoring fields are source pointers only; this map never grants approval.
A3: UC-ID | B3: Outcome-led use case | C3: Service / workflow | D3: Service Owner | E3: Canonical AIG-INV-03 / source ref | F3: AIR-ID (only if issued) | G3: Confidence | H3: Verified on | I3: State | J3: Row check | K3: Use-specific decision / minutes ref (pointer only) | L3: UC-specific monitoring ref (pointer only) | M3: Index role (descriptive; not approval)
J4: =IF(COUNTA(A4:I4)=0,"",IF(A4="","UC-ID missing",IF(COUNTIF($A$4:$A$253,A4)>1,"Duplicate UC-ID",IF(OR(B4="",D4="",E4=""),"Use/owner/source missing",IF(AND(F4<>"",COUNTIF('System map'!$A$4:$A$203,F4)<>1),"AIR-ID not reconciled in map",IF(AND(I4="Confirmed",OR(H4="",NOT(ISNUMBER(H4)),G4="",G4="Unknown",G4="Low")),"Confirmed use lacks verification",IF(AND(I4="Confirmed",H4>TODAY()),"Verified-on date is in the future","OK — verify source")))))))
J5: =IF(COUNTA(A5:I5)=0,"",IF(A5="","UC-ID missing",IF(COUNTIF($A$4:$A$253,A5)>1,"Duplicate UC-ID",IF(OR(B5="",D5="",E5=""),"Use/owner/source missing",IF(AND(F5<>"",COUNTIF('System map'!$A$4:$A$203,F5)<>1),"AIR-ID not reconciled in map",IF(AND(I5="Confirmed",OR(H5="",NOT(ISNUMBER(H5)),G5="",G5="Unknown",G5="Low")),"Confirmed use lacks verification",IF(AND(I5="Confirmed",H5>TODAY()),"Verified-on date is in the future","OK — verify source")))))))
J6: =IF(COUNTA(A6:I6)=0,"",IF(A6="","UC-ID missing",IF(COUNTIF($A$4:$A$253,A6)>1,"Duplicate UC-ID",IF(OR(B6="",D6="",E6=""),"Use/owner/source missing",IF(AND(F6<>"",COUNTIF('System map'!$A$4:$A$203,F6)<>1),"AIR-ID not reconciled in map",IF(AND(I6="Confirmed",OR(H6="",NOT(ISNUMBER(H6)),G6="",G6="Unknown",G6="Low")),"Confirmed use lacks verification",IF(AND(I6="Confirmed",H6>TODAY()),"Verified-on date is in the future","OK — verify source")))))))
J7: =IF(COUNTA(A7:I7)=0,"",IF(A7="","UC-ID missing",IF(COUNTIF($A$4:$A$253,A7)>1,"Duplicate UC-ID",IF(OR(B7="",D7="",E7=""),"Use/owner/source missing",IF(AND(F7<>"",COUNTIF('System map'!$A$4:$A$203,F7)<>1),"AIR-ID not reconciled in map",IF(AND(I7="Confirmed",OR(H7="",NOT(ISNUMBER(H7)),G7="",G7="Unknown",G7="Low")),"Confirmed use lacks verification",IF(AND(I7="Confirmed",H7>TODAY()),"Verified-on date is in the future","OK — verify source")))))))
J8: =IF(COUNTA(A8:I8)=0,"",IF(A8="","UC-ID missing",IF(COUNTIF($A$4:$A$253,A8)>1,"Duplicate UC-ID",IF(OR(B8="",D8="",E8=""),"Use/owner/source missing",IF(AND(F8<>"",COUNTIF('System map'!$A$4:$A$203,F8)<>1),"AIR-ID not reconciled in map",IF(AND(I8="Confirmed",OR(H8="",NOT(ISNUMBER(H8)),G8="",G8="Unknown",G8="Low")),"Confirmed use lacks verification",IF(AND(I8="Confirmed",H8>TODAY()),"Verified-on date is in the future","OK — verify source")))))))
J9: =IF(COUNTA(A9:I9)=0,"",IF(A9="","UC-ID missing",IF(COUNTIF($A$4:$A$253,A9)>1,"Duplicate UC-ID",IF(OR(B9="",D9="",E9=""),"Use/owner/source missing",IF(AND(F9<>"",COUNTIF('System map'!$A$4:$A$203,F9)<>1),"AIR-ID not reconciled in map",IF(AND(I9="Confirmed",OR(H9="",NOT(ISNUMBER(H9)),G9="",G9="Unknown",G9="Low")),"Confirmed use lacks verification",IF(AND(I9="Confirmed",H9>TODAY()),"Verified-on date is in the future","OK — verify source")))))))
J10: =IF(COUNTA(A10:I10)=0,"",IF(A10="","UC-ID missing",IF(COUNTIF($A$4:$A$253,A10)>1,"Duplicate UC-ID",IF(OR(B10="",D10="",E10=""),"Use/owner/source missing",IF(AND(F10<>"",COUNTIF('System map'!$A$4:$A$203,F10)<>1),"AIR-ID not reconciled in map",IF(AND(I10="Confirmed",OR(H10="",NOT(ISNUMBER(H10)),G10="",G10="Unknown",G10="Low")),"Confirmed use lacks verification",IF(AND(I10="Confirmed",H10>TODAY()),"Verified-on date is in the future","OK — verify source")))))))
J11: =IF(COUNTA(A11:I11)=0,"",IF(A11="","UC-ID missing",IF(COUNTIF($A$4:$A$253,A11)>1,"Duplicate UC-ID",IF(OR(B11="",D11="",E11=""),"Use/owner/source missing",IF(AND(F11<>"",COUNTIF('System map'!$A$4:$A$203,F11)<>1),"AIR-ID not reconciled in map",IF(AND(I11="Confirmed",OR(H11="",NOT(ISNUMBER(H11)),G11="",G11="Unknown",G11="Low")),"Confirmed use lacks verification",IF(AND(I11="Confirmed",H11>TODAY()),"Verified-on date is in the future","OK — verify source")))))))
J12: =IF(COUNTA(A12:I12)=0,"",IF(A12="","UC-ID missing",IF(COUNTIF($A$4:$A$253,A12)>1,"Duplicate UC-ID",IF(OR(B12="",D12="",E12=""),"Use/owner/source missing",IF(AND(F12<>"",COUNTIF('System map'!$A$4:$A$203,F12)<>1),"AIR-ID not reconciled in map",IF(AND(I12="Confirmed",OR(H12="",NOT(ISNUMBER(H12)),G12="",G12="Unknown",G12="Low")),"Confirmed use lacks verification",IF(AND(I12="Confirmed",H12>TODAY()),"Verified-on date is in the future","OK — verify source")))))))
J13: =IF(COUNTA(A13:I13)=0,"",IF(A13="","UC-ID missing",IF(COUNTIF($A$4:$A$253,A13)>1,"Duplicate UC-ID",IF(OR(B13="",D13="",E13=""),"Use/owner/source missing",IF(AND(F13<>"",COUNTIF('System map'!$A$4:$A$203,F13)<>1),"AIR-ID not reconciled in map",IF(AND(I13="Confirmed",OR(H13="",NOT(ISNUMBER(H13)),G13="",G13="Unknown",G13="Low")),"Confirmed use lacks verification",IF(AND(I13="Confirmed",H13>TODAY()),"Verified-on date is in the future","OK — verify source")))))))
J14: =IF(COUNTA(A14:I14)=0,"",IF(A14="","UC-ID missing",IF(COUNTIF($A$4:$A$253,A14)>1,"Duplicate UC-ID",IF(OR(B14="",D14="",E14=""),"Use/owner/source missing",IF(AND(F14<>"",COUNTIF('System map'!$A$4:$A$203,F14)<>1),"AIR-ID not reconciled in map",IF(AND(I14="Confirmed",OR(H14="",NOT(ISNUMBER(H14)),G14="",G14="Unknown",G14="Low")),"Confirmed use lacks verification",IF(AND(I14="Confirmed",H14>TODAY()),"Verified-on date is in the future","OK — verify source")))))))
J15: =IF(COUNTA(A15:I15)=0,"",IF(A15="","UC-ID missing",IF(COUNTIF($A$4:$A$253,A15)>1,"Duplicate UC-ID",IF(OR(B15="",D15="",E15=""),"Use/owner/source missing",IF(AND(F15<>"",COUNTIF('System map'!$A$4:$A$203,F15)<>1),"AIR-ID not reconciled in map",IF(AND(I15="Confirmed",OR(H15="",NOT(ISNUMBER(H15)),G15="",G15="Unknown",G15="Low")),"Confirmed use lacks verification",IF(AND(I15="Confirmed",H15>TODAY()),"Verified-on date is in the future","OK — verify source")))))))
... J253: =IF(COUNTA(A253:I253)=0,"",IF(A253="","UC-ID missing",IF(COUNTIF($A$4:$A$253,A253)>1,"Duplicate UC-ID",IF(OR(B253="",D253="",E253=""),"Use/owner/source missing",IF(AND(F253<>"",COUNTIF('System map'!$A$4:$A$203,F253)<>1),"AIR-ID not reconciled in map",IF(AND(I253="Confirmed",OR(H253="",NOT(ISNUMBER(H253)),G253="",G253="Unknown",G253="Low")),"Confirmed use lacks verification",IF(AND(I253="Confirmed",H253>TODAY()),"Verified-on date is in the future","OK — verify source")))))))

Sheet Capabilities
A1: ATOMIC REUSABLE CAPABILITIES
A2: Describe a function as a verb + noun, not as a vendor product, AI agent permission or project title. Reuse an existing canonical capability catalogue if agreed.
A3: CAP-ID | B3: Function (verb + noun) | C3: Inputs | D3: Outputs | E3: Boundary / excluded use | F3: Capability owner | G3: Definition source ref | H3: Confidence | I3: Verified on | J3: State | K3: Row check
K4: =IF(COUNTA(A4:J4)=0,"",IF(A4="","CAP-ID missing",IF(COUNTIF($A$4:$A$253,A4)>1,"Duplicate CAP-ID",IF(OR(B4="",C4="",D4="",E4="",F4="",G4=""),"Definition / owner / source missing",IF(AND(J4="Confirmed",OR(I4="",H4="",H4="Unknown",H4="Low")),"Confirmed capability lacks verification","OK — verify source")))))
K5: =IF(COUNTA(A5:J5)=0,"",IF(A5="","CAP-ID missing",IF(COUNTIF($A$4:$A$253,A5)>1,"Duplicate CAP-ID",IF(OR(B5="",C5="",D5="",E5="",F5="",G5=""),"Definition / owner / source missing",IF(AND(J5="Confirmed",OR(I5="",H5="",H5="Unknown",H5="Low")),"Confirmed capability lacks verification","OK — verify source")))))
K6: =IF(COUNTA(A6:J6)=0,"",IF(A6="","CAP-ID missing",IF(COUNTIF($A$4:$A$253,A6)>1,"Duplicate CAP-ID",IF(OR(B6="",C6="",D6="",E6="",F6="",G6=""),"Definition / owner / source missing",IF(AND(J6="Confirmed",OR(I6="",H6="",H6="Unknown",H6="Low")),"Confirmed capability lacks verification","OK — verify source")))))
K7: =IF(COUNTA(A7:J7)=0,"",IF(A7="","CAP-ID missing",IF(COUNTIF($A$4:$A$253,A7)>1,"Duplicate CAP-ID",IF(OR(B7="",C7="",D7="",E7="",F7="",G7=""),"Definition / owner / source missing",IF(AND(J7="Confirmed",OR(I7="",H7="",H7="Unknown",H7="Low")),"Confirmed capability lacks verification","OK — verify source")))))
K8: =IF(COUNTA(A8:J8)=0,"",IF(A8="","CAP-ID missing",IF(COUNTIF($A$4:$A$253,A8)>1,"Duplicate CAP-ID",IF(OR(B8="",C8="",D8="",E8="",F8="",G8=""),"Definition / owner / source missing",IF(AND(J8="Confirmed",OR(I8="",H8="",H8="Unknown",H8="Low")),"Confirmed capability lacks verification","OK — verify source")))))
K9: =IF(COUNTA(A9:J9)=0,"",IF(A9="","CAP-ID missing",IF(COUNTIF($A$4:$A$253,A9)>1,"Duplicate CAP-ID",IF(OR(B9="",C9="",D9="",E9="",F9="",G9=""),"Definition / owner / source missing",IF(AND(J9="Confirmed",OR(I9="",H9="",H9="Unknown",H9="Low")),"Confirmed capability lacks verification","OK — verify source")))))
K10: =IF(COUNTA(A10:J10)=0,"",IF(A10="","CAP-ID missing",IF(COUNTIF($A$4:$A$253,A10)>1,"Duplicate CAP-ID",IF(OR(B10="",C10="",D10="",E10="",F10="",G10=""),"Definition / owner / source missing",IF(AND(J10="Confirmed",OR(I10="",H10="",H10="Unknown",H10="Low")),"Confirmed capability lacks verification","OK — verify source")))))
K11: =IF(COUNTA(A11:J11)=0,"",IF(A11="","CAP-ID missing",IF(COUNTIF($A$4:$A$253,A11)>1,"Duplicate CAP-ID",IF(OR(B11="",C11="",D11="",E11="",F11="",G11=""),"Definition / owner / source missing",IF(AND(J11="Confirmed",OR(I11="",H11="",H11="Unknown",H11="Low")),"Confirmed capability lacks verification","OK — verify source")))))
K12: =IF(COUNTA(A12:J12)=0,"",IF(A12="","CAP-ID missing",IF(COUNTIF($A$4:$A$253,A12)>1,"Duplicate CAP-ID",IF(OR(B12="",C12="",D12="",E12="",F12="",G12=""),"Definition / owner / source missing",IF(AND(J12="Confirmed",OR(I12="",H12="",H12="Unknown",H12="Low")),"Confirmed capability lacks verification","OK — verify source")))))
K13: =IF(COUNTA(A13:J13)=0,"",IF(A13="","CAP-ID missing",IF(COUNTIF($A$4:$A$253,A13)>1,"Duplicate CAP-ID",IF(OR(B13="",C13="",D13="",E13="",F13="",G13=""),"Definition / owner / source missing",IF(AND(J13="Confirmed",OR(I13="",H13="",H13="Unknown",H13="Low")),"Confirmed capability lacks verification","OK — verify source")))))
K14: =IF(COUNTA(A14:J14)=0,"",IF(A14="","CAP-ID missing",IF(COUNTIF($A$4:$A$253,A14)>1,"Duplicate CAP-ID",IF(OR(B14="",C14="",D14="",E14="",F14="",G14=""),"Definition / owner / source missing",IF(AND(J14="Confirmed",OR(I14="",H14="",H14="Unknown",H14="Low")),"Confirmed capability lacks verification","OK — verify source")))))
K15: =IF(COUNTA(A15:J15)=0,"",IF(A15="","CAP-ID missing",IF(COUNTIF($A$4:$A$253,A15)>1,"Duplicate CAP-ID",IF(OR(B15="",C15="",D15="",E15="",F15="",G15=""),"Definition / owner / source missing",IF(AND(J15="Confirmed",OR(I15="",H15="",H15="Unknown",H15="Low")),"Confirmed capability lacks verification","OK — verify source")))))
... K253: =IF(COUNTA(A253:J253)=0,"",IF(A253="","CAP-ID missing",IF(COUNTIF($A$4:$A$253,A253)>1,"Duplicate CAP-ID",IF(OR(B253="",C253="",D253="",E253="",F253="",G253=""),"Definition / owner / source missing",IF(AND(J253="Confirmed",OR(I253="",H253="",H253="Unknown",H253="Low")),"Confirmed capability lacks verification","OK — verify source")))))

Sheet Components
A1: COMPONENT REFERENCES / NOT CONTROL COPIES
A2: One version-specific pointer per model, data asset, interface, agent or tool. AIG-ASS-09/AIG-AGT-04/AIG-AGT-05, catalogue and specialist sources remain authoritative; no permission is granted here.
A3: Reference ID | B3: Type | C3: Name / short label | D3: Version / config | E3: Canonical source artefact | F3: Exact source row / URI | G3: Owning AIR-ID (if any) | H3: Source owner | I3: Confidence | J3: Verified on | K3: State | L3: Row check
L4: =IF(COUNTA(A4:K4)=0,"",IF(A4="","Reference ID missing",IF(COUNTIF($A$4:$A$253,A4)>1,"Duplicate reference ID",IF(OR(B4="",C4="",E4="",F4="",H4=""),"Type / source / owner missing",IF(AND(G4<>"",COUNTIF('System map'!$A$4:$A$203,G4)<>1),"Owning AIR-ID not reconciled",IF(AND(K4="Confirmed",OR(J4="",I4="",I4="Unknown",I4="Low")),"Confirmed reference lacks verification","OK — verify source"))))))
L5: =IF(COUNTA(A5:K5)=0,"",IF(A5="","Reference ID missing",IF(COUNTIF($A$4:$A$253,A5)>1,"Duplicate reference ID",IF(OR(B5="",C5="",E5="",F5="",H5=""),"Type / source / owner missing",IF(AND(G5<>"",COUNTIF('System map'!$A$4:$A$203,G5)<>1),"Owning AIR-ID not reconciled",IF(AND(K5="Confirmed",OR(J5="",I5="",I5="Unknown",I5="Low")),"Confirmed reference lacks verification","OK — verify source"))))))
L6: =IF(COUNTA(A6:K6)=0,"",IF(A6="","Reference ID missing",IF(COUNTIF($A$4:$A$253,A6)>1,"Duplicate reference ID",IF(OR(B6="",C6="",E6="",F6="",H6=""),"Type / source / owner missing",IF(AND(G6<>"",COUNTIF('System map'!$A$4:$A$203,G6)<>1),"Owning AIR-ID not reconciled",IF(AND(K6="Confirmed",OR(J6="",I6="",I6="Unknown",I6="Low")),"Confirmed reference lacks verification","OK — verify source"))))))
L7: =IF(COUNTA(A7:K7)=0,"",IF(A7="","Reference ID missing",IF(COUNTIF($A$4:$A$253,A7)>1,"Duplicate reference ID",IF(OR(B7="",C7="",E7="",F7="",H7=""),"Type / source / owner missing",IF(AND(G7<>"",COUNTIF('System map'!$A$4:$A$203,G7)<>1),"Owning AIR-ID not reconciled",IF(AND(K7="Confirmed",OR(J7="",I7="",I7="Unknown",I7="Low")),"Confirmed reference lacks verification","OK — verify source"))))))
L8: =IF(COUNTA(A8:K8)=0,"",IF(A8="","Reference ID missing",IF(COUNTIF($A$4:$A$253,A8)>1,"Duplicate reference ID",IF(OR(B8="",C8="",E8="",F8="",H8=""),"Type / source / owner missing",IF(AND(G8<>"",COUNTIF('System map'!$A$4:$A$203,G8)<>1),"Owning AIR-ID not reconciled",IF(AND(K8="Confirmed",OR(J8="",I8="",I8="Unknown",I8="Low")),"Confirmed reference lacks verification","OK — verify source"))))))
L9: =IF(COUNTA(A9:K9)=0,"",IF(A9="","Reference ID missing",IF(COUNTIF($A$4:$A$253,A9)>1,"Duplicate reference ID",IF(OR(B9="",C9="",E9="",F9="",H9=""),"Type / source / owner missing",IF(AND(G9<>"",COUNTIF('System map'!$A$4:$A$203,G9)<>1),"Owning AIR-ID not reconciled",IF(AND(K9="Confirmed",OR(J9="",I9="",I9="Unknown",I9="Low")),"Confirmed reference lacks verification","OK — verify source"))))))
L10: =IF(COUNTA(A10:K10)=0,"",IF(A10="","Reference ID missing",IF(COUNTIF($A$4:$A$253,A10)>1,"Duplicate reference ID",IF(OR(B10="",C10="",E10="",F10="",H10=""),"Type / source / owner missing",IF(AND(G10<>"",COUNTIF('System map'!$A$4:$A$203,G10)<>1),"Owning AIR-ID not reconciled",IF(AND(K10="Confirmed",OR(J10="",I10="",I10="Unknown",I10="Low")),"Confirmed reference lacks verification","OK — verify source"))))))
L11: =IF(COUNTA(A11:K11)=0,"",IF(A11="","Reference ID missing",IF(COUNTIF($A$4:$A$253,A11)>1,"Duplicate reference ID",IF(OR(B11="",C11="",E11="",F11="",H11=""),"Type / source / owner missing",IF(AND(G11<>"",COUNTIF('System map'!$A$4:$A$203,G11)<>1),"Owning AIR-ID not reconciled",IF(AND(K11="Confirmed",OR(J11="",I11="",I11="Unknown",I11="Low")),"Confirmed reference lacks verification","OK — verify source"))))))
L12: =IF(COUNTA(A12:K12)=0,"",IF(A12="","Reference ID missing",IF(COUNTIF($A$4:$A$253,A12)>1,"Duplicate reference ID",IF(OR(B12="",C12="",E12="",F12="",H12=""),"Type / source / owner missing",IF(AND(G12<>"",COUNTIF('System map'!$A$4:$A$203,G12)<>1),"Owning AIR-ID not reconciled",IF(AND(K12="Confirmed",OR(J12="",I12="",I12="Unknown",I12="Low")),"Confirmed reference lacks verification","OK — verify source"))))))
L13: =IF(COUNTA(A13:K13)=0,"",IF(A13="","Reference ID missing",IF(COUNTIF($A$4:$A$253,A13)>1,"Duplicate reference ID",IF(OR(B13="",C13="",E13="",F13="",H13=""),"Type / source / owner missing",IF(AND(G13<>"",COUNTIF('System map'!$A$4:$A$203,G13)<>1),"Owning AIR-ID not reconciled",IF(AND(K13="Confirmed",OR(J13="",I13="",I13="Unknown",I13="Low")),"Confirmed reference lacks verification","OK — verify source"))))))
L14: =IF(COUNTA(A14:K14)=0,"",IF(A14="","Reference ID missing",IF(COUNTIF($A$4:$A$253,A14)>1,"Duplicate reference ID",IF(OR(B14="",C14="",E14="",F14="",H14=""),"Type / source / owner missing",IF(AND(G14<>"",COUNTIF('System map'!$A$4:$A$203,G14)<>1),"Owning AIR-ID not reconciled",IF(AND(K14="Confirmed",OR(J14="",I14="",I14="Unknown",I14="Low")),"Confirmed reference lacks verification","OK — verify source"))))))
L15: =IF(COUNTA(A15:K15)=0,"",IF(A15="","Reference ID missing",IF(COUNTIF($A$4:$A$253,A15)>1,"Duplicate reference ID",IF(OR(B15="",C15="",E15="",F15="",H15=""),"Type / source / owner missing",IF(AND(G15<>"",COUNTIF('System map'!$A$4:$A$203,G15)<>1),"Owning AIR-ID not reconciled",IF(AND(K15="Confirmed",OR(J15="",I15="",I15="Unknown",I15="Low")),"Confirmed reference lacks verification","OK — verify source"))))))
... L253: =IF(COUNTA(A253:K253)=0,"",IF(A253="","Reference ID missing",IF(COUNTIF($A$4:$A$253,A253)>1,"Duplicate reference ID",IF(OR(B253="",C253="",E253="",F253="",H253=""),"Type / source / owner missing",IF(AND(G253<>"",COUNTIF('System map'!$A$4:$A$203,G253)<>1),"Owning AIR-ID not reconciled",IF(AND(K253="Confirmed",OR(J253="",I253="",I253="Unknown",I253="Low")),"Confirmed reference lacks verification","OK — verify source"))))))

Sheet Relationships
A1: EVIDENCED RELATIONSHIPS / EDGES
A2: UC → CAP may be staged without AIR-ID. Other edges need official AIR context. Confirmed links require owner, source, confidence and verification date; links do not confer permissions. Superseded rows are kept as history and excluded from duplicate tests; an AIR → component edge must match the component's owning AIR-ID.
A3: Map Edge ID | B3: From type | C3: From ID | D3: Relationship | E3: To type | F3: To ID | G3: AIR context | H3: Meaning / data or action flow | I3: Link owner | J3: Evidence / source ref | K3: Confidence | L3: Verified on | M3: State | N3: Link check
N4: =IF(COUNTA(A4:M4)=0,"",IF(OR(A4="",B4="",C4="",D4="",E4="",F4="",I4="",J4="",K4="",M4=""),"Required link detail missing",IF(COUNTIF($A$4:$A$1003,A4)>1,"Duplicate Map Edge ID",IF(NOT(OR(AND(B4="UC",E4="CAP",D4="requires"),AND(B4="CAP",E4="AIR",D4="provided by"),AND(B4="AIR",OR(E4="MOD",E4="DATA",E4="IF",E4="AG",E4="TOOL"),D4="references"),AND(B4="AIR",E4="AIR",D4="depends on"))),"Invalid relationship",IF(AND(M4<>"Superseded",COUNTIFS($B$4:$B$1003,B4,$C$4:$C$1003,C4,$D$4:$D$1003,D4,$E$4:$E$1003,E4,$F$4:$F$1003,F4,$G$4:$G$1003,G4,$M$4:$M$1003,"<>Superseded")>1),"Duplicate relationship",IF(OR(IF(B4="UC",COUNTIF('Use cases'!$A$4:$A$253,C4),IF(B4="CAP",COUNTIF(Capabilities!$A$4:$A$253,C4),IF(B4="AIR",COUNTIF('System map'!$A$4:$A$203,C4),COUNTIFS(Components!$A$4:$A$253,C4,Components!$B$4:$B$253,B4))))<>1,IF(E4="UC",COUNTIF('Use cases'!$A$4:$A$253,F4),IF(E4="CAP",COUNTIF(Capabilities!$A$4:$A$253,F4),IF(E4="AIR",COUNTIF('System map'!$A$4:$A$203,F4),COUNTIFS(Components!$A$4:$A$253,F4,Components!$B$4:$B$253,E4))))<>1),"Endpoint missing or duplicated",IF(AND(NOT(AND(B4="UC",E4="CAP")),OR(G4="",COUNTIF('System map'!$A$4:$A$203,G4)<>1)),"AIR context missing / unknown",IF(AND(B4="CAP",E4="AIR",G4<>F4),"AIR context mismatch",IF(AND(B4="AIR",G4<>C4),"AIR context mismatch",IF(AND(B4="AIR",E4="AIR",C4=F4),"Self-dependency",IF(AND(B4="AIR",E4="AIR",M4<>"Superseded",COUNTIFS($B$4:$B$1003,"AIR",$C$4:$C$1003,F4,$E$4:$E$1003,"AIR",$F$4:$F$1003,C4,$M$4:$M$1003,"<>Superseded")>0),"Dependency cycle (A↔B) — review",IF(AND(B4="AIR",OR(E4="MOD",E4="DATA",E4="IF",E4="AG",E4="TOOL"),IFERROR(INDEX(Components!$G$4:$G$253,MATCH(F4,Components!$A$4:$A$253,0)),"")<>"",IFERROR(INDEX(Components!$G$4:$G$253,MATCH(F4,Components!$A$4:$A$253,0)),"")<>C4),"Component owned by another AIR-ID",IF(AND(M4="Confirmed",OR(IF(B4="UC",COUNTIFS('Use cases'!$A$4:$A$253,C4,'Use cases'!$I$4:$I$253,"Confirmed",'Use cases'!$J$4:$J$253,"OK — verify source"),IF(B4="CAP",COUNTIFS(Capabilities!$A$4:$A$253,C4,Capabilities!$J$4:$J$253,"Confirmed",Capabilities!$K$4:$K$253,"OK — verify source"),IF(B4="AIR",COUNTIFS('System map'!$A$4:$A$203,C4,'System map'!$B$4:$B$203,"<>",'System map'!$C$4:$C$203,"<>",'System map'!$D$4:$D$203,"<>"),COUNTIFS(Components!$A$4:$A$253,C4,Components!$B$4:$B$253,B4,Components!$K$4:$K$253,"Confirmed",Components!$L$4:$L$253,"OK — verify source"))))<>1,IF(E4="UC",COUNTIFS('Use cases'!$A$4:$A$253,F4,'Use cases'!$I$4:$I$253,"Confirmed",'Use cases'!$J$4:$J$253,"OK — verify source"),IF(E4="CAP",COUNTIFS(Capabilities!$A$4:$A$253,F4,Capabilities!$J$4:$J$253,"Confirmed",Capabilities!$K$4:$K$253,"OK — verify source"),IF(E4="AIR",COUNTIFS('System map'!$A$4:$A$203,F4,'System map'!$B$4:$B$203,"<>",'System map'!$C$4:$C$203,"<>",'System map'!$D$4:$D$203,"<>"),COUNTIFS(Components!$A$4:$A$253,F4,Components!$B$4:$B$253,E4,Components!$K$4:$K$253,"Confirmed",Components!$L$4:$L$253,"OK — verify source"))))<>1)),"Endpoint not source-reconciled",IF(AND(M4="Confirmed",OR(L4="",K4="",K4="Unknown",K4="Low")),"Confirmed link lacks verification","OK — verify source"))))))))))))))
N5: =IF(COUNTA(A5:M5)=0,"",IF(OR(A5="",B5="",C5="",D5="",E5="",F5="",I5="",J5="",K5="",M5=""),"Required link detail missing",IF(COUNTIF($A$4:$A$1003,A5)>1,"Duplicate Map Edge ID",IF(NOT(OR(AND(B5="UC",E5="CAP",D5="requires"),AND(B5="CAP",E5="AIR",D5="provided by"),AND(B5="AIR",OR(E5="MOD",E5="DATA",E5="IF",E5="AG",E5="TOOL"),D5="references"),AND(B5="AIR",E5="AIR",D5="depends on"))),"Invalid relationship",IF(AND(M5<>"Superseded",COUNTIFS($B$4:$B$1003,B5,$C$4:$C$1003,C5,$D$4:$D$1003,D5,$E$4:$E$1003,E5,$F$4:$F$1003,F5,$G$4:$G$1003,G5,$M$4:$M$1003,"<>Superseded")>1),"Duplicate relationship",IF(OR(IF(B5="UC",COUNTIF('Use cases'!$A$4:$A$253,C5),IF(B5="CAP",COUNTIF(Capabilities!$A$4:$A$253,C5),IF(B5="AIR",COUNTIF('System map'!$A$4:$A$203,C5),COUNTIFS(Components!$A$4:$A$253,C5,Components!$B$4:$B$253,B5))))<>1,IF(E5="UC",COUNTIF('Use cases'!$A$4:$A$253,F5),IF(E5="CAP",COUNTIF(Capabilities!$A$4:$A$253,F5),IF(E5="AIR",COUNTIF('System map'!$A$4:$A$203,F5),COUNTIFS(Components!$A$4:$A$253,F5,Components!$B$4:$B$253,E5))))<>1),"Endpoint missing or duplicated",IF(AND(NOT(AND(B5="UC",E5="CAP")),OR(G5="",COUNTIF('System map'!$A$4:$A$203,G5)<>1)),"AIR context missing / unknown",IF(AND(B5="CAP",E5="AIR",G5<>F5),"AIR context mismatch",IF(AND(B5="AIR",G5<>C5),"AIR context mismatch",IF(AND(B5="AIR",E5="AIR",C5=F5),"Self-dependency",IF(AND(B5="AIR",E5="AIR",M5<>"Superseded",COUNTIFS($B$4:$B$1003,"AIR",$C$4:$C$1003,F5,$E$4:$E$1003,"AIR",$F$4:$F$1003,C5,$M$4:$M$1003,"<>Superseded")>0),"Dependency cycle (A↔B) — review",IF(AND(B5="AIR",OR(E5="MOD",E5="DATA",E5="IF",E5="AG",E5="TOOL"),IFERROR(INDEX(Components!$G$4:$G$253,MATCH(F5,Components!$A$4:$A$253,0)),"")<>"",IFERROR(INDEX(Components!$G$4:$G$253,MATCH(F5,Components!$A$4:$A$253,0)),"")<>C5),"Component owned by another AIR-ID",IF(AND(M5="Confirmed",OR(IF(B5="UC",COUNTIFS('Use cases'!$A$4:$A$253,C5,'Use cases'!$I$4:$I$253,"Confirmed",'Use cases'!$J$4:$J$253,"OK — verify source"),IF(B5="CAP",COUNTIFS(Capabilities!$A$4:$A$253,C5,Capabilities!$J$4:$J$253,"Confirmed",Capabilities!$K$4:$K$253,"OK — verify source"),IF(B5="AIR",COUNTIFS('System map'!$A$4:$A$203,C5,'System map'!$B$4:$B$203,"<>",'System map'!$C$4:$C$203,"<>",'System map'!$D$4:$D$203,"<>"),COUNTIFS(Components!$A$4:$A$253,C5,Components!$B$4:$B$253,B5,Components!$K$4:$K$253,"Confirmed",Components!$L$4:$L$253,"OK — verify source"))))<>1,IF(E5="UC",COUNTIFS('Use cases'!$A$4:$A$253,F5,'Use cases'!$I$4:$I$253,"Confirmed",'Use cases'!$J$4:$J$253,"OK — verify source"),IF(E5="CAP",COUNTIFS(Capabilities!$A$4:$A$253,F5,Capabilities!$J$4:$J$253,"Confirmed",Capabilities!$K$4:$K$253,"OK — verify source"),IF(E5="AIR",COUNTIFS('System map'!$A$4:$A$203,F5,'System map'!$B$4:$B$203,"<>",'System map'!$C$4:$C$203,"<>",'System map'!$D$4:$D$203,"<>"),COUNTIFS(Components!$A$4:$A$253,F5,Components!$B$4:$B$253,E5,Components!$K$4:$K$253,"Confirmed",Components!$L$4:$L$253,"OK — verify source"))))<>1)),"Endpoint not source-reconciled",IF(AND(M5="Confirmed",OR(L5="",K5="",K5="Unknown",K5="Low")),"Confirmed link lacks verification","OK — verify source"))))))))))))))
N6: =IF(COUNTA(A6:M6)=0,"",IF(OR(A6="",B6="",C6="",D6="",E6="",F6="",I6="",J6="",K6="",M6=""),"Required link detail missing",IF(COUNTIF($A$4:$A$1003,A6)>1,"Duplicate Map Edge ID",IF(NOT(OR(AND(B6="UC",E6="CAP",D6="requires"),AND(B6="CAP",E6="AIR",D6="provided by"),AND(B6="AIR",OR(E6="MOD",E6="DATA",E6="IF",E6="AG",E6="TOOL"),D6="references"),AND(B6="AIR",E6="AIR",D6="depends on"))),"Invalid relationship",IF(AND(M6<>"Superseded",COUNTIFS($B$4:$B$1003,B6,$C$4:$C$1003,C6,$D$4:$D$1003,D6,$E$4:$E$1003,E6,$F$4:$F$1003,F6,$G$4:$G$1003,G6,$M$4:$M$1003,"<>Superseded")>1),"Duplicate relationship",IF(OR(IF(B6="UC",COUNTIF('Use cases'!$A$4:$A$253,C6),IF(B6="CAP",COUNTIF(Capabilities!$A$4:$A$253,C6),IF(B6="AIR",COUNTIF('System map'!$A$4:$A$203,C6),COUNTIFS(Components!$A$4:$A$253,C6,Components!$B$4:$B$253,B6))))<>1,IF(E6="UC",COUNTIF('Use cases'!$A$4:$A$253,F6),IF(E6="CAP",COUNTIF(Capabilities!$A$4:$A$253,F6),IF(E6="AIR",COUNTIF('System map'!$A$4:$A$203,F6),COUNTIFS(Components!$A$4:$A$253,F6,Components!$B$4:$B$253,E6))))<>1),"Endpoint missing or duplicated",IF(AND(NOT(AND(B6="UC",E6="CAP")),OR(G6="",COUNTIF('System map'!$A$4:$A$203,G6)<>1)),"AIR context missing / unknown",IF(AND(B6="CAP",E6="AIR",G6<>F6),"AIR context mismatch",IF(AND(B6="AIR",G6<>C6),"AIR context mismatch",IF(AND(B6="AIR",E6="AIR",C6=F6),"Self-dependency",IF(AND(B6="AIR",E6="AIR",M6<>"Superseded",COUNTIFS($B$4:$B$1003,"AIR",$C$4:$C$1003,F6,$E$4:$E$1003,"AIR",$F$4:$F$1003,C6,$M$4:$M$1003,"<>Superseded")>0),"Dependency cycle (A↔B) — review",IF(AND(B6="AIR",OR(E6="MOD",E6="DATA",E6="IF",E6="AG",E6="TOOL"),IFERROR(INDEX(Components!$G$4:$G$253,MATCH(F6,Components!$A$4:$A$253,0)),"")<>"",IFERROR(INDEX(Components!$G$4:$G$253,MATCH(F6,Components!$A$4:$A$253,0)),"")<>C6),"Component owned by another AIR-ID",IF(AND(M6="Confirmed",OR(IF(B6="UC",COUNTIFS('Use cases'!$A$4:$A$253,C6,'Use cases'!$I$4:$I$253,"Confirmed",'Use cases'!$J$4:$J$253,"OK — verify source"),IF(B6="CAP",COUNTIFS(Capabilities!$A$4:$A$253,C6,Capabilities!$J$4:$J$253,"Confirmed",Capabilities!$K$4:$K$253,"OK — verify source"),IF(B6="AIR",COUNTIFS('System map'!$A$4:$A$203,C6,'System map'!$B$4:$B$203,"<>",'System map'!$C$4:$C$203,"<>",'System map'!$D$4:$D$203,"<>"),COUNTIFS(Components!$A$4:$A$253,C6,Components!$B$4:$B$253,B6,Components!$K$4:$K$253,"Confirmed",Components!$L$4:$L$253,"OK — verify source"))))<>1,IF(E6="UC",COUNTIFS('Use cases'!$A$4:$A$253,F6,'Use cases'!$I$4:$I$253,"Confirmed",'Use cases'!$J$4:$J$253,"OK — verify source"),IF(E6="CAP",COUNTIFS(Capabilities!$A$4:$A$253,F6,Capabilities!$J$4:$J$253,"Confirmed",Capabilities!$K$4:$K$253,"OK — verify source"),IF(E6="AIR",COUNTIFS('System map'!$A$4:$A$203,F6,'System map'!$B$4:$B$203,"<>",'System map'!$C$4:$C$203,"<>",'System map'!$D$4:$D$203,"<>"),COUNTIFS(Components!$A$4:$A$253,F6,Components!$B$4:$B$253,E6,Components!$K$4:$K$253,"Confirmed",Components!$L$4:$L$253,"OK — verify source"))))<>1)),"Endpoint not source-reconciled",IF(AND(M6="Confirmed",OR(L6="",K6="",K6="Unknown",K6="Low")),"Confirmed link lacks verification","OK — verify source"))))))))))))))
N7: =IF(COUNTA(A7:M7)=0,"",IF(OR(A7="",B7="",C7="",D7="",E7="",F7="",I7="",J7="",K7="",M7=""),"Required link detail missing",IF(COUNTIF($A$4:$A$1003,A7)>1,"Duplicate Map Edge ID",IF(NOT(OR(AND(B7="UC",E7="CAP",D7="requires"),AND(B7="CAP",E7="AIR",D7="provided by"),AND(B7="AIR",OR(E7="MOD",E7="DATA",E7="IF",E7="AG",E7="TOOL"),D7="references"),AND(B7="AIR",E7="AIR",D7="depends on"))),"Invalid relationship",IF(AND(M7<>"Superseded",COUNTIFS($B$4:$B$1003,B7,$C$4:$C$1003,C7,$D$4:$D$1003,D7,$E$4:$E$1003,E7,$F$4:$F$1003,F7,$G$4:$G$1003,G7,$M$4:$M$1003,"<>Superseded")>1),"Duplicate relationship",IF(OR(IF(B7="UC",COUNTIF('Use cases'!$A$4:$A$253,C7),IF(B7="CAP",COUNTIF(Capabilities!$A$4:$A$253,C7),IF(B7="AIR",COUNTIF('System map'!$A$4:$A$203,C7),COUNTIFS(Components!$A$4:$A$253,C7,Components!$B$4:$B$253,B7))))<>1,IF(E7="UC",COUNTIF('Use cases'!$A$4:$A$253,F7),IF(E7="CAP",COUNTIF(Capabilities!$A$4:$A$253,F7),IF(E7="AIR",COUNTIF('System map'!$A$4:$A$203,F7),COUNTIFS(Components!$A$4:$A$253,F7,Components!$B$4:$B$253,E7))))<>1),"Endpoint missing or duplicated",IF(AND(NOT(AND(B7="UC",E7="CAP")),OR(G7="",COUNTIF('System map'!$A$4:$A$203,G7)<>1)),"AIR context missing / unknown",IF(AND(B7="CAP",E7="AIR",G7<>F7),"AIR context mismatch",IF(AND(B7="AIR",G7<>C7),"AIR context mismatch",IF(AND(B7="AIR",E7="AIR",C7=F7),"Self-dependency",IF(AND(B7="AIR",E7="AIR",M7<>"Superseded",COUNTIFS($B$4:$B$1003,"AIR",$C$4:$C$1003,F7,$E$4:$E$1003,"AIR",$F$4:$F$1003,C7,$M$4:$M$1003,"<>Superseded")>0),"Dependency cycle (A↔B) — review",IF(AND(B7="AIR",OR(E7="MOD",E7="DATA",E7="IF",E7="AG",E7="TOOL"),IFERROR(INDEX(Components!$G$4:$G$253,MATCH(F7,Components!$A$4:$A$253,0)),"")<>"",IFERROR(INDEX(Components!$G$4:$G$253,MATCH(F7,Components!$A$4:$A$253,0)),"")<>C7),"Component owned by another AIR-ID",IF(AND(M7="Confirmed",OR(IF(B7="UC",COUNTIFS('Use cases'!$A$4:$A$253,C7,'Use cases'!$I$4:$I$253,"Confirmed",'Use cases'!$J$4:$J$253,"OK — verify source"),IF(B7="CAP",COUNTIFS(Capabilities!$A$4:$A$253,C7,Capabilities!$J$4:$J$253,"Confirmed",Capabilities!$K$4:$K$253,"OK — verify source"),IF(B7="AIR",COUNTIFS('System map'!$A$4:$A$203,C7,'System map'!$B$4:$B$203,"<>",'System map'!$C$4:$C$203,"<>",'System map'!$D$4:$D$203,"<>"),COUNTIFS(Components!$A$4:$A$253,C7,Components!$B$4:$B$253,B7,Components!$K$4:$K$253,"Confirmed",Components!$L$4:$L$253,"OK — verify source"))))<>1,IF(E7="UC",COUNTIFS('Use cases'!$A$4:$A$253,F7,'Use cases'!$I$4:$I$253,"Confirmed",'Use cases'!$J$4:$J$253,"OK — verify source"),IF(E7="CAP",COUNTIFS(Capabilities!$A$4:$A$253,F7,Capabilities!$J$4:$J$253,"Confirmed",Capabilities!$K$4:$K$253,"OK — verify source"),IF(E7="AIR",COUNTIFS('System map'!$A$4:$A$203,F7,'System map'!$B$4:$B$203,"<>",'System map'!$C$4:$C$203,"<>",'System map'!$D$4:$D$203,"<>"),COUNTIFS(Components!$A$4:$A$253,F7,Components!$B$4:$B$253,E7,Components!$K$4:$K$253,"Confirmed",Components!$L$4:$L$253,"OK — verify source"))))<>1)),"Endpoint not source-reconciled",IF(AND(M7="Confirmed",OR(L7="",K7="",K7="Unknown",K7="Low")),"Confirmed link lacks verification","OK — verify source"))))))))))))))
