Workbook

Sheet Risk Assessment
A1: The Council — AI Risk Assessment Worksheet
A2: Governance-use worksheet · AIG-ASS-02 v1.10 draft · Draft for Council review. The web triage pre-populates factual fields; the assessor confirms or amends scores and evidence.
A3: Colour key: blue = pre-populated from triage • pale yellow = assessor input/confirmation • gold = calculated result. Where a confirmed score differs from triage, record the reason in Step 6.
A5: Triage context — pre-populated from the canonical web triage record
A6: System / model name | B6: =IF('Triage Import'!B6="","",'Triage Import'!B6)
A7: AIR-ID | B7: =IF('Triage Import'!B5="","",'Triage Import'!B5) | C7: Triage | D7: Persistent key across all governance artefacts.
A8: Purpose / description | B8: =IF('Triage Import'!B7="","",'Triage Import'!B7)
A9: Service area | B9: =IF('Triage Import'!B8="","",'Triage Import'!B8)
A10: Service owner | B10: =IF('Triage Import'!B9="","",'Triage Import'!B9)
A11: Triage date | B11: =IF('Triage Import'!B17="","",'Triage Import'!B17)
A12: AGPI score (0–100) | B12: =IF('Triage Import'!B18="","",'Triage Import'!B18) | D12: Governance-priority score from AIG-ASS-01/web triage.
A13: Raw AGPI priority | B13: =IF('Triage Import'!B19="","",'Triage Import'!B19) | D13: Governance priority produced by AGPI before any formally authorised governance-priority uplift.
A14: Effective governance priority | B14: =IF('Triage Import'!B21="","",'Triage Import'!B21) | D14: Stricter of raw AGPI priority and any formally authorised governance-priority uplift. This is not derived from the mandatory risk floor.
A15: Risk assessment scope | B15: =IF('Triage Import'!B63="","",'Triage Import'!B63) | D15: A shared baseline can provide evidence but does not replace the assessment of materially different use contexts.
A16: Assessment ownership — completed by the assessor
A17: Assessed by | D17: Name and role of the assessor.
A18: Assessment date | D18: Date detailed assessment was confirmed.
A19: Evidence bundle / case reference | D19: Reference evidence rather than duplicating it in this worksheet.
A20: UC-ID / use outcome assessed | B20: =IF('Triage Import'!B62="","",'Triage Import'!B62) | C20: Scope-key check | D20: =IF(OR(B15="UC-ID specific",B15="UC-ID-specific"),IF(B20="","UC-ID REQUIRED","UC-ID recorded"),IF(B15="Shared system baseline",IF(B20<>"","REMOVE UC-ID OR CORRECT SCOPE","SYSTEM BASELINE ONLY — NOT USE APPROVAL"),"ASSESSMENT SCOPE REQUIRED")) | E20: Use one assessment per materially different UC-ID; cite shared controls and evidence by source reference. Assessment outputs route assurance and are not approval.
A21: Step 1 — Impact: confirm or amend triage scores (1 Minimal to 5 Severe)
A22: Impact dimension | B22: Triage score | C22: Confirmed score | D22: What it covers
A23: Resident Impact | B23: =IF('Triage Import'!B22="","",'Triage Import'!B22) | C23: =IF(B23="","",B23) | D23: Physical, psychological, financial or social harm to individuals or communities, including vulnerable groups.
A24: Legal & Regulatory Impact | B24: =IF('Triage Import'!B23="","",'Triage Import'!B23) | C24: =IF(B24="","",B24) | D24: Regulatory sanctions, enforcement, legal proceedings or breach of statutory obligations.
A25: Reputational Impact | B25: =IF('Triage Import'!B24="","",'Triage Import'!B24) | C25: =IF(B25="","",B25) | D25: Damage to public trust, media coverage, political scrutiny or the Council's standing.
A26: Operational Impact | B26: =IF('Triage Import'!B25="","",'Triage Import'!B25) | C26: =IF(B26="","",B26) | D26: Disruption to service delivery, operational failures, remediation cost and impact on staff.
A27: Financial Impact | B27: =IF('Triage Import'!B26="","",'Triage Import'!B26) | C27: =IF(B27="","",B27) | D27: Direct financial costs including compensation, regulatory fines, remediation expenditure and lost efficiency.
A28: Impact score (I) — highest confirmed dimension | C28: =IF(COUNT(C23:C27)<5,"",IF(OR(MIN(C23:C27)<1,MAX(C23:C27)>5),"Invalid score",MAX(C23:C27))) | D28: Confirmed impact is the highest of five 1–5 dimensions. An incomplete or out-of-range score leaves the risk route incomplete. Impact floor (Proposed — for Council confirmation): any confirmed 5 (Severe) sets a minimum governing tier of Medium, whatever the likelihood (E28). | E28: =IF(C28=5,"Impact floor (Severe impact) → Medium","")
A30: Step 2 — Likelihood and control effectiveness: confirm or amend triage scores
A31: Metric | B31: Triage score | C31: Confirmed score
A32: Likelihood (L) | B32: =IF('Triage Import'!B27="","",'Triage Import'!B27) | C32: =IF(B32="","",B32)
A33: Control Effectiveness (C) | B33: =IF('Triage Import'!B28="","",'Triage Import'!B28) | C33: =IF(B33="","",B33)
A35: Step 3 — Risk results and governance floor
A36: Result | B36: Triage result | C36: Confirmed / calculated result | D36: Rule / note
A37: Inherent risk score (L × I) | B37: =IF('Triage Import'!B30="","",'Triage Import'!B30) | C37: =IF(OR(NOT(ISNUMBER(C28)),NOT(ISNUMBER(C32))),"",IF(OR(C32<1,C32>5),"",C32*C28)) | D37: Controls evidenced?
A38: Inherent risk tier | B38: =IF('Triage Import'!B31="","",'Triage Import'!B31) | C38: =IF(C37="","",IF(C37>=16,"Critical",IF(C37>=11,"High",IF(C37>=6,"Medium","Low")))) | D38: Control evidence ref
A39: Control effectiveness factor (C ÷ 5) | C39: =IF(NOT(ISNUMBER(C33)),"",IF(OR(C33<1,C33>5),"",C33/5)) | D39: Independent check?
A40: Residual risk score | B40: =IF('Triage Import'!B32="","",'Triage Import'!B32) | C40: =IF(OR(C37="",C39=""),"",C37*C39) | D40: Verification ref
A41: Residual risk tier | B41: =IF('Triage Import'!B33="","",'Triage Import'!B33) | C41: =IF(C40="","",IF(C40>15,"Critical",IF(C40>10,"High",IF(C40>5,"Medium","Low")))) | D41: Reduced tier eligible? | E41: =IF(AND(E37="Yes",E38<>"",OR(AND(C38<>"High",C38<>"Critical"),AND(E39="Yes",E40<>""))),"Yes","No")
A42: Mandatory risk floor | B42: =IF('Triage Import'!B41="","",'Triage Import'!B41) | C42: =IF(COUNTIF(C50:C56,"Yes")+COUNTIF(C50:C56,"No")+COUNTIF(C56,"Unsure")<7,"Incomplete",IF(OR(C54="Yes",C56="Yes",C56="Unsure"),"Critical",IF(COUNTIF(C50:C56,"Yes")>0,"High","Low"))) | D42: Critical for statutory or agentic trigger; High for any other mandatory trigger. This is a risk-routing floor and does not rewrite AGPI governance priority.
A43: Effective governance tier | B43: =IF('Triage Import'!B42="","",'Triage Import'!B42) | C43: =IF(OR(C82="AGENTIC TRIGGER CONFLICT",C82="Incomplete",C38="",C41="",C42="Incomplete"),"Incomplete",INDEX({"Low","Medium","High","Critical"},MAX(MATCH(IF(E41="Yes",C41,C38),{"Low","Medium","High","Critical"},0),MATCH(C42,{"Low","Medium","High","Critical"},0),IF(C82="Critical",4,IF(C82="High",3,IF(C82="Medium",2,1))),IF(C28=5,2,1)))) | D43: Inherent tier until controls are evidenced; High/Critical reduction requires independent verification. The trigger floor, the impact floor (any confirmed Impact 5 → at least Medium; Proposed — for Council confirmation) and the agentic floor (row 82) always apply; the highest wins. B43 is the web triage pre-control tier (no control-based reduction).
...

Sheet Document Control
A1: AIG-ASS-02 — Document Control
A2: Controlled working template. Draft for Council review; not Council-adopted and not effective until formally approved.
A4: Field | B4: Controlled value
A5: Document ID | B5: AIG-ASS-02
A6: Artefact | B6: AI Risk Assessment Worksheet
A7: Version | B7: 1.10 draft
A8: Status | B8: Draft for Council review
A9: Document owner | B9: AI Governance Lead
A10: Approving body | B10: Competent Council authority under Constitution and Scheme of Delegation; AI Assurance Board provides assurance where applicable
A11: Approval date | B11: Not yet approved
A12: Effective date | B12: Not yet effective
A13: Next review date | B13: To be set on approval: 12 months after effective date or sooner following material change
A15: Change history
A16: Version | B16: Date | C16: Change | D16: Author / owner
A17: 1.0 draft | B17: 6 August 2026 | C17: Step 4.3 spreadsheet QA controls and document-control baseline established. | D17: AI Governance Lead
A18: 1.1 draft | B18: Not recorded in source | C18: Not recorded in source (placeholder added during QA remediation so the history is continuous). | D18: Not recorded in source
A19: 1.2 draft | B19: 20 September 2026 | C19: Lean operating model: clarified governance-led completion, source evidence by reference, and no duplicate Service Owner paperwork; decision routing remains with the effective delegated authority. | D19: AI Governance Lead
A20: 1.3 draft | B20: Not recorded in source | C20: Not recorded in source (placeholder added during QA remediation so the history is continuous). | D20: Not recorded in source
A21: 1.4 draft | B21: Not recorded in source | C21: Not recorded in source (placeholder added during QA remediation so the history is continuous). | D21: Not recorded in source
A22: 1.5 draft | B22: 23 September 2026 | C22: Agentic classification and triage revision: Is Agent includes human-approved actions. Export fields and scoring unchanged. | D22: AI Governance Lead
A23: 1.6 draft | B23: 28 September 2026 | C23: Repair score inputs and formulas; align tier bands, evidence gate, scope vocabulary, validation and warnings. | D23: AI Governance Lead
A24: 1.7 draft | B24: 29 September 2026 | C24: QA remediation — applied findings QA-208, QA-215, QA-218, QA-235, QA-240, QA-247, QA-251, QA-263, QA-264, QA-273, QA-279, QA-280, QA-284, QA-290, QA-291 (see QA change log). | D24: AI Governance Lead
A25: 1.8 draft | B25: 30 September 2026 | C25: v3.8: impact floor added to the effective governing tier (any confirmed Impact 5 → at least Medium; flag “Impact floor (Severe impact) → Medium” in E28 and the tier floor rationale); assurance intensity now follows the governing tier and triggers only (AGPI priority sets urgency, not depth or route); Step 6 priority vs governing tier safeguard line (row 100). Final tidy-up: D66 “Can-it-act gate” → “can it act?” screen (“gate” is reserved for Gate 0 to Gate 8). Proposed — for Council confirmation. | D25: AI Governance Lead
A26: 1.9 draft | B26: 30 September 2026 | C26: v3.9.1: the agentic floor (row 82) now applies the T2 minimum pathway: T2 bounded agent (or an agentic pathway at Medium) sets a governing tier of at least Medium, as in the Gate Map (AIG-DEC-01 v1.6, Agentic pathway), AIG-AGT-02, AIG-AGT-03 §6 and the Playbook (Appendix F.2). C82 returns Medium, the governing tier (C43) ranks it, the tier floor rationale (C44) names it and the D82 note gives the full mapping (T0 and T1 none; T2 Medium; T3 High; T4 High, Critical through the C56 floor without evidenced per-action review; T5 Critical). Earlier versions applied T3 to T5 only. Proposed — for Council confirmation. | D26: AI Governance Lead
A27: 1.10 draft | B27: 30 September 2026 | C27: v3.9.2: the agentic floor (C82) now reads the agency tier token in C73 (T0–T5) by exact match (T0–T1 none; T2 Medium; T3–T4 High; T5 Critical) and uses the controlled pathway wording in C74 only where no tier is recorded, by its leading label or “minimum pathway” phrase. It no longer searches C74 for the word “Critical”, so the controlled T4 wording “High (Critical where actions run without evidenced per-action human review)” no longer raises a false AGENTIC TRIGGER CONFLICT; T4 still reaches Critical through the C56 trigger floor (scenario finding W-09; 1,944-case grid re-run). Triage Import E20/E21 notes: the AIG-ASS-01 §3.9.6 trigger floor is a rule, not an uplift (W-05). Proposed — for Council confirmation. | D27: AI Governance Lead
A28: Classification: OFFICIAL. Approval, effective and review dates must be completed by the document owner following formal governance approval.

Sheet Triage Import
A1: AIG-ASS-02 — Triage Import / Pre-population Map
A2: Paste / generate one canonical triage record here. For each use-specific assessment, copy the exact AIR-ID, UC-ID, priority and facts from the corresponding UC-scoped AIG-ASS-01 triage; this import is not synchronised.
A4: Canonical field | B4: Value | C4: Capture status | D4: Used in AIG-ASS-02 | E4: Implementation note
A5: AIR-ID | C5: AUTO — current web triage | D5: Identity | E5: Direct profile field.
A6: System / Model Name | C6: AUTO — current web triage | D6: Identity | E6: Direct profile field.
A7: Purpose / Description | C7: AUTO — current web triage | D7: Identity | E7: Direct profile field.
A8: Service Area | C8: AUTO — current web triage | D8: Identity | E8: Direct profile field.
A9: Service Owner | C9: AUTO — current web triage | D9: Identity | E9: Direct profile field.
A10: Supplier / Developer | C10: AUTO — current web triage | D10: Context | E10: Direct profile field; retained for traceability.
A11: Source | C11: AUTO — current web triage | D11: Context | E11: Direct profile field.
A12: AI Capability | C12: AUTO — current web triage | D12: Context / agentic gate | E12: Direct profile field.
A13: Automated Action Authority | C13: AUTO — current web triage | D13: Agentic context | E13: Direct profile field.
A14: Systems / Tools Accessed | C14: AUTO — current web triage | D14: Agentic context | E14: Direct profile field.
A15: Lifecycle Stage | C15: AUTO — current web triage | D15: Context | E15: Direct profile field.
A16: Personal / Special Category Data | C16: AUTO — current web triage | D16: Escalation context | E16: Direct profile field.
... A61: Agent Record (ASBOM) Ref | C61: AUTO — current Agentic Triage | D61: Step 5 | E61: Reference entered by user.
A62: UC-ID (blank only for explicit system baseline) | C62: Scope key | D62: Enter stable UC-ID when this triage / risk assessment is use-specific.
A63: Triage / assessment scope | C63: ASSESSOR INPUT | D63: Scope key | E63: Select UC-ID specific for a use assessment or Shared system baseline for shared controls. A shared baseline never approves a use.

Sheet INTEGRATION INV-04 DEC-04
A1: PROPOSED INTEGRATION CONTRACT — AIG-INV-04 / AIG-DEC-03 / AIG-DEC-04 / AIG-OPS-02
A2: NOT APPROVED — additive integration annex only; existing workbook content and formulas are retained unchanged. AIG-INV-04 (AI Register) and AIG-DEC-04 (Gate Log) are themselves proposed designs: until the Council approves their adoption and migration, the Council’s existing records remain authoritative and the AIG-INV-04/AIG-DEC-04 joins below are design references only. No live system, event, evidence, approval or Council decision is asserted.
A3: Native evidence index: AIG-INV-04 → Evidence index. Evidence IDs locate native records; they do not replace the underlying artefact, decision or minute.
A4: Provenance rule: every reused fact/result must carry its source record/sheet and row (or document section/record ID), source version and as-of/snapshot date. Leave unavailable provenance explicitly missing; do not fabricate it.
A5: Integration relationship | B5: Native source / artefact | C5: Native record locator | D5: Join key(s) | E5: Proposed integration rule / use | F5: Required provenance: row, version, as-of | G5: Blank / zero handling | H5: Reporting / audit reconciliation
A6: Key/evidence joins | B6: AIG-INV-04 (AI Register; Evidence index) | C6: AI Register: AIR-ID; Evidence index: Evidence ID + AIR-ID | D6: AIR-ID | E6: Use AIR-ID for all system-level joins; use Evidence ID to point to an indexed evidence record. Do not join on system name. | F6: Native source row (sheet + row), artefact/record ID, source version, evidence date and source as-of/snapshot date; location/link where permitted. | G6: Blank means unknown/not supplied/not applicable only when explicitly marked; never coerce blank to 0 or infer an evidence record. | H6: Reconcile unique AIR-ID and the evidence index reference against the native AIG-INV-04 workbook before relying on it.
A7: Risk assessment | B7: AIG-ASS-02 Risk Assessment Worksheet | C7: Risk Assessment + Document Control | D7: AIR-ID | E7: Link the current assessment to the system record; retain assessment details and scoring rationale in AIG-ASS-02, not duplicated here. | F7: AIG-ASS-02 version; worksheet row/section or assessment record identifier; assessment date; source evidence IDs; as-of date for inputs. | G7: Unanswered risk or score is not zero and must not be treated as a completed assessment. | H7: Confirm risk inputs and calculated result against the native AIG-ASS-02 record and indexed evidence.
A8: Decision / minutes | B8: AIG-DEC-03 Governance Decision Record and the native forum minutes | C8: Decision record ID; meeting/minute reference | D8: AIR-ID + Decision Record ID; relate to AIG-DEC-04 Event ID where present | E8: AIG-DEC-03 owns the reasoned decision; minutes remain native records; cross-reference, do not reproduce the decision narrative. | F8: Decision-record version/ID, meeting/minute reference, record row/section, decision date and as-of date. | G8: No decision, approver or date is inferred from a paper, plan or empty field. | H8: Reconcile the decision record and minute reference with delegated authority and corresponding AIG-DEC-04 event.
A9: Gate plan / event / condition | B9: AIG-DEC-04 AI Governance Gate Log | C9: Gate Log record; native Event ID, AIR-ID, conditions and due/status fields | D9: AIR-ID + Event ID; Condition ID if assigned by the Council | E9: Distinguish proposed/planned gate from dated event; conditions are attached to an event. Do not treat a plan as an approval. | F9: Native sheet + row, Event ID, Condition reference, AIG-DEC-04 version and as-of/snapshot date. | G9: Missing date/status remains missing; open, overdue, waived and not applicable are distinct states, not numeric zero. | H9: Match event, condition, evidence reference and latest recorded decision; investigate inconsistencies.
A10: Live monitoring / review | B10: AIG-OPS-02 AI Post-Deployment Monitoring and Review Log | C10: Monitoring Log; Sampling Method; record row | D10: AIR-ID + monitoring period + metric/review record; Event ID/Condition ref when relevant | E10: Link observed result and reproducible sample to AIG-OPS-02; threshold breaches trigger documented consideration and, where applicable, AIG-DEC-04 escalation. | F10: AIG-OPS-02 version, Monitoring Log row, monitoring period, review date, sample source/population and as-of date. | G10: Blank result/sample/threshold is not zero, compliance or no breach. | H10: Reproduce sample and compare actual result with the approved threshold; trace breach response to AIG-DEC-03/AIG-DEC-04/AIG-OPS-03/AIG-AIMS-08 as appropriate.
A11: Reporting population | B11: AIG-INV-04 AI Register and Assessment summary; AIG-DEC-03 and native minutes; AIG-DEC-04 plan/event/condition; AIG-OPS-02 | C11: Source records for each reporting period; native evidence index for evidence pointers | D11: AIR-ID, Evidence ID, Decision Record ID, Event ID, Condition ref, monitoring period | E11: Report at the declared snapshot date; show numerator, denominator, exclusions, missing/unknown and not-applicable separately. Report plans versus completed events separately. | F11: Freeze reporting as-of date; retain the source workbook/document version and source row identifiers for each sampled/aggregated record. | G11: Do not count blanks as zero or complete; distinguish zero observed from no data and from not applicable. | H11: Reconcile totals to source populations and document filters, period, exclusions and unresolved links.
A12: Audit sampling | B12: AIG-AIMS-07 Internal Audit Programme and Procedure; sample sources AIG-INV-04 AI Register/Assessment summary, AIG-DEC-03/minutes, AIG-DEC-04 plan/event/condition, AIG-OPS-02 log | C12: Auditor-selected native records; evidence index is a locator, not a substitute for evidence | D12: AIR-ID + each native record key above | E12: Record sampling frame, population size, inclusion/exclusion criteria, selection method and seed/date where random; inspect source records rather than only summary views. | F12: Record each sampled native sheet/document and row/record ID, version, source as-of date, retrieval date, criterion tested, and evidence index reference. | G12: An absent record is a sample finding/gap, not a zero; unknown is not pass. | H12: Auditor records independent selection, trace-back and reproducibility in the AIG-AIMS-07 audit working papers/findings.
A13: Native evidence index | B13: AIG-INV-04 Evidence index (native evidence index) | C13: Evidence ID, AIR-ID, artefact/record ID, version, evidence/decision date, status, location/link, gate/condition reference as present | D13: Evidence ID + AIR-ID; optionally Event ID / Condition ref | E13: Use as a pointer to the authoritative artefact, not as the decision itself or a copied evidence store. Preserve its native metadata. | F13: Capture source row, source workbook version and as-of date alongside index metadata when reporting/auditing. | G13: Empty index fields signal missing provenance; do not supply invented versions, dates, links or approval. | H13: Check that linked artefact exists, version matches, is appropriate to the question and has not been superseded.

Sheet STANDARDS SCOPE QA
A1: PROPOSED QA INDEX — NOT APPROVED. A source reference does not establish applicability or compliance. See AIG-AIMS-05 and AIG-AIMS-13; owners must validate the current source, case-specific scope, control evidence and adopted status.
A2: Requirement ID | B2: Instrument / edition | C2: Conditional scope / relevance | D2: Source URL | E2: Owner validation status
A3: REQ-001 | B3: UK General Data Protection Regulation (UK GDPR), as amended | C3: Where personal data is processed; test each UK GDPR provision separately. | D3: https://www.legislation.gov.uk/eur/2016/679/contents | E3: Specialist validation required
A4: REQ-005 | B4: Equality Act 2010, including Public Sector Equality Duty section 149 | C4: Public authority due regard under s.149; case-level equality screening is not risk-tier gated. | D4: https://www.legislation.gov.uk/ukpga/2010/15/section/149 | E4: Specialist validation required
A5: REQ-006 | B5: Human Rights Act 1998 | C5: Public-authority compatibility under s.6; assess Convention rights engaged by the case. | D5: https://www.legislation.gov.uk/ukpga/1998/42/contents | E5: Specialist validation required
A6: REQ-014 | B6: Local Government Act 1999 (Best Value Duty) and 2024 statutory guidance | C6: Screen the legislation and statutory guidance requirement against this artefact's actual use and record evidence/version in the AIG-AIMS-05 entry for this requirement. | D6: https://www.gov.uk/government/publications/best-value-standards-and-intervention-a-statutory-guide-for-best-value-authorities | E6: Specialist validation required
A7: REQ-033 | B7: ICO Guidance on AI and Data Protection and AI Risk Toolkit | C7: Screen the regulatory guidance requirement against this artefact's actual use and record evidence/version in the AIG-AIMS-05 entry for this requirement. | D7: https://ico.org.uk/for-organisations/uk-gdpr-guidance-and-resources/artificial-intelligence/guidance-on-ai-and-data-protection/ | E7: Specialist validation required
A8: REQ-035 | B8: EHRC Artificial Intelligence in Public Services and PSED guidance | C8: Screen the regulatory guidance requirement against this artefact's actual use and record evidence/version in the AIG-AIMS-05 entry for this requirement. | D8: https://www.equalityhumanrights.com/guidance/artificial-intelligence-public-services | E8: Specialist validation required
A9: REQ-041 | B9: ISO/IEC 23894:2023 AI — Guidance on risk management | C9: Voluntary risk-management guidance; proposed alignment, not statutory conformity. | D9: https://www.iso.org/standard/77304.html | E9: Specialist validation required
A10: NIST-AI-100-1 | B10: NIST AI Risk Management Framework 1.0 (NIST AI 100-1, January 2023) | C10: Voluntary alignment reference; not certification or statutory conformity | D10: https://www.nist.gov/publications/artificial-intelligence-risk-management-framework-ai-rmf-10 | E10: Voluntary alignment reference; not certification or statutory conformity

Sheet MAP & SPLIT CONTRACT
A1: AIG-ASS-02 / PROPOSED THREE-ARTEFACT SOURCE CONTRACT
A3: Status | B3: PROPOSED INTEGRATION DESIGN ONLY. This sheet does not amend the artefact's native assessment, decision authority, data or formulas.
A4: Role of this file | B4: Risk assessment: AIG-ASS-02 owns inherent/control/residual assessment; AIG-INV-04 Assessment summary holds only a pointer. A map edge never proves a risk control operates.
A5: AIG-INV-04 source | B5: Separate AIG-INV-04 AI Register: official AIR-ID, current position, in-file Assessment summary/Evidence index. Reconcile against authoritative AIG-INV-04 before using a copied value.
A6: AIG-DEC-04 source | B6: Separate AIG-DEC-04 Gate Log: prospective Gate plan, dated Gate events, event-linked Conditions. A planned gate is not a decision. A decision requires AIG-DEC-03 or approved minutes and proper delegation.
A7: Map source | B7: Proposed standalone Capabilities and System Map (candidate catalogue ID AIG-INV-05): UC/CAP and component relationship pointers. Edge ID is not an approval or permission; AIG-AGT-04/AIG-AGT-05 remain sources of agent scope/authority.
A8: Data exchange | B8: Use controlled AIR-ID across files. Where applicable reference exact Event ID, Condition ID, Evidence ID, AG-ID and Edge ID. Record source file/version/as-at with imported or quoted evidence; no live cross-workbook formula is assumed.
A9: Change trigger | B9: New or expanded system/tool access, or a material model, data, interface, purpose or agent change: log the map change, obtain owner reassessment and escalate to the proper AIG-DEC-04 gate/AIG-DEC-03 decision when required.
A10: Validation before use | B10: The INTEGRATION INV-04 DEC-04 tab in this workbook is current supporting design guidance (not historical) and holds the detailed join notes. Controlled owners must reconcile real records, validate values and formulas in Excel, and approve migration/cutover; existing Council records remain unchanged until then.
