Workbook

Sheet Summary
A1: The Council — AIMS Objectives, Risk Treatment and Improvement Plan
A2: AIG-AIMS-03 · v1.2 draft · Draft for Council review · OFFICIAL · ISO/IEC 42001:2023
A3: Purpose: translate the proposed AIMS scope and control design into measurable objectives, treated risks, opportunities and controlled implementation actions.
A4: Status statement: all objectives, risk scores, treatments, opportunities and improvement actions are proposed starting positions. The Council must validate and approve owners, resources, baselines, targets, dates and risk decisions before use.
A6: Document control | B6: Controlled value | D6: Objective readiness | G6: Risk and improvement readiness
A7: Document ID | B7: AIG-AIMS-03 | D7: Measure | E7: Result | G7: Measure | H7: Result
A8: Version | B8: 1.2 draft | D8: Proposed objectives | E8: =COUNTA('AIMS Objectives'!$A$7:$A$14) | G8: AIMS-level risks | H8: =COUNTA('Risk Treatment'!$A$7:$A$21)
A9: Status | B9: Draft for Council review | D9: Approved / active | E9: =COUNTIF('AIMS Objectives'!$N$7:$N$14,"Approved")+COUNTIF('AIMS Objectives'!$N$7:$N$14,"Active")+COUNTIF('AIMS Objectives'!$N$7:$N$14,"Achieved") | G9: Critical / high inherent | H9: =COUNTIF('Risk Treatment'!$J$7:$J$21,"Critical")+COUNTIF('Risk Treatment'!$J$7:$J$21,"High")
A10: Document owner | B10: AI Governance Lead | D10: At risk | E10: =COUNTIF('AIMS Objectives'!$N$7:$N$14,"At risk") | G10: Residual ratings complete | H10: =COUNT('Risk Treatment'!$R$7:$R$21)
A11: Approving authority | B11: To be confirmed under Council delegations | D11: Average progress | E11: =AVERAGE('AIMS Objectives'!$P$7:$P$14) | G11: Risk QA complete | H11: =COUNTIF('Risk Treatment'!$X$7:$X$21,"Complete")
A12: Effective date | B12: Pending formal approval | D12: Objectives with target dates | E12: =COUNT('AIMS Objectives'!$I$7:$I$14) | G12: Opportunities | H12: =COUNTA(Opportunities!$A$7:$A$11)
A13: Review frequency | B13: Monthly during implementation; at least quarterly thereafter | D13: Last reviews recorded | E13: =COUNT('AIMS Objectives'!$Q$7:$Q$14) | G13: Improvement actions | H13: =COUNTA('Improvement Plan'!$A$7:$A$23)
A14: Source position | B14: AIG-AIMS-01, AIG-AIMS-02 and AI Governance Playbook (AIG-GOV-02, current controlled version per AIG-GOV-03) | D14: Objective QA complete | E14: =COUNTIF('AIMS Objectives'!$S$7:$S$14,"Complete") | G14: Actions complete | H14: =COUNTIF('Improvement Plan'!$K$7:$K$23,"Complete")
A15: Classification | B15: OFFICIAL | G15: Action QA complete | H15: =COUNTIF('Improvement Plan'!$T$7:$T$23,"Complete")
A17: Inherent risk profile | D17: Objective status | G17: Improvement status
A18: Critical | B18: =COUNTIF('Risk Treatment'!$J$7:$J$21,A18) | D18: Draft | E18: =COUNTIF('AIMS Objectives'!$N$7:$N$14,D18) | G18: Not started | H18: =COUNTIF('Improvement Plan'!$K$7:$K$23,G18)
A19: High | B19: =COUNTIF('Risk Treatment'!$J$7:$J$21,A19) | D19: Approved | E19: =COUNTIF('AIMS Objectives'!$N$7:$N$14,D19) | G19: Planned | H19: =COUNTIF('Improvement Plan'!$K$7:$K$23,G19)
A20: Medium | B20: =COUNTIF('Risk Treatment'!$J$7:$J$21,A20) | D20: Active | E20: =COUNTIF('AIMS Objectives'!$N$7:$N$14,D20) | G20: In progress | H20: =COUNTIF('Improvement Plan'!$K$7:$K$23,G20)
A21: Low | B21: =COUNTIF('Risk Treatment'!$J$7:$J$21,A21) | D21: At risk | E21: =COUNTIF('AIMS Objectives'!$N$7:$N$14,D21) | G21: Blocked | H21: =COUNTIF('Improvement Plan'!$K$7:$K$23,G21)
D22: Achieved | E22: =COUNTIF('AIMS Objectives'!$N$7:$N$14,D22) | G22: Complete | H22: =COUNTIF('Improvement Plan'!$K$7:$K$23,G22)
D23: Paused | E23: =COUNTIF('AIMS Objectives'!$N$7:$N$14,D23) | G23: Cancelled | H23: =COUNTIF('Improvement Plan'!$K$7:$K$23,G23)
D24: Closed | E24: =COUNTIF('AIMS Objectives'!$N$7:$N$14,D24)
A26: Recommended adoption sequence
A27: 1. Confirm accountable ownership, approval authority and the proposed AIMS scope (AIG-AIMS-01).
A28: 2. Validate the 38 Annex A decisions against the Council’s licensed standard and approve AIG-AIMS-02.
A29: 3. Approve policy, objectives, risk criteria, risk acceptance and the implementation programme.
A30: 4. Establish roles, competence, applicable requirements, inventory completeness and controlled evidence arrangements.
A31: 5. Pilot the full lifecycle, supplier controls and monitoring on representative real AI systems.
A32: 6. Exercise incident and corrective-action processes, then conduct the first internal audit.
A33: 7. Complete management review; update objectives, risks, SoA and improvement priorities from evidence.
A35: Version | B35: Date | C35: Change | G35: Author / owner
A36: 1.0 draft | B36: 46241 | C36: Initial AIMS objectives, risk treatment, opportunities and improvement plan mapped to the AI Governance Playbook (AIG-GOV-02), AIG-AIMS-01 and AIG-AIMS-02. | G36: AI Governance Lead
A37: 1.1 draft | B37: 28 September 2026 | C37: Correct risk-tier boundaries, residual-rating thresholds and objective QA colours.
A38: 1.2 draft | B38: 29 September 2026 | C38: QA remediation — applied findings QA-074, QA-214, QA-218, QA-220, QA-238, QA-240, QA-241, QA-243, QA-251, QA-254, QA-281, QA-284, QA-291 (see QA change log). Residual scoring now uses the Playbook §4.4.3 control-effectiveness factor. | G38: AI Governance Lead

Sheet AIMS Objectives
A1: The Council — AIMS Objectives Register
A2: AIG-AIMS-03 · v1.2 draft · Draft for Council review · OFFICIAL
A3: Purpose: define proposed measurable AIMS objectives, owners, evidence, review arrangements and progress.
A4: Current position: the eight entries are draft management-system objectives. Baselines, targets, dates, resources and approval must be validated before they become Council commitments.
A6: Objective ID | B6: Objective statement | C6: Intended outcome | D6: ISO / SoA links | E6: Related AIMS risks | F6: Measure | G6: Baseline | H6: Proposed target | I6: Target date | J6: Proposed owner | K6: Supporting roles | L6: Review cadence | M6: Evidence source | N6: Status | O6: Current performance | P6: Progress % | Q6: Last reviewed | R6: Decision / next action | S6: Record QA
A7: OBJ-01 | B7: Maintain a complete and current inventory of in-scope AI activity. | C7: Leadership has reliable visibility of every Council AI use, its owner, lifecycle status and governance tier. | D7: ISO 6.2; A.4.2; A.8.5; A.9.2 | E7: R-02, R-03 | F7: Percentage of known in-scope AI systems with a valid AI Register ID, accountable owner, AGPI tier, lifecycle status and review date. | G7: Not established — inventory completeness review required. | H7: Proposed: 100% of known in-scope systems complete; quarterly completeness checks and documented shadow-AI follow-up. | J7: AI Governance Lead | K7: Service Owners; Digital; Data; Procurement; Security; Internal Audit | L7: Monthly during implementation; quarterly when established | M7: AIG-INV-04 AI Register; AIG-OPS-06 Dashboard; completeness-review records | N7: Draft | O7: Not measured | P7: 0 | R7: Approve the metric definition, data owner, completeness-testing method and target date. | S7: =IF(AND(A7<>"",B7<>"",C7<>"",D7<>"",E7<>"",F7<>"",G7<>"",H7<>"",J7<>"",L7<>"",M7<>"",N7<>"",R7<>""),IF(OR(N7="Draft",I7<>""),"Complete","Target date missing"),"Incomplete")
A8: OBJ-02 | B8: Apply proportionate governance and approval before AI deployment or material change. | C8: AI systems progress through traceable, risk-tiered decisions with conditions closed before operational use. | D8: ISO 6.2, 8.1; A.5.2-A.5.5; A.6.2.2-A.6.2.6; A.9.2 | E8: R-01, R-03, R-04 | F8: Percentage of high/critical cases with complete required assessments, authorised decision record and no open critical go-live condition. | G8: Not established — live case baseline required. | H8: Proposed: 100% before go-live or material change; zero operational systems with an unresolved critical approval condition. | J8: AI Governance Lead / Service Owner | K8: Governance bodies; Legal; DPO; Equality; Security; Procurement | L8: At every decision gate; monthly portfolio review | M8: AIG-INV-03, AIG-INV-04, AIG-ASS-01, AIG-ASS-02, AIG-ASS-03, AIG-ASS-04, AIG-ASS-05, AIG-ASS-06, AIG-ASS-07, AIG-ASS-08, AIG-ASS-09, AIG-ASS-10 and AIG-DEC-03; AIG-GOV-06; AIG-OPS-01; governance minutes | N8: Draft | O8: Not measured | P8: 0 | R8: Validate the decision thresholds, exception route, approval authority and reporting frequency. | S8: =IF(AND(A8<>"",B8<>"",C8<>"",D8<>"",E8<>"",F8<>"",G8<>"",H8<>"",J8<>"",L8<>"",M8<>"",N8<>"",R8<>""),IF(OR(N8="Draft",I8<>""),"Complete","Target date missing"),"Incomplete")
A9: OBJ-03 | B9: Identify and manage impacts on residents, staff, communities and protected or vulnerable groups. | C9: Material privacy, equality, human-rights, safeguarding and societal impacts are assessed and treated before approval and monitored in use. | D9: ISO 6.2; A.5.2-A.5.5; A.8.2-A.8.5 | E9: R-06, R-07, R-08, R-13 | F9: Percentage of cases triggering DPIA, Equality Impact Assessment, Human Rights Assessment or Responsible AI Assessment completed, approved and linked to the AI Register. | G9: Not established — assessment population and baseline required. | H9: Proposed: 100% of triggered assessments completed before approval; all material actions assigned and tracked to closure. | J9: Service Owner / AI Governance Lead | K9: DPO; Equality and Human Rights Leads; Legal; Safeguarding; Communications | L9: At intake, before approval and on material change | M9: AIG-ASS-04 to AIG-ASS-07; AIG-DEC-03; AIG-OPS-05; action records | N9: Draft | O9: Not measured | P9: 0 | R9: Confirm assessment triggers, specialist sign-off rules, action ownership and evidence retention. | S9: =IF(AND(A9<>"",B9<>"",C9<>"",D9<>"",E9<>"",F9<>"",G9<>"",H9<>"",J9<>"",L9<>"",M9<>"",N9<>"",R9<>""),IF(OR(N9="Draft",I9<>""),"Complete","Target date missing"),"Incomplete")
A10: OBJ-04 | B10: Assure data, technical, security and operational readiness for production AI. | C10: AI systems operate within approved data, performance, resilience, security and change-control parameters. | D10: ISO 6.2, 8.1; A.4.2-A.4.6; A.6.2.2-A.6.2.8; A.7.2-A.7.6 | E10: R-07, R-10, R-11, R-15 | F10: Percentage of production systems with approved data controls, verification/validation, security review, deployment plan, monitoring thresholds and rollback or exit arrangements. | G10: Not established — production-system baseline required. | H10: Proposed: 100% of production systems meet the applicable readiness set; zero unresolved critical security or validation finding at go-live. | J10: Service Owner / AI Technical Lead | K10: Data Owner; Security; Architecture; Information Governance; Supplier Owner | L10: Before go-live; monthly or risk-based operational review | M10: AIG-ASS-02; AIG-ASS-09; AIG-ASS-11; AIG-OPS-01; test and monitoring evidence | N10: Draft | O10: Not measured | P10: 0 | R10: Agree the minimum readiness set by risk tier and establish evidence owners for each live system. | S10: =IF(AND(A10<>"",B10<>"",C10<>"",D10<>"",E10<>"",F10<>"",G10<>"",H10<>"",J10<>"",L10<>"",M10<>"",N10<>"",R10<>""),IF(OR(N10="Draft",I10<>""),"Complete","Target date missing"),"Incomplete")
A11: OBJ-05 | B11: Provide effective human oversight, transparency, challenge and redress. | C11: People affected by Council AI can understand relevant use, obtain appropriate human consideration and raise concerns safely. | D11: ISO 6.2; A.5.4; A.8.2-A.8.5; A.9.2-A.9.4 | E11: R-08, R-12 | F11: Percentage of applicable systems with tested human-oversight and override arrangements, accessible user information, complaint routes and response monitoring. | G11: Not established — applicability and baseline review required. | H11: Proposed: 100% of applicable systems; all material complaints and oversight failures investigated and actioned within approved timescales. | J11: Service Owner / Communications | K11: AI Governance Lead; Complaints; Legal; Equality; Frontline Teams | L11: Before go-live; quarterly and after material complaint or incident | M11: AIG-ASS-09; AIG-ASS-10; AIG-OPS-05; AIG-OPS-03; user testing and complaint records | N11: Draft | O11: Not measured | P11: 0 | R11: Define applicability, accessibility standards, service-response times and oversight-effectiveness measures. | S11: =IF(AND(A11<>"",B11<>"",C11<>"",D11<>"",E11<>"",F11<>"",G11<>"",H11<>"",J11<>"",L11<>"",M11<>"",N11<>"",R11<>""),IF(OR(N11="Draft",I11<>""),"Complete","Target date missing"),"Incomplete")
A12: OBJ-06 | B12: Control AI supplier, partner and shared-service dependencies. | C12: Third-party AI responsibilities, evidence, change, incident, resilience and exit obligations are understood and enforceable. | D12: ISO 6.2; A.10.2-A.10.4 | E12: R-09, R-10, R-15 | F12: Percentage of material AI suppliers with completed due diligence, approved contractual controls, evidence access, change notification, incident support and exit plan. | G12: Not established — contract and supplier baseline required. | H12: Proposed: 100% before contract, renewal or material change; all critical supplier gaps resolved or formally accepted. | J12: Procurement / Service Owner | K12: Legal; Security; DPO; AI Governance Lead; Commercial and Contract Owners | L12: At procurement, renewal and material supplier change; quarterly portfolio review | M12: AIG-ASS-08; AIG-ASS-11; contracts; supplier review and assurance records | N12: Draft | O12: Not measured | P12: 0 | R12: Confirm the material-supplier population, mandatory clauses, acceptance authority and assurance cadence. | S12: =IF(AND(A12<>"",B12<>"",C12<>"",D12<>"",E12<>"",F12<>"",G12<>"",H12<>"",J12<>"",L12<>"",M12<>"",N12<>"",R12<>""),IF(OR(N12="Draft",I12<>""),"Complete","Target date missing"),"Incomplete")
A13: OBJ-07 | B13: Detect, respond to and learn from AI incidents, concerns, performance deterioration and control failures. | C13: Potential harm is contained promptly and recurring causes drive corrective action and control improvement. | D13: ISO 6.2, 9.1, 10.1-10.2; A.3.3; A.6.2.6-A.6.2.8; A.8.3-A.8.4 | E13: R-11, R-12, R-14 | F13: Percentage of AI incidents and material control exceptions triaged within approved timescale, root-caused where required and closed with effectiveness evidence. | G13: Not established — incident taxonomy and baseline required. | H13: Proposed: 100% triaged within approved severity timescales; 100% material corrective actions tracked to verified closure. | J13: Incident Lead / AI Governance Lead | K13: Service Owners; Security; DPO; Legal; Complaints; Communications | L13: Per incident; monthly trend review; quarterly governance review | M13: AIG-OPS-05; AIG-OPS-06; AIG-OPS-03; incident, action and lessons-learned records | N13: Draft | O13: Not measured | P13: 0 | R13: Align severity, notification, escalation, investigation and effectiveness criteria with Council incident processes. | S13: =IF(AND(A13<>"",B13<>"",C13<>"",D13<>"",E13<>"",F13<>"",G13<>"",H13<>"",J13<>"",L13<>"",M13<>"",N13<>"",R13<>""),IF(OR(N13="Draft",I13<>""),"Complete","Target date missing"),"Incomplete")
A14: OBJ-08 | B14: Establish an effective, competent and continually improving AIMS. | C14: The management system is approved, resourced, audited, reviewed and improved on evidence rather than policy intent alone. | D14: ISO 5-10; A.2.2-A.2.4; A.3.2; A.4.6 | E14: R-01, R-04, R-05, R-13, R-14 | F14: Completion of approved AIMS programme, role-based competence, internal audit, management review and improvement actions by agreed dates. | G14: Design suite exists; operational baseline and effectiveness evidence not established. | H14: Proposed: all governance roles appointed and trained; annual internal audit and management review completed; 100% critical/high actions closed by target or formally escalated. | J14: Executive Sponsor / AI Governance Lead | K14: AI Assurance Board; Internal Audit; HR/L&D; Legal; Risk; all control owners | L14: Monthly implementation review; at least annual audit and management review | M14: AIG-GOV-02; AIG-OPS-05; AIG-OPS-06; AIG-GOV-06; AIG-AIMS-01 to AIG-AIMS-03; audit and review records | N14: Draft | O14: Not measured | P14: 0 | R14: Approve the AIMS programme, resources, competence plan, audit programme and management-review calendar. | S14: =IF(AND(A14<>"",B14<>"",C14<>"",D14<>"",E14<>"",F14<>"",G14<>"",H14<>"",J14<>"",L14<>"",M14<>"",N14<>"",R14<>""),IF(OR(N14="Draft",I14<>""),"Complete","Target date missing"),"Incomplete")

Sheet Risk Treatment
A1: The Council — AIMS Risk Treatment Plan
A2: AIG-AIMS-03 · v1.2 draft · Draft for Council review · OFFICIAL
A3: Purpose: maintain AIMS-level risks, provisional inherent assessment, proposed treatment, ownership, evidence and residual-risk review.
A4: Current position: scores and treatments are a desk-review starting point only. Validate them in a Council risk workshop and do not enter a control-effectiveness (CE) score until treatment implementation and evidence have been reviewed. Residual score = inherent score × CE factor (CE ÷ 5), per Playbook §4.4.3; the effective tier stays at the inherent tier until controls are evidenced, and a reduction from High or Critical also needs independent verification.
A6: Risk ID | B6: Risk scenario | C6: Cause / current gap | D6: Potential consequence | E6: Source | F6: ISO / Annex A links | G6: Inherent likelihood | H6: Inherent impact | I6: Inherent score | J6: Inherent rating | K6: Treatment option | L6: Treatment / control action | M6: Proposed owner | N6: Status | O6: Target date | P6: Control effectiveness (CE 1-5; 1 very strong, 5 ineffective) | Q6: CE factor (CE ÷ 5) | R6: Residual score | S6: Residual rating | T6: Related objective(s) | U6: SoA control links | V6: Evidence / record | W6: Review trigger | X6: Record QA
A7: R-01 | B7: The AIMS remains unapproved or is treated as operational before formal adoption. | C7: Scope, policy, authority, objectives and control decisions are still draft. | D7: Unclear accountability, inconsistent decisions, unsupported conformity claims and inability to demonstrate effective governance. | E7: Suite QA; AIG-AIMS-01 and AIG-AIMS-02 draft status | F7: ISO 4.4, 5.1-5.3, 6.2; A.2.2-A.2.4 | G7: 4 | H7: 5 | I7: =IF(OR(G7="",H7=""),"",G7*H7) | J7: =IF(I7="","",IF(I7>=16,"Critical",IF(I7>=11,"High",IF(I7>=6,"Medium","Low")))) | K7: Modify | L7: Confirm adopting authority and accountable owner; approve scope, policy, objectives, risk criteria and SoA; communicate effective date and transition plan. | M7: Executive Sponsor / AI Governance Lead | N7: Treatment planned | Q7: =IF(P7="","",P7/5) | R7: =IF(OR(I7="",Q7=""),"",I7*Q7) | S7: =IF(R7="","",IF(R7>15,"Critical",IF(R7>10,"High",IF(R7>5,"Medium","Low")))) | T7: OBJ-02, OBJ-08 | U7: A.2.2-A.2.4; A.3.2 | V7: Approval, communication and controlled-document records | W7: Change in leadership, delegations, scope or certification intent | X7: =IF(AND(A7<>"",B7<>"",C7<>"",D7<>"",E7<>"",F7<>"",G7<>"",H7<>"",K7<>"",L7<>"",M7<>"",N7<>"",T7<>"",U7<>"",W7<>""),"Complete","Incomplete")
A8: R-02 | B8: AI activity is omitted from the inventory, including embedded, pilot, supplier or shadow AI. | C8: Distributed ownership and inconsistent discovery, registration and procurement triggers. | D8: Unassessed systems may process data or affect services without ownership, controls, monitoring or approval. | E8: AIG-AIMS-01 internal context; inventory completeness not evidenced | F8: ISO 4.1, 6.1, 8.1; A.4.2; A.9.2 | G8: 4 | H8: 5 | I8: =IF(OR(G8="",H8=""),"",G8*H8) | J8: =IF(I8="","",IF(I8>=16,"Critical",IF(I8>=11,"High",IF(I8>=6,"Medium","Low")))) | K8: Modify | L8: Run a Council-wide inventory baseline and shadow-AI campaign; integrate registration triggers into procurement, digital delivery, security and data processes; test completeness periodically. | M8: AI Governance Lead / Service Owners | N8: Treatment planned | Q8: =IF(P8="","",P8/5) | R8: =IF(OR(I8="",Q8=""),"",I8*Q8) | S8: =IF(R8="","",IF(R8>15,"Critical",IF(R8>10,"High",IF(R8>5,"Medium","Low")))) | T8: OBJ-01 | U8: A.4.2; A.8.5; A.9.2 | V8: AI Register, discovery results, reconciliation and exception records | W8: New service, procurement, embedded feature or audit finding | X8: =IF(AND(A8<>"",B8<>"",C8<>"",D8<>"",E8<>"",F8<>"",G8<>"",H8<>"",K8<>"",L8<>"",M8<>"",N8<>"",T8<>"",U8<>"",W8<>""),"Complete","Incomplete")
A9: R-03 | B9: Governance evidence and decisions become fragmented across boards, tools and lifecycle stages. | C9: Multiple approval interfaces and inconsistent use of a single AI Register ID and evidence links. | D9: Conditions, actions or material facts may be lost, duplicated or contradicted, allowing premature deployment or weak auditability. | E9: AIG-AIMS-01 distributed ownership/evidence context | F9: ISO 7.5, 8.1, 9.1; A.6.2.3; A.8.5 | G9: 4 | H9: 4 | I9: =IF(OR(G9="",H9=""),"",G9*H9) | J9: =IF(I9="","",IF(I9>=16,"Critical",IF(I9>=11,"High",IF(I9>=6,"Medium","Low")))) | K9: Modify | L9: Mandate one AI Register ID, controlled decision record and evidence index across all gates; define hand-offs, action closure and register-update accountability. | M9: AI Governance Lead / Governance Secretariat | N9: Treatment planned | Q9: =IF(P9="","",P9/5) | R9: =IF(OR(I9="",Q9=""),"",I9*Q9) | S9: =IF(R9="","",IF(R9>15,"Critical",IF(R9>10,"High",IF(R9>5,"Medium","Low")))) | T9: OBJ-01, OBJ-02 | U9: A.3.2; A.6.2.3; A.8.5 | V9: Register audit trail, decision records, minutes and evidence links | W9: Any gate transfer, ownership change, material condition or audit exception | X9: =IF(AND(A9<>"",B9<>"",C9<>"",D9<>"",E9<>"",F9<>"",G9<>"",H9<>"",K9<>"",L9<>"",M9<>"",N9<>"",T9<>"",U9<>"",W9<>""),"Complete","Incomplete")
A10: R-04 | B10: Roles, delegations or approval authorities are unclear or conflict with Council governance. | C10: Proposed governance bodies and responsibilities have not been formally appointed and aligned to delegations. | D10: Decisions may lack authority; specialist accountability may be bypassed; escalation and ownership may fail. | E10: AIG-GOV-06 and AIG-AIMS-01 adoption decisions pending | F10: ISO 5.3, 7.1; A.3.2 | G10: 3 | H10: 5 | I10: =IF(OR(G10="",H10=""),"",G10*H10) | J10: =IF(I10="","",IF(I10>=16,"Critical",IF(I10>=11,"High",IF(I10>=6,"Medium","Low")))) | K10: Modify | L10: Approve Terms of Reference, delegations, membership, deputies, conflicts process and RACI interfaces; retain appointment and decision-authority evidence. | M10: Executive Sponsor / Monitoring Officer | N10: Treatment planned | Q10: =IF(P10="","",P10/5) | R10: =IF(OR(I10="",Q10=""),"",I10*Q10) | S10: =IF(R10="","",IF(R10>15,"Critical",IF(R10>10,"High",IF(R10>5,"Medium","Low")))) | T10: OBJ-02, OBJ-08 | U10: A.3.2; A.10.2 | V10: Approved governance documents, appointments and delegations | W10: Organisational restructure, delegation change or disputed decision | X10: =IF(AND(A10<>"",B10<>"",C10<>"",D10<>"",E10<>"",F10<>"",G10<>"",H10<>"",K10<>"",L10<>"",M10<>"",N10<>"",T10<>"",U10<>"",W10<>""),"Complete","Incomplete")
A11: R-05 | B11: Insufficient competence or capacity causes inconsistent AI governance and control operation. | C11: Variable AI literacy and limited specialist capacity across services and assurance functions. | D11: Risk signals may be missed, documentation may be poor and governance may create delay or unsafe shortcuts. | E11: AIG-AIMS-01 capability and capacity issue | F11: ISO 7.1-7.3; A.4.6 | G11: 4 | H11: 4 | I11: =IF(OR(G11="",H11=""),"",G11*H11) | J11: =IF(I11="","",IF(I11>=16,"Critical",IF(I11>=11,"High",IF(I11>=6,"Medium","Low")))) | K11: Modify | L11: Complete role-to-competence mapping, resource plan, role-based training and effectiveness checks; establish specialist escalation and succession arrangements. | M11: AI Governance Lead / HR-L&D | N11: Treatment planned | Q11: =IF(P11="","",P11/5) | R11: =IF(OR(I11="",Q11=""),"",I11*Q11) | S11: =IF(R11="","",IF(R11>15,"Critical",IF(R11>10,"High",IF(R11>5,"Medium","Low")))) | T11: OBJ-08 | U11: A.3.2; A.4.6 | V11: Competence matrix, training records, assessments and resource decisions | W11: New role, control failure, audit finding or material workload change | X11: =IF(AND(A11<>"",B11<>"",C11<>"",D11<>"",E11<>"",F11<>"",G11<>"",H11<>"",K11<>"",L11<>"",M11<>"",N11<>"",T11<>"",U11<>"",W11<>""),"Complete","Incomplete")
A12: R-06 | B12: Material impacts on people or communities are not identified or treated before use. | C12: Impact assessment triggers, participation and specialist reviews are not consistently applied to live cases. | D12: Unfair, unlawful, inaccessible or harmful outcomes and weakened public trust or legal defensibility. | E12: AIG-ASS-04 to AIG-ASS-07 are controlled templates; live application not yet evidenced | F12: ISO 6.1, 8.1; A.5.2-A.5.5 | G12: 3 | H12: 5 | I12: =IF(OR(G12="",H12=""),"",G12*H12) | J12: =IF(I12="","",IF(I12>=16,"Critical",IF(I12>=11,"High",IF(I12>=6,"Medium","Low")))) | K12: Modify | L12: Validate assessment triggers; complete and approve assessments for priority systems; engage affected groups proportionately; track mitigations and residual-risk acceptance. | M12: Service Owner / AI Governance Lead | N12: Treatment planned | Q12: =IF(P12="","",P12/5) | R12: =IF(OR(I12="",Q12=""),"",I12*Q12) | S12: =IF(R12="","",IF(R12>15,"Critical",IF(R12>10,"High",IF(R12>5,"Medium","Low")))) | T12: OBJ-03 | U12: A.5.2-A.5.5; A.8.3-A.8.5 | V12: Approved assessments, engagement, decisions and action closure | W12: New affected group, complaint, material change or adverse outcome | X12: =IF(AND(A12<>"",B12<>"",C12<>"",D12<>"",E12<>"",F12<>"",G12<>"",H12<>"",K12<>"",L12<>"",M12<>"",N12<>"",T12<>"",U12<>"",W12<>""),"Complete","Incomplete")
A13: R-07 | B13: Poor data quality, provenance, representativeness or preparation undermines AI outcomes. | C13: System-level data controls and evidence have not been validated across live systems. | D13: Inaccurate, biased or unreliable outputs; inability to reproduce decisions or investigate incidents. | E13: AIG-ASS-02, AIG-ASS-05 and AIG-ASS-09 design controls; operational evidence required | F13: ISO 6.1, 8.1; A.7.2-A.7.6 | G13: 4 | H13: 4 | I13: =IF(OR(G13="",H13=""),"",G13*H13) | J13: =IF(I13="","",IF(I13>=16,"Critical",IF(I13>=11,"High",IF(I13>=6,"Medium","Low")))) | K13: Modify | L13: Create dataset inventories and data-management plans; set measurable quality and representativeness criteria; retain provenance, preparation, approval and monitoring evidence. | M13: Data Owner / Service Owner | N13: Treatment planned | Q13: =IF(P13="","",P13/5) | R13: =IF(OR(I13="",Q13=""),"",I13*Q13) | S13: =IF(R13="","",IF(R13>15,"Critical",IF(R13>10,"High",IF(R13>5,"Medium","Low")))) | T13: OBJ-03, OBJ-04 | U13: A.4.3; A.7.2-A.7.6 | V13: Dataset records, tests, lineage, exceptions and monitoring | W13: Dataset, purpose, population, supplier or preparation change | X13: =IF(AND(A13<>"",B13<>"",C13<>"",D13<>"",E13<>"",F13<>"",G13<>"",H13<>"",K13<>"",L13<>"",M13<>"",N13<>"",T13<>"",U13<>"",W13<>""),"Complete","Incomplete")
A14: R-08 | B14: Human oversight, transparency, challenge or redress is ineffective. | C14: Oversight design, instructions and public information may be generic or untested. | D14: People may be unable to understand, contest or correct AI-supported decisions; harmful automation bias may persist. | E14: AIG-ASS-09, AIG-ASS-10 and AIG-OPS-03 require live validation | F14: ISO 6.1, 8.1; A.5.4; A.8.2-A.8.5; A.9.2-A.9.4 | G14: 3 | H14: 5 | I14: =IF(OR(G14="",H14=""),"",G14*H14) | J14: =IF(I14="","",IF(I14>=16,"Critical",IF(I14>=11,"High",IF(I14>=6,"Medium","Low")))) | K14: Modify | L14: Define and test oversight, pause/override and escalation; publish accessible information; integrate complaints and redress; monitor oversight use and effectiveness. | M14: Service Owner / Communications | N14: Treatment planned | Q14: =IF(P14="","",P14/5) | R14: =IF(OR(I14="",Q14=""),"",I14*Q14) | S14: =IF(R14="","",IF(R14>15,"Critical",IF(R14>10,"High",IF(R14>5,"Medium","Low")))) | T14: OBJ-03, OBJ-05 | U14: A.5.4; A.8.2-A.8.5; A.9.2-A.9.4 | V14: User tests, oversight logs, complaints, decisions and corrections | W14: Complaint, override failure, user research or material service change | X14: =IF(AND(A14<>"",B14<>"",C14<>"",D14<>"",E14<>"",F14<>"",G14<>"",H14<>"",K14<>"",L14<>"",M14<>"",N14<>"",T14<>"",U14<>"",W14<>""),"Complete","Incomplete")
A15: R-09 | B15: Supplier or partner dependencies are accepted without sufficient assurance or enforceable obligations. | C15: Due diligence, contracts and evidence access have not been tested consistently on material live suppliers. | D15: Hidden model/data risks, unnotified change, delayed incident support, lock-in or ineffective exit. | E15: AIG-ASS-08 and AIG-ASS-11 design controls; supplier baseline required | F15: ISO 6.1, 8.1; A.10.2-A.10.4 | G15: 4 | H15: 4 | I15: =IF(OR(G15="",H15=""),"",G15*H15) | J15: =IF(I15="","",IF(I15>=16,"Critical",IF(I15>=11,"High",IF(I15>=6,"Medium","Low")))) | K15: Modify | L15: Baseline material suppliers; apply due diligence and mandatory contract controls; set review cadence, evidence rights, change/incident notification, resilience and exit obligations. | M15: Procurement / Service Owner | N15: Treatment planned | Q15: =IF(P15="","",P15/5) | R15: =IF(OR(I15="",Q15=""),"",I15*Q15) | S15: =IF(R15="","",IF(R15>15,"Critical",IF(R15>10,"High",IF(R15>5,"Medium","Low")))) | T15: OBJ-06 | U15: A.10.2-A.10.4; A.4.4-A.4.5 | V15: Due diligence, contracts, assurance reviews and exit tests | W15: Procurement, renewal, supplier change, incident or performance failure | X15: =IF(AND(A15<>"",B15<>"",C15<>"",D15<>"",E15<>"",F15<>"",G15<>"",H15<>"",K15<>"",L15<>"",M15<>"",N15<>"",T15<>"",U15<>"",W15<>""),"Complete","Incomplete")
A16: R-10 | B16: AI security, privacy or misuse controls are inadequate for the system and threat context. | C16: AI-specific threat modelling, access, logging and supplier controls are not evidenced for all priority systems. | D16: Data leakage, manipulation, unauthorised use, service disruption, compromised outputs or regulatory breach. | E16: AIG-ASS-11 controlled checklist; live security evidence required | F16: ISO 6.1, 8.1; A.4.4-A.4.5; A.6.2.4-A.6.2.8 | G16: 3 | H16: 5 | I16: =IF(OR(G16="",H16=""),"",G16*H16) | J16: =IF(I16="","",IF(I16>=16,"Critical",IF(I16>=11,"High",IF(I16>=6,"Medium","Low")))) | K16: Modify | L16: Perform risk-tiered security and privacy reviews; define technical controls, abuse testing, logging, vulnerability handling and go-live closure criteria. | M16: Security Lead / Service Owner | N16: Treatment planned | Q16: =IF(P16="","",P16/5) | R16: =IF(OR(I16="",Q16=""),"",I16*Q16) | S16: =IF(R16="","",IF(R16>15,"Critical",IF(R16>10,"High",IF(R16>5,"Medium","Low")))) | T16: OBJ-04, OBJ-06 | U16: A.4.4-A.4.5; A.6.2.4-A.6.2.8; A.10.3 | V16: Threat model, test results, security decision and monitoring | W16: Threat, vulnerability, architecture, model or hosting change | X16: =IF(AND(A16<>"",B16<>"",C16<>"",D16<>"",E16<>"",F16<>"",G16<>"",H16<>"",K16<>"",L16<>"",M16<>"",N16<>"",T16<>"",U16<>"",W16<>""),"Complete","Incomplete")
A17: R-11 | B17: Performance deterioration, drift or material change is not detected and reassessed. | C17: Operational thresholds, ownership and material-change triggers are not yet operating across the portfolio. | D17: Systems may remain in use outside approved performance, risk, purpose or data conditions. | E17: AIG-OPS-05, AIG-OPS-06 and AIG-OPS-01 require live monitoring records | F17: ISO 8.1, 9.1; A.6.2.6-A.6.2.8 | G17: 4 | H17: 4 | I17: =IF(OR(G17="",H17=""),"",G17*H17) | J17: =IF(I17="","",IF(I17>=16,"Critical",IF(I17>=11,"High",IF(I17>=6,"Medium","Low")))) | K17: Modify | L17: Approve system monitoring plans and thresholds; assign review owners; connect alerts and material changes to pause, investigation, reapproval and register update. | M17: System Owner / Service Owner | N17: Treatment planned | Q17: =IF(P17="","",P17/5) | R17: =IF(OR(I17="",Q17=""),"",I17*Q17) | S17: =IF(R17="","",IF(R17>15,"Critical",IF(R17>10,"High",IF(R17>5,"Medium","Low")))) | T17: OBJ-04, OBJ-07 | U17: A.6.2.6-A.6.2.8; A.8.4 | V17: Monitoring logs, alerts, reviews, changes and reapproval | W17: Threshold breach, drift, supplier update or scope change | X17: =IF(AND(A17<>"",B17<>"",C17<>"",D17<>"",E17<>"",F17<>"",G17<>"",H17<>"",K17<>"",L17<>"",M17<>"",N17<>"",T17<>"",U17<>"",W17<>""),"Complete","Incomplete")
A18: R-12 | B18: AI incidents, complaints or concerns are not escalated, investigated or converted into corrective action. | C18: Reporting routes and incident workflow have not been exercised end to end. | D18: Continuing harm, missed notification, repeated failures and loss of trust or learning. | E18: AIG-OPS-03 design form; exercise and live records required | F18: ISO 7.4, 10.1-10.2; A.3.3; A.8.3-A.8.4 | G18: 3 | H18: 5 | I18: =IF(OR(G18="",H18=""),"",G18*H18) | J18: =IF(I18="","",IF(I18>=16,"Critical",IF(I18>=11,"High",IF(I18>=6,"Medium","Low")))) | K18: Modify | L18: Align incident taxonomy and routes; run a tabletop exercise; confirm authority, communications and notifications; track root cause, corrective action and effectiveness. | M18: Incident Lead / AI Governance Lead | N18: Treatment planned | Q18: =IF(P18="","",P18/5) | R18: =IF(OR(I18="",Q18=""),"",I18*Q18) | S18: =IF(R18="","",IF(R18>15,"Critical",IF(R18>10,"High",IF(R18>5,"Medium","Low")))) | T18: OBJ-05, OBJ-07 | U18: A.3.3; A.8.3-A.8.4 | V18: Exercise report, incident records, actions and effectiveness checks | W18: Incident, complaint, near miss, control failure or external report | X18: =IF(AND(A18<>"",B18<>"",C18<>"",D18<>"",E18<>"",F18<>"",G18<>"",H18<>"",K18<>"",L18<>"",M18<>"",N18<>"",T18<>"",U18<>"",W18<>""),"Complete","Incomplete")
... A21: R-15 | B21: AI systems or supplier dependencies are retired or exited without controlled records, continuity or data handling. | C21: Retirement, archival, replacement and supplier-exit controls are not evidenced across real systems. | D21: Service disruption, retained access/data, lost audit trail, unmanaged dependency or re-emergence of retired use. | E21: AIG-OPS-01 deployment and live-control design; exit evidence required | F21: ISO 8.1; A.4.2-A.4.5; A.6.2.3; A.10.2-A.10.3 | G21: 3 | H21: 4 | I21: =IF(OR(G21="",H21=""),"",G21*H21) | J21: =IF(I21="","",IF(I21>=16,"Critical",IF(I21>=11,"High",IF(I21>=6,"Medium","Low")))) | K21: Modify | L21: Define decommissioning and exit criteria; revoke access, manage data/records, update the AI Register, validate replacement/continuity and retain closure evidence. | M21: Service Owner / Technology Owner | N21: Treatment planned | Q21: =IF(P21="","",P21/5) | R21: =IF(OR(I21="",Q21=""),"",I21*Q21) | S21: =IF(R21="","",IF(R21>15,"Critical",IF(R21>10,"High",IF(R21>5,"Medium","Low")))) | T21: OBJ-04, OBJ-06 | U21: A.4.2-A.4.5; A.6.2.3; A.10.2-A.10.3 | V21: Retirement plan, access/data closure, register and contract records | W21: Retirement decision, supplier exit, replacement or service transfer | X21: =IF(AND(A21<>"",B21<>"",C21<>"",D21<>"",E21<>"",F21<>"",G21<>"",H21<>"",K21<>"",L21<>"",M21<>"",N21<>"",T21<>"",U21<>"",W21<>""),"Complete","Incomplete")

Sheet Opportunities
A1: The Council — AIMS Opportunities Register
A2: AIG-AIMS-03 · v1.2 draft · Draft for Council review · OFFICIAL
A3: Purpose: record opportunities that can improve AIMS effectiveness, efficiency, integration and public value.
A4: Current position: these opportunities are proposed for evaluation. Benefits, resources, owners and dates must be approved before commitment.
A6: Opportunity ID | B6: Opportunity | C6: Expected benefit | D6: Enablement / action | E6: Related objective(s) | F6: ISO / SoA links | G6: Proposed owner | H6: Priority | I6: Status | J6: Target date | K6: Evidence / indicator | L6: Review trigger | M6: Record QA
A7: OPP-01 | B7: Use one AI Register ID as the continuous governance thread across every lifecycle stage and board. | C7: Less fragmentation, faster evidence retrieval, clearer ownership and safer hand-offs. | D7: Mandate the identifier in intake, assessments, contracts, decision records, deployment, monitoring, incidents and reporting; test completeness. | E7: OBJ-01, OBJ-02 | F7: ISO 6.1, 7.5, 8.1 | G7: AI Governance Lead | H7: High | I7: Proposed | K7: Cross-artefact linkage rate; missing-link exceptions; audit retrieval time | L7: Pilot completion, register change or governance-interface review | M7: =IF(AND(A7<>"",B7<>"",C7<>"",D7<>"",E7<>"",F7<>"",G7<>"",H7<>"",I7<>"",K7<>"",L7<>""),"Complete","Incomplete")
A8: OPP-02 | B8: Integrate AIMS controls into existing digital, data, procurement, security, legal and service-management processes. | C8: Reduced duplication, earlier specialist involvement and a governance route that teams can use in practice. | D8: Map control triggers and hand-offs into existing methods, gates and systems; retain specialist authority and measure cycle time and rework. | E8: OBJ-02, OBJ-08 | F8: ISO 4.4, 8.1 | G8: Executive Sponsor / AI Governance Lead | H8: High | I8: Proposed | K8: Process integration map; cycle time; late-review exceptions; stakeholder feedback | L8: Process redesign, audit finding or repeated delay | M8: =IF(AND(A8<>"",B8<>"",C8<>"",D8<>"",E8<>"",F8<>"",G8<>"",H8<>"",I8<>"",K8<>"",L8<>""),"Complete","Incomplete")
A9: OPP-03 | B9: Turn the AI Register and dashboard into an evidence-led portfolio view. | C9: Earlier identification of systemic risk, trends, capacity constraints and improvement priorities. | D9: Define data-quality rules and automated or controlled feeds for risk, status, incidents, actions, assurance, training and benefits. | E9: OBJ-01, OBJ-07, OBJ-08 | F9: ISO 9.1-9.3 | G9: AI Governance Lead / Data Owner | H9: Medium | I9: Proposed | K9: Dashboard completeness, timeliness, exception rate and decisions supported | L9: Reporting cycle, data-quality failure or management review | M9: =IF(AND(A9<>"",B9<>"",C9<>"",D9<>"",E9<>"",F9<>"",G9<>"",H9<>"",I9<>"",K9<>"",L9<>""),"Complete","Incomplete")
A10: OPP-04 | B10: Create reusable supplier assurance patterns and evidence requirements. | C10: More consistent procurement decisions, stronger leverage, less duplicated review and better exit readiness. | D10: Develop risk-tiered clauses, evidence packs, review cadence and exception routes using AIG-ASS-08 and AIG-ASS-11; pilot on material procurements. | E10: OBJ-06 | F10: ISO 8.1; A.10.2-A.10.4 | G10: Procurement / Legal Services | H10: High | I10: Proposed | K10: Supplier review completion, clause exceptions, assurance findings and renewal outcomes | L10: Procurement pipeline, renewal, material supplier change or incident | M10: =IF(AND(A10<>"",B10<>"",C10<>"",D10<>"",E10<>"",F10<>"",G10<>"",H10<>"",I10<>"",K10<>"",L10<>""),"Complete","Incomplete")
A11: OPP-05 | B11: Use transparent governance and accessible engagement to strengthen resident and staff trust. | C11: Better service design, earlier discovery of unintended impacts and more defensible public decisions. | D11: Build user research, affected-group engagement, transparency and feedback into high-impact cases and monitor resulting changes. | E11: OBJ-03, OBJ-05 | F11: ISO 4.2, 6.1, 9.1; A.5.4; A.8.2-A.8.5 | G11: Service Owner / Communications | H11: Medium | I11: Proposed | K11: Engagement coverage, accessibility findings, complaints, trust feedback and design changes | L11: New high-impact case, complaint trend or public-interest concern | M11: =IF(AND(A11<>"",B11<>"",C11<>"",D11<>"",E11<>"",F11<>"",G11<>"",H11<>"",I11<>"",K11<>"",L11<>""),"Complete","Incomplete")

Sheet Improvement Plan
A1: The Council — AIMS Improvement and Implementation Plan
A2: AIG-AIMS-03 · v1.2 draft · Draft for Council review · OFFICIAL
A3: Purpose: control the actions required to move the AIMS from documented design to approved, operating and evidenced practice.
A4: Current position: all actions are proposed; none has started (IMP-17 is planned). Council governance must confirm sequencing, owners, resources, target dates, dependencies and acceptance evidence.
A6: Action ID | B6: Improvement / implementation action | C6: Rationale / source | D6: Related risk(s) | E6: Related objective(s) | F6: ISO / SoA links | G6: Acceptance criteria / evidence | H6: Proposed owner | I6: Supporting roles | J6: Priority | K6: Status | L6: Planned start | M6: Target completion | N6: Progress % | O6: Dependency | P6: Evidence location | Q6: Closure validation | R6: Last reviewed | S6: RAG | T6: Record QA
A7: IMP-01 | B7: Confirm the senior accountable owner, adopting authority and formal AIMS scope. | C7: AIG-AIMS-01 adoption decisions remain pending. | D7: R-01, R-04 | E7: OBJ-08 | F7: ISO 4.3-4.4, 5.1-5.3 | G7: Approved AIG-AIMS-01; named accountable owner; approval evidence; effective date and communicated boundary. | H7: Executive Sponsor | I7: AI Governance Lead; Monitoring Officer; Legal | J7: Critical | K7: Not started | N7: 0 | O7: Council delegations and governance route confirmed | S7: =IF(A7="","",IF(K7="Cancelled","Grey",IF(K7="Complete",IF(T7="Complete","Green","Amber"),IF(OR(K7="Blocked",AND(ISNUMBER(M7),M7<TODAY())),"Red",IF(OR(K7="In progress",AND(ISNUMBER(M7),M7-TODAY()<=30)),"Amber",IF(K7="Planned","Blue","Grey")))))) | T7: =IF(AND(A7<>"",B7<>"",C7<>"",D7<>"",E7<>"",F7<>"",G7<>"",H7<>"",J7<>"",K7<>"",O7<>""),IF(K7="Complete",IF(AND(P7<>"",Q7<>""),"Complete","Closure evidence missing"),IF(OR(K7="Not started",M7<>""),"Complete","Target date missing")),"Incomplete")
A8: IMP-02 | B8: Validate and approve all Statement of Applicability decisions. | C8: AIG-AIMS-02 contains 38 proposed applicable controls but no operational evidence. | D8: R-01, R-14 | E8: OBJ-08 | F8: ISO 6.1; Annex A | G8: Licensed-standard validation; approved applicability and owners; justified exclusions if any; controlled approval record. | H8: AI Governance Lead | I8: Control Owners; Legal; Internal Audit | J8: Critical | K8: Not started | N8: 0 | O8: IMP-01 and approved risk criteria | S8: =IF(A8="","",IF(K8="Cancelled","Grey",IF(K8="Complete",IF(T8="Complete","Green","Amber"),IF(OR(K8="Blocked",AND(ISNUMBER(M8),M8<TODAY())),"Red",IF(OR(K8="In progress",AND(ISNUMBER(M8),M8-TODAY()<=30)),"Amber",IF(K8="Planned","Blue","Grey")))))) | T8: =IF(AND(A8<>"",B8<>"",C8<>"",D8<>"",E8<>"",F8<>"",G8<>"",H8<>"",J8<>"",K8<>"",O8<>""),IF(K8="Complete",IF(AND(P8<>"",Q8<>""),"Complete","Closure evidence missing"),IF(OR(K8="Not started",M8<>""),"Complete","Target date missing")),"Incomplete")
A9: IMP-03 | B9: Approve the AI policy, AIMS objectives, risk criteria and acceptance authority. | C9: Policy and measurable management-system objectives require leadership approval and resources. | D9: R-01, R-04 | E9: OBJ-01 to OBJ-08 | F9: ISO 5.2, 6.1-6.2 | G9: Approved policy and objectives; baselines, targets, owners, dates, reporting cadence and risk-acceptance authority recorded. | H9: Executive Sponsor / AI Assurance Board | I9: AI Governance Lead; Risk; Finance; Service Owners | J9: Critical | K9: Not started | N9: 0 | O9: IMP-01; strategic and resource decisions | S9: =IF(A9="","",IF(K9="Cancelled","Grey",IF(K9="Complete",IF(T9="Complete","Green","Amber"),IF(OR(K9="Blocked",AND(ISNUMBER(M9),M9<TODAY())),"Red",IF(OR(K9="In progress",AND(ISNUMBER(M9),M9-TODAY()<=30)),"Amber",IF(K9="Planned","Blue","Grey")))))) | T9: =IF(AND(A9<>"",B9<>"",C9<>"",D9<>"",E9<>"",F9<>"",G9<>"",H9<>"",J9<>"",K9<>"",O9<>""),IF(K9="Complete",IF(AND(P9<>"",Q9<>""),"Complete","Closure evidence missing"),IF(OR(K9="Not started",M9<>""),"Complete","Target date missing")),"Incomplete")
A10: IMP-04 | B10: Establish the controlled AIMS applicable-requirements and change register. | C10: AIG-AIMS-01 requires a validated obligations record. | D10: R-13 | E10: OBJ-03, OBJ-08 | F10: ISO 4.2, 6.1, 9.1; A.2.3 | G10: Requirements have authoritative source, owner, applicability, affected process/control, review date, change status and evidence. | H10: Legal Services / AI Governance Lead | I10: DPO; IG; Equality; Procurement; Security | J10: High | K10: Not started | N10: 0 | O10: IMP-01 and confirmed scope | S10: =IF(A10="","",IF(K10="Cancelled","Grey",IF(K10="Complete",IF(T10="Complete","Green","Amber"),IF(OR(K10="Blocked",AND(ISNUMBER(M10),M10<TODAY())),"Red",IF(OR(K10="In progress",AND(ISNUMBER(M10),M10-TODAY()<=30)),"Amber",IF(K10="Planned","Blue","Grey")))))) | T10: =IF(AND(A10<>"",B10<>"",C10<>"",D10<>"",E10<>"",F10<>"",G10<>"",H10<>"",J10<>"",K10<>"",O10<>""),IF(K10="Complete",IF(AND(P10<>"",Q10<>""),"Complete","Closure evidence missing"),IF(OR(K10="Not started",M10<>""),"Complete","Target date missing")),"Incomplete")
A11: IMP-05 | B11: Approve governance Terms of Reference, delegations, RACI and competence/resource plan. | C11: Proposed governance bodies and roles need formal authority and capability. | D11: R-04, R-05 | E11: OBJ-02, OBJ-08 | F11: ISO 5.3, 7.1-7.3; A.3.2; A.4.6 | G11: Approved roles, membership, deputies, conflicts, delegations and escalation; competence matrix and resourcing decisions retained. | H11: Executive Sponsor / AI Governance Lead | I11: HR-L&D; Monitoring Officer; Governance Bodies | J11: Critical | K11: Not started | N11: 0 | O11: IMP-01 and organisational design | S11: =IF(A11="","",IF(K11="Cancelled","Grey",IF(K11="Complete",IF(T11="Complete","Green","Amber"),IF(OR(K11="Blocked",AND(ISNUMBER(M11),M11<TODAY())),"Red",IF(OR(K11="In progress",AND(ISNUMBER(M11),M11-TODAY()<=30)),"Amber",IF(K11="Planned","Blue","Grey")))))) | T11: =IF(AND(A11<>"",B11<>"",C11<>"",D11<>"",E11<>"",F11<>"",G11<>"",H11<>"",J11<>"",K11<>"",O11<>""),IF(K11="Complete",IF(AND(P11<>"",Q11<>""),"Complete","Closure evidence missing"),IF(OR(K11="Not started",M11<>""),"Complete","Target date missing")),"Incomplete")
A12: IMP-06 | B12: Complete an AI inventory baseline and shadow-AI discovery campaign. | C12: Inventory completeness has not been evidenced. | D12: R-02, R-03 | E12: OBJ-01 | F12: ISO 6.1, 8.1; A.4.2; A.9.2 | G12: Directorate attestations, procurement and technology reconciliations, discovered cases registered/contained, completeness result and actions approved. | H12: AI Governance Lead | I12: Service Owners; Digital; Procurement; Security; Data | J12: Critical | K12: Not started | N12: 0 | O12: IMP-05 roles and communications | S12: =IF(A12="","",IF(K12="Cancelled","Grey",IF(K12="Complete",IF(T12="Complete","Green","Amber"),IF(OR(K12="Blocked",AND(ISNUMBER(M12),M12<TODAY())),"Red",IF(OR(K12="In progress",AND(ISNUMBER(M12),M12-TODAY()<=30)),"Amber",IF(K12="Planned","Blue","Grey")))))) | T12: =IF(AND(A12<>"",B12<>"",C12<>"",D12<>"",E12<>"",F12<>"",G12<>"",H12<>"",J12<>"",K12<>"",O12<>""),IF(K12="Complete",IF(AND(P12<>"",Q12<>""),"Complete","Closure evidence missing"),IF(OR(K12="Not started",M12<>""),"Complete","Target date missing")),"Incomplete")
A13: IMP-07 | B13: Pilot the complete governance lifecycle on representative real AI cases. | C13: Controlled templates require operational validation and process learning. | D13: R-03, R-06, R-10 | E13: OBJ-02, OBJ-03, OBJ-04 | F13: ISO 8.1; Annex A lifecycle controls | G13: At least three cases spanning different risk tiers follow intake through decision and live/closure status; timing, rework, gaps and user feedback recorded. | H13: AI Governance Lead / Service Owners | I13: All applicable control functions and governance bodies | J13: High | K13: Not started | N13: 0 | O13: IMP-03 to IMP-06; suitable live cases | S13: =IF(A13="","",IF(K13="Cancelled","Grey",IF(K13="Complete",IF(T13="Complete","Green","Amber"),IF(OR(K13="Blocked",AND(ISNUMBER(M13),M13<TODAY())),"Red",IF(OR(K13="In progress",AND(ISNUMBER(M13),M13-TODAY()<=30)),"Amber",IF(K13="Planned","Blue","Grey")))))) | T13: =IF(AND(A13<>"",B13<>"",C13<>"",D13<>"",E13<>"",F13<>"",G13<>"",H13<>"",J13<>"",K13<>"",O13<>""),IF(K13="Complete",IF(AND(P13<>"",Q13<>""),"Complete","Closure evidence missing"),IF(OR(K13="Not started",M13<>""),"Complete","Target date missing")),"Incomplete")
A14: IMP-08 | B14: Implement a controlled AIMS evidence repository, document-control and retention structure. | C14: Design documents exist, but live evidence locations and retention controls are not populated. | D14: R-03, R-14, R-15 | E14: OBJ-01, OBJ-08 | F14: ISO 7.5, 9.1-9.3, 10.2 | G14: Approved taxonomy, access, versioning, retention, disposal and evidence-index rules; sampled records retrievable by AI Register ID and control. | H14: AI Governance Lead / Information Governance | I14: Records Management; Security; Control Owners | J14: High | K14: Not started | N14: 0 | O14: IMP-01 and corporate records requirements | S14: =IF(A14="","",IF(K14="Cancelled","Grey",IF(K14="Complete",IF(T14="Complete","Green","Amber"),IF(OR(K14="Blocked",AND(ISNUMBER(M14),M14<TODAY())),"Red",IF(OR(K14="In progress",AND(ISNUMBER(M14),M14-TODAY()<=30)),"Amber",IF(K14="Planned","Blue","Grey")))))) | T14: =IF(AND(A14<>"",B14<>"",C14<>"",D14<>"",E14<>"",F14<>"",G14<>"",H14<>"",J14<>"",K14<>"",O14<>""),IF(K14="Complete",IF(AND(P14<>"",Q14<>""),"Complete","Closure evidence missing"),IF(OR(K14="Not started",M14<>""),"Complete","Target date missing")),"Incomplete")
A15: IMP-09 | B15: Deliver role-based AI governance training and verify competence. | C15: Capability and capacity are material implementation risks. | D15: R-05 | E15: OBJ-08 | F15: ISO 7.2-7.3; A.4.6 | G15: Target populations and competencies defined; training completed; assessment/effectiveness results and remedial actions retained. | H15: AI Governance Lead / HR-L&D | I15: Service Owners; Specialist Control Functions | J15: High | K15: Not started | N15: 0 | O15: IMP-05 competence matrix and resource plan | S15: =IF(A15="","",IF(K15="Cancelled","Grey",IF(K15="Complete",IF(T15="Complete","Green","Amber"),IF(OR(K15="Blocked",AND(ISNUMBER(M15),M15<TODAY())),"Red",IF(OR(K15="In progress",AND(ISNUMBER(M15),M15-TODAY()<=30)),"Amber",IF(K15="Planned","Blue","Grey")))))) | T15: =IF(AND(A15<>"",B15<>"",C15<>"",D15<>"",E15<>"",F15<>"",G15<>"",H15<>"",J15<>"",K15<>"",O15<>""),IF(K15="Complete",IF(AND(P15<>"",Q15<>""),"Complete","Closure evidence missing"),IF(OR(K15="Not started",M15<>""),"Complete","Target date missing")),"Incomplete")
A16: IMP-10 | B16: Apply supplier due diligence and contract controls to material live procurements or renewals. | C16: Supplier controls need operational proof and refinement. | D16: R-09, R-10, R-15 | E16: OBJ-06 | F16: ISO 8.1; A.10.2-A.10.4 | G16: At least two material supplier cases evidence due diligence, risk-tiered terms, exceptions, assurance rights, change/incident duties and exit arrangements. | H16: Procurement / Service Owners | I16: Legal; Security; DPO; AI Governance Lead | J16: High | K16: Not started | N16: 0 | O16: Procurement pipeline and IMP-04 requirements | S16: =IF(A16="","",IF(K16="Cancelled","Grey",IF(K16="Complete",IF(T16="Complete","Green","Amber"),IF(OR(K16="Blocked",AND(ISNUMBER(M16),M16<TODAY())),"Red",IF(OR(K16="In progress",AND(ISNUMBER(M16),M16-TODAY()<=30)),"Amber",IF(K16="Planned","Blue","Grey")))))) | T16: =IF(AND(A16<>"",B16<>"",C16<>"",D16<>"",E16<>"",F16<>"",G16<>"",H16<>"",J16<>"",K16<>"",O16<>""),IF(K16="Complete",IF(AND(P16<>"",Q16<>""),"Complete","Closure evidence missing"),IF(OR(K16="Not started",M16<>""),"Complete","Target date missing")),"Incomplete")
A17: IMP-11 | B17: Complete live impact, data, security and technical assurance for priority systems. | C17: System-level evidence is needed to move controls beyond designed status. | D17: R-06, R-07, R-08, R-10 | E17: OBJ-03, OBJ-04, OBJ-05 | F17: ISO 8.1; A.5-A.9 | G17: Priority systems have approved assessments, data plans, test results, security decisions, oversight/transparency controls and action closure. | H17: Service Owners | I17: DPO; Equality; Human Rights; Data; Security; Technical Reviewers | J17: High | K17: Not started | N17: 0 | O17: IMP-06 inventory and risk prioritisation | S17: =IF(A17="","",IF(K17="Cancelled","Grey",IF(K17="Complete",IF(T17="Complete","Green","Amber"),IF(OR(K17="Blocked",AND(ISNUMBER(M17),M17<TODAY())),"Red",IF(OR(K17="In progress",AND(ISNUMBER(M17),M17-TODAY()<=30)),"Amber",IF(K17="Planned","Blue","Grey")))))) | T17: =IF(AND(A17<>"",B17<>"",C17<>"",D17<>"",E17<>"",F17<>"",G17<>"",H17<>"",J17<>"",K17<>"",O17<>""),IF(K17="Complete",IF(AND(P17<>"",Q17<>""),"Complete","Closure evidence missing"),IF(OR(K17="Not started",M17<>""),"Complete","Target date missing")),"Incomplete")
A18: IMP-12 | B18: Establish operational monitoring plans and AI dashboard data-quality rules. | C18: Monitoring and dashboard artefacts require owners, thresholds and reliable live data. | D18: R-11, R-14 | E18: OBJ-01, OBJ-04, OBJ-07 | F18: ISO 9.1; A.6.2.6-A.6.2.8 | G18: Live systems have approved measures, thresholds, owners, review cadence and change triggers; dashboard fields reconcile to source evidence. | H18: AI Governance Lead / System Owners | I18: Data Owner; Service Managers; Assurance Functions | J18: High | K18: Not started | N18: 0 | O18: IMP-06 inventory and IMP-11 system assurance | S18: =IF(A18="","",IF(K18="Cancelled","Grey",IF(K18="Complete",IF(T18="Complete","Green","Amber"),IF(OR(K18="Blocked",AND(ISNUMBER(M18),M18<TODAY())),"Red",IF(OR(K18="In progress",AND(ISNUMBER(M18),M18-TODAY()<=30)),"Amber",IF(K18="Planned","Blue","Grey")))))) | T18: =IF(AND(A18<>"",B18<>"",C18<>"",D18<>"",E18<>"",F18<>"",G18<>"",H18<>"",J18<>"",K18<>"",O18<>""),IF(K18="Complete",IF(AND(P18<>"",Q18<>""),"Complete","Closure evidence missing"),IF(OR(K18="Not started",M18<>""),"Complete","Target date missing")),"Incomplete")
... A22: IMP-16 | B22: Validate controlled retirement, decommissioning, archival and supplier-exit arrangements. | C22: Lifecycle closure controls need evidence from real or simulated cases. | D22: R-15 | E22: OBJ-04, OBJ-06 | F22: ISO 8.1; A.4.2-A.4.5; A.6.2.3; A.10.2-A.10.3 | G22: At least one retirement or exit test confirms decision, continuity, access revocation, data/records treatment, contract closure and AI Register status. | H22: Service Owner / Technology Owner | I22: Procurement; IG; Security; Data; AI Governance Lead | J22: Medium | K22: Not started | N22: 0 | O22: Suitable system or controlled simulation | S22: =IF(A22="","",IF(K22="Cancelled","Grey",IF(K22="Complete",IF(T22="Complete","Green","Amber"),IF(OR(K22="Blocked",AND(ISNUMBER(M22),M22<TODAY())),"Red",IF(OR(K22="In progress",AND(ISNUMBER(M22),M22-TODAY()<=30)),"Amber",IF(K22="Planned","Blue","Grey")))))) | T22: =IF(AND(A22<>"",B22<>"",C22<>"",D22<>"",E22<>"",F22<>"",G22<>"",H22<>"",J22<>"",K22<>"",O22<>""),IF(K22="Complete",IF(AND(P22<>"",Q22<>""),"Complete","Closure evidence missing"),IF(OR(K22="Not started",M22<>""),"Complete","Target date missing")),"Incomplete")
A23: IMP-17 | B23: Societal impact assessment (ISO/IEC 42001 A.5.5): add a societal-impact prompt to the Responsible AI Assessment (AIG-ASS-04) and assess societal impacts for priority AI uses. | C23: AIG-AIMS-11 known limitation: societal impacts (A.5.5) are not yet assessed explicitly for each use. | D23: R-06 | E23: OBJ-03 | F23: ISO 6.1.4, 8.4; A.5.5 | G23: Societal-impact prompt approved in AIG-ASS-04; priority uses assessed for societal impacts with outcomes and treatment recorded; A.5.5 entry in AIG-AIMS-02 updated. | H23: AI Governance Lead | I23: Service Owners; Equality; Human Rights; Legal; Communities | J23: Medium | K23: Planned | L23: 46391 | M23: 46477 | N23: 0 | O23: IMP-11 system assurance; AIG-AIMS-11 coverage mapping | S23: =IF(A23="","",IF(K23="Cancelled","Grey",IF(K23="Complete",IF(T23="Complete","Green","Amber"),IF(OR(K23="Blocked",AND(ISNUMBER(M23),M23<TODAY())),"Red",IF(OR(K23="In progress",AND(ISNUMBER(M23),M23-TODAY()<=30)),"Amber",IF(K23="Planned","Blue","Grey")))))) | T23: =IF(AND(A23<>"",B23<>"",C23<>"",D23<>"",E23<>"",F23<>"",G23<>"",H23<>"",J23<>"",K23<>"",O23<>""),IF(K23="Complete",IF(AND(P23<>"",Q23<>""),"Complete","Closure evidence missing"),IF(OR(K23="Not started",M23<>""),"Complete","Target date missing")),"Incomplete")

Sheet Lists & Guidance
A1: AIG-AIMS-03 — Status Definitions, Risk Matrix and Use Guidance
A3: Objective status | B3: Meaning | D3: Risk status | E3: Meaning | G3: Action status | H3: Meaning
A4: Draft | B4: Proposed objective; not yet approved as a Council commitment. | D4: Draft assessment | E4: Risk description or scoring awaits validation. | G4: Not started | H4: Action is proposed and not authorised or scheduled.
A5: Approved | B5: Objective, owner, measure, baseline, target, resources and date are authorised. | D5: Open | E5: Risk is confirmed and requires a decision or treatment. | G5: Planned | H5: Owner and target date are confirmed.
A6: Active | B6: The objective is being pursued and monitored. | D6: Treatment planned | E6: Treatment is selected but not yet operating. | G6: In progress | H6: Work is actively under way.
A7: At risk | B7: Evidence indicates the target may not be met without intervention. | D7: In progress | E7: Treatment action is under way. | G7: Blocked | H7: A dependency or decision prevents progress and requires escalation.
A8: Achieved | B8: The target is met and supporting evidence has been reviewed. | D8: Accepted | E8: Authorised risk owner has accepted residual risk with review conditions. | G8: Complete | H8: Acceptance criteria, evidence and independent closure validation are complete.
A9: Paused | B9: Progress is formally paused with reason, authority and review date. | D9: Monitoring | E9: Treatment is operating and residual risk/effectiveness is under review. | G9: Cancelled | H9: Action is withdrawn through an authorised, recorded decision.
A10: Closed | B10: Objective is retired or replaced through an approved decision. | D10: Closed | E10: Risk no longer applies or is controlled within approved criteria, with evidence.
A12: Risk scoring matrix — likelihood × impact | G12: Rating | H12: Score
A13: Likelihood / Impact | B13: 1 | C13: 2 | D13: 3 | E13: 4 | F13: 5 | G13: Low | H13: 1-5
A14: 1 | B14: 1 | C14: 2 | D14: 3 | E14: 4 | F14: 5 | G14: Medium | H14: 6-10
A15: 2 | B15: 2 | C15: 4 | D15: 6 | E15: 8 | F15: 10 | G15: High | H15: 11-15
A16: 3 | B16: 3 | C16: 6 | D16: 9 | E16: 12 | F16: 15 | G16: Critical | H16: 16-25
A17: 4 | B17: 4 | C17: 8 | D17: 12 | E17: 16 | F17: 20
A18: 5 | B18: 5 | C18: 10 | D18: 15 | E18: 20 | F18: 25
A20: Likelihood scale
A21: 1 | B21: Rare | C21: Unlikely except in exceptional circumstances — Council to validate criteria.
A22: 2 | B22: Unlikely | C22: Could occur but is not expected — Council to validate criteria.
A23: 3 | B23: Possible | C23: Might occur during the planning horizon — Council to validate criteria.
A24: 4 | B24: Likely | C24: Expected to occur in several circumstances — Council to validate criteria.
A25: 5 | B25: Almost certain | C25: Expected frequently or already evident — Council to validate criteria.
A27: Impact scale
A28: 1 | B28: Minimal | C28: Limited effect; routine local correction — Council to validate criteria.
A29: 2 | B29: Minor | C29: Contained disruption or reversible limited impact — Council to validate criteria.
A30: 3 | B30: Moderate | C30: Material service, legal, financial or trust impact — Council to validate criteria.
A31: 4 | B31: Major | C31: Serious or widespread impact requiring senior response — Council to validate criteria.
A32: 5 | B32: Severe | C32: Potential grave, systemic or irreversible harm — Council to validate criteria.
A34: Decision and evidence rules
A35: • This workbook is an AIMS-level control document; system-specific risks remain in AIG-ASS-02 and link back through the AI Register ID.
A36: • Objective approval requires a baseline, target, owner, resources, target date, monitoring method and evidence source.
A37: • Inherent scores are provisional desk-review judgements. Validate them against the Council’s adopted corporate risk criteria.
